<mujoco model="piplus">
  <compiler angle="radian" meshdir="./assets/meshes/"/>
  <default>
    <default class="pi_joint_arm">
      <joint damping="0.66" actuatorfrcrange="-10 10" armature="0.01317" frictionloss="0.2"/>
      <!-- damping = 10Nm / (155rpm - 10 rpm (in rad/s)) -->
    </default>
    <default class="pi_joint_leg">
      <joint damping="1.5" actuatorfrcrange="-20 20" armature="0.01316"/>
      <!--<joint damping="2.94" actuatorfrcrange="-20 20" armature="0.01316" frictionloss="0.2"/>-->
      <!-- damping = 20Nm / (75rpm - 10 rpm (in rad/s)) -->
    </default>
    <default class="pi_joint_head">
      <joint damping="0.48" actuatorfrcrange="-2.5 2.5" armature="0.00249" frictionloss="0.1"/>
      <!-- damping = 2.5Nm / (60rpm - 10 rpm (in rad/s))-->
    </default>
    <default class="pi_actuator_arm">
      <!-- ctrllimited is false because policies should be able to set values outside the ranges to reach torques required -->
      <position kp="30" kv="0.6" forcerange="-10 10" ctrllimited="false"/>
    </default>
    <default class="pi_actuator_leg">
      <position kp="30" kv="1.1" forcerange="-20 20" ctrllimited="false"/>
    </default>
    <default class="pi_actuator_head">
      <position kp="6" kv="0.6" forcerange="-2.5 2.5" ctrllimited="false"/>
    </default>
    <default class="collision">
      <geom group="3" contype="1" conaffinity="1"/>
    </default>
    <default class="visual">
      <geom contype="0" conaffinity="0" group="2" density="0"/>
    </default>
  </default>

  <asset>
    <mesh name="base_link" file="base_link.STL"/>
    <mesh name="torso_link" file="torso_link.STL"/>
    <mesh name="torso_link_simplify" file="torso_link_simplify.STL"/>
    <mesh name="r_shoulder_pitch_link" file="r_shoulder_pitch_link.STL"/>
    <mesh name="r_shoulder_pitch_link_simplify" file="r_shoulder_pitch_link_simplify.STL"/>
    <mesh name="r_shoulder_roll_link" file="r_shoulder_roll_link.STL"/>
    <mesh name="r_upper_arm_link" file="r_upper_arm_link.STL"/>
    <mesh name="r_elbow_link" file="r_elbow_link.STL"/>
    <mesh name="r_wrist_link" file="r_wrist_link.STL"/>
    <mesh name="l_shoulder_pitch_link" file="l_shoulder_pitch_link.STL"/>
    <mesh name="l_shoulder_pitch_link_simplify" file="l_shoulder_pitch_link_simplify.STL"/>
    <mesh name="l_shoulder_roll_link" file="l_shoulder_roll_link.STL"/>
    <mesh name="l_upper_arm_link" file="l_upper_arm_link.STL"/>
    <mesh name="l_elbow_link" file="l_elbow_link.STL"/>
    <mesh name="l_wrist_link" file="l_wrist_link.STL"/>
    <mesh name="head_yaw_link" file="head_yaw_link.STL"/>
    <mesh name="head_yaw_link_simplify" file="head_yaw_link_simplify.STL"/>
    <mesh name="head_pitch_link" file="head_pitch_link.STL"/>
    <mesh name="camera_link" file="camera_link.STL"/>
    <mesh name="r_hip_pitch_link" file="r_hip_pitch_link.STL"/>
    <mesh name="r_hip_roll_link" file="r_hip_roll_link.STL"/>
    <mesh name="r_thigh_link" file="r_thigh_link.STL"/>
    <mesh name="r_calf_link" file="r_calf_link.STL"/>
    <mesh name="r_calf_link_simplify" file="r_calf_link_simplify.STL"/>
    <mesh name="r_ankle_pitch_link" file="r_ankle_pitch_link.STL"/>
    <mesh name="r_ankle_roll_link" file="r_ankle_roll_link.STL"/>
    <mesh name="r_ankle_roll_link_simplify" file="r_ankle_roll_link_simplify.STL"/>
    <mesh name="l_hip_pitch_link" file="l_hip_pitch_link.STL"/>
    <mesh name="l_hip_roll_link" file="l_hip_roll_link.STL"/>
    <mesh name="l_thigh_link" file="l_thigh_link.STL"/>
    <mesh name="l_calf_link" file="l_calf_link.STL"/>
    <mesh name="l_calf_link_simplify" file="l_calf_link_simplify.STL"/>
    <mesh name="l_ankle_pitch_link" file="l_ankle_pitch_link.STL"/>
    <mesh name="l_ankle_roll_link" file="l_ankle_roll_link.STL"/>
    <mesh name="l_ankle_roll_link_simplify" file="l_ankle_roll_link_simplify.STL"/>
  </asset>

  <worldbody>
    <body name="base_link" pos="0 0 0.385">
      <joint name="floating_base_joint" type="free" limited="false" actuatorfrclimited="false"/>
      <site name="imu"/>
      <camera name="front" pos="1.210 -0.435 0.32" xyaxes="0.342 0.940 0.000 -0.321 0.117 0.940" mode="trackcom"/>
      <camera name="track" pos="0.805 -1.105 0.2" xyaxes="0.814 0.580 0.000 -0.140 0.196 0.971" mode="trackcom"/>

      <inertial pos="-0.00041617 7.079e-05 -0.0392999" quat="0.707016 0.706374 -0.0255218 0.0226693" mass="1.4947" diaginertia="0.00182015 0.00167434 0.00111607"/>
      <geom type="mesh" class="visual" rgba="0.752941 0.752941 0.752941 1" mesh="base_link"/>
      <geom name="base_link_collision0" class="collision" pos="0 0 -0.045" type="box" size="0.025 0.035 0.025"/>
      <body name="torso_link">
        <inertial pos="0.00153764 -3.179e-05 0.0959554" quat="0.705415 0.708147 0.0225102 -0.0202894" mass="2.82494" diaginertia="0.0159234 0.0140664 0.0134032"/>
        <geom type="mesh" class="visual" rgba="0.752941 0.752941 0.752941 1" mesh="torso_link"/>
        <geom name="torso_link_collision0" class="collision" pos="0 0 0.09" type="box" size="0.0775 0.0775 0.0775"/>
        <body name="r_shoulder_pitch_link" pos="0 -0.1084 0.117">
          <inertial pos="-0.0023165 -0.0172048 0.00020825" quat="-0.034283 0.706989 0.0142854 0.706249" mass="0.139352" diaginertia="0.000145208 0.000122162 7.54598e-05"/>
          <joint name="r_shoulder_pitch_joint" class="pi_joint_arm" pos="0 0 0" axis="0 -1 0" ref="1.5708" range="-2.55 2.55"/>
          <geom type="mesh" class="visual" rgba="0.752941 0.752941 0.752941 1" mesh="r_shoulder_pitch_link"/>
          <body name="r_shoulder_roll_link" pos="0 -0.038 0">
            <inertial pos="-0.00164862 -0.00020989 -0.024888" quat="0.692267 -0.0208066 -0.015904 0.721166" mass="0.55615" diaginertia="0.000521636 0.000513996 0.000152408"/>
            <joint name="r_shoulder_roll_joint" class="pi_joint_arm" pos="0 0 0" axis="1 0 0" ref="1.5708" range="-1.65 1.4"/>
            <geom type="mesh" class="visual" rgba="0.752941 0.752941 0.752941 1" mesh="r_shoulder_roll_link"/>
            <body name="r_upper_arm_link" pos="0 0 -0.0724">
              <inertial pos="3.107e-05 -0.00138646 -0.0121349" quat="0.619141 0.785272 -0.00344701 0.000473666" mass="0.153183" diaginertia="0.000177072 0.000143883 0.000111845"/>
              <joint name="r_upper_arm_joint" class="pi_joint_arm" pos="0 0 0" axis="0 0 -1" range="-2.55 2.55"/>
              <geom type="mesh" class="visual" rgba="0.752941 0.752941 0.752941 1" mesh="r_upper_arm_link"/>
              <geom name="r_upper_arm_link_collision0" class="collision" pos="0 0 0.025" type="cylinder" size="0.035 0.0475"/>
              <body name="r_elbow_link" pos="0 0 -0.038">
                <inertial pos="5.69e-05 -0.00308341 -0.00211549" quat="0.671089 0.741218 0.0118416 -0.00978532" mass="0.313175" diaginertia="0.000107759 9.78655e-05 9.33151e-05"/>
                <joint name="r_elbow_joint" class="pi_joint_arm" pos="0 0 0" axis="0 -1 0" range="-1.8 2.04"/>
                <geom type="mesh" class="visual" rgba="0.752941 0.752941 0.752941 1" mesh="r_elbow_link"/>
                <body name="r_wrist_link" pos="0 0 -0.029">
                  <inertial pos="3.045e-05 4.83e-06 -0.0407825" quat="0.707163 -0.000330349 -0.00046236 0.70705" mass="0.0751806" diaginertia="0.00011823 0.00011809 1.10499e-05"/>
                  <geom type="mesh" class="visual" rgba="0.752941 0.752941 0.752941 1" mesh="r_wrist_link"/>
                  <geom name="r_wrist_link_collision0" class="collision" pos="0 0 -0.035" type="cylinder" size="0.008 0.015"/>
                  <geom name="r_wrist_link_collision1" class="collision" pos="0 0 -0.095" type="sphere" size="0.0175"/>
                </body>
              </body>
            </body>
          </body>
        </body>
        <body name="l_shoulder_pitch_link" pos="0 0.1084 0.11698">
          <inertial pos="-0.00215543 0.0172048 0.00022511" quat="0.0355111 0.707216 -0.0147967 0.70595" mass="0.139352" diaginertia="0.00014525 0.000122217 7.54432e-05"/>
          <joint name="l_shoulder_pitch_joint" class="pi_joint_arm" pos="0 0 0" axis="0 1 0" ref="-1.5708" range="-2.55 2.55"/>
          <geom type="mesh" class="visual" rgba="0.752941 0.752941 0.752941 1" mesh="l_shoulder_pitch_link"/>
          <body name="l_shoulder_roll_link" pos="0 0.038 0">
            <inertial pos="-0.00140359 0.00022205 -0.024888" quat="0.658223 -0.023097 -0.0218074 0.752153" mass="0.55615" diaginertia="0.000522159 0.000514351 0.00015235"/>
            <joint name="l_shoulder_roll_joint" class="pi_joint_arm" pos="0 0 0" axis="1 0 0" ref="-1.5708" range="-1.4 1.65"/>
            <geom type="mesh" class="visual" rgba="0.752941 0.752941 0.752941 1" mesh="l_shoulder_roll_link"/>
            <body name="l_upper_arm_link" pos="0 0 -0.0724">
              <inertial pos="-0.00013535 0.00129534 -0.0121342" quat="0.786804 0.617162 -0.00567645 0.00431653" mass="0.153183" diaginertia="0.000177157 0.000144033 0.00011178"/>
              <joint name="l_upper_arm_joint" class="pi_joint_arm" pos="0 0 0" axis="0 0 -1" range="-2.55 2.55"/>
              <geom type="mesh" class="visual" rgba="0.752941 0.752941 0.752941 1" mesh="l_upper_arm_link"/>
              <geom name="l_upper_arm_link_collision0" class="collision" pos="0 0 0.025" type="cylinder" size="0.035 0.0475"/>
              <body name="l_elbow_link" pos="0 0 -0.038">
                <inertial pos="-5.422e-05 0.00312726 -0.00211549" quat="0.705312 0.708745 -0.00907225 0.0115636" mass="0.313175" diaginertia="0.000107669 9.77316e-05 9.33597e-05"/>
                <joint name="l_elbow_joint" class="pi_joint_arm" pos="0 0 0" axis="0 1 0" range="-2.04 1.8"/>
                <geom type="mesh" class="visual" rgba="0.752941 0.752941 0.752941 1" mesh="l_elbow_link"/>
                <body name="l_wrist_link" pos="0 0 -0.029">
                  <inertial pos="3.045e-05 4.83e-06 -0.0407825" quat="0.707163 -0.000330349 -0.00046236 0.70705" mass="0.0751806" diaginertia="0.00011823 0.00011809 1.10499e-05"/>
                  <geom type="mesh" class="visual" rgba="0.752941 0.752941 0.752941 1" mesh="l_wrist_link"/>
                  <geom name="l_wrist_link_collision0" class="collision" pos="0 0 -0.035" type="cylinder" size="0.008 0.015"/>
                  <geom name="l_wrist_link_collision1" class="collision" pos="0 0 -0.095" type="sphere" size="0.0175"/>
                </body>
              </body>
            </body>
          </body>
        </body>
        <body name="head_yaw_link" pos="0.014 -0.00026667 0.1981">
          <inertial pos="6.097e-05 0.00133898 0.0240816" quat="0.998747 -0.0440354 -0.0231093 -0.00560078" mass="0.209663" diaginertia="5.60112e-05 5.44082e-05 5.07706e-05"/>
          <joint name="head_yaw_joint" class="pi_joint_head" pos="0 0 0" axis="0 0 1" range="-1.43 1.43"/>
          <geom type="mesh" class="visual" rgba="0.752941 0.752941 0.752941 1" mesh="head_yaw_link"/>
          <geom name="head_yaw_link_collision0" class="collision" pos="0 0 0.0195" type="box" size="0.0175 0.02 0.0175"/>
          <body name="head_pitch_link" pos="0 0 0.0275">
            <inertial pos="0.0266546 -0.00167129 0.0555251" quat="0.453472 0.464811 -0.534731 0.540719" mass="0.33297" diaginertia="0.00102166 0.000807505 0.000557328"/>
            <joint name="head_pitch_joint" class="pi_joint_head" pos="0 0 0" axis="0 1 0" range="-1.23 1.01"/>
            <geom type="mesh" class="visual" rgba="0.752941 0.752941 0.752941 1" mesh="head_pitch_link"/>
            <geom name="head_pitch_link_collision0" class="collision" pos="0.026 0 0.055" type="box" size="0.05 0.055 0.0225"/>
            <body name="camera_link" pos="0.048925 0.0053519 0.058472">
              <inertial pos="0.00963743 0.00075253 0.00058537" quat="0.70738 0.706786 0.00245222 0.00788061" mass="0.0584" diaginertia="7.26043e-05 7.249e-05 5.51563e-06"/>
              <geom type="mesh" class="visual" rgba="0.752941 0.752941 0.752941 1" mesh="camera_link"/>
              <camera name="head_camera" focalpixel="362.6533508300781 362.6533508300781" resolution="672 376" sensorsize="672 376" pos="0.03 0.024 0.0" xyaxes="0.0 -1.0 0.0 0.5 0.0 0.866"/>
            </body>
          </body>
        </body>
      </body>
      <body name="r_hip_pitch_link" pos="0 -0.0475 -0.0435">
        <inertial pos="7.92e-05 -0.0319026 9.097e-05" quat="0.428329 0.522509 -0.486869 0.553604" mass="0.459314" diaginertia="0.000279632 0.000271753 0.000264745"/>
        <joint name="r_hip_pitch_joint" class="pi_joint_leg" pos="0 0 0" axis="0 -1 0" range="-2.84 2.84"/>
        <geom type="mesh" class="visual" rgba="0.752941 0.752941 0.752941 1" mesh="r_hip_pitch_link"/>
        <body name="r_hip_roll_link" pos="0 -0.034 0">
          <inertial pos="0.00102172 -0.00033797 -0.0584583" quat="0.701595 0.0555068 0.0565269 0.708158" mass="0.558201" diaginertia="0.000740261 0.000626564 0.000407515"/>
          <joint name="r_hip_roll_joint" class="pi_joint_leg" pos="0 0 0" axis="1 0 0" range="-3.1 0.15"/>
          <geom type="mesh" class="visual" rgba="0.752941 0.752941 0.752941 1" mesh="r_hip_roll_link"/>
          <body name="r_thigh_link" pos="-0.00035 0 -0.0974">
            <inertial pos="0.00064557 -0.00075206 -0.0208405" quat="0.703792 0.710207 0.0135977 -0.00990732" mass="0.154843" diaginertia="0.000187812 0.000161216 0.000100573"/>
            <joint name="r_thigh_joint" class="pi_joint_leg" pos="0 0 0" axis="0 0 -1" range="-2.77 2.45"/>
            <geom type="mesh" class="visual" rgba="0.752941 0.752941 0.752941 1" mesh="r_thigh_link"/>
            <geom name="r_thigh_link_collision0" class="collision" pos="0 0 0.065" type="cylinder" size="0.035 0.0275"/>
            <body name="r_calf_link" pos="0 0 -0.045">
              <inertial pos="-1.001e-05 -0.00237049 -0.0666124" quat="0.999998 -0.000800274 0.00132271 -0.000965395" mass="0.858523" diaginertia="0.00416944 0.00414653 0.000429274"/>
              <joint name="r_calf_joint" class="pi_joint_leg" pos="0 0 0" axis="0 1 0" range="-1.97 2.21"/>
              <geom type="mesh" class="visual" rgba="0.752941 0.752941 0.752941 1" mesh="r_calf_link"/>
              <geom name="r_calf_link_collision0" class="collision" pos="0 0 0" type="box" size="0.0275 0.0275 0.0275"/>
              <geom name="r_calf_link_collision1" class="collision" pos="0 0 -0.065" type="box" size="0.005 0.01 0.0275"/>
              <body name="r_ankle_pitch_link" pos="0 0 -0.14">
                <inertial pos="0.00503044 0.00051345 -0.00016685" quat="-0.00108772 0.710445 -0.00435661 0.703738" mass="0.163526" diaginertia="0.00028931 0.000208237 0.000115362"/>
                <joint name="r_ankle_pitch_joint" class="pi_joint_leg" pos="0 0 0" axis="0 -1 0" range="-0.95 0.85"/>
                <geom type="mesh" class="visual" rgba="0.752941 0.752941 0.752941 1" mesh="r_ankle_pitch_link"/>
                <geom name="r_ankle_pitch_link_collision0" class="collision" pos="0.0035 0 0" type="box" size="0.035 0.035 0.021"/>
                <body name="r_ankle_roll_link" pos="0.051 0 0">
                  <site name="r_foot" pos="-0.05 0 -0.05"/>
                  <inertial pos="0.0046213 8.211e-05 -0.015021" quat="0.563454 0.425204 0.421185 0.569494" mass="0.616626" diaginertia="0.00150793 0.00140979 0.000471117"/>
                  <joint name="r_ankle_roll_joint" class="pi_joint_leg" pos="0 0 0" axis="1 0 0" range="-0.72 0.72"/>
                  <geom type="mesh" class="visual" rgba="0.752941 0.752941 0.752941 1" mesh="r_ankle_roll_link"/>
                  <geom name="r_ankle_roll_link_collision0" class="collision" pos="0.028 0 0" type="box" size="0.03 0.03 0.021"/>
                  <geom name="r_ankle_roll_link_collision1" class="collision" pos="-0.017 -0.025 -0.04" quat="0.7071 0 0.7071 0" type="capsule" size="0.01 0.065"/>
                  <geom name="r_ankle_roll_link_collision2" class="collision" pos="-0.0272 -0.009 -0.04" quat="0.7071 0 -0.7071 0" type="capsule" size="0.01 0.082"/>
                  <geom name="r_ankle_roll_link_collision3" class="collision" pos="-0.0272 0.009 -0.04" quat="0.7071 0 -0.7071 0" type="capsule" size="0.01 0.082"/>
                  <geom name="r_ankle_roll_link_collision4" class="collision" pos="-0.017 0.025 -0.04" quat="0.7071 0 0.7071 0" type="capsule" size="0.01 0.065"/>
                </body>
              </body>
            </body>
          </body>
        </body>
      </body>
      <body name="l_hip_pitch_link" pos="0 0.0475 -0.0435">
        <inertial pos="7.921e-05 0.0319025 -0.0001562" quat="0.497171 0.489511 -0.578693 0.422273" mass="0.459318" diaginertia="0.000279904 0.000271819 0.000264407"/>
        <joint name="l_hip_pitch_joint" class="pi_joint_leg" pos="0 0 0" axis="0 1 0" range="-2.84 2.84"/>
        <geom type="mesh" class="visual" rgba="0.752941 0.752941 0.752941 1" mesh="l_hip_pitch_link"/>
        <body name="l_hip_roll_link" pos="0 0.034 0">
          <inertial pos="0.00087873 1.341e-05 -0.0584583" quat="0.702052 0.056967 0.0602688 0.70728" mass="0.558201" diaginertia="0.000740475 0.000627166 0.00040724"/>
          <joint name="l_hip_roll_joint" class="pi_joint_leg" pos="0 0 0" axis="1 0 0" range="-0.15 3.1"/>
          <geom type="mesh" class="visual" rgba="0.752941 0.752941 0.752941 1" mesh="l_hip_roll_link"/>
          <body name="l_thigh_link" pos="-0.00035 0 -0.0974">
            <inertial pos="0.00071587 0.00075215 -0.0208406" quat="0.710169 0.70371 0.0141108 -0.015948" mass="0.154842" diaginertia="0.000187829 0.000161177 0.000100564"/>
            <joint name="l_thigh_joint" class="pi_joint_leg" pos="0 0 0" axis="0 0 -1" range="-2.77 2.45"/>
            <geom type="mesh" class="visual" rgba="0.752941 0.752941 0.752941 1" mesh="l_thigh_link"/>
            <geom name="l_thigh_link_collision0" class="collision" pos="0 0 0.065" type="cylinder" size="0.035 0.0275"/>
            <body name="l_calf_link" pos="0 0 -0.045">
              <inertial pos="-1.001e-05 0.00237048 -0.0666125" quat="0.999997 0.000796813 -0.00130207 0.00164731" mass="0.858523" diaginertia="0.00416944 0.00414652 0.000429275"/>
              <joint name="l_calf_joint" class="pi_joint_leg" pos="0 0 0" axis="0 -1 0" range="-2.21 1.97"/>
              <geom type="mesh" class="visual" rgba="0.752941 0.752941 0.752941 1" mesh="l_calf_link"/>
              <geom name="l_calf_link_collision0" class="collision" pos="0 0 0" type="box" size="0.0275 0.0275 0.0275"/>
              <geom name="l_calf_link_collision1" class="collision" pos="0 0 -0.065" type="box" size="0.005 0.01 0.0275"/>
              <body name="l_ankle_pitch_link" pos="0 0 -0.14">
                <inertial pos="0.00503044 -0.00051345 -0.00016685" quat="0.00108772 0.710445 0.00435661 0.703738" mass="0.163526" diaginertia="0.00028931 0.000208237 0.000115362"/>
                <joint name="l_ankle_pitch_joint" class="pi_joint_leg" pos="0 0 0" axis="0 1 0" range="-0.85 0.95"/>
                <geom type="mesh" class="visual" rgba="0.752941 0.752941 0.752941 1" mesh="l_ankle_pitch_link"/>
                <geom name="l_ankle_pitch_link_collision0" class="collision" pos="0.0035 0 0" type="box" size="0.035 0.035 0.021"/>
                <body name="l_ankle_roll_link" pos="0.051 0 0">
                  <site name="l_foot" pos="-0.05 0 -0.05"/>
                  <inertial pos="0.00456214 8.211e-05 -0.0125654" quat="0.563454 0.425204 0.421185 0.569494" mass="0.616626" diaginertia="0.00150793 0.00140979 0.000471117"/>
                  <joint name="l_ankle_roll_joint" class="pi_joint_leg" pos="0 0 0" axis="1 0 0" range="-0.72 0.72"/>
                  <geom type="mesh" class="visual" rgba="0.752941 0.752941 0.752941 1" mesh="l_ankle_roll_link"/>
                  <geom name="l_ankle_roll_link_collision0" class="collision" pos="0.028 0 0" type="box" size="0.03 0.03 0.021"/>
                  <geom name="l_ankle_roll_link_collision1" class="collision" pos="-0.017 -0.025 -0.04" quat="0.7071 0 0.7071 0" type="capsule" size="0.01 0.065"/>
                  <geom name="l_ankle_roll_link_collision2" class="collision" pos="-0.0272 -0.009 -0.04" quat="0.7071 0 -0.7071 0" type="capsule" size="0.01 0.082"/>
                  <geom name="l_ankle_roll_link_collision3" class="collision" pos="-0.0272 0.009 -0.04" quat="0.7071 0 -0.7071 0" type="capsule" size="0.01 0.082"/>
                  <geom name="l_ankle_roll_link_collision4" class="collision" pos="-0.017 0.025 -0.04" quat="0.7071 0 0.7071 0" type="capsule" size="0.01 0.065"/>
                </body>
              </body>
            </body>
          </body>
        </body>
      </body>
    </body>
  </worldbody>

  <actuator>
    <!-- Arms: 4438 motors -->
    <position class="pi_actuator_arm" name="r_shoulder_pitch" joint="r_shoulder_pitch_joint"/>
    <position class="pi_actuator_arm" name="r_shoulder_roll" joint="r_shoulder_roll_joint"/>
    <position class="pi_actuator_arm" name="r_upper_arm" joint="r_upper_arm_joint"/>
    <position class="pi_actuator_arm" name="r_elbow" joint="r_elbow_joint"/>
    <position class="pi_actuator_arm" name="l_shoulder_pitch" joint="l_shoulder_pitch_joint"/>
    <position class="pi_actuator_arm" name="l_shoulder_roll" joint="l_shoulder_roll_joint"/>
    <position class="pi_actuator_arm" name="l_upper_arm" joint="l_upper_arm_joint"/>
    <position class="pi_actuator_arm" name="l_elbow" joint="l_elbow_joint"/>
    <!-- Legs: 5036 motors -->
    <position class="pi_actuator_leg" name="r_hip_pitch" joint="r_hip_pitch_joint"/>
    <position class="pi_actuator_leg" name="r_hip_roll" joint="r_hip_roll_joint"/>
    <position class="pi_actuator_leg" name="r_thigh" joint="r_thigh_joint"/>
    <position class="pi_actuator_leg" name="r_calf" joint="r_calf_joint"/>
    <position class="pi_actuator_leg" name="r_ankle_pitch" joint="r_ankle_pitch_joint"/>
    <position class="pi_actuator_leg" name="r_ankle_roll" joint="r_ankle_roll_joint"/>
    <position class="pi_actuator_leg" name="l_hip_pitch" joint="l_hip_pitch_joint"/>
    <position class="pi_actuator_leg" name="l_hip_roll" joint="l_hip_roll_joint"/>
    <position class="pi_actuator_leg" name="l_thigh" joint="l_thigh_joint"/>
    <position class="pi_actuator_leg" name="l_calf" joint="l_calf_joint"/>
    <position class="pi_actuator_leg" name="l_ankle_pitch" joint="l_ankle_pitch_joint"/>
    <position class="pi_actuator_leg" name="l_ankle_roll" joint="l_ankle_roll_joint"/>
    <!-- Head: 3536 motors -->
    <position class="pi_actuator_head" name="head_yaw" joint="head_yaw_joint"/>
    <position class="pi_actuator_head" name="head_pitch" joint="head_pitch_joint"/>
  </actuator>

  <sensor>
    <framequat name='orientation' objtype='site' noise='0.001' objname='imu'/>
    <framepos name='position' objtype='site' noise='0.001' objname='imu'/>
    <gyro site="imu" name="gyro"/>
    <velocimeter site="imu" name="local_linvel"/>
    <accelerometer site="imu" name="accelerometer"/>
    <framezaxis objtype="site" objname="imu" name="upvector"/>
    <framexaxis objtype="site" objname="imu" name="forwardvector"/>
    <framelinvel objtype="site" objname="imu" name="global_linvel"/>
    <frameangvel objtype="site" objname="imu" name="global_angvel"/>
    <subtreeangmom name="root_angmom" body="base_link"/>
    <framelinvel objtype="site" objname="l_foot" name="l_foot_global_linvel"/>
    <framelinvel objtype="site" objname="r_foot" name="r_foot_global_linvel"/>
    <framexaxis objtype="site" objname="l_foot" name="l_foot_upvector"/>
    <framexaxis objtype="site" objname="r_foot" name="r_foot_upvector"/>
    <framepos objtype="site" objname="l_foot" name="l_foot_pos"/>
    <framepos objtype="site" objname="r_foot" name="r_foot_pos"/>
  </sensor>
</mujoco>
