<robot xmlns:xacro="http://www.ros.org/wiki/xacro" name="wolfgang">
<link name="base_link"><inertial><origin xyz="0 0 0" rpy="0 0 0"/><mass value="0.0001" /><inertia ixx="0.0" ixy="0.0" ixz="0.0" iyy="0.0" iyz="0.0" izz="0.0" /></inertial></link>
<joint name="base_link_to_base" type="fixed">
<parent link="base_link"/>
<child link="torso" />
<origin rpy="0.0 0 0" xyz="0 0 0"/>
</joint>
<link name="torso">
<visual>
<origin xyz="0 0 0" rpy="0 -0 0" />
<geometry>
<mesh filename="package://wolfgang_description/urdf/torso.stl"/>
</geometry>
<material name="torso_material">
<color rgba="0.521597 0.56403 0.586584 1.0"/>
</material>
</visual>
<collision>
<origin xyz="0 0 0" rpy="0 -0 0" />
<geometry>
<mesh filename="package://wolfgang_description/urdf/torso.stl"/>
</geometry>
<material name="torso_material">
<color rgba="0.521597 0.56403 0.586584 1.0"/>
</material>
</collision>
<inertial>
<origin xyz="-0.00126934 -7.4367e-05 0.113634" rpy="0 0 0"/>
<mass value="2.03744" />
<inertia ixx="0.0175155" ixy="5.62027e-06"  ixz="-0.000893204" iyy="0.0152666" iyz="0.000153846" izz="0.00729047" />
</inertial>
</link>

<link name="imu_frame">
<inertial>
<origin xyz="0 0 0" rpy="0 0 0" />
<mass value="1e-9" />
<inertia ixx="0" ixy="0" ixz="0" iyy="0" iyz="0" izz="0" />
</inertial>
</link>
<joint name="imu_frame_frame" type="fixed">
<origin xyz="-0.0369597 -0.0475181 0.224" rpy="5.31321e-16 -3.12873e-17 4.65401e-17" />
<parent link="torso" />
<child link="imu_frame" />
<axis xyz="0 0 0"/>
</joint>

<link name="r_shoulder">
<visual>
<origin xyz="0 0 0" rpy="0 -0 0" />
<geometry>
<mesh filename="package://wolfgang_description/urdf/r_shoulder.stl"/>
</geometry>
<material name="r_shoulder_material">
<color rgba="0.557143 0.318926 0.636303 1.0"/>
</material>
</visual>
<collision>
<origin xyz="0 0 0" rpy="0 -0 0" />
<geometry>
<mesh filename="package://wolfgang_description/urdf/r_shoulder.stl"/>
</geometry>
<material name="r_shoulder_material">
<color rgba="0.557143 0.318926 0.636303 1.0"/>
</material>
</collision>
<inertial>
<origin xyz="-0.0135397 0.0284022 -1.54699e-06" rpy="0 0 0"/>
<mass value="0.041445" />
<inertia ixx="1.85473e-05" ixy="7.63058e-06"  ixz="-9.41386e-10" iyy="2.76649e-05" iyz="8.71825e-10" izz="3.49573e-05" />
</inertial>
</link>

<link name="r_upper_arm">
<visual>
<origin xyz="0 0 0" rpy="0 -0 0" />
<geometry>
<mesh filename="package://wolfgang_description/urdf/r_upper_arm.stl"/>
</geometry>
<material name="r_upper_arm_material">
<color rgba="0.466361 0.466361 0.466361 1.0"/>
</material>
</visual>
<collision>
<origin xyz="0 0 0" rpy="0 -0 0" />
<geometry>
<mesh filename="package://wolfgang_description/urdf/r_upper_arm.stl"/>
</geometry>
<material name="r_upper_arm_material">
<color rgba="0.466361 0.466361 0.466361 1.0"/>
</material>
</collision>
<inertial>
<origin xyz="9.77435e-05 -0.0325821 -0.0239229" rpy="0 0 0"/>
<mass value="0.228498" />
<inertia ixx="0.000241455" ixy="8.09479e-07"  ixz="7.57095e-08" iyy="0.000179491" iyz="-2.7985e-06" izz="0.000371127" />
</inertial>
</link>

<link name="r_lower_arm">
<visual>
<origin xyz="0 0 0" rpy="0 -0 0" />
<geometry>
<mesh filename="package://wolfgang_description/urdf/r_lower_arm.stl"/>
</geometry>
<material name="r_lower_arm_material">
<color rgba="0.457801 0.457801 0.457801 1.0"/>
</material>
</visual>
<collision>
<origin xyz="0 0 0" rpy="0 -0 0" />
<geometry>
<mesh filename="package://wolfgang_description/urdf/r_lower_arm.stl"/>
</geometry>
<material name="r_lower_arm_material">
<color rgba="0.457801 0.457801 0.457801 1.0"/>
</material>
</collision>
<inertial>
<origin xyz="0.000436307 -0.0605126 -0.0235553" rpy="0 0 0"/>
<mass value="0.207774" />
<inertia ixx="0.001088" ixy="-1.16188e-06"  ixz="-5.01515e-09" iyy="8.90324e-05" iyz="-3.22666e-08" izz="0.00110076" />
</inertial>
</link>

<link name="r_wrist">
<inertial>
<origin xyz="0 0 0" rpy="0 0 0" />
<mass value="1e-9" />
<inertia ixx="0" ixy="0" ixz="0" iyy="0" iyz="0" izz="0" />
</inertial>
</link>
<joint name="r_wrist_frame" type="fixed">
<origin xyz="3.1225e-16 -0.226182 -0.0235" rpy="1.5708 7.31053e-15 -1.5708" />
<parent link="r_lower_arm" />
<child link="r_wrist" />
<axis xyz="0 0 0"/>
</joint>

<joint name="RElbow" type="revolute">
<origin xyz="0.024 -0.144 -0.0235" rpy="-1.5708 1.27676e-15 -1.5708" />
<parent link="r_upper_arm" />
<child link="r_lower_arm" />
<axis xyz="0 0 1"/>
<limit effort="5.43" velocity="10.33" lower="-1.0472" upper="1.5708"/>
<dynamics friction="0" damping="0.53"/>
</joint>

<joint name="RShoulderRoll" type="revolute">
<origin xyz="-0.01695 0.042 0" rpy="1.5708 8.32338e-16 -1.5708" />
<parent link="r_shoulder" />
<child link="r_upper_arm" />
<axis xyz="0 0 1"/>
<limit effort="5.43" velocity="10.33" lower="-3.14159" upper="0"/>
<dynamics friction="0" damping="0.53"/>
</joint>

<joint name="RShoulderPitch" type="revolute">
<origin xyz="-0.0015 -0.0765 0.2035" rpy="-4.34612e-17 1.66533e-15 -3.14159" />
<parent link="torso" />
<child link="r_shoulder" />
<axis xyz="-0 1 -0"/>
<limit effort="5.43" velocity="10.33" lower="-3.14159" upper="3.14159"/>
<dynamics friction="0" damping="0.53"/>
</joint>

<link name="l_shoulder">
<visual>
<origin xyz="0 0 0" rpy="0 -0 0" />
<geometry>
<mesh filename="package://wolfgang_description/urdf/l_shoulder.stl"/>
</geometry>
<material name="l_shoulder_material">
<color rgba="0.557143 0.318926 0.636303 1.0"/>
</material>
</visual>
<collision>
<origin xyz="0 0 0" rpy="0 -0 0" />
<geometry>
<mesh filename="package://wolfgang_description/urdf/l_shoulder.stl"/>
</geometry>
<material name="l_shoulder_material">
<color rgba="0.557143 0.318926 0.636303 1.0"/>
</material>
</collision>
<inertial>
<origin xyz="-0.0135397 0.0284022 1.54699e-06" rpy="0 0 0"/>
<mass value="0.041445" />
<inertia ixx="1.85473e-05" ixy="7.63058e-06"  ixz="9.41386e-10" iyy="2.76649e-05" iyz="-8.71825e-10" izz="3.49573e-05" />
</inertial>
</link>

<link name="l_upper_arm">
<visual>
<origin xyz="0 0 0" rpy="0 -0 0" />
<geometry>
<mesh filename="package://wolfgang_description/urdf/l_upper_arm.stl"/>
</geometry>
<material name="l_upper_arm_material">
<color rgba="0.466361 0.466361 0.466361 1.0"/>
</material>
</visual>
<collision>
<origin xyz="0 0 0" rpy="0 -0 0" />
<geometry>
<mesh filename="package://wolfgang_description/urdf/l_upper_arm.stl"/>
</geometry>
<material name="l_upper_arm_material">
<color rgba="0.466361 0.466361 0.466361 1.0"/>
</material>
</collision>
<inertial>
<origin xyz="9.77435e-05 -0.0325821 -0.0239229" rpy="0 0 0"/>
<mass value="0.228498" />
<inertia ixx="0.000241455" ixy="8.09479e-07"  ixz="7.57095e-08" iyy="0.000179491" iyz="-2.7985e-06" izz="0.000371127" />
</inertial>
</link>

<link name="l_lower_arm">
<visual>
<origin xyz="0 0 0" rpy="0 -0 0" />
<geometry>
<mesh filename="package://wolfgang_description/urdf/l_lower_arm.stl"/>
</geometry>
<material name="l_lower_arm_material">
<color rgba="0.457801 0.457801 0.457801 1.0"/>
</material>
</visual>
<collision>
<origin xyz="0 0 0" rpy="0 -0 0" />
<geometry>
<mesh filename="package://wolfgang_description/urdf/l_lower_arm.stl"/>
</geometry>
<material name="l_lower_arm_material">
<color rgba="0.457801 0.457801 0.457801 1.0"/>
</material>
</collision>
<inertial>
<origin xyz="-0.000436306 -0.0605126 -0.0235553" rpy="0 0 0"/>
<mass value="0.207774" />
<inertia ixx="0.001088" ixy="-1.14836e-05"  ixz="5.01178e-09" iyy="8.90324e-05" iyz="-3.22666e-08" izz="0.00110076" />
</inertial>
</link>

<link name="l_wrist">
<inertial>
<origin xyz="0 0 0" rpy="0 0 0" />
<mass value="1e-9" />
<inertia ixx="0" ixy="0" ixz="0" iyy="0" iyz="0" izz="0" />
</inertial>
</link>
<joint name="l_wrist_frame" type="fixed">
<origin xyz="2.91434e-16 -0.225182 -0.0235" rpy="-1.5708 6.97876e-16 -1.5708" />
<parent link="l_lower_arm" />
<child link="l_wrist" />
<axis xyz="0 0 0"/>
</joint>

<joint name="LElbow" type="revolute">
<origin xyz="-0.024 -0.144 -0.0235" rpy="-1.5708 1.11022e-14 1.5708" />
<parent link="l_upper_arm" />
<child link="l_lower_arm" />
<axis xyz="0 0 1"/>
<limit effort="5.43" velocity="10.33" lower="-1.5708" upper="1.0472"/>
<dynamics friction="0" damping="0.53"/>
</joint>

<joint name="LShoulderRoll" type="revolute">
<origin xyz="-0.01695 0.042 8.32667e-17" rpy="-1.5708 8.42077e-17 1.5708" />
<parent link="l_shoulder" />
<child link="l_upper_arm" />
<axis xyz="0 0 1"/>
<limit effort="5.43" velocity="10.33" lower="0" upper="3.14159"/>
<dynamics friction="0" damping="0.53"/>
</joint>

<joint name="LShoulderPitch" type="revolute">
<origin xyz="-0.0015 0.0765 0.2035" rpy="3.14159 7.77156e-16 3.14159" />
<parent link="torso" />
<child link="l_shoulder" />
<axis xyz="-0 1 -0"/>
<limit effort="5.43" velocity="10.33" lower="-3.14159" upper="3.14159"/>
<dynamics friction="0" damping="0.53"/>
</joint>

<link name="r_hip_1">
<visual>
<origin xyz="0 0 0" rpy="0 -0 0" />
<geometry>
<mesh filename="package://wolfgang_description/urdf/r_hip_1.stl"/>
</geometry>
<material name="r_hip_1_material">
<color rgba="0.647059 0.647059 0.647059 1.0"/>
</material>
</visual>
<collision>
<origin xyz="0 0 0" rpy="0 -0 0" />
<geometry>
<mesh filename="package://wolfgang_description/urdf/r_hip_1.stl"/>
</geometry>
<material name="r_hip_1_material">
<color rgba="0.647059 0.647059 0.647059 1.0"/>
</material>
</collision>
<inertial>
<origin xyz="1.20984e-11 0.010315 -1.06799e-07" rpy="0 0 0"/>
<mass value="0.0689735" />
<inertia ixx="2.18955e-05" ixy="-2.44475e-14"  ixz="3.06793e-15" iyy="0.00010714" iyz="-6.56688e-11" izz="0.000110523" />
</inertial>
</link>

<link name="r_hip_2">
<visual>
<origin xyz="0 0 0" rpy="0 -0 0" />
<geometry>
<mesh filename="package://wolfgang_description/urdf/r_hip_2.stl"/>
</geometry>
<material name="r_hip_2_material">
<color rgba="0.283325 0.302819 0.324631 1.0"/>
</material>
</visual>
<collision>
<origin xyz="0 0 0" rpy="0 -0 0" />
<geometry>
<mesh filename="package://wolfgang_description/urdf/r_hip_2.stl"/>
</geometry>
<material name="r_hip_2_material">
<color rgba="0.283325 0.302819 0.324631 1.0"/>
</material>
</collision>
<inertial>
<origin xyz="1.38724e-05 -0.0155281 -0.0486407" rpy="0 0 0"/>
<mass value="0.319807" />
<inertia ixx="0.000268627" ixy="6.08561e-08"  ixz="6.67248e-07" iyy="0.000268049" iyz="3.87608e-06" izz="0.000121331" />
</inertial>
</link>

<link name="r_upper_leg">
<visual>
<origin xyz="0 0 0" rpy="0 -0 0" />
<geometry>
<mesh filename="package://wolfgang_description/urdf/r_upper_leg.stl"/>
</geometry>
<material name="r_upper_leg_material">
<color rgba="0.51222 0.47486 0.47486 1.0"/>
</material>
</visual>
<collision>
<origin xyz="0 0 0" rpy="0 -0 0" />
<geometry>
<mesh filename="package://wolfgang_description/urdf/r_upper_leg.stl"/>
</geometry>
<material name="r_upper_leg_material">
<color rgba="0.51222 0.47486 0.47486 1.0"/>
</material>
</collision>
<inertial>
<origin xyz="0.00493985 -0.0283223 -0.133144" rpy="0 0 0"/>
<mass value="0.242311" />
<inertia ixx="0.000501721" ixy="8.33582e-06"  ixz="1.67743e-05" iyy="0.000458929" iyz="-4.68914e-06" izz="0.000113409" />
</inertial>
</link>

<link name="r_lower_leg">
<visual>
<origin xyz="0 0 0" rpy="0 -0 0" />
<geometry>
<mesh filename="package://wolfgang_description/urdf/r_lower_leg.stl"/>
</geometry>
<material name="r_lower_leg_material">
<color rgba="0.504245 0.543744 0.48638 1.0"/>
</material>
</visual>
<collision>
<origin xyz="0 0 0" rpy="0 -0 0" />
<geometry>
<mesh filename="package://wolfgang_description/urdf/r_lower_leg.stl"/>
</geometry>
<material name="r_lower_leg_material">
<color rgba="0.504245 0.543744 0.48638 1.0"/>
</material>
</collision>
<inertial>
<origin xyz="0.00162251 0.0115707 -0.048584" rpy="0 0 0"/>
<mass value="0.112618" />
<inertia ixx="0.000378482" ixy="1.20214e-06"  ixz="-1.03313e-05" iyy="0.000316715" iyz="6.38309e-05" izz="9.77108e-05" />
</inertial>
</link>

<link name="r_ankle">
<visual>
<origin xyz="0 0 0" rpy="0 -0 0" />
<geometry>
<mesh filename="package://wolfgang_description/urdf/r_ankle.stl"/>
</geometry>
<material name="r_ankle_material">
<color rgba="0.283325 0.302819 0.324631 1.0"/>
</material>
</visual>
<collision>
<origin xyz="0 0 0" rpy="0 -0 0" />
<geometry>
<mesh filename="package://wolfgang_description/urdf/r_ankle.stl"/>
</geometry>
<material name="r_ankle_material">
<color rgba="0.283325 0.302819 0.324631 1.0"/>
</material>
</collision>
<inertial>
<origin xyz="-0.0204557 -0.0155281 -0.0260036" rpy="0 0 0"/>
<mass value="0.319807" />
<inertia ixx="0.000116775" ixy="-4.53798e-06"  ixz="6.10986e-07" iyy="0.000268473" iyz="-7.45081e-07" izz="0.000272856" />
</inertial>
</link>

<link name="r_foot">
<visual>
<origin xyz="0 0 0" rpy="0 -0 0" />
<geometry>
<mesh filename="package://wolfgang_description/urdf/r_foot.stl"/>
</geometry>
<material name="r_foot_material">
<color rgba="0.687389 0.697641 0.687389 1.0"/>
</material>
</visual>
<collision>
<origin xyz="0 0 0" rpy="0 -0 0" />
<geometry>
<mesh filename="package://wolfgang_description/urdf/r_foot.stl"/>
</geometry>
<material name="r_foot_material">
<color rgba="0.687389 0.697641 0.687389 1.0"/>
</material>
</collision>
<inertial>
<origin xyz="0.0119766 0.0911644 -0.0298577" rpy="0 0 0"/>
<mass value="0.267778" />
<inertia ixx="0.000883619" ixy="-3.28755e-05"  ixz="5.11659e-06" iyy="0.000317104" iyz="-1.76091e-05" izz="0.00115244" />
</inertial>
</link>

<link name="r_sole">
<inertial>
<origin xyz="0 0 0" rpy="0 0 0" />
<mass value="1e-9" />
<inertia ixx="0" ixy="0" ixz="0" iyy="0" iyz="0" izz="0" />
</inertial>
</link>
<joint name="r_sole_frame" type="fixed">
<origin xyz="0.0152219 0.0907683 -0.0529" rpy="3.33669e-15 3.22983e-14 1.5708" />
<parent link="r_foot" />
<child link="r_sole" />
<axis xyz="0 0 0"/>
</joint>

<link name="rlb">
<visual>
<origin xyz="0 0 0" rpy="0 -0 0" />
<geometry>
<mesh filename="package://wolfgang_description/urdf/rlb.stl"/>
</geometry>
<material name="rlb_material">
<color rgba="0.615686 0.811765 0.929412 1.0"/>
</material>
</visual>
<collision>
<origin xyz="0 0 0" rpy="0 -0 0" />
<geometry>
<mesh filename="package://wolfgang_description/urdf/rlb.stl"/>
</geometry>
<material name="rlb_material">
<color rgba="0.615686 0.811765 0.929412 1.0"/>
</material>
</collision>
<inertial>
<origin xyz="1.17069e-19 0.000155519 -0.00775879" rpy="0 0 0"/>
<mass value="0.00165976" />
<inertia ixx="4.3352e-08" ixy="5.86271e-26"  ixz="-1.26553e-24" iyy="4.44049e-08" iyz="-1.0993e-09" izz="3.04397e-08" />
</inertial>
</link>

<link name="r_cleat_l_back">
<inertial>
<origin xyz="0 0 0" rpy="0 0 0" />
<mass value="1e-9" />
<inertia ixx="0" ixy="0" ixz="0" iyy="0" iyz="0" izz="0" />
</inertial>
</link>
<joint name="r_cleat_l_back_frame" type="fixed">
<origin xyz="0 -0.0005 -0.016" rpy="8.14947e-17 -3.2143e-16 -3.14159" />
<parent link="rlb" />
<child link="r_cleat_l_back" />
<axis xyz="0 0 0"/>
</joint>

<joint name="RLB" type="fixed">
<origin xyz="-0.03 -0.007 -0.034" rpy="-2.20568e-16 -1.44743e-15 -1.5708" />
<parent link="r_foot" />
<child link="rlb" />
<axis xyz="0 1.22465e-16 1"/>
<limit effort="0" velocity="0" />
<dynamics friction="0" damping="0"/>
</joint>

<link name="rlf">
<visual>
<origin xyz="0 0 0" rpy="0 -0 0" />
<geometry>
<mesh filename="package://wolfgang_description/urdf/rlf.stl"/>
</geometry>
<material name="rlf_material">
<color rgba="0.615686 0.811765 0.929412 1.0"/>
</material>
</visual>
<collision>
<origin xyz="0 0 0" rpy="0 -0 0" />
<geometry>
<mesh filename="package://wolfgang_description/urdf/rlf.stl"/>
</geometry>
<material name="rlf_material">
<color rgba="0.615686 0.811765 0.929412 1.0"/>
</material>
</collision>
<inertial>
<origin xyz="2.14788e-20 0.000155519 -0.00775879" rpy="0 0 0"/>
<mass value="0.00165976" />
<inertia ixx="4.3352e-08" ixy="2.74826e-27"  ixz="-1.56725e-24" iyy="4.44049e-08" iyz="-1.0993e-09" izz="3.04397e-08" />
</inertial>
</link>

<link name="r_cleat_l_front">
<inertial>
<origin xyz="0 0 0" rpy="0 0 0" />
<mass value="1e-9" />
<inertia ixx="0" ixy="0" ixz="0" iyy="0" iyz="0" izz="0" />
</inertial>
</link>
<joint name="r_cleat_l_front_frame" type="fixed">
<origin xyz="-1.38778e-17 -0.0005 -0.016" rpy="3.37705e-16 1.87148e-15 3.14159" />
<parent link="rlf" />
<child link="r_cleat_l_front" />
<axis xyz="0 0 0"/>
</joint>

<joint name="RLF" type="fixed">
<origin xyz="-0.03 0.177 -0.034" rpy="-1.06437e-15 1.50083e-15 -1.5708" />
<parent link="r_foot" />
<child link="rlf" />
<axis xyz="0 1.22465e-16 1"/>
<limit effort="0" velocity="0" />
<dynamics friction="0" damping="0"/>
</joint>

<link name="rrf">
<visual>
<origin xyz="0 0 0" rpy="0 -0 0" />
<geometry>
<mesh filename="package://wolfgang_description/urdf/rrf.stl"/>
</geometry>
<material name="rrf_material">
<color rgba="0.615686 0.811765 0.929412 1.0"/>
</material>
</visual>
<collision>
<origin xyz="0 0 0" rpy="0 -0 0" />
<geometry>
<mesh filename="package://wolfgang_description/urdf/rrf.stl"/>
</geometry>
<material name="rrf_material">
<color rgba="0.615686 0.811765 0.929412 1.0"/>
</material>
</collision>
<inertial>
<origin xyz="1.40666e-17 0.000155519 -0.00775879" rpy="0 0 0"/>
<mass value="0.00165976" />
<inertia ixx="4.3352e-08" ixy="-7.43969e-27"  ixz="1.95249e-24" iyy="4.44049e-08" iyz="-1.0993e-09" izz="3.04397e-08" />
</inertial>
</link>

<link name="r_cleat_r_front">
<inertial>
<origin xyz="0 0 0" rpy="0 0 0" />
<mass value="1e-9" />
<inertia ixx="0" ixy="0" ixz="0" iyy="0" iyz="0" izz="0" />
</inertial>
</link>
<joint name="r_cleat_r_front_frame" type="fixed">
<origin xyz="-1.38778e-17 -0.0005 -0.016" rpy="2.75421e-16 9.31542e-16 3.14159" />
<parent link="rrf" />
<child link="r_cleat_r_front" />
<axis xyz="0 0 0"/>
</joint>

<joint name="RRF" type="fixed">
<origin xyz="0.06 0.177 -0.034" rpy="-8.29268e-17 1.40387e-15 -1.5708" />
<parent link="r_foot" />
<child link="rrf" />
<axis xyz="0 1.22465e-16 1"/>
<limit effort="0" velocity="0" />
<dynamics friction="0" damping="0"/>
</joint>

<link name="rrb">
<visual>
<origin xyz="0 0 0" rpy="0 -0 0" />
<geometry>
<mesh filename="package://wolfgang_description/urdf/rrb.stl"/>
</geometry>
<material name="rrb_material">
<color rgba="0.615686 0.811765 0.929412 1.0"/>
</material>
</visual>
<collision>
<origin xyz="0 0 0" rpy="0 -0 0" />
<geometry>
<mesh filename="package://wolfgang_description/urdf/rrb.stl"/>
</geometry>
<material name="rrb_material">
<color rgba="0.615686 0.811765 0.929412 1.0"/>
</material>
</collision>
<inertial>
<origin xyz="1.39786e-17 0.000155519 -0.00775879" rpy="0 0 0"/>
<mass value="0.00165976" />
<inertia ixx="4.3352e-08" ixy="7.23281e-27"  ixz="-1.5703e-25" iyy="4.44049e-08" iyz="-1.0993e-09" izz="3.04397e-08" />
</inertial>
</link>

<link name="r_cleat_r_back">
<inertial>
<origin xyz="0 0 0" rpy="0 0 0" />
<mass value="1e-9" />
<inertia ixx="0" ixy="0" ixz="0" iyy="0" iyz="0" izz="0" />
</inertial>
</link>
<joint name="r_cleat_r_back_frame" type="fixed">
<origin xyz="1.38778e-17 -0.0005 -0.016" rpy="2.94118e-16 7.40154e-17 3.14159" />
<parent link="rrb" />
<child link="r_cleat_r_back" />
<axis xyz="0 0 0"/>
</joint>

<joint name="RRB" type="fixed">
<origin xyz="0.06 -0.007 -0.034" rpy="-1.81005e-15 5.43559e-14 -1.5708" />
<parent link="r_foot" />
<child link="rrb" />
<axis xyz="0 1.22465e-16 1"/>
<limit effort="0" velocity="0" />
<dynamics friction="0" damping="0"/>
</joint>

<joint name="RAnkleRoll" type="revolute">
<origin xyz="-0.0691 0 -0.026" rpy="1.5708 1.5708 0" />
<parent link="r_ankle" />
<child link="r_foot" />
<axis xyz="0 -1 0"/>
<limit effort="7.57" velocity="8.22" lower="-1.0472" upper="1.0472"/>
<dynamics friction="0" damping="0.92"/>
</joint>

<joint name="RAnklePitch" type="revolute">
<origin xyz="4.23273e-16 0.0505 -0.17" rpy="-1.5708 -7.47915e-15 1.91582e-15" />
<parent link="r_lower_leg" />
<child link="r_ankle" />
<axis xyz="-0 -0 -1"/>
<limit effort="7.57" velocity="8.22" lower="-1.5708" upper="1.22173"/>
<dynamics friction="0" damping="0.92"/>
</joint>

<joint name="RKnee" type="revolute">
<origin xyz="-0.00392295 -0.051 -0.169043" rpy="1.05132e-15 -0.261799 -2.52921e-15" />
<parent link="r_upper_leg" />
<child link="r_lower_leg" />
<axis xyz="0 1 0"/>
<limit effort="10" velocity="10" lower="0" upper="2.96706"/>
<dynamics friction="0" damping="1"/>
</joint>

<joint name="RHipPitch" type="revolute">
<origin xyz="-0.0265 -2.77556e-17 -0.0691" rpy="-1.5708 1.5708 0" />
<parent link="r_hip_2" />
<child link="r_upper_leg" />
<axis xyz="-0 1 -0"/>
<limit effort="7.57" velocity="8.22" lower="-1.5708" upper="1.5708"/>
<dynamics friction="0" damping="0.92"/>
</joint>

<joint name="RHipRoll" type="revolute">
<origin xyz="-0.046 0.0414 6.93889e-18" rpy="-3.14159 1.5708 0" />
<parent link="r_hip_1" />
<child link="r_hip_2" />
<axis xyz="-0 -0 -1"/>
<limit effort="7.57" velocity="8.22" lower="-1.5708" upper="1.5708"/>
<dynamics friction="0" damping="0.92"/>
</joint>

<joint name="RHipYaw" type="revolute">
<origin xyz="-1.33227e-15 -0.055 -7.91468e-18" rpy="-1.5708 -0 0" />
<parent link="torso" />
<child link="r_hip_1" />
<axis xyz="0 -1 0"/>
<limit effort="7.57" velocity="8.22" lower="-1.5708" upper="1.5708"/>
<dynamics friction="0" damping="0.92"/>
</joint>

<link name="l_hip_1">
<visual>
<origin xyz="0 0 0" rpy="0 -0 0" />
<geometry>
<mesh filename="package://wolfgang_description/urdf/l_hip_1.stl"/>
</geometry>
<material name="l_hip_1_material">
<color rgba="0.647059 0.647059 0.647059 1.0"/>
</material>
</visual>
<collision>
<origin xyz="0 0 0" rpy="0 -0 0" />
<geometry>
<mesh filename="package://wolfgang_description/urdf/l_hip_1.stl"/>
</geometry>
<material name="l_hip_1_material">
<color rgba="0.647059 0.647059 0.647059 1.0"/>
</material>
</collision>
<inertial>
<origin xyz="1.20984e-11 0.010315 -1.06799e-07" rpy="0 0 0"/>
<mass value="0.0689735" />
<inertia ixx="2.18955e-05" ixy="-2.44475e-14"  ixz="3.06793e-15" iyy="0.00010714" iyz="-6.56688e-11" izz="0.000110523" />
</inertial>
</link>

<link name="l_hip_2">
<visual>
<origin xyz="0 0 0" rpy="0 -0 0" />
<geometry>
<mesh filename="package://wolfgang_description/urdf/l_hip_2.stl"/>
</geometry>
<material name="l_hip_2_material">
<color rgba="0.283325 0.302819 0.324631 1.0"/>
</material>
</visual>
<collision>
<origin xyz="0 0 0" rpy="0 -0 0" />
<geometry>
<mesh filename="package://wolfgang_description/urdf/l_hip_2.stl"/>
</geometry>
<material name="l_hip_2_material">
<color rgba="0.283325 0.302819 0.324631 1.0"/>
</material>
</collision>
<inertial>
<origin xyz="-3.60783e-06 -0.0155281 -0.0486443" rpy="0 0 0"/>
<mass value="0.319807" />
<inertia ixx="0.000268673" ixy="-7.40992e-08"  ixz="-6.18751e-07" iyy="0.000268098" iyz="3.88325e-06" izz="0.000121333" />
</inertial>
</link>

<link name="l_upper_leg">
<visual>
<origin xyz="0 0 0" rpy="0 -0 0" />
<geometry>
<mesh filename="package://wolfgang_description/urdf/l_upper_leg.stl"/>
</geometry>
<material name="l_upper_leg_material">
<color rgba="0.51222 0.47486 0.47486 1.0"/>
</material>
</visual>
<collision>
<origin xyz="0 0 0" rpy="0 -0 0" />
<geometry>
<mesh filename="package://wolfgang_description/urdf/l_upper_leg.stl"/>
</geometry>
<material name="l_upper_leg_material">
<color rgba="0.51222 0.47486 0.47486 1.0"/>
</material>
</collision>
<inertial>
<origin xyz="-0.00463142 -0.132966 0.0263223" rpy="0 0 0"/>
<mass value="0.242311" />
<inertia ixx="0.000495112" ixy="-2.80704e-05"  ixz="2.53373e-06" iyy="0.000120828" iyz="4.33405e-06" izz="0.000454597" />
</inertial>
</link>

<link name="l_lower_leg">
<visual>
<origin xyz="0 0 0" rpy="0 -0 0" />
<geometry>
<mesh filename="package://wolfgang_description/urdf/l_lower_leg.stl"/>
</geometry>
<material name="l_lower_leg_material">
<color rgba="0.43841 0.479617 0.424823 1.0"/>
</material>
</visual>
<collision>
<origin xyz="0 0 0" rpy="0 -0 0" />
<geometry>
<mesh filename="package://wolfgang_description/urdf/l_lower_leg.stl"/>
</geometry>
<material name="l_lower_leg_material">
<color rgba="0.43841 0.479617 0.424823 1.0"/>
</material>
</collision>
<inertial>
<origin xyz="0.0016224 -0.0119702 -0.0485721" rpy="0 0 0"/>
<mass value="0.112624" />
<inertia ixx="0.000379713" ixy="-1.51612e-06"  ixz="-1.03829e-05" iyy="0.000316829" iyz="-6.25424e-05" izz="9.88108e-05" />
</inertial>
</link>

<link name="l_ankle">
<visual>
<origin xyz="0 0 0" rpy="0 -0 0" />
<geometry>
<mesh filename="package://wolfgang_description/urdf/l_ankle.stl"/>
</geometry>
<material name="l_ankle_material">
<color rgba="0.283325 0.302819 0.324631 1.0"/>
</material>
</visual>
<collision>
<origin xyz="0 0 0" rpy="0 -0 0" />
<geometry>
<mesh filename="package://wolfgang_description/urdf/l_ankle.stl"/>
</geometry>
<material name="l_ankle_material">
<color rgba="0.283325 0.302819 0.324631 1.0"/>
</material>
</collision>
<inertial>
<origin xyz="0.0204593 -0.0155281 -0.0260139" rpy="0 0 0"/>
<mass value="0.319807" />
<inertia ixx="0.000116773" ixy="4.53857e-06"  ixz="-6.75013e-07" iyy="0.000268424" iyz="-7.24073e-07" izz="0.00027281" />
</inertial>
</link>

<link name="l_foot">
<visual>
<origin xyz="0 0 0" rpy="0 -0 0" />
<geometry>
<mesh filename="package://wolfgang_description/urdf/l_foot.stl"/>
</geometry>
<material name="l_foot_material">
<color rgba="0.687389 0.697641 0.687389 1.0"/>
</material>
</visual>
<collision>
<origin xyz="0 0 0" rpy="0 -0 0" />
<geometry>
<mesh filename="package://wolfgang_description/urdf/l_foot.stl"/>
</geometry>
<material name="l_foot_material">
<color rgba="0.687389 0.697641 0.687389 1.0"/>
</material>
</collision>
<inertial>
<origin xyz="-0.0120469 0.0911644 -0.0298577" rpy="0 0 0"/>
<mass value="0.267778" />
<inertia ixx="0.000883619" ixy="3.20503e-05"  ixz="-5.19449e-06" iyy="0.000316651" iyz="-1.76091e-05" izz="0.00115199" />
</inertial>
</link>

<link name="l_sole">
<inertial>
<origin xyz="0 0 0" rpy="0 0 0" />
<mass value="1e-9" />
<inertia ixx="0" ixy="0" ixz="0" iyy="0" iyz="0" izz="0" />
</inertial>
</link>
<joint name="l_sole_frame" type="fixed">
<origin xyz="-0.0152219 0.0907683 -0.0529" rpy="-5.77818e-15 -6.98371e-15 1.5708" />
<parent link="l_foot" />
<child link="l_sole" />
<axis xyz="0 0 0"/>
</joint>

<link name="llb">
<visual>
<origin xyz="0 0 0" rpy="0 -0 0" />
<geometry>
<mesh filename="package://wolfgang_description/urdf/llb.stl"/>
</geometry>
<material name="llb_material">
<color rgba="0.615686 0.811765 0.929412 1.0"/>
</material>
</visual>
<collision>
<origin xyz="0 0 0" rpy="0 -0 0" />
<geometry>
<mesh filename="package://wolfgang_description/urdf/llb.stl"/>
</geometry>
<material name="llb_material">
<color rgba="0.615686 0.811765 0.929412 1.0"/>
</material>
</collision>
<inertial>
<origin xyz="1.39725e-17 0.000155519 -0.00775879" rpy="0 0 0"/>
<mass value="0.00165976" />
<inertia ixx="4.3352e-08" ixy="-2.54026e-27"  ixz="-3.40123e-27" iyy="4.44049e-08" iyz="-1.0993e-09" izz="3.04397e-08" />
</inertial>
</link>

<link name="l_cleat_l_back">
<inertial>
<origin xyz="0 0 0" rpy="0 0 0" />
<mass value="1e-9" />
<inertia ixx="0" ixy="0" ixz="0" iyy="0" iyz="0" izz="0" />
</inertial>
</link>
<joint name="l_cleat_l_back_frame" type="fixed">
<origin xyz="1.38778e-17 -0.0005 -0.016" rpy="1.67348e-16 -4.15297e-16 3.14159" />
<parent link="llb" />
<child link="l_cleat_l_back" />
<axis xyz="0 0 0"/>
</joint>

<joint name="LLB" type="fixed">
<origin xyz="-0.06 -0.007 -0.034" rpy="1.75801e-15 -5.02709e-15 -1.5708" />
<parent link="l_foot" />
<child link="llb" />
<axis xyz="0 1.22465e-16 1"/>
<limit effort="0" velocity="0" />
<dynamics friction="0" damping="0"/>
</joint>

<link name="llf">
<visual>
<origin xyz="0 0 0" rpy="0 -0 0" />
<geometry>
<mesh filename="package://wolfgang_description/urdf/llf.stl"/>
</geometry>
<material name="llf_material">
<color rgba="0.615686 0.811765 0.929412 1.0"/>
</material>
</visual>
<collision>
<origin xyz="0 0 0" rpy="0 -0 0" />
<geometry>
<mesh filename="package://wolfgang_description/urdf/llf.stl"/>
</geometry>
<material name="llf_material">
<color rgba="0.615686 0.811765 0.929412 1.0"/>
</material>
</collision>
<inertial>
<origin xyz="-1.37344e-17 0.000155519 -0.00775879" rpy="0 0 0"/>
<mass value="0.00165976" />
<inertia ixx="4.3352e-08" ixy="2.25172e-27"  ixz="8.03696e-25" iyy="4.44049e-08" iyz="-1.0993e-09" izz="3.04397e-08" />
</inertial>
</link>

<link name="l_cleat_l_front">
<inertial>
<origin xyz="0 0 0" rpy="0 0 0" />
<mass value="1e-9" />
<inertia ixx="0" ixy="0" ixz="0" iyy="0" iyz="0" izz="0" />
</inertial>
</link>
<joint name="l_cleat_l_front_frame" type="fixed">
<origin xyz="0 -0.0005 -0.016" rpy="3.06162e-16 -4.4319e-17 -3.14159" />
<parent link="llf" />
<child link="l_cleat_l_front" />
<axis xyz="0 0 0"/>
</joint>

<joint name="LLF" type="fixed">
<origin xyz="-0.06 0.177 -0.034" rpy="2.68959e-15 -5.26048e-15 -1.5708" />
<parent link="l_foot" />
<child link="llf" />
<axis xyz="0 1.22465e-16 1"/>
<limit effort="0" velocity="0" />
<dynamics friction="0" damping="0"/>
</joint>

<link name="lrf">
<visual>
<origin xyz="0 0 0" rpy="0 -0 0" />
<geometry>
<mesh filename="package://wolfgang_description/urdf/lrf.stl"/>
</geometry>
<material name="lrf_material">
<color rgba="0.615686 0.811765 0.929412 1.0"/>
</material>
</visual>
<collision>
<origin xyz="0 0 0" rpy="0 -0 0" />
<geometry>
<mesh filename="package://wolfgang_description/urdf/lrf.stl"/>
</geometry>
<material name="lrf_material">
<color rgba="0.615686 0.811765 0.929412 1.0"/>
</material>
</collision>
<inertial>
<origin xyz="2.78989e-17 0.000155519 -0.00775879" rpy="0 0 0"/>
<mass value="0.00165976" />
<inertia ixx="4.3352e-08" ixy="2.25172e-27"  ixz="8.03696e-25" iyy="4.44049e-08" iyz="-1.0993e-09" izz="3.04397e-08" />
</inertial>
</link>

<link name="l_cleat_r_front">
<inertial>
<origin xyz="0 0 0" rpy="0 0 0" />
<mass value="1e-9" />
<inertia ixx="0" ixy="0" ixz="0" iyy="0" iyz="0" izz="0" />
</inertial>
</link>
<joint name="l_cleat_r_front_frame" type="fixed">
<origin xyz="0 -0.0005 -0.016" rpy="3.00788e-16 -1.03785e-15 -3.14159" />
<parent link="lrf" />
<child link="l_cleat_r_front" />
<axis xyz="0 0 0"/>
</joint>

<joint name="LRF" type="fixed">
<origin xyz="0.03 0.177 -0.034" rpy="2.68959e-15 -5.26048e-15 -1.5708" />
<parent link="l_foot" />
<child link="lrf" />
<axis xyz="0 -1.22465e-16 -1"/>
<limit effort="0" velocity="0" />
<dynamics friction="0" damping="0"/>
</joint>

<link name="lrb">
<visual>
<origin xyz="0 0 0" rpy="0 -0 0" />
<geometry>
<mesh filename="package://wolfgang_description/urdf/lrb.stl"/>
</geometry>
<material name="lrb_material">
<color rgba="0.615686 0.811765 0.929412 1.0"/>
</material>
</visual>
<collision>
<origin xyz="0 0 0" rpy="0 -0 0" />
<geometry>
<mesh filename="package://wolfgang_description/urdf/lrb.stl"/>
</geometry>
<material name="lrb_material">
<color rgba="0.615686 0.811765 0.929412 1.0"/>
</material>
</collision>
<inertial>
<origin xyz="-1.38113e-17 0.000155519 -0.00775879" rpy="0 0 0"/>
<mass value="0.00165976" />
<inertia ixx="4.3352e-08" ixy="1.6966e-26"  ixz="-1.09118e-24" iyy="4.44049e-08" iyz="-1.0993e-09" izz="3.04397e-08" />
</inertial>
</link>

<link name="l_cleat_r_back">
<inertial>
<origin xyz="0 0 0" rpy="0 0 0" />
<mass value="1e-9" />
<inertia ixx="0" ixy="0" ixz="0" iyy="0" iyz="0" izz="0" />
</inertial>
</link>
<joint name="l_cleat_r_back_frame" type="fixed">
<origin xyz="0 -0.0005 -0.016" rpy="2.92719e-16 -4.05989e-17 -3.14159" />
<parent link="lrb" />
<child link="l_cleat_r_back" />
<axis xyz="0 0 0"/>
</joint>

<joint name="LRB" type="fixed">
<origin xyz="0.03 -0.007 -0.034" rpy="-1.44208e-14 -1.69268e-14 -1.5708" />
<parent link="l_foot" />
<child link="lrb" />
<axis xyz="0 1.22465e-16 1"/>
<limit effort="0" velocity="0" />
<dynamics friction="0" damping="0"/>
</joint>

<joint name="LAnkleRoll" type="revolute">
<origin xyz="0.0691 1.66533e-16 -0.026" rpy="1.5708 -1.5708 0" />
<parent link="l_ankle" />
<child link="l_foot" />
<axis xyz="-0 -1 -0"/>
<limit effort="7.57" velocity="8.22" lower="-1.0472" upper="1.0472"/>
<dynamics friction="0" damping="0.92"/>
</joint>

<joint name="LAnklePitch" type="revolute">
<origin xyz="1.11022e-16 -0.0505 -0.17" rpy="-1.5708 -1.45847e-15 3.14159" />
<parent link="l_lower_leg" />
<child link="l_ankle" />
<axis xyz="-0 -0 -1"/>
<limit effort="7.57" velocity="8.22" lower="-1.22173" upper="1.5708"/>
<dynamics friction="0" damping="0.92"/>
</joint>

<joint name="LKnee" type="revolute">
<origin xyz="0.00435596 -0.168793 0.049" rpy="1.5708 -4.90478e-17 2.87979" />
<parent link="l_upper_leg" />
<child link="l_lower_leg" />
<axis xyz="0 -1 0"/>
<limit effort="10" velocity="10" lower="-2.96706" upper="0"/>
<dynamics friction="0" damping="1"/>
</joint>

<joint name="LHipPitch" type="revolute">
<origin xyz="0.026 6.93889e-18 -0.0691" rpy="2.67116e-16 -1.5708 0" />
<parent link="l_hip_2" />
<child link="l_upper_leg" />
<axis xyz="7.95491e-17 -3.00167e-16 -1"/>
<limit effort="7.57" velocity="8.22" lower="-1.5708" upper="1.5708"/>
<dynamics friction="0" damping="0.92"/>
</joint>

<joint name="LHipRoll" type="revolute">
<origin xyz="-0.046 0.0414 6.93889e-18" rpy="3.14159 1.5708 0" />
<parent link="l_hip_1" />
<child link="l_hip_2" />
<axis xyz="-0 -0 -1"/>
<limit effort="7.57" velocity="8.22" lower="-1.5708" upper="1.5708"/>
<dynamics friction="0" damping="0.92"/>
</joint>

<joint name="LHipYaw" type="revolute">
<origin xyz="1.82493e-15 0.055 -4.22839e-18" rpy="-1.5708 -0 0" />
<parent link="torso" />
<child link="l_hip_1" />
<axis xyz="0 -1 0"/>
<limit effort="7.57" velocity="8.22" lower="-1.5708" upper="1.5708"/>
<dynamics friction="0" damping="0.92"/>
</joint>

<link name="neck">
<visual>
<origin xyz="0 0 0" rpy="0 -0 0" />
<geometry>
<mesh filename="package://wolfgang_description/urdf/neck.stl"/>
</geometry>
<material name="neck_material">
<color rgba="0.291135 0.291135 0.291135 1.0"/>
</material>
</visual>
<collision>
<origin xyz="0 0 0" rpy="0 -0 0" />
<geometry>
<mesh filename="package://wolfgang_description/urdf/neck.stl"/>
</geometry>
<material name="neck_material">
<color rgba="0.291135 0.291135 0.291135 1.0"/>
</material>
</collision>
<inertial>
<origin xyz="0.0186912 -7.75177e-05 -0.0220143" rpy="0 0 0"/>
<mass value="0.148233" />
<inertia ixx="3.89355e-05" ixy="-5.28709e-07"  ixz="4.95698e-06" iyy="5.76318e-05" iyz="-2.28158e-08" izz="6.25414e-05" />
</inertial>
</link>

<link name="head">
<visual>
<origin xyz="0 0 0" rpy="0 -0 0" />
<geometry>
<mesh filename="package://wolfgang_description/urdf/head.stl"/>
</geometry>
<material name="head_material">
<color rgba="0.705291 0.67253 0.716178 1.0"/>
</material>
</visual>
<collision>
<origin xyz="0 0 0" rpy="0 -0 0" />
<geometry>
<mesh filename="package://wolfgang_description/urdf/head.stl"/>
</geometry>
<material name="head_material">
<color rgba="0.705291 0.67253 0.716178 1.0"/>
</material>
</collision>
<inertial>
<origin xyz="0.000411708 0.0674937 -0.0200647" rpy="0 0 0"/>
<mass value="0.301358" />
<inertia ixx="0.000344265" ixy="-2.07263e-05"  ixz="1.05826e-06" iyy="0.000333713" iyz="5.11722e-05" izz="0.000421898" />
</inertial>
</link>

<link name="camera">
<inertial>
<origin xyz="0 0 0" rpy="0 0 0" />
<mass value="1e-9" />
<inertia ixx="0" ixy="0" ixz="0" iyy="0" iyz="0" izz="0" />
</inertial>
</link>
<joint name="camera_frame" type="fixed">
<origin xyz="0.0437 0.0795 -0.0235" rpy="-1.5708 -1.45465e-14 -3.33067e-16" />
<parent link="head" />
<child link="camera" />
<axis xyz="0 0 0"/>
</joint>

<link name="camera_optical_frame">
<inertial>
<origin xyz="0 0 0" rpy="0 0 0" />
<mass value="1e-9" />
<inertia ixx="0" ixy="0" ixz="0" iyy="0" iyz="0" izz="0" />
</inertial>
</link>
<joint name="camera_optical_frame_frame" type="fixed">
<origin xyz="0.0432 0.08 -0.0235" rpy="3.14159 -1.5708 0" />
<parent link="head" />
<child link="camera_optical_frame" />
<axis xyz="0 0 0"/>
</joint>

<link name="imu_frame_2">
<inertial>
<origin xyz="0 0 0" rpy="0 0 0" />
<mass value="1e-9" />
<inertia ixx="0" ixy="0" ixz="0" iyy="0" iyz="0" izz="0" />
</inertial>
</link>
<joint name="imu_frame_2_frame" type="fixed">
<origin xyz="-0.02545 0.0535 -0.0235" rpy="-1.5708 -3.88578e-16 3.33067e-16" />
<parent link="head" />
<child link="imu_frame_2" />
<axis xyz="0 0 0"/>
</joint>

<joint name="HeadTilt" type="revolute">
<origin xyz="0.036 0.0235 -0.024" rpy="-1.5708 3.17216e-15 -5.33479e-15" />
<parent link="neck" />
<child link="head" />
<axis xyz="0 0 -1"/>
<limit effort="5.43" velocity="10.33" lower="-0.523599" upper="1.5708"/>
<dynamics friction="0" damping="0.53"/>
</joint>

<joint name="HeadPan" type="revolute">
<origin xyz="-0.0095 2.82644e-16 0.2345" rpy="-3.14159 3.41087e-16 -4.44089e-16" />
<parent link="torso" />
<child link="neck" />
<axis xyz="0 0 1"/>
<limit effort="5.43" velocity="10.33" lower="-2.0944" upper="2.0944"/>
<dynamics friction="0" damping="0.53"/>
</joint>

<xacro:arg name="use_fake_walk" default="False"/>
<xacro:property name="fake_walk" value="$(arg use_fake_walk)" />
<xacro:arg name="sim_ns" default="/" />

<transmission name="HeadPanTransmission">
<type>transmission_interface/SimpleTransmission</type>
<joint name="HeadPan">
    <hardwareInterface>hardware_interface/EffortJointInterface</hardwareInterface>
</joint>
<actuator name="HeadPanMotor">
    <hardwareInterface>hardware_interface/EffortJointInterface</hardwareInterface>
    <mechanicalReduction>1</mechanicalReduction>
</actuator>
</transmission>
<transmission name="HeadTiltTransmission">
<type>transmission_interface/SimpleTransmission</type>
<joint name="HeadTilt">
    <hardwareInterface>hardware_interface/EffortJointInterface</hardwareInterface>
</joint>
<actuator name="HeadTiltMotor">
    <hardwareInterface>hardware_interface/EffortJointInterface</hardwareInterface>
    <mechanicalReduction>1</mechanicalReduction>
</actuator>
</transmission>
<transmission name="LShoulderPitchTransmission">
<type>transmission_interface/SimpleTransmission</type>
<joint name="LShoulderPitch">
    <hardwareInterface>hardware_interface/EffortJointInterface</hardwareInterface>
</joint>
<actuator name="LShoulderPitchMotor">
    <hardwareInterface>hardware_interface/EffortJointInterface</hardwareInterface>
    <mechanicalReduction>1</mechanicalReduction>
</actuator>
</transmission>
<transmission name="LShoulderRollTransmission">
<type>transmission_interface/SimpleTransmission</type>
<joint name="LShoulderRoll">
    <hardwareInterface>hardware_interface/EffortJointInterface</hardwareInterface>
</joint>
<actuator name="LShoulderRollTransmission">
    <hardwareInterface>hardware_interface/EffortJointInterface</hardwareInterface>
    <mechanicalReduction>1</mechanicalReduction>
</actuator>
</transmission>
<transmission name="LElbowTransmission">
<type>transmission_interface/SimpleTransmission</type>
<joint name="LElbow">
    <hardwareInterface>hardware_interface/EffortJointInterface</hardwareInterface>
</joint>
<actuator name="LElbowMotor">
    <hardwareInterface>hardware_interface/EffortJointInterface</hardwareInterface>
    <mechanicalReduction>1</mechanicalReduction>
</actuator>
</transmission>
<transmission name="RShoulderPitchTransmission">
<type>transmission_interface/SimpleTransmission</type>
<joint name="RShoulderPitch">
    <hardwareInterface>hardware_interface/EffortJointInterface</hardwareInterface>
</joint>
<actuator name="RShoulderPitchMotor">
    <hardwareInterface>hardware_interface/EffortJointInterface</hardwareInterface>
    <mechanicalReduction>1</mechanicalReduction>
</actuator>
</transmission>
<transmission name="RShoulderRollTransmission">
<type>transmission_interface/SimpleTransmission</type>
<joint name="RShoulderRoll">
    <hardwareInterface>hardware_interface/EffortJointInterface</hardwareInterface>
</joint>
<actuator name="RShoulderRollMotor">
    <hardwareInterface>hardware_interface/EffortJointInterface</hardwareInterface>
    <mechanicalReduction>1</mechanicalReduction>
</actuator>
</transmission>
<transmission name="RElbowTransmission">
<type>transmission_interface/SimpleTransmission</type>
<joint name="RElbow">
    <hardwareInterface>hardware_interface/EffortJointInterface</hardwareInterface>
</joint>
<actuator name="RElbowMotor">
    <hardwareInterface>hardware_interface/EffortJointInterface</hardwareInterface>
    <mechanicalReduction>1</mechanicalReduction>
</actuator>
</transmission>
<transmission name="LHipYawTransmission">
<type>transmission_interface/SimpleTransmission</type>
<joint name="LHipYaw">
    <hardwareInterface>hardware_interface/EffortJointInterface</hardwareInterface>
</joint>
<actuator name="LHipYawMotor">
    <hardwareInterface>hardware_interface/EffortJointInterface</hardwareInterface>
    <mechanicalReduction>1</mechanicalReduction>
</actuator>
</transmission>
<transmission name="LHipRollTransmission">
<type>transmission_interface/SimpleTransmission</type>
<joint name="LHipRoll">
    <hardwareInterface>hardware_interface/EffortJointInterface</hardwareInterface>
</joint>
<actuator name="LHipRollMotor">
    <hardwareInterface>hardware_interface/EffortJointInterface</hardwareInterface>
    <mechanicalReduction>1</mechanicalReduction>
</actuator>
</transmission>
<transmission name="LHipPitchTransmission">
<type>transmission_interface/SimpleTransmission</type>
<joint name="LHipPitch">
    <hardwareInterface>hardware_interface/EffortJointInterface</hardwareInterface>
</joint>
<actuator name="LHipPitchMotor">
    <hardwareInterface>hardware_interface/EffortJointInterface</hardwareInterface>
    <mechanicalReduction>1</mechanicalReduction>
</actuator>
</transmission>
<transmission name="LKneeTransmission">
<type>transmission_interface/SimpleTransmission</type>
<joint name="LKnee">
    <hardwareInterface>hardware_interface/EffortJointInterface</hardwareInterface>
</joint>
<actuator name="LKneeMotor">
    <hardwareInterface>hardware_interface/EffortJointInterface</hardwareInterface>
    <mechanicalReduction>1</mechanicalReduction>
</actuator>
</transmission>
<transmission name="LAnklePitchTransmission">
<type>transmission_interface/SimpleTransmission</type>
<joint name="LAnklePitch">
    <hardwareInterface>hardware_interface/EffortJointInterface</hardwareInterface>
</joint>
<actuator name="LAnklePitchMotor">
    <hardwareInterface>hardware_interface/EffortJointInterface</hardwareInterface>
    <mechanicalReduction>1</mechanicalReduction>
</actuator>
</transmission>
<transmission name="LAnkleRollTransmission">
<type>transmission_interface/SimpleTransmission</type>
<joint name="LAnkleRoll">
    <hardwareInterface>hardware_interface/EffortJointInterface</hardwareInterface>
</joint>
<actuator name="LAnkleRollMotor">
    <hardwareInterface>hardware_interface/EffortJointInterface</hardwareInterface>
    <mechanicalReduction>1</mechanicalReduction>
</actuator>
</transmission>
<transmission name="RHipYawTransmission">
<type>transmission_interface/SimpleTransmission</type>
<joint name="RHipYaw">
    <hardwareInterface>hardware_interface/EffortJointInterface</hardwareInterface>
</joint>
<actuator name="RHipYawMotor">
    <hardwareInterface>hardware_interface/EffortJointInterface</hardwareInterface>
    <mechanicalReduction>1</mechanicalReduction>
</actuator>
</transmission>
<transmission name="RHipRollTransmission">
<type>transmission_interface/SimpleTransmission</type>
<joint name="RHipRoll">
    <hardwareInterface>hardware_interface/EffortJointInterface</hardwareInterface>
</joint>
<actuator name="RHipRollMotor">
    <hardwareInterface>hardware_interface/EffortJointInterface</hardwareInterface>
    <mechanicalReduction>1</mechanicalReduction>
</actuator>
</transmission>
<transmission name="RHipPitchTransmission">
<type>transmission_interface/SimpleTransmission</type>
<joint name="RHipPitch">
    <hardwareInterface>hardware_interface/EffortJointInterface</hardwareInterface>
</joint>
<actuator name="RHipPitchMotor">
    <hardwareInterface>hardware_interface/EffortJointInterface</hardwareInterface>
    <mechanicalReduction>1</mechanicalReduction>
</actuator>
</transmission>
<transmission name="RKneeTransmission">
<type>transmission_interface/SimpleTransmission</type>
<joint name="RKnee">
    <hardwareInterface>hardware_interface/EffortJointInterface</hardwareInterface>
</joint>
<actuator name="RKneeMotor">
    <hardwareInterface>hardware_interface/EffortJointInterface</hardwareInterface>
    <mechanicalReduction>1</mechanicalReduction>
</actuator>
</transmission>
<transmission name="RAnklePitchTransmission">
<type>transmission_interface/SimpleTransmission</type>
<joint name="RAnklePitch">
    <hardwareInterface>hardware_interface/EffortJointInterface</hardwareInterface>
</joint>
<actuator name="RAnklePitchMotor">
    <hardwareInterface>hardware_interface/EffortJointInterface</hardwareInterface>
    <mechanicalReduction>1</mechanicalReduction>
</actuator>
</transmission>
<transmission name="RAnkleRollTransmission">
<type>transmission_interface/SimpleTransmission</type>
<joint name="RAnkleRoll">
    <hardwareInterface>hardware_interface/EffortJointInterface</hardwareInterface>
</joint>
<actuator name="RAnkleRollMotor">
    <hardwareInterface>hardware_interface/EffortJointInterface</hardwareInterface>
    <mechanicalReduction>1</mechanicalReduction>
</actuator>
</transmission>
<gazebo reference="r_foot">
<material>Gazebo/FlatBlack</material>
<kp>1000000.0</kp>
<kd>100.0</kd>
<mu1>1.0</mu1>
<mu2>1.0</mu2>
<fdir1>1 0 0</fdir1>
<maxVel>1.0</maxVel>
<minDepth>0.00</minDepth>
</gazebo>
<gazebo reference="l_foot">
<material>Gazebo/FlatBlack</material>
<kp>1000000.0</kp>
<kd>100.0</kd>
<mu1>1.0</mu1>
<mu2>1.0</mu2>
<fdir1>1 0 0</fdir1>
<maxVel>1.0</maxVel>
<minDepth>0.00</minDepth>
</gazebo>

<!-- joint controller -->
<gazebo>
<plugin filename="libgazebo_ros_control.so" name="gazebo_ros_control">
    <robotNamespace>$(arg sim_ns)</robotNamespace>
</plugin>
</gazebo>

<!-- camera sensor -->
<gazebo reference="camera">
    <sensor name='camera' type='camera'>
      <pose>-0.050000 -0.010000 0.000000 -1.5708 0.000000 -3.141592</pose>
      <camera name='__default__'>
        <horizontal_fov>0.57</horizontal_fov>
        <image>
          <width>620</width>
          <height>480</height>
        </image>
        <clip>
          <near>0.001000</near>
          <far>100.000000</far>
        </clip>
      </camera>
      <always_on>1</always_on>
      <update_rate>30.000000</update_rate>
      <visualize>1</visualize>
      <plugin name="camera_controller" filename="libgazebo_ros_camera.so">
        <alwaysOn>true</alwaysOn>
        <updateRate>30</updateRate>
        <cameraName>camera</cameraName>
        <imageTopicName>image_raw</imageTopicName>
        <cameraInfoTopicName>camera_info</cameraInfoTopicName>
        <frameName>camera_optical_frame</frameName>
        <hackBaseline>0.07</hackBaseline>
        <distortionK1>0.0</distortionK1>
        <distortionK2>0.0</distortionK2>
        <distortionK3>0.0</distortionK3>
        <distortionT1>0.0</distortionT1>
        <distortionT2>0.0</distortionT2>
      </plugin>
    </sensor>
</gazebo>


<!-- IMU sensor -->
<gazebo reference="imu_frame">
    <gravity>true</gravity>
    <sensor name="imu_sensor" type="imu">
        <always_on>true</always_on>
        <update_rate>100</update_rate>
        <visualize>true</visualize>
        <topic>__default_topic__</topic>
        <plugin filename="libgazebo_ros_imu_sensor.so" name="imu_plugin">
            <topicName>imu</topicName>
            <bodyName>imu_frame</bodyName>
            <updateRateHZ>100.0</updateRateHZ>
            <gaussianNoise>0.0</gaussianNoise>
            <xyzOffset>0 0 0</xyzOffset>
            <rpyOffset>0 0 0</rpyOffset>
            <frameName>imu_frame</frameName>
        </plugin>
        <pose>0 0 0 0 0 0</pose>
    </sensor>
</gazebo>

<!-- force plugins for foot strain gauges -->
<gazebo>
    <plugin filename="libgazebo_ros_f3d.so" name="gazebo_ros_f3d">
        <alwaysOn>true</alwaysOn>
        <updateRate>100.0</updateRate>
        <bodyName>llb</bodyName>
        <topicName>sim_strain_gauges/llb</topicName>
        <robotNamespace>$(arg sim_ns)</robotNamespace>
    </plugin>

    <plugin filename="libgazebo_ros_f3d.so" name="gazebo_ros_f3d">
        <alwaysOn>true</alwaysOn>
        <updateRate>100.0</updateRate>
        <bodyName>llf</bodyName>
        <topicName>sim_strain_gauges/llf</topicName>
        <robotNamespace>$(arg sim_ns)</robotNamespace>
    </plugin>

    <plugin filename="libgazebo_ros_f3d.so" name="gazebo_ros_f3d">
        <alwaysOn>true</alwaysOn>
        <updateRate>100.0</updateRate>
        <bodyName>lrf</bodyName>
        <topicName>sim_strain_gauges/lrf</topicName>
        <robotNamespace>$(arg sim_ns)</robotNamespace>
    </plugin>

    <plugin filename="libgazebo_ros_f3d.so" name="gazebo_ros_f3d">
        <alwaysOn>true</alwaysOn>
        <updateRate>100.0</updateRate>
        <bodyName>lrb</bodyName>
        <topicName>sim_strain_gauges/lrb</topicName>
        <robotNamespace>$(arg sim_ns)</robotNamespace>
    </plugin>

    <plugin filename="libgazebo_ros_f3d.so" name="gazebo_ros_f3d">
        <alwaysOn>true</alwaysOn>
        <updateRate>100.0</updateRate>
        <bodyName>rlb</bodyName>
        <topicName>sim_strain_gauges/rlb</topicName>
        <robotNamespace>$(arg sim_ns)</robotNamespace>
    </plugin>

    <plugin filename="libgazebo_ros_f3d.so" name="gazebo_ros_f3d">
        <alwaysOn>true</alwaysOn>
        <updateRate>100.0</updateRate>
        <bodyName>rlf</bodyName>
        <topicName>sim_strain_gauges/rlf</topicName>
        <robotNamespace>$(arg sim_ns)</robotNamespace>
    </plugin>

    <plugin filename="libgazebo_ros_f3d.so" name="gazebo_ros_f3d">
        <alwaysOn>true</alwaysOn>
        <updateRate>100.0</updateRate>
        <bodyName>rrf</bodyName>
        <topicName>sim_strain_gauges/rrf</topicName>
        <robotNamespace>$(arg sim_ns)</robotNamespace>
    </plugin>

    <plugin filename="libgazebo_ros_f3d.so" name="gazebo_ros_f3d">
        <alwaysOn>true</alwaysOn>
        <updateRate>100.0</updateRate>
        <bodyName>rrb</bodyName>
        <topicName>sim_strain_gauges/rrb</topicName>
        <robotNamespace>$(arg sim_ns)</robotNamespace>
    </plugin>
</gazebo>

<!-- fake controller that allows us to move the robot and to get its oposition -->
<!-- rostopic pub /cmd_vel geometry_msgs/Twist "{ linear: [ 0.1, 0, 0], angular: [0.2, 0, 0.1] }" -->
<xacro:if value="${fake_walk == True}">
    <!-- only active when fake_walk param is set to True -->
    <gazebo>
        <plugin name="object_controller" filename="libgazebo_ros_planar_move.so">
            <robotNamespace>/</robotNamespace>
            <commandTopic>cmd_vel</commandTopic>
            <odometryTopic>odom</odometryTopic>
            <odometryFrame>odom</odometryFrame>
            <odometryRate>100.0</odometryRate>
            <robotBaseFrame>base_link</robotBaseFrame>
        </plugin>
    </gazebo>
</xacro:if>

</robot>
