<robot xmlns:xacro="http://www.ros.org/wiki/xacro" name="wolfgang">
<link name="base_link"></link>
<joint name="base_link_to_base" type="fixed">
<parent link="base_link"/>
<child link="body_1" />
<origin rpy="0.0 0 0" xyz="0 0 0"/>
</joint>
<link name="body_1">
<visual>
<origin xyz="-0.0015 0.053 0.2035" rpy="-3.14159 1.5708 0" />
<geometry>
<mesh filename="package://wolfgang_description/urdf/mx-64-body.stl"/>
</geometry>
<material name="mx-64-body_material">
<color rgba="0.247059 0.247059 0.247059 1.0"/>
</material>
</visual>
<collision>
<origin xyz="-0.0015 0.053 0.2035" rpy="-3.14159 1.5708 0" />
<geometry>
<mesh filename="package://wolfgang_description/urdf/mx-64-body.stl"/>
</geometry>
<material name="mx-64-body_material">
<color rgba="0.247059 0.247059 0.247059 1.0"/>
</material>
</collision>
<visual>
<origin xyz="0.058 0.07 0.1455" rpy="1.5708 1.5708 0" />
<geometry>
<mesh filename="package://wolfgang_description/urdf/nuc_holdingrail_left.stl"/>
</geometry>
<material name="nuc_holdingrail_left_material">
<color rgba="0.717647 0.717647 0.717647 1.0"/>
</material>
</visual>
<collision>
<origin xyz="0.058 0.07 0.1455" rpy="1.5708 1.5708 0" />
<geometry>
<mesh filename="package://wolfgang_description/urdf/nuc_holdingrail_left.stl"/>
</geometry>
<material name="nuc_holdingrail_left_material">
<color rgba="0.717647 0.717647 0.717647 1.0"/>
</material>
</collision>
<visual>
<origin xyz="-0.02625 0.0025 0.0275" rpy="1.5708 -0 -1.5708" />
<geometry>
<mesh filename="package://wolfgang_description/urdf/battery_dummy.stl"/>
</geometry>
<material name="battery_dummy_material">
<color rgba="0.615686 0.811765 0.929412 1.0"/>
</material>
</visual>
<collision>
<origin xyz="-0.02625 0.0025 0.0275" rpy="1.5708 -0 -1.5708" />
<geometry>
<mesh filename="package://wolfgang_description/urdf/battery_dummy.stl"/>
</geometry>
<material name="battery_dummy_material">
<color rgba="0.615686 0.811765 0.929412 1.0"/>
</material>
</collision>
<visual>
<origin xyz="-0.0015 -0.053 0.2035" rpy="-1.2326e-32 -1.5708 0" />
<geometry>
<mesh filename="package://wolfgang_description/urdf/mx-64-body.stl"/>
</geometry>
<material name="mx-64-body_material">
<color rgba="0.247059 0.247059 0.247059 1.0"/>
</material>
</visual>
<collision>
<origin xyz="-0.0015 -0.053 0.2035" rpy="-1.2326e-32 -1.5708 0" />
<geometry>
<mesh filename="package://wolfgang_description/urdf/mx-64-body.stl"/>
</geometry>
<material name="mx-64-body_material">
<color rgba="0.247059 0.247059 0.247059 1.0"/>
</material>
</collision>
<visual>
<origin xyz="-2.17271e-16 0.055 0.043" rpy="-1.5708 -0 1.5708" />
<geometry>
<mesh filename="package://wolfgang_description/urdf/router_left.stl"/>
</geometry>
<material name="router_left_material">
<color rgba="0.717647 0.717647 0.717647 1.0"/>
</material>
</visual>
<collision>
<origin xyz="-2.17271e-16 0.055 0.043" rpy="-1.5708 -0 1.5708" />
<geometry>
<mesh filename="package://wolfgang_description/urdf/router_left.stl"/>
</geometry>
<material name="router_left_material">
<color rgba="0.717647 0.717647 0.717647 1.0"/>
</material>
</collision>
<visual>
<origin xyz="-0.057 0.077 0.213915" rpy="-1.5708 6.08341e-17 1.5708" />
<geometry>
<mesh filename="package://wolfgang_description/urdf/torso_bumper_right.stl"/>
</geometry>
<material name="torso_bumper_right_material">
<color rgba="0.717647 0.717647 0.717647 1.0"/>
</material>
</visual>
<collision>
<origin xyz="-0.057 0.077 0.213915" rpy="-1.5708 6.08341e-17 1.5708" />
<geometry>
<mesh filename="package://wolfgang_description/urdf/torso_bumper_right.stl"/>
</geometry>
<material name="torso_bumper_right_material">
<color rgba="0.717647 0.717647 0.717647 1.0"/>
</material>
</collision>
<visual>
<origin xyz="-0.01 0.001 0.118" rpy="-5.55112e-17 8.2173e-33 -1.5708" />
<geometry>
<mesh filename="package://wolfgang_description/urdf/core.stl"/>
</geometry>
<material name="core_material">
<color rgba="0.282353 0.54902 0.160784 1.0"/>
</material>
</visual>
<collision>
<origin xyz="-0.01 0.001 0.118" rpy="-5.55112e-17 8.2173e-33 -1.5708" />
<geometry>
<mesh filename="package://wolfgang_description/urdf/core.stl"/>
</geometry>
<material name="core_material">
<color rgba="0.282353 0.54902 0.160784 1.0"/>
</material>
</collision>
<visual>
<origin xyz="0 -0.055 0.026" rpy="1.5708 -0 -1.5708" />
<geometry>
<mesh filename="package://wolfgang_description/urdf/mx-106_body.stl"/>
</geometry>
<material name="mx-106_body_material">
<color rgba="0.262745 0.282353 0.301961 1.0"/>
</material>
</visual>
<collision>
<origin xyz="0 -0.055 0.026" rpy="1.5708 -0 -1.5708" />
<geometry>
<mesh filename="package://wolfgang_description/urdf/mx-106_body.stl"/>
</geometry>
<material name="mx-106_body_material">
<color rgba="0.262745 0.282353 0.301961 1.0"/>
</material>
</collision>
<visual>
<origin xyz="0.053 0.077 0.213915" rpy="-1.5708 -6.08341e-17 -1.5708" />
<geometry>
<mesh filename="package://wolfgang_description/urdf/torso_bumper_left.stl"/>
</geometry>
<material name="torso_bumper_left_material">
<color rgba="0.717647 0.717647 0.717647 1.0"/>
</material>
</visual>
<collision>
<origin xyz="0.053 0.077 0.213915" rpy="-1.5708 -6.08341e-17 -1.5708" />
<geometry>
<mesh filename="package://wolfgang_description/urdf/torso_bumper_left.stl"/>
</geometry>
<material name="torso_bumper_left_material">
<color rgba="0.717647 0.717647 0.717647 1.0"/>
</material>
</collision>
<visual>
<origin xyz="-2.2754e-16 0.055 0.026" rpy="1.5708 -0 -1.5708" />
<geometry>
<mesh filename="package://wolfgang_description/urdf/mx-106_body.stl"/>
</geometry>
<material name="mx-106_body_material">
<color rgba="0.262745 0.282353 0.301961 1.0"/>
</material>
</visual>
<collision>
<origin xyz="-2.2754e-16 0.055 0.026" rpy="1.5708 -0 -1.5708" />
<geometry>
<mesh filename="package://wolfgang_description/urdf/mx-106_body.stl"/>
</geometry>
<material name="mx-106_body_material">
<color rgba="0.262745 0.282353 0.301961 1.0"/>
</material>
</collision>
<visual>
<origin xyz="0.00265 -0.0001 0.1455" rpy="1.11022e-16 1.0261e-16 1.5708" />
<geometry>
<mesh filename="package://wolfgang_description/urdf/nuc_bottom.stl"/>
</geometry>
<material name="nuc_bottom_material">
<color rgba="0.301961 0.301961 0.301961 1.0"/>
</material>
</visual>
<collision>
<origin xyz="0.00265 -0.0001 0.1455" rpy="1.11022e-16 1.0261e-16 1.5708" />
<geometry>
<mesh filename="package://wolfgang_description/urdf/nuc_bottom.stl"/>
</geometry>
<material name="nuc_bottom_material">
<color rgba="0.301961 0.301961 0.301961 1.0"/>
</material>
</collision>
<visual>
<origin xyz="-0.0015 -0.036 0.2035" rpy="-3.14159 1.5708 0" />
<geometry>
<mesh filename="package://wolfgang_description/urdf/imu_holder.stl"/>
</geometry>
<material name="imu_holder_material">
<color rgba="0.717647 0.717647 0.717647 1.0"/>
</material>
</visual>
<collision>
<origin xyz="-0.0015 -0.036 0.2035" rpy="-3.14159 1.5708 0" />
<geometry>
<mesh filename="package://wolfgang_description/urdf/imu_holder.stl"/>
</geometry>
<material name="imu_holder_material">
<color rgba="0.717647 0.717647 0.717647 1.0"/>
</material>
</collision>
<visual>
<origin xyz="0.00265 -0.0001 0.1455" rpy="1.66533e-16 -1.9123e-16 1.5708" />
<geometry>
<mesh filename="package://wolfgang_description/urdf/nuc_front.stl"/>
</geometry>
<material name="nuc_front_material">
<color rgba="0.4 0.4 0.4 1.0"/>
</material>
</visual>
<collision>
<origin xyz="0.00265 -0.0001 0.1455" rpy="1.66533e-16 -1.9123e-16 1.5708" />
<geometry>
<mesh filename="package://wolfgang_description/urdf/nuc_front.stl"/>
</geometry>
<material name="nuc_front_material">
<color rgba="0.4 0.4 0.4 1.0"/>
</material>
</collision>
<visual>
<origin xyz="-0.062 0.075 0.003" rpy="0 -0 0" />
<geometry>
<mesh filename="package://wolfgang_description/urdf/torso_bottom.stl"/>
</geometry>
<material name="torso_bottom_material">
<color rgba="0.717647 0.717647 0.717647 1.0"/>
</material>
</visual>
<collision>
<origin xyz="-0.062 0.075 0.003" rpy="0 -0 0" />
<geometry>
<mesh filename="package://wolfgang_description/urdf/torso_bottom.stl"/>
</geometry>
<material name="torso_bottom_material">
<color rgba="0.717647 0.717647 0.717647 1.0"/>
</material>
</collision>
<visual>
<origin xyz="-0.037 -0.0478 0.2141" rpy="3.14159 5.34761e-17 -1.5708" />
<geometry>
<mesh filename="package://wolfgang_description/urdf/imu_bottom_cover.stl"/>
</geometry>
<material name="imu_bottom_cover_material">
<color rgba="0.717647 0.717647 0.717647 1.0"/>
</material>
</visual>
<collision>
<origin xyz="-0.037 -0.0478 0.2141" rpy="3.14159 5.34761e-17 -1.5708" />
<geometry>
<mesh filename="package://wolfgang_description/urdf/imu_bottom_cover.stl"/>
</geometry>
<material name="imu_bottom_cover_material">
<color rgba="0.717647 0.717647 0.717647 1.0"/>
</material>
</collision>
<visual>
<origin xyz="-0.0095 2.94903e-16 0.211" rpy="-1.5708 -0 1.5708" />
<geometry>
<mesh filename="package://wolfgang_description/urdf/mx-64-body.stl"/>
</geometry>
<material name="mx-64-body_material">
<color rgba="0.247059 0.247059 0.247059 1.0"/>
</material>
</visual>
<collision>
<origin xyz="-0.0095 2.94903e-16 0.211" rpy="-1.5708 -0 1.5708" />
<geometry>
<mesh filename="package://wolfgang_description/urdf/mx-64-body.stl"/>
</geometry>
<material name="mx-64-body_material">
<color rgba="0.247059 0.247059 0.247059 1.0"/>
</material>
</collision>
<visual>
<origin xyz="1.35075e-15 -0.055 0.043" rpy="-1.5708 1.0261e-16 1.5708" />
<geometry>
<mesh filename="package://wolfgang_description/urdf/router_right.stl"/>
</geometry>
<material name="router_right_material">
<color rgba="0.717647 0.717647 0.717647 1.0"/>
</material>
</visual>
<collision>
<origin xyz="1.35075e-15 -0.055 0.043" rpy="-1.5708 1.0261e-16 1.5708" />
<geometry>
<mesh filename="package://wolfgang_description/urdf/router_right.stl"/>
</geometry>
<material name="router_right_material">
<color rgba="0.717647 0.717647 0.717647 1.0"/>
</material>
</collision>
<visual>
<origin xyz="-0.057 -0.077 0.213915" rpy="-1.5708 -6.08341e-17 1.5708" />
<geometry>
<mesh filename="package://wolfgang_description/urdf/torso_bumper_left.stl"/>
</geometry>
<material name="torso_bumper_left_material">
<color rgba="0.717647 0.717647 0.717647 1.0"/>
</material>
</visual>
<collision>
<origin xyz="-0.057 -0.077 0.213915" rpy="-1.5708 -6.08341e-17 1.5708" />
<geometry>
<mesh filename="package://wolfgang_description/urdf/torso_bumper_left.stl"/>
</geometry>
<material name="torso_bumper_left_material">
<color rgba="0.717647 0.717647 0.717647 1.0"/>
</material>
</collision>
<visual>
<origin xyz="-0.002 -3.19189e-16 0.088" rpy="-5.55112e-17 -1.64346e-32 -1.5708" />
<geometry>
<mesh filename="package://wolfgang_description/urdf/baseplate_odroid_xu4_core.stl"/>
</geometry>
<material name="baseplate_odroid_xu4_core_material">
<color rgba="0.717647 0.717647 0.717647 1.0"/>
</material>
</visual>
<collision>
<origin xyz="-0.002 -3.19189e-16 0.088" rpy="-5.55112e-17 -1.64346e-32 -1.5708" />
<geometry>
<mesh filename="package://wolfgang_description/urdf/baseplate_odroid_xu4_core.stl"/>
</geometry>
<material name="baseplate_odroid_xu4_core_material">
<color rgba="0.717647 0.717647 0.717647 1.0"/>
</material>
</collision>
<visual>
<origin xyz="0.051 0.0367 0.057" rpy="-1.5708 6.91935e-17 -1.5708" />
<geometry>
<mesh filename="package://wolfgang_description/urdf/router.stl"/>
</geometry>
<material name="router_material">
<color rgba="0.717647 0.717647 0.717647 1.0"/>
</material>
</visual>
<collision>
<origin xyz="0.051 0.0367 0.057" rpy="-1.5708 6.91935e-17 -1.5708" />
<geometry>
<mesh filename="package://wolfgang_description/urdf/router.stl"/>
</geometry>
<material name="router_material">
<color rgba="0.717647 0.717647 0.717647 1.0"/>
</material>
</collision>
<visual>
<origin xyz="0.00265 -0.0001 0.1455" rpy="1.11022e-16 2.83582e-16 1.5708" />
<geometry>
<mesh filename="package://wolfgang_description/urdf/nuc_main.stl"/>
</geometry>
<material name="nuc_main_material">
<color rgba="0.603922 0.647059 0.686275 1.0"/>
</material>
</visual>
<collision>
<origin xyz="0.00265 -0.0001 0.1455" rpy="1.11022e-16 2.83582e-16 1.5708" />
<geometry>
<mesh filename="package://wolfgang_description/urdf/nuc_main.stl"/>
</geometry>
<material name="nuc_main_material">
<color rgba="0.603922 0.647059 0.686275 1.0"/>
</material>
</collision>
<visual>
<origin xyz="0.053 -0.077 0.213915" rpy="-1.5708 6.08341e-17 -1.5708" />
<geometry>
<mesh filename="package://wolfgang_description/urdf/torso_bumper_right.stl"/>
</geometry>
<material name="torso_bumper_right_material">
<color rgba="0.717647 0.717647 0.717647 1.0"/>
</material>
</visual>
<collision>
<origin xyz="0.053 -0.077 0.213915" rpy="-1.5708 6.08341e-17 -1.5708" />
<geometry>
<mesh filename="package://wolfgang_description/urdf/torso_bumper_right.stl"/>
</geometry>
<material name="torso_bumper_right_material">
<color rgba="0.717647 0.717647 0.717647 1.0"/>
</material>
</collision>
<visual>
<origin xyz="0.058 -0.07 0.1455" rpy="1.5708 1.5708 0" />
<geometry>
<mesh filename="package://wolfgang_description/urdf/nuc_holdingrail_right.stl"/>
</geometry>
<material name="nuc_holdingrail_right_material">
<color rgba="0.717647 0.717647 0.717647 1.0"/>
</material>
</visual>
<collision>
<origin xyz="0.058 -0.07 0.1455" rpy="1.5708 1.5708 0" />
<geometry>
<mesh filename="package://wolfgang_description/urdf/nuc_holdingrail_right.stl"/>
</geometry>
<material name="nuc_holdingrail_right_material">
<color rgba="0.717647 0.717647 0.717647 1.0"/>
</material>
</collision>
<visual>
<origin xyz="-0.077 -0.075 0.083" rpy="0 -0 1.5708" />
<geometry>
<mesh filename="package://wolfgang_description/urdf/torso_top.stl"/>
</geometry>
<material name="torso_top_material">
<color rgba="0.717647 0.717647 0.717647 1.0"/>
</material>
</visual>
<collision>
<origin xyz="-0.077 -0.075 0.083" rpy="0 -0 1.5708" />
<geometry>
<mesh filename="package://wolfgang_description/urdf/torso_top.stl"/>
</geometry>
<material name="torso_top_material">
<color rgba="0.717647 0.717647 0.717647 1.0"/>
</material>
</collision>
<inertial>
<origin xyz="-0.00177581 -9.7212e-05 0.107062" rpy="0 0 0"/>
<mass value="1.79116" />
<inertia ixx="0.0165883" ixy="5.67507e-06"  ixz="-0.000843992" iyy="0.0143606" iyz="0.000156333" izz="0.00676935" />
</inertial>
</link>

<link name="imu_frame">
<inertial>
<origin xyz="0 0 0" rpy="0 0 0" />
<mass value="1e-9" />
<inertia ixx="0" ixy="0" ixz="0" iyy="0" iyz="0" izz="0" />
</inertial>
</link>
<joint name="imu_frame_frame" type="fixed">
<origin xyz="-0.0367504 -0.0478024 0.224" rpy="5.31321e-16 -3.12873e-17 4.65401e-17" />
<parent link="body_1" />
<child link="imu_frame" />
<axis xyz="0 0 0"/>
</joint>

<link name="shoulder_right_1">
<visual>
<origin xyz="-0.02595 0.042 2.77556e-17" rpy="-1.5708 2.89513e-24 1.5708" />
<geometry>
<mesh filename="package://wolfgang_description/urdf/sea_connector.stl"/>
</geometry>
<material name="sea_connector_material">
<color rgba="0.262745 0.282353 0.301961 1.0"/>
</material>
</visual>
<collision>
<origin xyz="-0.02595 0.042 2.77556e-17" rpy="-1.5708 2.89513e-24 1.5708" />
<geometry>
<mesh filename="package://wolfgang_description/urdf/sea_connector.stl"/>
</geometry>
<material name="sea_connector_material">
<color rgba="0.262745 0.282353 0.301961 1.0"/>
</material>
</collision>
<visual>
<origin xyz="-0.01695 0.042 8.32667e-17" rpy="-1.5708 2.89513e-24 1.5708" />
<geometry>
<mesh filename="package://wolfgang_description/urdf/sea_ninjaflex.stl"/>
</geometry>
<material name="sea_ninjaflex_material">
<color rgba="0.717647 0.717647 0.717647 1.0"/>
</material>
</visual>
<collision>
<origin xyz="-0.01695 0.042 8.32667e-17" rpy="-1.5708 2.89513e-24 1.5708" />
<geometry>
<mesh filename="package://wolfgang_description/urdf/sea_ninjaflex.stl"/>
</geometry>
<material name="sea_ninjaflex_material">
<color rgba="0.717647 0.717647 0.717647 1.0"/>
</material>
</collision>
<visual>
<origin xyz="0 0 2.77556e-17" rpy="2.4048e-34 -1.72563e-31 -1.5783e-33" />
<geometry>
<mesh filename="package://wolfgang_description/urdf/shoulder_connector.stl"/>
</geometry>
<material name="shoulder_connector_material">
<color rgba="0.717647 0.717647 0.717647 1.0"/>
</material>
</visual>
<collision>
<origin xyz="0 0 2.77556e-17" rpy="2.4048e-34 -1.72563e-31 -1.5783e-33" />
<geometry>
<mesh filename="package://wolfgang_description/urdf/shoulder_connector.stl"/>
</geometry>
<material name="shoulder_connector_material">
<color rgba="0.717647 0.717647 0.717647 1.0"/>
</material>
</collision>
<inertial>
<origin xyz="-0.0135397 0.0284022 -1.54699e-06" rpy="0 0 0"/>
<mass value="0.041445" />
<inertia ixx="1.85473e-05" ixy="7.63058e-06"  ixz="-9.41386e-10" iyy="2.76649e-05" iyz="8.71825e-10" izz="3.49573e-05" />
</inertial>
</link>

<link name="upper_arm_1">
<visual>
<origin xyz="1.38778e-17 1.11022e-16 -0.0235" rpy="-1.5708 4.16334e-16 -2.10942e-15" />
<geometry>
<mesh filename="package://wolfgang_description/urdf/mx-64-body.stl"/>
</geometry>
<material name="mx-64-body_material">
<color rgba="0.247059 0.247059 0.247059 1.0"/>
</material>
</visual>
<collision>
<origin xyz="1.38778e-17 1.11022e-16 -0.0235" rpy="-1.5708 4.16334e-16 -2.10942e-15" />
<geometry>
<mesh filename="package://wolfgang_description/urdf/mx-64-body.stl"/>
</geometry>
<material name="mx-64-body_material">
<color rgba="0.247059 0.247059 0.247059 1.0"/>
</material>
</collision>
<visual>
<origin xyz="0.0265 -0.144 -0.0235" rpy="-1.5708 -1.5708 0" />
<geometry>
<mesh filename="package://wolfgang_description/urdf/upper_arm.stl"/>
</geometry>
<material name="upper_arm_material">
<color rgba="0.960784 0.960784 0.960784 1.0"/>
</material>
</visual>
<collision>
<origin xyz="0.0265 -0.144 -0.0235" rpy="-1.5708 -1.5708 0" />
<geometry>
<mesh filename="package://wolfgang_description/urdf/upper_arm.stl"/>
</geometry>
<material name="upper_arm_material">
<color rgba="0.960784 0.960784 0.960784 1.0"/>
</material>
</collision>
<visual>
<origin xyz="-0.0147 -0.0105 -0.0235" rpy="-1.5708 -8.88178e-16 1.5708" />
<geometry>
<mesh filename="package://wolfgang_description/urdf/connector_shoulder.stl"/>
</geometry>
<material name="connector_shoulder_material">
<color rgba="0.717647 0.717647 0.717647 1.0"/>
</material>
</visual>
<collision>
<origin xyz="-0.0147 -0.0105 -0.0235" rpy="-1.5708 -8.88178e-16 1.5708" />
<geometry>
<mesh filename="package://wolfgang_description/urdf/connector_shoulder.stl"/>
</geometry>
<material name="connector_shoulder_material">
<color rgba="0.717647 0.717647 0.717647 1.0"/>
</material>
</collision>
<visual>
<origin xyz="-0.0265 -0.144 -0.0235" rpy="-1.5708 1.5708 0" />
<geometry>
<mesh filename="package://wolfgang_description/urdf/upper_arm.stl"/>
</geometry>
<material name="upper_arm_material">
<color rgba="0.960784 0.960784 0.960784 1.0"/>
</material>
</visual>
<collision>
<origin xyz="-0.0265 -0.144 -0.0235" rpy="-1.5708 1.5708 0" />
<geometry>
<mesh filename="package://wolfgang_description/urdf/upper_arm.stl"/>
</geometry>
<material name="upper_arm_material">
<color rgba="0.960784 0.960784 0.960784 1.0"/>
</material>
</collision>
<visual>
<origin xyz="0.0147 -0.0105 -0.0235" rpy="1.5708 -8.88178e-16 1.5708" />
<geometry>
<mesh filename="package://wolfgang_description/urdf/connector_shoulder.stl"/>
</geometry>
<material name="connector_shoulder_material">
<color rgba="0.717647 0.717647 0.717647 1.0"/>
</material>
</visual>
<collision>
<origin xyz="0.0147 -0.0105 -0.0235" rpy="1.5708 -8.88178e-16 1.5708" />
<geometry>
<mesh filename="package://wolfgang_description/urdf/connector_shoulder.stl"/>
</geometry>
<material name="connector_shoulder_material">
<color rgba="0.717647 0.717647 0.717647 1.0"/>
</material>
</collision>
<inertial>
<origin xyz="6.71448e-10 -0.0286557 -0.0235557" rpy="0 0 0"/>
<mass value="0.206164" />
<inertia ixx="0.000204986" ixy="1.94871e-12"  ixz="3.40342e-12" iyy="0.000171949" iyz="-3.58687e-07" izz="0.000333232" />
</inertial>
</link>

<link name="lower_arm_right_1">
<visual>
<origin xyz="3.19189e-16 -0.163682 -0.0065" rpy="-1.5708 -1.02349e-15 -3.14159" />
<geometry>
<mesh filename="package://wolfgang_description/urdf/lower_arm.stl"/>
</geometry>
<material name="lower_arm_material">
<color rgba="0.960784 0.960784 0.960784 1.0"/>
</material>
</visual>
<collision>
<origin xyz="3.19189e-16 -0.163682 -0.0065" rpy="-1.5708 -1.02349e-15 -3.14159" />
<geometry>
<mesh filename="package://wolfgang_description/urdf/lower_arm.stl"/>
</geometry>
<material name="lower_arm_material">
<color rgba="0.960784 0.960784 0.960784 1.0"/>
</material>
</collision>
<visual>
<origin xyz="0 -3.46945e-18 -0.0235" rpy="-1.5708 5.6205e-16 -5.30016e-31" />
<geometry>
<mesh filename="package://wolfgang_description/urdf/mx-64-body.stl"/>
</geometry>
<material name="mx-64-body_material">
<color rgba="0.247059 0.247059 0.247059 1.0"/>
</material>
</visual>
<collision>
<origin xyz="0 -3.46945e-18 -0.0235" rpy="-1.5708 5.6205e-16 -5.30016e-31" />
<geometry>
<mesh filename="package://wolfgang_description/urdf/mx-64-body.stl"/>
</geometry>
<material name="mx-64-body_material">
<color rgba="0.247059 0.247059 0.247059 1.0"/>
</material>
</collision>
<visual>
<origin xyz="2.70617e-16 -0.163682 -0.0065" rpy="1.5708 1.84661e-15 9.4369e-16" />
<geometry>
<mesh filename="package://wolfgang_description/urdf/hand.stl"/>
</geometry>
<material name="hand_material">
<color rgba="0.647059 0.647059 0.647059 1.0"/>
</material>
</visual>
<collision>
<origin xyz="2.70617e-16 -0.163682 -0.0065" rpy="1.5708 1.84661e-15 9.4369e-16" />
<geometry>
<mesh filename="package://wolfgang_description/urdf/hand.stl"/>
</geometry>
<material name="hand_material">
<color rgba="0.647059 0.647059 0.647059 1.0"/>
</material>
</collision>
<visual>
<origin xyz="2.84495e-16 -0.163682 -0.0425" rpy="-1.5708 -7.02563e-16 -3.14159" />
<geometry>
<mesh filename="package://wolfgang_description/urdf/lower_arm.stl"/>
</geometry>
<material name="lower_arm_material">
<color rgba="0.960784 0.960784 0.960784 1.0"/>
</material>
</visual>
<collision>
<origin xyz="2.84495e-16 -0.163682 -0.0425" rpy="-1.5708 -7.02563e-16 -3.14159" />
<geometry>
<mesh filename="package://wolfgang_description/urdf/lower_arm.stl"/>
</geometry>
<material name="lower_arm_material">
<color rgba="0.960784 0.960784 0.960784 1.0"/>
</material>
</collision>
<inertial>
<origin xyz="0.000436307 -0.0605126 -0.0235553" rpy="0 0 0"/>
<mass value="0.207774" />
<inertia ixx="0.001088" ixy="-1.16188e-06"  ixz="-5.01515e-09" iyy="8.90324e-05" iyz="-3.22666e-08" izz="0.00110076" />
</inertial>
</link>

<link name="r_wrist">
<inertial>
<origin xyz="0 0 0" rpy="0 0 0" />
<mass value="1e-9" />
<inertia ixx="0" ixy="0" ixz="0" iyy="0" iyz="0" izz="0" />
</inertial>
</link>
<joint name="r_wrist_frame" type="fixed">
<origin xyz="3.1225e-16 -0.226182 -0.0235" rpy="1.5708 7.31053e-15 -1.5708" />
<parent link="lower_arm_right_1" />
<child link="r_wrist" />
<axis xyz="0 0 0"/>
</joint>

<joint name="RElbow" type="revolute">
<origin xyz="0.024 -0.144 -0.0235" rpy="-1.5708 1.27676e-15 -1.5708" />
<parent link="upper_arm_1" />
<child link="lower_arm_right_1" />
<axis xyz="0 0 1"/>
<limit effort="6" velocity="6" lower="-1.0472" upper="1.5708"/>
<joint_properties friction="0.0"/>
</joint>

<joint name="RShoulderRoll" type="revolute">
<origin xyz="-0.01695 0.042 0" rpy="1.5708 8.32338e-16 -1.5708" />
<parent link="shoulder_right_1" />
<child link="upper_arm_1" />
<axis xyz="0 0 1"/>
<limit effort="6" velocity="6" lower="-3.14159" upper="0"/>
<joint_properties friction="0.0"/>
</joint>

<joint name="RShoulderPitch" type="revolute">
<origin xyz="-0.0015 -0.0765 0.2035" rpy="-4.34612e-17 1.66533e-15 -3.14159" />
<parent link="body_1" />
<child link="shoulder_right_1" />
<axis xyz="0 -1 0"/>
<limit effort="6" velocity="6" lower="-3.14159" upper="3.14159"/>
<joint_properties friction="0.0"/>
</joint>

<link name="shoulder_left_1">
<visual>
<origin xyz="-0.02595 0.042 0" rpy="1.5708 -2.47462e-18 -1.5708" />
<geometry>
<mesh filename="package://wolfgang_description/urdf/sea_connector.stl"/>
</geometry>
<material name="sea_connector_material">
<color rgba="0.262745 0.282353 0.301961 1.0"/>
</material>
</visual>
<collision>
<origin xyz="-0.02595 0.042 0" rpy="1.5708 -2.47462e-18 -1.5708" />
<geometry>
<mesh filename="package://wolfgang_description/urdf/sea_connector.stl"/>
</geometry>
<material name="sea_connector_material">
<color rgba="0.262745 0.282353 0.301961 1.0"/>
</material>
</collision>
<visual>
<origin xyz="0 0 0" rpy="-1.07025e-32 -0 1.2024e-34" />
<geometry>
<mesh filename="package://wolfgang_description/urdf/shoulder_connector.stl"/>
</geometry>
<material name="shoulder_connector_material">
<color rgba="0.717647 0.717647 0.717647 1.0"/>
</material>
</visual>
<collision>
<origin xyz="0 0 0" rpy="-1.07025e-32 -0 1.2024e-34" />
<geometry>
<mesh filename="package://wolfgang_description/urdf/shoulder_connector.stl"/>
</geometry>
<material name="shoulder_connector_material">
<color rgba="0.717647 0.717647 0.717647 1.0"/>
</material>
</collision>
<visual>
<origin xyz="-0.01695 0.042 0" rpy="1.5708 -2.47462e-18 -1.5708" />
<geometry>
<mesh filename="package://wolfgang_description/urdf/sea_ninjaflex.stl"/>
</geometry>
<material name="sea_ninjaflex_material">
<color rgba="0.717647 0.717647 0.717647 1.0"/>
</material>
</visual>
<collision>
<origin xyz="-0.01695 0.042 0" rpy="1.5708 -2.47462e-18 -1.5708" />
<geometry>
<mesh filename="package://wolfgang_description/urdf/sea_ninjaflex.stl"/>
</geometry>
<material name="sea_ninjaflex_material">
<color rgba="0.717647 0.717647 0.717647 1.0"/>
</material>
</collision>
<inertial>
<origin xyz="-0.0135397 0.0284022 1.54699e-06" rpy="0 0 0"/>
<mass value="0.041445" />
<inertia ixx="1.85473e-05" ixy="7.63058e-06"  ixz="9.41386e-10" iyy="2.76649e-05" iyz="-8.71825e-10" izz="3.49573e-05" />
</inertial>
</link>

<link name="upper_arm_2">
<visual>
<origin xyz="1.38778e-17 5.55112e-17 -0.0235" rpy="-1.5708 4.4964e-15 1.1855e-29" />
<geometry>
<mesh filename="package://wolfgang_description/urdf/mx-64-body.stl"/>
</geometry>
<material name="mx-64-body_material">
<color rgba="0.247059 0.247059 0.247059 1.0"/>
</material>
</visual>
<collision>
<origin xyz="1.38778e-17 5.55112e-17 -0.0235" rpy="-1.5708 4.4964e-15 1.1855e-29" />
<geometry>
<mesh filename="package://wolfgang_description/urdf/mx-64-body.stl"/>
</geometry>
<material name="mx-64-body_material">
<color rgba="0.247059 0.247059 0.247059 1.0"/>
</material>
</collision>
<visual>
<origin xyz="-0.0147 -0.0105 -0.0235" rpy="-1.5708 9.99201e-15 1.5708" />
<geometry>
<mesh filename="package://wolfgang_description/urdf/connector_shoulder.stl"/>
</geometry>
<material name="connector_shoulder_material">
<color rgba="0.717647 0.717647 0.717647 1.0"/>
</material>
</visual>
<collision>
<origin xyz="-0.0147 -0.0105 -0.0235" rpy="-1.5708 9.99201e-15 1.5708" />
<geometry>
<mesh filename="package://wolfgang_description/urdf/connector_shoulder.stl"/>
</geometry>
<material name="connector_shoulder_material">
<color rgba="0.717647 0.717647 0.717647 1.0"/>
</material>
</collision>
<visual>
<origin xyz="0.0147 -0.0105 -0.0235" rpy="1.5708 1.02696e-14 1.5708" />
<geometry>
<mesh filename="package://wolfgang_description/urdf/connector_shoulder.stl"/>
</geometry>
<material name="connector_shoulder_material">
<color rgba="0.717647 0.717647 0.717647 1.0"/>
</material>
</visual>
<collision>
<origin xyz="0.0147 -0.0105 -0.0235" rpy="1.5708 1.02696e-14 1.5708" />
<geometry>
<mesh filename="package://wolfgang_description/urdf/connector_shoulder.stl"/>
</geometry>
<material name="connector_shoulder_material">
<color rgba="0.717647 0.717647 0.717647 1.0"/>
</material>
</collision>
<visual>
<origin xyz="-0.0265 -0.144 -0.0235" rpy="-1.5708 1.5708 0" />
<geometry>
<mesh filename="package://wolfgang_description/urdf/upper_arm.stl"/>
</geometry>
<material name="upper_arm_material">
<color rgba="0.960784 0.960784 0.960784 1.0"/>
</material>
</visual>
<collision>
<origin xyz="-0.0265 -0.144 -0.0235" rpy="-1.5708 1.5708 0" />
<geometry>
<mesh filename="package://wolfgang_description/urdf/upper_arm.stl"/>
</geometry>
<material name="upper_arm_material">
<color rgba="0.960784 0.960784 0.960784 1.0"/>
</material>
</collision>
<visual>
<origin xyz="0.0265 -0.144 -0.0235" rpy="-1.5708 -1.5708 0" />
<geometry>
<mesh filename="package://wolfgang_description/urdf/upper_arm.stl"/>
</geometry>
<material name="upper_arm_material">
<color rgba="0.960784 0.960784 0.960784 1.0"/>
</material>
</visual>
<collision>
<origin xyz="0.0265 -0.144 -0.0235" rpy="-1.5708 -1.5708 0" />
<geometry>
<mesh filename="package://wolfgang_description/urdf/upper_arm.stl"/>
</geometry>
<material name="upper_arm_material">
<color rgba="0.960784 0.960784 0.960784 1.0"/>
</material>
</collision>
<inertial>
<origin xyz="6.71449e-10 -0.0286557 -0.0235557" rpy="0 0 0"/>
<mass value="0.206164" />
<inertia ixx="0.000204986" ixy="1.94871e-12"  ixz="3.40342e-12" iyy="0.000171949" iyz="-3.58687e-07" izz="0.000333232" />
</inertial>
</link>

<link name="lower_arm_left_1">
<visual>
<origin xyz="0 -1.73472e-18 -0.0235" rpy="-1.5708 -8.30884e-31 -1.04771e-30" />
<geometry>
<mesh filename="package://wolfgang_description/urdf/mx-64-body.stl"/>
</geometry>
<material name="mx-64-body_material">
<color rgba="0.247059 0.247059 0.247059 1.0"/>
</material>
</visual>
<collision>
<origin xyz="0 -1.73472e-18 -0.0235" rpy="-1.5708 -8.30884e-31 -1.04771e-30" />
<geometry>
<mesh filename="package://wolfgang_description/urdf/mx-64-body.stl"/>
</geometry>
<material name="mx-64-body_material">
<color rgba="0.247059 0.247059 0.247059 1.0"/>
</material>
</collision>
<visual>
<origin xyz="1.84575e-15 -0.163682 -0.0405" rpy="1.5708 -5.48692e-31 -8.50491e-31" />
<geometry>
<mesh filename="package://wolfgang_description/urdf/lower_arm.stl"/>
</geometry>
<material name="lower_arm_material">
<color rgba="0.960784 0.960784 0.960784 1.0"/>
</material>
</visual>
<collision>
<origin xyz="1.84575e-15 -0.163682 -0.0405" rpy="1.5708 -5.48692e-31 -8.50491e-31" />
<geometry>
<mesh filename="package://wolfgang_description/urdf/lower_arm.stl"/>
</geometry>
<material name="lower_arm_material">
<color rgba="0.960784 0.960784 0.960784 1.0"/>
</material>
</collision>
<visual>
<origin xyz="-5.13478e-16 -0.163682 -0.0405" rpy="-1.5708 5.10009e-16 3.14159" />
<geometry>
<mesh filename="package://wolfgang_description/urdf/hand.stl"/>
</geometry>
<material name="hand_material">
<color rgba="0.647059 0.647059 0.647059 1.0"/>
</material>
</visual>
<collision>
<origin xyz="-5.13478e-16 -0.163682 -0.0405" rpy="-1.5708 5.10009e-16 3.14159" />
<geometry>
<mesh filename="package://wolfgang_description/urdf/hand.stl"/>
</geometry>
<material name="hand_material">
<color rgba="0.647059 0.647059 0.647059 1.0"/>
</material>
</collision>
<visual>
<origin xyz="9.02056e-17 -0.163682 -0.0045" rpy="1.5708 -5.10009e-16 -1.72085e-15" />
<geometry>
<mesh filename="package://wolfgang_description/urdf/lower_arm.stl"/>
</geometry>
<material name="lower_arm_material">
<color rgba="0.960784 0.960784 0.960784 1.0"/>
</material>
</visual>
<collision>
<origin xyz="9.02056e-17 -0.163682 -0.0045" rpy="1.5708 -5.10009e-16 -1.72085e-15" />
<geometry>
<mesh filename="package://wolfgang_description/urdf/lower_arm.stl"/>
</geometry>
<material name="lower_arm_material">
<color rgba="0.960784 0.960784 0.960784 1.0"/>
</material>
</collision>
<inertial>
<origin xyz="-0.000436306 -0.0605126 -0.0235553" rpy="0 0 0"/>
<mass value="0.207774" />
<inertia ixx="0.001088" ixy="-1.14836e-05"  ixz="5.01178e-09" iyy="8.90324e-05" iyz="-3.22666e-08" izz="0.00110076" />
</inertial>
</link>

<link name="l_wrist">
<inertial>
<origin xyz="0 0 0" rpy="0 0 0" />
<mass value="1e-9" />
<inertia ixx="0" ixy="0" ixz="0" iyy="0" iyz="0" izz="0" />
</inertial>
</link>
<joint name="l_wrist_frame" type="fixed">
<origin xyz="2.91434e-16 -0.225182 -0.0235" rpy="-1.5708 6.97876e-16 -1.5708" />
<parent link="lower_arm_left_1" />
<child link="l_wrist" />
<axis xyz="0 0 0"/>
</joint>

<joint name="LElbow" type="revolute">
<origin xyz="-0.024 -0.144 -0.0235" rpy="-1.5708 1.11022e-14 1.5708" />
<parent link="upper_arm_2" />
<child link="lower_arm_left_1" />
<axis xyz="0 0 1"/>
<limit effort="6" velocity="6" lower="-1.5708" upper="1.0472"/>
<joint_properties friction="0.0"/>
</joint>

<joint name="LShoulderRoll" type="revolute">
<origin xyz="-0.01695 0.042 8.32667e-17" rpy="-1.5708 8.42077e-17 1.5708" />
<parent link="shoulder_left_1" />
<child link="upper_arm_2" />
<axis xyz="0 0 1"/>
<limit effort="6" velocity="6" lower="0" upper="3.14159"/>
<joint_properties friction="0.0"/>
</joint>

<joint name="LShoulderPitch" type="revolute">
<origin xyz="-0.0015 0.0765 0.2035" rpy="3.14159 7.77156e-16 3.14159" />
<parent link="body_1" />
<child link="shoulder_left_1" />
<axis xyz="0 -1 0"/>
<limit effort="6" velocity="6" lower="-3.14159" upper="3.14159"/>
<joint_properties friction="0.0"/>
</joint>

<link name="hip_u_connector_1">
<visual>
<origin xyz="0 -0.0006 -0.018" rpy="-5.5278e-33 -0 0" />
<geometry>
<mesh filename="package://wolfgang_description/urdf/hip_u_connector.stl"/>
</geometry>
<material name="hip_u_connector_material">
<color rgba="0.647059 0.647059 0.647059 1.0"/>
</material>
</visual>
<collision>
<origin xyz="0 -0.0006 -0.018" rpy="-5.5278e-33 -0 0" />
<geometry>
<mesh filename="package://wolfgang_description/urdf/hip_u_connector.stl"/>
</geometry>
<material name="hip_u_connector_material">
<color rgba="0.647059 0.647059 0.647059 1.0"/>
</material>
</collision>
<inertial>
<origin xyz="1.20984e-11 0.010315 -1.06799e-07" rpy="0 0 0"/>
<mass value="0.0689735" />
<inertia ixx="2.18955e-05" ixy="-2.44475e-14"  ixz="3.06793e-15" iyy="0.00010714" iyz="-6.56688e-11" izz="0.000110523" />
</inertial>
</link>

<link name="right_hip_left_ankle_1">
<visual>
<origin xyz="0 0 -0.026" rpy="-1.5708 4.34181e-16 -6.8556e-16" />
<geometry>
<mesh filename="package://wolfgang_description/urdf/mx-106_body.stl"/>
</geometry>
<material name="mx-106_body_material">
<color rgba="0.262745 0.282353 0.301961 1.0"/>
</material>
</visual>
<collision>
<origin xyz="0 0 -0.026" rpy="-1.5708 4.34181e-16 -6.8556e-16" />
<geometry>
<mesh filename="package://wolfgang_description/urdf/mx-106_body.stl"/>
</geometry>
<material name="mx-106_body_material">
<color rgba="0.262745 0.282353 0.301961 1.0"/>
</material>
</collision>
<visual>
<origin xyz="-0.0145 -0.021 -0.043" rpy="-3.14159 -3.01408e-17 1.5708" />
<geometry>
<mesh filename="package://wolfgang_description/urdf/motor_connector.stl"/>
</geometry>
<material name="motor_connector_material">
<color rgba="0.647059 0.647059 0.647059 1.0"/>
</material>
</visual>
<collision>
<origin xyz="-0.0145 -0.021 -0.043" rpy="-3.14159 -3.01408e-17 1.5708" />
<geometry>
<mesh filename="package://wolfgang_description/urdf/motor_connector.stl"/>
</geometry>
<material name="motor_connector_material">
<color rgba="0.647059 0.647059 0.647059 1.0"/>
</material>
</collision>
<visual>
<origin xyz="0.014 0.0105 -0.0892" rpy="2.03474e-16 7.21579e-17 -3.14159" />
<geometry>
<mesh filename="package://wolfgang_description/urdf/thrustbearingholder.stl"/>
</geometry>
<material name="thrustbearingholder_material">
<color rgba="0.792157 0.819608 0.933333 1.0"/>
</material>
</visual>
<collision>
<origin xyz="0.014 0.0105 -0.0892" rpy="2.03474e-16 7.21579e-17 -3.14159" />
<geometry>
<mesh filename="package://wolfgang_description/urdf/thrustbearingholder.stl"/>
</geometry>
<material name="thrustbearingholder_material">
<color rgba="0.792157 0.819608 0.933333 1.0"/>
</material>
</collision>
<visual>
<origin xyz="0.0145 0.007 -0.043" rpy="-3.14159 -2.1475e-16 -1.5708" />
<geometry>
<mesh filename="package://wolfgang_description/urdf/motor_connector.stl"/>
</geometry>
<material name="motor_connector_material">
<color rgba="0.647059 0.647059 0.647059 1.0"/>
</material>
</visual>
<collision>
<origin xyz="0.0145 0.007 -0.043" rpy="-3.14159 -2.1475e-16 -1.5708" />
<geometry>
<mesh filename="package://wolfgang_description/urdf/motor_connector.stl"/>
</geometry>
<material name="motor_connector_material">
<color rgba="0.647059 0.647059 0.647059 1.0"/>
</material>
</collision>
<visual>
<origin xyz="-4.22579e-15 -4.16334e-17 -0.0691" rpy="-1.5708 -1.5708 0" />
<geometry>
<mesh filename="package://wolfgang_description/urdf/mx-106_body.stl"/>
</geometry>
<material name="mx-106_body_material">
<color rgba="0.262745 0.282353 0.301961 1.0"/>
</material>
</visual>
<collision>
<origin xyz="-4.22579e-15 -4.16334e-17 -0.0691" rpy="-1.5708 -1.5708 0" />
<geometry>
<mesh filename="package://wolfgang_description/urdf/mx-106_body.stl"/>
</geometry>
<material name="mx-106_body_material">
<color rgba="0.262745 0.282353 0.301961 1.0"/>
</material>
</collision>
<inertial>
<origin xyz="1.38724e-05 -0.0155281 -0.0486407" rpy="0 0 0"/>
<mass value="0.319807" />
<inertia ixx="0.000268627" ixy="6.08561e-08"  ixz="6.67248e-07" iyy="0.000268049" iyz="3.87608e-06" izz="0.000121331" />
</inertial>
</link>

<link name="upper_leg_right_1">
<visual>
<origin xyz="0.0182355 -0.0226528 -0.130164" rpy="-1.5708 -0.523599 3.14159" />
<geometry>
<mesh filename="package://wolfgang_description/urdf/knee_connector.stl"/>
</geometry>
<material name="knee_connector_material">
<color rgba="0.647059 0.647059 0.647059 1.0"/>
</material>
</visual>
<collision>
<origin xyz="0.0182355 -0.0226528 -0.130164" rpy="-1.5708 -0.523599 3.14159" />
<geometry>
<mesh filename="package://wolfgang_description/urdf/knee_connector.stl"/>
</geometry>
<material name="knee_connector_material">
<color rgba="0.647059 0.647059 0.647059 1.0"/>
</material>
</collision>
<visual>
<origin xyz="-3.46945e-18 0.002 0" rpy="2.67816e-33 1.87111e-31 -7.84766e-32" />
<geometry>
<mesh filename="package://wolfgang_description/urdf/upper_leg.stl"/>
</geometry>
<material name="upper_leg_material">
<color rgba="0.647059 0.647059 0.647059 1.0"/>
</material>
</visual>
<collision>
<origin xyz="-3.46945e-18 0.002 0" rpy="2.67816e-33 1.87111e-31 -7.84766e-32" />
<geometry>
<mesh filename="package://wolfgang_description/urdf/upper_leg.stl"/>
</geometry>
<material name="upper_leg_material">
<color rgba="0.647059 0.647059 0.647059 1.0"/>
</material>
</collision>
<visual>
<origin xyz="-0.00392295 -0.053 -0.169043" rpy="-1.5708 -0.523599 3.14159" />
<geometry>
<mesh filename="package://wolfgang_description/urdf/part_1.stl"/>
</geometry>
<material name="part_1_material">
<color rgba="0.615686 0.811765 0.929412 1.0"/>
</material>
</visual>
<collision>
<origin xyz="-0.00392295 -0.053 -0.169043" rpy="-1.5708 -0.523599 3.14159" />
<geometry>
<mesh filename="package://wolfgang_description/urdf/part_1.stl"/>
</geometry>
<material name="part_1_material">
<color rgba="0.615686 0.811765 0.929412 1.0"/>
</material>
</collision>
<visual>
<origin xyz="-0.00392295 -0.0265 -0.169043" rpy="-1.5708 -0.523599 3.14159" />
<geometry>
<mesh filename="package://wolfgang_description/urdf/xh-540.stl"/>
</geometry>
<material name="xh-540_material">
<color rgba="0.498039 0.498039 0.498039 1.0"/>
</material>
</visual>
<collision>
<origin xyz="-0.00392295 -0.0265 -0.169043" rpy="-1.5708 -0.523599 3.14159" />
<geometry>
<mesh filename="package://wolfgang_description/urdf/xh-540.stl"/>
</geometry>
<material name="xh-540_material">
<color rgba="0.498039 0.498039 0.498039 1.0"/>
</material>
</collision>
<visual>
<origin xyz="0.014 -0.055 -0.138" rpy="1.5708 -1.25941e-15 -6.88035e-16" />
<geometry>
<mesh filename="package://wolfgang_description/urdf/spring_holder_upper.stl"/>
</geometry>
<material name="spring_holder_upper_material">
<color rgba="0.647059 0.647059 0.647059 1.0"/>
</material>
</visual>
<collision>
<origin xyz="0.014 -0.055 -0.138" rpy="1.5708 -1.25941e-15 -6.88035e-16" />
<geometry>
<mesh filename="package://wolfgang_description/urdf/spring_holder_upper.stl"/>
</geometry>
<material name="spring_holder_upper_material">
<color rgba="0.647059 0.647059 0.647059 1.0"/>
</material>
</collision>
<visual>
<origin xyz="-0.00392295 -0.002 -0.169043" rpy="-1.5708 -0.523599 3.14159" />
<geometry>
<mesh filename="package://wolfgang_description/urdf/part_1.stl"/>
</geometry>
<material name="part_1_material">
<color rgba="0.615686 0.811765 0.929412 1.0"/>
</material>
</visual>
<collision>
<origin xyz="-0.00392295 -0.002 -0.169043" rpy="-1.5708 -0.523599 3.14159" />
<geometry>
<mesh filename="package://wolfgang_description/urdf/part_1.stl"/>
</geometry>
<material name="part_1_material">
<color rgba="0.615686 0.811765 0.929412 1.0"/>
</material>
</collision>
<visual>
<origin xyz="3.46945e-17 -0.053 6.93889e-18" rpy="8.32667e-17 -8.32667e-17 -7.99057e-16" />
<geometry>
<mesh filename="package://wolfgang_description/urdf/upper_leg.stl"/>
</geometry>
<material name="upper_leg_material">
<color rgba="0.647059 0.647059 0.647059 1.0"/>
</material>
</visual>
<collision>
<origin xyz="3.46945e-17 -0.053 6.93889e-18" rpy="8.32667e-17 -8.32667e-17 -7.99057e-16" />
<geometry>
<mesh filename="package://wolfgang_description/urdf/upper_leg.stl"/>
</geometry>
<material name="upper_leg_material">
<color rgba="0.647059 0.647059 0.647059 1.0"/>
</material>
</collision>
<visual>
<origin xyz="0.0186686 -0.0303472 -0.130414" rpy="-1.5708 0.523599 -8.15765e-16" />
<geometry>
<mesh filename="package://wolfgang_description/urdf/knee_connector.stl"/>
</geometry>
<material name="knee_connector_material">
<color rgba="0.647059 0.647059 0.647059 1.0"/>
</material>
</visual>
<collision>
<origin xyz="0.0186686 -0.0303472 -0.130414" rpy="-1.5708 0.523599 -8.15765e-16" />
<geometry>
<mesh filename="package://wolfgang_description/urdf/knee_connector.stl"/>
</geometry>
<material name="knee_connector_material">
<color rgba="0.647059 0.647059 0.647059 1.0"/>
</material>
</collision>
<inertial>
<origin xyz="0.00466615 -0.0284999 -0.137529" rpy="0 0 0"/>
<mass value="0.220799" />
<inertia ixx="0.000445136" ixy="7.62336e-06"  ixz="2.06864e-05" iyy="0.000405122" iyz="-2.50431e-06" izz="0.000104011" />
</inertial>
</link>

<link name="lower_leg_right_1">
<visual>
<origin xyz="-1.86656e-15 -0.0062 -3.60934e-05" rpy="1.5708 0.0872665 3.72354e-16" />
<geometry>
<mesh filename="package://wolfgang_description/urdf/torsion_spring_sodemann_t105-180-813r.stl"/>
</geometry>
<material name="torsion_spring_sodemann_t105-180-813r_material">
<color rgba="0.490196 0.490196 0.501961 1.0"/>
</material>
</visual>
<collision>
<origin xyz="-1.86656e-15 -0.0062 -3.60934e-05" rpy="1.5708 0.0872665 3.72354e-16" />
<geometry>
<mesh filename="package://wolfgang_description/urdf/torsion_spring_sodemann_t105-180-813r.stl"/>
</geometry>
<material name="torsion_spring_sodemann_t105-180-813r_material">
<color rgba="0.490196 0.490196 0.501961 1.0"/>
</material>
</collision>
<visual>
<origin xyz="0.02797 0.017519 -0.15413" rpy="-5.54324e-33 2.09645e-17 6.20766e-32" />
<geometry>
<mesh filename="package://wolfgang_description/urdf/knee_spacer.stl"/>
</geometry>
<material name="knee_spacer_material">
<color rgba="0.647059 0.647059 0.647059 1.0"/>
</material>
</visual>
<collision>
<origin xyz="0.02797 0.017519 -0.15413" rpy="-5.54324e-33 2.09645e-17 6.20766e-32" />
<geometry>
<mesh filename="package://wolfgang_description/urdf/knee_spacer.stl"/>
</geometry>
<material name="knee_spacer_material">
<color rgba="0.647059 0.647059 0.647059 1.0"/>
</material>
</collision>
<visual>
<origin xyz="0.02797 0.068019 -0.15413" rpy="-2.73358e-17 -4.30156e-17 4.5122e-31" />
<geometry>
<mesh filename="package://wolfgang_description/urdf/knee_spacer.stl"/>
</geometry>
<material name="knee_spacer_material">
<color rgba="0.647059 0.647059 0.647059 1.0"/>
</material>
</visual>
<collision>
<origin xyz="0.02797 0.068019 -0.15413" rpy="-2.73358e-17 -4.30156e-17 4.5122e-31" />
<geometry>
<mesh filename="package://wolfgang_description/urdf/knee_spacer.stl"/>
</geometry>
<material name="knee_spacer_material">
<color rgba="0.647059 0.647059 0.647059 1.0"/>
</material>
</collision>
<visual>
<origin xyz="2.57433e-15 0.0525 -0.17" rpy="-9.91134e-16 -6.88388e-17 -9.66473e-32" />
<geometry>
<mesh filename="package://wolfgang_description/urdf/lower_leg.stl"/>
</geometry>
<material name="lower_leg_material">
<color rgba="0.960784 0.960784 0.960784 1.0"/>
</material>
</visual>
<collision>
<origin xyz="2.57433e-15 0.0525 -0.17" rpy="-9.91134e-16 -6.88388e-17 -9.66473e-32" />
<geometry>
<mesh filename="package://wolfgang_description/urdf/lower_leg.stl"/>
</geometry>
<material name="lower_leg_material">
<color rgba="0.960784 0.960784 0.960784 1.0"/>
</material>
</collision>
<visual>
<origin xyz="2.67147e-15 -0.0015 -0.17" rpy="-4.58562e-16 1.74099e-15 9.4894e-16" />
<geometry>
<mesh filename="package://wolfgang_description/urdf/lower_leg.stl"/>
</geometry>
<material name="lower_leg_material">
<color rgba="0.960784 0.960784 0.960784 1.0"/>
</material>
</visual>
<collision>
<origin xyz="2.67147e-15 -0.0015 -0.17" rpy="-4.58562e-16 1.74099e-15 9.4894e-16" />
<geometry>
<mesh filename="package://wolfgang_description/urdf/lower_leg.stl"/>
</geometry>
<material name="lower_leg_material">
<color rgba="0.960784 0.960784 0.960784 1.0"/>
</material>
</collision>
<visual>
<origin xyz="4.89192e-15 -0.0035 -0.17" rpy="-4.32032e-16 1.82249e-15 9.4894e-16" />
<geometry>
<mesh filename="package://wolfgang_description/urdf/springholder_new.stl"/>
</geometry>
<material name="springholder_new_material">
<color rgba="0.717647 0.717647 0.717647 1.0"/>
</material>
</visual>
<collision>
<origin xyz="4.89192e-15 -0.0035 -0.17" rpy="-4.32032e-16 1.82249e-15 9.4894e-16" />
<geometry>
<mesh filename="package://wolfgang_description/urdf/springholder_new.stl"/>
</geometry>
<material name="springholder_new_material">
<color rgba="0.717647 0.717647 0.717647 1.0"/>
</material>
</collision>
<visual>
<origin xyz="0.0202407 0.0033 0.0613528" rpy="-3.14159 -0.174533 3.14159" />
<geometry>
<mesh filename="package://wolfgang_description/urdf/spring_holder_lower.stl"/>
</geometry>
<material name="spring_holder_lower_material">
<color rgba="0.717647 0.717647 0.717647 1.0"/>
</material>
</visual>
<collision>
<origin xyz="0.0202407 0.0033 0.0613528" rpy="-3.14159 -0.174533 3.14159" />
<geometry>
<mesh filename="package://wolfgang_description/urdf/spring_holder_lower.stl"/>
</geometry>
<material name="spring_holder_lower_material">
<color rgba="0.717647 0.717647 0.717647 1.0"/>
</material>
</collision>
<visual>
<origin xyz="1.8735e-16 -0.0035 -8.04912e-16" rpy="-4.33564e-16 1.82249e-15 9.4894e-16" />
<geometry>
<mesh filename="package://wolfgang_description/urdf/springholder_bottom.stl"/>
</geometry>
<material name="springholder_bottom_material">
<color rgba="0.717647 0.717647 0.717647 1.0"/>
</material>
</visual>
<collision>
<origin xyz="1.8735e-16 -0.0035 -8.04912e-16" rpy="-4.33564e-16 1.82249e-15 9.4894e-16" />
<geometry>
<mesh filename="package://wolfgang_description/urdf/springholder_bottom.stl"/>
</geometry>
<material name="springholder_bottom_material">
<color rgba="0.717647 0.717647 0.717647 1.0"/>
</material>
</collision>
<inertial>
<origin xyz="0.00131527 0.00765262 -0.0457782" rpy="0 0 0"/>
<mass value="0.0842452" />
<inertia ixx="0.000356238" ixy="1.78249e-06"  ixz="-1.06939e-05" iyy="0.00030159" iyz="5.93058e-05" izz="7.37898e-05" />
</inertial>
</link>

<link name="left_hip_right_ankle_1">
<visual>
<origin xyz="-0.0261 -0.021 -0.0405" rpy="1.5708 6.96724e-15 1.5708" />
<geometry>
<mesh filename="package://wolfgang_description/urdf/motor_connector.stl"/>
</geometry>
<material name="motor_connector_material">
<color rgba="0.647059 0.647059 0.647059 1.0"/>
</material>
</visual>
<collision>
<origin xyz="-0.0261 -0.021 -0.0405" rpy="1.5708 6.96724e-15 1.5708" />
<geometry>
<mesh filename="package://wolfgang_description/urdf/motor_connector.stl"/>
</geometry>
<material name="motor_connector_material">
<color rgba="0.647059 0.647059 0.647059 1.0"/>
</material>
</collision>
<visual>
<origin xyz="-0.0431 1.11022e-16 -0.026" rpy="-1.5708 -1.5708 0" />
<geometry>
<mesh filename="package://wolfgang_description/urdf/mx-106_body.stl"/>
</geometry>
<material name="mx-106_body_material">
<color rgba="0.262745 0.282353 0.301961 1.0"/>
</material>
</visual>
<collision>
<origin xyz="-0.0431 1.11022e-16 -0.026" rpy="-1.5708 -1.5708 0" />
<geometry>
<mesh filename="package://wolfgang_description/urdf/mx-106_body.stl"/>
</geometry>
<material name="mx-106_body_material">
<color rgba="0.262745 0.282353 0.301961 1.0"/>
</material>
</collision>
<visual>
<origin xyz="-0.0261 0.007 -0.0115" rpy="-1.5708 -6.16753e-15 -1.5708" />
<geometry>
<mesh filename="package://wolfgang_description/urdf/motor_connector.stl"/>
</geometry>
<material name="motor_connector_material">
<color rgba="0.647059 0.647059 0.647059 1.0"/>
</material>
</visual>
<collision>
<origin xyz="-0.0261 0.007 -0.0115" rpy="-1.5708 -6.16753e-15 -1.5708" />
<geometry>
<mesh filename="package://wolfgang_description/urdf/motor_connector.stl"/>
</geometry>
<material name="motor_connector_material">
<color rgba="0.647059 0.647059 0.647059 1.0"/>
</material>
</collision>
<visual>
<origin xyz="0.0201 0.0105 -0.0109" rpy="-3.14159 1.5708 0" />
<geometry>
<mesh filename="package://wolfgang_description/urdf/thrustbearingholder.stl"/>
</geometry>
<material name="thrustbearingholder_material">
<color rgba="0.792157 0.819608 0.933333 1.0"/>
</material>
</visual>
<collision>
<origin xyz="0.0201 0.0105 -0.0109" rpy="-3.14159 1.5708 0" />
<geometry>
<mesh filename="package://wolfgang_description/urdf/thrustbearingholder.stl"/>
</geometry>
<material name="thrustbearingholder_material">
<color rgba="0.792157 0.819608 0.933333 1.0"/>
</material>
</collision>
<visual>
<origin xyz="-9.71445e-17 5.55112e-17 -0.026" rpy="-1.5708 5.31362e-31 -2.86392e-18" />
<geometry>
<mesh filename="package://wolfgang_description/urdf/mx-106_body.stl"/>
</geometry>
<material name="mx-106_body_material">
<color rgba="0.262745 0.282353 0.301961 1.0"/>
</material>
</visual>
<collision>
<origin xyz="-9.71445e-17 5.55112e-17 -0.026" rpy="-1.5708 5.31362e-31 -2.86392e-18" />
<geometry>
<mesh filename="package://wolfgang_description/urdf/mx-106_body.stl"/>
</geometry>
<material name="mx-106_body_material">
<color rgba="0.262745 0.282353 0.301961 1.0"/>
</material>
</collision>
<inertial>
<origin xyz="-0.0204557 -0.0155281 -0.0260036" rpy="0 0 0"/>
<mass value="0.319807" />
<inertia ixx="0.000116775" ixy="-4.53798e-06"  ixz="6.10986e-07" iyy="0.000268473" iyz="-7.45081e-07" izz="0.000272856" />
</inertial>
</link>

<link name="foot_right_1">
<visual>
<origin xyz="-0.029996 0.00604936 -0.03425" rpy="-1.63098e-15 2.20568e-16 3.73798e-18" />
<geometry>
<mesh filename="package://wolfgang_description/urdf/load_cell.stl"/>
</geometry>
<material name="load_cell_material">
<color rgba="0.717647 0.717647 0.717647 1.0"/>
</material>
</visual>
<collision>
<origin xyz="-0.029996 0.00604936 -0.03425" rpy="-1.63098e-15 2.20568e-16 3.73798e-18" />
<geometry>
<mesh filename="package://wolfgang_description/urdf/load_cell.stl"/>
</geometry>
<material name="load_cell_material">
<color rgba="0.717647 0.717647 0.717647 1.0"/>
</material>
</collision>
<visual>
<origin xyz="0 0.046 -0.036" rpy="-1.10438e-17 1.37914e-31 1.20468e-31" />
<geometry>
<mesh filename="package://wolfgang_description/urdf/ankle.stl"/>
</geometry>
<material name="ankle_material">
<color rgba="0.717647 0.717647 0.717647 1.0"/>
</material>
</visual>
<collision>
<origin xyz="0 0.046 -0.036" rpy="-1.10438e-17 1.37914e-31 1.20468e-31" />
<geometry>
<mesh filename="package://wolfgang_description/urdf/ankle.stl"/>
</geometry>
<material name="ankle_material">
<color rgba="0.717647 0.717647 0.717647 1.0"/>
</material>
</collision>
<visual>
<origin xyz="0.06 0.1635 -0.03425" rpy="7.87577e-16 -8.55971e-17 1.39379e-17" />
<geometry>
<mesh filename="package://wolfgang_description/urdf/load_cell.stl"/>
</geometry>
<material name="load_cell_material">
<color rgba="0.717647 0.717647 0.717647 1.0"/>
</material>
</visual>
<collision>
<origin xyz="0.06 0.1635 -0.03425" rpy="7.87577e-16 -8.55971e-17 1.39379e-17" />
<geometry>
<mesh filename="package://wolfgang_description/urdf/load_cell.stl"/>
</geometry>
<material name="load_cell_material">
<color rgba="0.717647 0.717647 0.717647 1.0"/>
</material>
</collision>
<visual>
<origin xyz="0.037 0.16 -0.0324" rpy="-3.14159 1.29252e-15 -5.35434e-17" />
<geometry>
<mesh filename="package://wolfgang_description/urdf/forcefoot_pcb.stl"/>
</geometry>
<material name="forcefoot_pcb_material">
<color rgba="0.141176 0.52549 0.141176 1.0"/>
</material>
</visual>
<collision>
<origin xyz="0.037 0.16 -0.0324" rpy="-3.14159 1.29252e-15 -5.35434e-17" />
<geometry>
<mesh filename="package://wolfgang_description/urdf/forcefoot_pcb.stl"/>
</geometry>
<material name="forcefoot_pcb_material">
<color rgba="0.141176 0.52549 0.141176 1.0"/>
</material>
</collision>
<visual>
<origin xyz="-0.03 0.1635 -0.03425" rpy="1.53365e-15 1.29252e-15 -5.35434e-17" />
<geometry>
<mesh filename="package://wolfgang_description/urdf/load_cell.stl"/>
</geometry>
<material name="load_cell_material">
<color rgba="0.717647 0.717647 0.717647 1.0"/>
</material>
</visual>
<collision>
<origin xyz="-0.03 0.1635 -0.03425" rpy="1.53365e-15 1.29252e-15 -5.35434e-17" />
<geometry>
<mesh filename="package://wolfgang_description/urdf/load_cell.stl"/>
</geometry>
<material name="load_cell_material">
<color rgba="0.717647 0.717647 0.717647 1.0"/>
</material>
</collision>
<visual>
<origin xyz="0.06 -0.007 -0.04425" rpy="1.36337e-17 2.2372e-15 -1.5708" />
<geometry>
<mesh filename="package://wolfgang_description/urdf/flex_stollen.stl"/>
</geometry>
<material name="flex_stollen_material">
<color rgba="0.615686 0.811765 0.929412 1.0"/>
</material>
</visual>
<collision>
<origin xyz="0.06 -0.007 -0.04425" rpy="1.36337e-17 2.2372e-15 -1.5708" />
<geometry>
<mesh filename="package://wolfgang_description/urdf/flex_stollen.stl"/>
</geometry>
<material name="flex_stollen_material">
<color rgba="0.615686 0.811765 0.929412 1.0"/>
</material>
</collision>
<visual>
<origin xyz="-0.145 0.085 -0.0395" rpy="-3.33669e-15 -3.23e-14 -1.5708" />
<geometry>
<mesh filename="package://wolfgang_description/urdf/foot_printed_right.stl"/>
</geometry>
<material name="foot_printed_right_material">
<color rgba="0.717647 0.717647 0.717647 1.0"/>
</material>
</visual>
<collision>
<origin xyz="-0.145 0.085 -0.0395" rpy="-3.33669e-15 -3.23e-14 -1.5708" />
<geometry>
<mesh filename="package://wolfgang_description/urdf/foot_printed_right.stl"/>
</geometry>
<material name="foot_printed_right_material">
<color rgba="0.717647 0.717647 0.717647 1.0"/>
</material>
</collision>
<visual>
<origin xyz="0.06 0.0065 -0.03425" rpy="-5.44998e-14 -2.30577e-15 3.14159" />
<geometry>
<mesh filename="package://wolfgang_description/urdf/load_cell.stl"/>
</geometry>
<material name="load_cell_material">
<color rgba="0.717647 0.717647 0.717647 1.0"/>
</material>
</visual>
<collision>
<origin xyz="0.06 0.0065 -0.03425" rpy="-5.44998e-14 -2.30577e-15 3.14159" />
<geometry>
<mesh filename="package://wolfgang_description/urdf/load_cell.stl"/>
</geometry>
<material name="load_cell_material">
<color rgba="0.717647 0.717647 0.717647 1.0"/>
</material>
</collision>
<visual>
<origin xyz="-0.03 0.177 -0.04425" rpy="1.40088e-15 -3.40328e-16 -1.5708" />
<geometry>
<mesh filename="package://wolfgang_description/urdf/flex_stollen.stl"/>
</geometry>
<material name="flex_stollen_material">
<color rgba="0.615686 0.811765 0.929412 1.0"/>
</material>
</visual>
<collision>
<origin xyz="-0.03 0.177 -0.04425" rpy="1.40088e-15 -3.40328e-16 -1.5708" />
<geometry>
<mesh filename="package://wolfgang_description/urdf/flex_stollen.stl"/>
</geometry>
<material name="flex_stollen_material">
<color rgba="0.615686 0.811765 0.929412 1.0"/>
</material>
</collision>
<visual>
<origin xyz="-0.029996 -0.00745064 -0.04425" rpy="-9.77723e-17 -1.1503e-15 -1.5708" />
<geometry>
<mesh filename="package://wolfgang_description/urdf/flex_stollen.stl"/>
</geometry>
<material name="flex_stollen_material">
<color rgba="0.615686 0.811765 0.929412 1.0"/>
</material>
</visual>
<collision>
<origin xyz="-0.029996 -0.00745064 -0.04425" rpy="-9.77723e-17 -1.1503e-15 -1.5708" />
<geometry>
<mesh filename="package://wolfgang_description/urdf/flex_stollen.stl"/>
</geometry>
<material name="flex_stollen_material">
<color rgba="0.615686 0.811765 0.929412 1.0"/>
</material>
</collision>
<visual>
<origin xyz="0.06 0.177 -0.04425" rpy="3.06655e-16 4.65859e-16 -1.5708" />
<geometry>
<mesh filename="package://wolfgang_description/urdf/flex_stollen.stl"/>
</geometry>
<material name="flex_stollen_material">
<color rgba="0.615686 0.811765 0.929412 1.0"/>
</material>
</visual>
<collision>
<origin xyz="0.06 0.177 -0.04425" rpy="3.06655e-16 4.65859e-16 -1.5708" />
<geometry>
<mesh filename="package://wolfgang_description/urdf/flex_stollen.stl"/>
</geometry>
<material name="flex_stollen_material">
<color rgba="0.615686 0.811765 0.929412 1.0"/>
</material>
</collision>
<visual>
<origin xyz="0.0234568 0.0618337 -0.0463905" rpy="-1.05977e-17 2.47597e-16 -1.5708" />
<geometry>
<mesh filename="package://wolfgang_description/urdf/foot_cover.stl"/>
</geometry>
<material name="foot_cover_material">
<color rgba="0.647059 0.647059 0.647059 1.0"/>
</material>
</visual>
<collision>
<origin xyz="0.0234568 0.0618337 -0.0463905" rpy="-1.05977e-17 2.47597e-16 -1.5708" />
<geometry>
<mesh filename="package://wolfgang_description/urdf/foot_cover.stl"/>
</geometry>
<material name="foot_cover_material">
<color rgba="0.647059 0.647059 0.647059 1.0"/>
</material>
</collision>
<inertial>
<origin xyz="0.0121001 0.0914942 -0.029994" rpy="0 0 0"/>
<mass value="0.281772" />
<inertia ixx="0.000952692" ixy="-3.29806e-05"  ixz="5.20707e-06" iyy="0.000344273" iyz="-1.94309e-05" izz="0.00124519" />
</inertial>
</link>

<link name="r_sole">
<inertial>
<origin xyz="0 0 0" rpy="0 0 0" />
<mass value="1e-9" />
<inertia ixx="0" ixy="0" ixz="0" iyy="0" iyz="0" izz="0" />
</inertial>
</link>
<joint name="r_sole_frame" type="fixed">
<origin xyz="0.0152261 0.0907683 -0.0529" rpy="3.33669e-15 3.2321e-14 1.5708" />
<parent link="foot_right_1" />
<child link="r_sole" />
<axis xyz="0 0 0"/>
</joint>

<link name="r_cleat_r_front">
<inertial>
<origin xyz="0 0 0" rpy="0 0 0" />
<mass value="1e-9" />
<inertia ixx="0" ixy="0" ixz="0" iyy="0" iyz="0" izz="0" />
</inertial>
</link>
<joint name="r_cleat_r_front_frame" type="fixed">
<origin xyz="0.0595 0.177 -0.05025" rpy="-1.69008e-16 -4.62076e-16 1.5708" />
<parent link="foot_right_1" />
<child link="r_cleat_r_front" />
<axis xyz="0 0 0"/>
</joint>

<link name="r_cleat_l_front">
<inertial>
<origin xyz="0 0 0" rpy="0 0 0" />
<mass value="1e-9" />
<inertia ixx="0" ixy="0" ixz="0" iyy="0" iyz="0" izz="0" />
</inertial>
</link>
<joint name="r_cleat_l_front_frame" type="fixed">
<origin xyz="-0.0305 0.177 -0.05025" rpy="-1.09592e-15 3.40328e-16 1.5708" />
<parent link="foot_right_1" />
<child link="r_cleat_l_front" />
<axis xyz="0 0 0"/>
</joint>

<link name="r_cleat_r_back">
<inertial>
<origin xyz="0 0 0" rpy="0 0 0" />
<mass value="1e-9" />
<inertia ixx="0" ixy="0" ixz="0" iyy="0" iyz="0" izz="0" />
</inertial>
</link>
<joint name="r_cleat_r_back_frame" type="fixed">
<origin xyz="0.0595 -0.007 -0.05025" rpy="7.71897e-16 -3.20424e-15 1.5708" />
<parent link="foot_right_1" />
<child link="r_cleat_r_back" />
<axis xyz="0 0 0"/>
</joint>

<link name="r_cleat_l_back">
<inertial>
<origin xyz="0 0 0" rpy="0 0 0" />
<mass value="1e-9" />
<inertia ixx="0" ixy="0" ixz="0" iyy="0" iyz="0" izz="0" />
</inertial>
</link>
<joint name="r_cleat_l_back_frame" type="fixed">
<origin xyz="-0.030496 -0.00745064 -0.05025" rpy="3.02062e-16 1.14651e-15 1.5708" />
<parent link="foot_right_1" />
<child link="r_cleat_l_back" />
<axis xyz="0 0 0"/>
</joint>

<joint name="RAnkleRoll" type="revolute">
<origin xyz="-0.0691 5.55112e-17 -0.026" rpy="1.5708 1.5708 0" />
<parent link="left_hip_right_ankle_1" />
<child link="foot_right_1" />
<axis xyz="0 -1 0"/>
<limit effort="9" velocity="9" lower="-1.0472" upper="1.0472"/>
<joint_properties friction="0.0"/>
</joint>

<joint name="RAnklePitch" type="revolute">
<origin xyz="2.69229e-15 0.0505 -0.17" rpy="-1.5708 -1.93533e-15 -2.52888e-15" />
<parent link="lower_leg_right_1" />
<child link="left_hip_right_ankle_1" />
<axis xyz="-0 -0 -1"/>
<limit effort="9" velocity="9" lower="-1.22173" upper="1.5708"/>
<joint_properties friction="0.0"/>
</joint>

<joint name="RKnee" type="revolute">
<origin xyz="-0.00392295 -0.051 -0.169043" rpy="1.50246e-15 -0.261799 -1.61204e-15" />
<parent link="upper_leg_right_1" />
<child link="lower_leg_right_1" />
<axis xyz="0 1 0"/>
<limit effort="10" velocity="10" lower="0" upper="2.96706"/>
<joint_properties friction="0.0"/>
</joint>

<joint name="RHipPitch" type="revolute">
<origin xyz="-0.0265 -2.77556e-17 -0.0691" rpy="-1.5708 1.5708 0" />
<parent link="right_hip_left_ankle_1" />
<child link="upper_leg_right_1" />
<axis xyz="-0 1 -0"/>
<limit effort="9" velocity="9" lower="-1.5708" upper="1.5708"/>
<joint_properties friction="0.0"/>
</joint>

<joint name="RHipRoll" type="revolute">
<origin xyz="-0.046 0.0414 5.34295e-16" rpy="-3.14159 1.5708 0" />
<parent link="hip_u_connector_1" />
<child link="right_hip_left_ankle_1" />
<axis xyz="-0 -0 -1"/>
<limit effort="9" velocity="9" lower="-1.5708" upper="1.5708"/>
<joint_properties friction="0.0"/>
</joint>

<joint name="RHipYaw" type="revolute">
<origin xyz="-1.38778e-17 -0.055 -9.75782e-19" rpy="-1.5708 -0 0" />
<parent link="body_1" />
<child link="hip_u_connector_1" />
<axis xyz="0 -1 0"/>
<limit effort="9" velocity="9" lower="-1.5708" upper="1.5708"/>
<joint_properties friction="0.0"/>
</joint>

<link name="hip_u_connector_2">
<visual>
<origin xyz="0 -0.0006 -0.018" rpy="0 -0 0" />
<geometry>
<mesh filename="package://wolfgang_description/urdf/hip_u_connector.stl"/>
</geometry>
<material name="hip_u_connector_material">
<color rgba="0.647059 0.647059 0.647059 1.0"/>
</material>
</visual>
<collision>
<origin xyz="0 -0.0006 -0.018" rpy="0 -0 0" />
<geometry>
<mesh filename="package://wolfgang_description/urdf/hip_u_connector.stl"/>
</geometry>
<material name="hip_u_connector_material">
<color rgba="0.647059 0.647059 0.647059 1.0"/>
</material>
</collision>
<inertial>
<origin xyz="1.20984e-11 0.010315 -1.06799e-07" rpy="0 0 0"/>
<mass value="0.0689735" />
<inertia ixx="2.18955e-05" ixy="-2.44475e-14"  ixz="3.06793e-15" iyy="0.00010714" iyz="-6.56688e-11" izz="0.000110523" />
</inertial>
</link>

<link name="left_hip_right_ankle_2">
<visual>
<origin xyz="0.0145 0.007 -0.043" rpy="-3.14159 1.52095e-16 -1.5708" />
<geometry>
<mesh filename="package://wolfgang_description/urdf/motor_connector.stl"/>
</geometry>
<material name="motor_connector_material">
<color rgba="0.647059 0.647059 0.647059 1.0"/>
</material>
</visual>
<collision>
<origin xyz="0.0145 0.007 -0.043" rpy="-3.14159 1.52095e-16 -1.5708" />
<geometry>
<mesh filename="package://wolfgang_description/urdf/motor_connector.stl"/>
</geometry>
<material name="motor_connector_material">
<color rgba="0.647059 0.647059 0.647059 1.0"/>
</material>
</collision>
<visual>
<origin xyz="6.93889e-18 0 -0.026" rpy="-1.5708 -1.96517e-16 7.99616e-16" />
<geometry>
<mesh filename="package://wolfgang_description/urdf/mx-106_body.stl"/>
</geometry>
<material name="mx-106_body_material">
<color rgba="0.262745 0.282353 0.301961 1.0"/>
</material>
</visual>
<collision>
<origin xyz="6.93889e-18 0 -0.026" rpy="-1.5708 -1.96517e-16 7.99616e-16" />
<geometry>
<mesh filename="package://wolfgang_description/urdf/mx-106_body.stl"/>
</geometry>
<material name="mx-106_body_material">
<color rgba="0.262745 0.282353 0.301961 1.0"/>
</material>
</collision>
<visual>
<origin xyz="2.08167e-17 -6.93889e-18 -0.0691" rpy="-1.5708 1.5708 0" />
<geometry>
<mesh filename="package://wolfgang_description/urdf/mx-106_body.stl"/>
</geometry>
<material name="mx-106_body_material">
<color rgba="0.262745 0.282353 0.301961 1.0"/>
</material>
</visual>
<collision>
<origin xyz="2.08167e-17 -6.93889e-18 -0.0691" rpy="-1.5708 1.5708 0" />
<geometry>
<mesh filename="package://wolfgang_description/urdf/mx-106_body.stl"/>
</geometry>
<material name="mx-106_body_material">
<color rgba="0.262745 0.282353 0.301961 1.0"/>
</material>
</collision>
<visual>
<origin xyz="-0.0145 -0.021 -0.043" rpy="3.14159 -1.57669e-16 1.5708" />
<geometry>
<mesh filename="package://wolfgang_description/urdf/motor_connector.stl"/>
</geometry>
<material name="motor_connector_material">
<color rgba="0.647059 0.647059 0.647059 1.0"/>
</material>
</visual>
<collision>
<origin xyz="-0.0145 -0.021 -0.043" rpy="3.14159 -1.57669e-16 1.5708" />
<geometry>
<mesh filename="package://wolfgang_description/urdf/motor_connector.stl"/>
</geometry>
<material name="motor_connector_material">
<color rgba="0.647059 0.647059 0.647059 1.0"/>
</material>
</collision>
<visual>
<origin xyz="0.0151 0.0105 -0.0892" rpy="-1.52095e-16 2.65906e-16 -3.14159" />
<geometry>
<mesh filename="package://wolfgang_description/urdf/thrustbearingholder.stl"/>
</geometry>
<material name="thrustbearingholder_material">
<color rgba="0.792157 0.819608 0.933333 1.0"/>
</material>
</visual>
<collision>
<origin xyz="0.0151 0.0105 -0.0892" rpy="-1.52095e-16 2.65906e-16 -3.14159" />
<geometry>
<mesh filename="package://wolfgang_description/urdf/thrustbearingholder.stl"/>
</geometry>
<material name="thrustbearingholder_material">
<color rgba="0.792157 0.819608 0.933333 1.0"/>
</material>
</collision>
<inertial>
<origin xyz="-3.60783e-06 -0.0155281 -0.0486443" rpy="0 0 0"/>
<mass value="0.319807" />
<inertia ixx="0.000268673" ixy="-7.40992e-08"  ixz="-6.18751e-07" iyy="0.000268098" iyz="3.88325e-06" izz="0.000121333" />
</inertial>
</link>

<link name="upper_leg_left_1">
<visual>
<origin xyz="-0.0182355 -0.130164 0.0283472" rpy="3.14159 6.1423e-17 0.523599" />
<geometry>
<mesh filename="package://wolfgang_description/urdf/knee_connector.stl"/>
</geometry>
<material name="knee_connector_material">
<color rgba="0.647059 0.647059 0.647059 1.0"/>
</material>
</visual>
<collision>
<origin xyz="-0.0182355 -0.130164 0.0283472" rpy="3.14159 6.1423e-17 0.523599" />
<geometry>
<mesh filename="package://wolfgang_description/urdf/knee_connector.stl"/>
</geometry>
<material name="knee_connector_material">
<color rgba="0.647059 0.647059 0.647059 1.0"/>
</material>
</collision>
<visual>
<origin xyz="-0.0811244 -0.148357 0.049" rpy="-3.14159 -5.23638e-16 -9.5356e-16" />
<geometry>
<mesh filename="package://wolfgang_description/urdf/part_1.stl"/>
</geometry>
<material name="part_1_material">
<color rgba="0.615686 0.811765 0.929412 1.0"/>
</material>
</visual>
<collision>
<origin xyz="-0.0811244 -0.148357 0.049" rpy="-3.14159 -5.23638e-16 -9.5356e-16" />
<geometry>
<mesh filename="package://wolfgang_description/urdf/part_1.stl"/>
</geometry>
<material name="part_1_material">
<color rgba="0.615686 0.811765 0.929412 1.0"/>
</material>
</collision>
<visual>
<origin xyz="-0.0178025 -0.129914 0.0206528" rpy="1.28647e-15 9.85727e-17 -2.61799" />
<geometry>
<mesh filename="package://wolfgang_description/urdf/knee_connector.stl"/>
</geometry>
<material name="knee_connector_material">
<color rgba="0.647059 0.647059 0.647059 1.0"/>
</material>
</visual>
<collision>
<origin xyz="-0.0178025 -0.129914 0.0206528" rpy="1.28647e-15 9.85727e-17 -2.61799" />
<geometry>
<mesh filename="package://wolfgang_description/urdf/knee_connector.stl"/>
</geometry>
<material name="knee_connector_material">
<color rgba="0.647059 0.647059 0.647059 1.0"/>
</material>
</collision>
<visual>
<origin xyz="0.00435596 -0.168793 0.0245" rpy="5.2714e-16 -4.13578e-16 -2.61799" />
<geometry>
<mesh filename="package://wolfgang_description/urdf/xh-540.stl"/>
</geometry>
<material name="xh-540_material">
<color rgba="0.498039 0.498039 0.498039 1.0"/>
</material>
</visual>
<collision>
<origin xyz="0.00435596 -0.168793 0.0245" rpy="5.2714e-16 -4.13578e-16 -2.61799" />
<geometry>
<mesh filename="package://wolfgang_description/urdf/xh-540.stl"/>
</geometry>
<material name="xh-540_material">
<color rgba="0.498039 0.498039 0.498039 1.0"/>
</material>
</collision>
<visual>
<origin xyz="-0.014 -0.138 0.053" rpy="-9.82513e-16 6.31125e-16 2.61799" />
<geometry>
<mesh filename="package://wolfgang_description/urdf/spring_holder_upper.stl"/>
</geometry>
<material name="spring_holder_upper_material">
<color rgba="0.647059 0.647059 0.647059 1.0"/>
</material>
</visual>
<collision>
<origin xyz="-0.014 -0.138 0.053" rpy="-9.82513e-16 6.31125e-16 2.61799" />
<geometry>
<mesh filename="package://wolfgang_description/urdf/spring_holder_upper.stl"/>
</geometry>
<material name="spring_holder_upper_material">
<color rgba="0.647059 0.647059 0.647059 1.0"/>
</material>
</collision>
<visual>
<origin xyz="-0.0811244 0.148357 -2.00465e-14" rpy="0 -9.66999e-33 0" />
<geometry>
<mesh filename="package://wolfgang_description/urdf/part_1.stl"/>
</geometry>
<material name="part_1_material">
<color rgba="0.615686 0.811765 0.929412 1.0"/>
</material>
</visual>
<collision>
<origin xyz="-0.0811244 0.148357 -2.00465e-14" rpy="0 -9.66999e-33 0" />
<geometry>
<mesh filename="package://wolfgang_description/urdf/part_1.stl"/>
</geometry>
<material name="part_1_material">
<color rgba="0.615686 0.811765 0.929412 1.0"/>
</material>
</collision>
<visual>
<origin xyz="0 0 -0.002" rpy="1.5708 -2.22045e-16 -3.14159" />
<geometry>
<mesh filename="package://wolfgang_description/urdf/upper_leg.stl"/>
</geometry>
<material name="upper_leg_material">
<color rgba="0.647059 0.647059 0.647059 1.0"/>
</material>
</visual>
<collision>
<origin xyz="0 0 -0.002" rpy="1.5708 -2.22045e-16 -3.14159" />
<geometry>
<mesh filename="package://wolfgang_description/urdf/upper_leg.stl"/>
</geometry>
<material name="upper_leg_material">
<color rgba="0.647059 0.647059 0.647059 1.0"/>
</material>
</collision>
<visual>
<origin xyz="1.73472e-17 6.93889e-18 0.053" rpy="1.5708 3.88578e-16 3.14159" />
<geometry>
<mesh filename="package://wolfgang_description/urdf/upper_leg.stl"/>
</geometry>
<material name="upper_leg_material">
<color rgba="0.647059 0.647059 0.647059 1.0"/>
</material>
</visual>
<collision>
<origin xyz="1.73472e-17 6.93889e-18 0.053" rpy="1.5708 3.88578e-16 3.14159" />
<geometry>
<mesh filename="package://wolfgang_description/urdf/upper_leg.stl"/>
</geometry>
<material name="upper_leg_material">
<color rgba="0.647059 0.647059 0.647059 1.0"/>
</material>
</collision>
<inertial>
<origin xyz="-0.00432766 -0.137334 0.0264999" rpy="0 0 0"/>
<mass value="0.220799" />
<inertia ixx="0.000439144" ixy="-3.21416e-05"  ixz="2.66786e-06" iyy="0.000110922" iyz="2.40516e-06" izz="0.000401348" />
</inertial>
</link>

<link name="lower_leg_left_1">
<visual>
<origin xyz="2.04003e-15 0.0035 0.17" rpy="3.14159 -2.52611e-17 -2.06283e-15" />
<geometry>
<mesh filename="package://wolfgang_description/urdf/springholder_new.stl"/>
</geometry>
<material name="springholder_new_material">
<color rgba="0.717647 0.717647 0.717647 1.0"/>
</material>
</visual>
<collision>
<origin xyz="2.04003e-15 0.0035 0.17" rpy="3.14159 -2.52611e-17 -2.06283e-15" />
<geometry>
<mesh filename="package://wolfgang_description/urdf/springholder_new.stl"/>
</geometry>
<material name="springholder_new_material">
<color rgba="0.717647 0.717647 0.717647 1.0"/>
</material>
</collision>
<visual>
<origin xyz="0.00217889 -0.0033 -0.145095" rpy="3.39734e-17 8.69256e-14 -3.14159" />
<geometry>
<mesh filename="package://wolfgang_description/urdf/spring_holder_lower.stl"/>
</geometry>
<material name="spring_holder_lower_material">
<color rgba="0.717647 0.717647 0.717647 1.0"/>
</material>
</visual>
<collision>
<origin xyz="0.00217889 -0.0033 -0.145095" rpy="3.39734e-17 8.69256e-14 -3.14159" />
<geometry>
<mesh filename="package://wolfgang_description/urdf/spring_holder_lower.stl"/>
</geometry>
<material name="spring_holder_lower_material">
<color rgba="0.717647 0.717647 0.717647 1.0"/>
</material>
</collision>
<visual>
<origin xyz="2.22045e-16 0.0035 -3.60822e-16" rpy="3.14159 -8.64467e-17 -4.26392e-30" />
<geometry>
<mesh filename="package://wolfgang_description/urdf/springholder_bottom.stl"/>
</geometry>
<material name="springholder_bottom_material">
<color rgba="0.717647 0.717647 0.717647 1.0"/>
</material>
</visual>
<collision>
<origin xyz="2.22045e-16 0.0035 -3.60822e-16" rpy="3.14159 -8.64467e-17 -4.26392e-30" />
<geometry>
<mesh filename="package://wolfgang_description/urdf/springholder_bottom.stl"/>
</geometry>
<material name="springholder_bottom_material">
<color rgba="0.717647 0.717647 0.717647 1.0"/>
</material>
</collision>
<visual>
<origin xyz="2.28983e-16 0.0062 -3.60822e-16" rpy="-1.5708 0.0872665 -2.54457e-15" />
<geometry>
<mesh filename="package://wolfgang_description/urdf/torson_spring_sodemann_t105-180-813l.stl"/>
</geometry>
<material name="torson_spring_sodemann_t105-180-813l_material">
<color rgba="0.490196 0.490196 0.501961 1.0"/>
</material>
</visual>
<collision>
<origin xyz="2.28983e-16 0.0062 -3.60822e-16" rpy="-1.5708 0.0872665 -2.54457e-15" />
<geometry>
<mesh filename="package://wolfgang_description/urdf/torson_spring_sodemann_t105-180-813l.stl"/>
</geometry>
<material name="torson_spring_sodemann_t105-180-813l_material">
<color rgba="0.490196 0.490196 0.501961 1.0"/>
</material>
</collision>
<visual>
<origin xyz="0.02797 0.019019 -0.15413" rpy="-8.11627e-32 -5.23998e-17 1.25521e-31" />
<geometry>
<mesh filename="package://wolfgang_description/urdf/knee_spacer.stl"/>
</geometry>
<material name="knee_spacer_material">
<color rgba="0.647059 0.647059 0.647059 1.0"/>
</material>
</visual>
<collision>
<origin xyz="0.02797 0.019019 -0.15413" rpy="-8.11627e-32 -5.23998e-17 1.25521e-31" />
<geometry>
<mesh filename="package://wolfgang_description/urdf/knee_spacer.stl"/>
</geometry>
<material name="knee_spacer_material">
<color rgba="0.647059 0.647059 0.647059 1.0"/>
</material>
</collision>
<visual>
<origin xyz="0.02797 -0.031481 -0.15413" rpy="-4.78814e-17 -1.0347e-16 6.41104e-31" />
<geometry>
<mesh filename="package://wolfgang_description/urdf/knee_spacer.stl"/>
</geometry>
<material name="knee_spacer_material">
<color rgba="0.647059 0.647059 0.647059 1.0"/>
</material>
</visual>
<collision>
<origin xyz="0.02797 -0.031481 -0.15413" rpy="-4.78814e-17 -1.0347e-16 6.41104e-31" />
<geometry>
<mesh filename="package://wolfgang_description/urdf/knee_spacer.stl"/>
</geometry>
<material name="knee_spacer_material">
<color rgba="0.647059 0.647059 0.647059 1.0"/>
</material>
</collision>
<visual>
<origin xyz="3.747e-15 -0.0505 -0.17" rpy="-4.76965e-17 -1.58036e-17 -2.53255e-31" />
<geometry>
<mesh filename="package://wolfgang_description/urdf/lower_leg.stl"/>
</geometry>
<material name="lower_leg_material">
<color rgba="0.960784 0.960784 0.960784 1.0"/>
</material>
</visual>
<collision>
<origin xyz="3.747e-15 -0.0505 -0.17" rpy="-4.76965e-17 -1.58036e-17 -2.53255e-31" />
<geometry>
<mesh filename="package://wolfgang_description/urdf/lower_leg.stl"/>
</geometry>
<material name="lower_leg_material">
<color rgba="0.960784 0.960784 0.960784 1.0"/>
</material>
</collision>
<visual>
<origin xyz="3.51802e-15 0.0035 -0.17" rpy="-4.78063e-16 -3.09356e-17 -2.15511e-15" />
<geometry>
<mesh filename="package://wolfgang_description/urdf/lower_leg.stl"/>
</geometry>
<material name="lower_leg_material">
<color rgba="0.960784 0.960784 0.960784 1.0"/>
</material>
</visual>
<collision>
<origin xyz="3.51802e-15 0.0035 -0.17" rpy="-4.78063e-16 -3.09356e-17 -2.15511e-15" />
<geometry>
<mesh filename="package://wolfgang_description/urdf/lower_leg.stl"/>
</geometry>
<material name="lower_leg_material">
<color rgba="0.960784 0.960784 0.960784 1.0"/>
</material>
</collision>
<inertial>
<origin xyz="0.00131514 -0.00765101 -0.0457625" rpy="0 0 0"/>
<mass value="0.0842512" />
<inertia ixx="0.000356356" ixy="-1.78213e-06"  ixz="-1.07459e-05" iyy="0.000301696" iyz="-5.93333e-05" izz="7.37841e-05" />
</inertial>
</link>

<link name="right_hip_left_ankle_2">
<visual>
<origin xyz="0.0261 0.007 -0.0405" rpy="1.5708 1.52434e-16 -1.5708" />
<geometry>
<mesh filename="package://wolfgang_description/urdf/motor_connector.stl"/>
</geometry>
<material name="motor_connector_material">
<color rgba="0.647059 0.647059 0.647059 1.0"/>
</material>
</visual>
<collision>
<origin xyz="0.0261 0.007 -0.0405" rpy="1.5708 1.52434e-16 -1.5708" />
<geometry>
<mesh filename="package://wolfgang_description/urdf/motor_connector.stl"/>
</geometry>
<material name="motor_connector_material">
<color rgba="0.647059 0.647059 0.647059 1.0"/>
</material>
</collision>
<visual>
<origin xyz="-0.0201 0.0105 -0.04" rpy="-3.14159 -1.5708 0" />
<geometry>
<mesh filename="package://wolfgang_description/urdf/thrustbearingholder.stl"/>
</geometry>
<material name="thrustbearingholder_material">
<color rgba="0.792157 0.819608 0.933333 1.0"/>
</material>
</visual>
<collision>
<origin xyz="-0.0201 0.0105 -0.04" rpy="-3.14159 -1.5708 0" />
<geometry>
<mesh filename="package://wolfgang_description/urdf/thrustbearingholder.stl"/>
</geometry>
<material name="thrustbearingholder_material">
<color rgba="0.792157 0.819608 0.933333 1.0"/>
</material>
</collision>
<visual>
<origin xyz="0.0261 -0.021 -0.0115" rpy="-1.5708 1.17853e-16 1.5708" />
<geometry>
<mesh filename="package://wolfgang_description/urdf/motor_connector.stl"/>
</geometry>
<material name="motor_connector_material">
<color rgba="0.647059 0.647059 0.647059 1.0"/>
</material>
</visual>
<collision>
<origin xyz="0.0261 -0.021 -0.0115" rpy="-1.5708 1.17853e-16 1.5708" />
<geometry>
<mesh filename="package://wolfgang_description/urdf/motor_connector.stl"/>
</geometry>
<material name="motor_connector_material">
<color rgba="0.647059 0.647059 0.647059 1.0"/>
</material>
</collision>
<visual>
<origin xyz="1.38778e-17 0 -0.026" rpy="-1.5708 -5.16101e-15 -5.5874e-18" />
<geometry>
<mesh filename="package://wolfgang_description/urdf/mx-106_body.stl"/>
</geometry>
<material name="mx-106_body_material">
<color rgba="0.262745 0.282353 0.301961 1.0"/>
</material>
</visual>
<collision>
<origin xyz="1.38778e-17 0 -0.026" rpy="-1.5708 -5.16101e-15 -5.5874e-18" />
<geometry>
<mesh filename="package://wolfgang_description/urdf/mx-106_body.stl"/>
</geometry>
<material name="mx-106_body_material">
<color rgba="0.262745 0.282353 0.301961 1.0"/>
</material>
</collision>
<visual>
<origin xyz="0.0431 1.11022e-16 -0.026" rpy="-1.5708 1.5708 0" />
<geometry>
<mesh filename="package://wolfgang_description/urdf/mx-106_body.stl"/>
</geometry>
<material name="mx-106_body_material">
<color rgba="0.262745 0.282353 0.301961 1.0"/>
</material>
</visual>
<collision>
<origin xyz="0.0431 1.11022e-16 -0.026" rpy="-1.5708 1.5708 0" />
<geometry>
<mesh filename="package://wolfgang_description/urdf/mx-106_body.stl"/>
</geometry>
<material name="mx-106_body_material">
<color rgba="0.262745 0.282353 0.301961 1.0"/>
</material>
</collision>
<inertial>
<origin xyz="0.0204593 -0.0155281 -0.0260139" rpy="0 0 0"/>
<mass value="0.319807" />
<inertia ixx="0.000116773" ixy="4.53857e-06"  ixz="-6.75013e-07" iyy="0.000268424" iyz="-7.24073e-07" izz="0.00027281" />
</inertial>
</link>

<link name="foot_left_1">
<visual>
<origin xyz="0.03 -0.007 -0.04375" rpy="6.79277e-16 -1.97403e-15 -1.5708" />
<geometry>
<mesh filename="package://wolfgang_description/urdf/flex_stollen.stl"/>
</geometry>
<material name="flex_stollen_material">
<color rgba="0.615686 0.811765 0.929412 1.0"/>
</material>
</visual>
<collision>
<origin xyz="0.03 -0.007 -0.04375" rpy="6.79277e-16 -1.97403e-15 -1.5708" />
<geometry>
<mesh filename="package://wolfgang_description/urdf/flex_stollen.stl"/>
</geometry>
<material name="flex_stollen_material">
<color rgba="0.615686 0.811765 0.929412 1.0"/>
</material>
</collision>
<visual>
<origin xyz="-0.06 0.177 -0.04375" rpy="6.80641e-15 -4.22482e-15 -1.5708" />
<geometry>
<mesh filename="package://wolfgang_description/urdf/flex_stollen.stl"/>
</geometry>
<material name="flex_stollen_material">
<color rgba="0.615686 0.811765 0.929412 1.0"/>
</material>
</visual>
<collision>
<origin xyz="-0.06 0.177 -0.04375" rpy="6.80641e-15 -4.22482e-15 -1.5708" />
<geometry>
<mesh filename="package://wolfgang_description/urdf/flex_stollen.stl"/>
</geometry>
<material name="flex_stollen_material">
<color rgba="0.615686 0.811765 0.929412 1.0"/>
</material>
</collision>
<visual>
<origin xyz="-0.06 0.1635 -0.03375" rpy="-4.35665e-15 -5.77818e-15 -2.20171e-17" />
<geometry>
<mesh filename="package://wolfgang_description/urdf/load_cell.stl"/>
</geometry>
<material name="load_cell_material">
<color rgba="0.717647 0.717647 0.717647 1.0"/>
</material>
</visual>
<collision>
<origin xyz="-0.06 0.1635 -0.03375" rpy="-4.35665e-15 -5.77818e-15 -2.20171e-17" />
<geometry>
<mesh filename="package://wolfgang_description/urdf/load_cell.stl"/>
</geometry>
<material name="load_cell_material">
<color rgba="0.717647 0.717647 0.717647 1.0"/>
</material>
</collision>
<visual>
<origin xyz="0.03 0.0065 -0.03375" rpy="4.02671e-15 5.77818e-15 3.14159" />
<geometry>
<mesh filename="package://wolfgang_description/urdf/load_cell.stl"/>
</geometry>
<material name="load_cell_material">
<color rgba="0.717647 0.717647 0.717647 1.0"/>
</material>
</visual>
<collision>
<origin xyz="0.03 0.0065 -0.03375" rpy="4.02671e-15 5.77818e-15 3.14159" />
<geometry>
<mesh filename="package://wolfgang_description/urdf/load_cell.stl"/>
</geometry>
<material name="load_cell_material">
<color rgba="0.717647 0.717647 0.717647 1.0"/>
</material>
</collision>
<visual>
<origin xyz="-0.015 0.085 -0.0395" rpy="5.77818e-15 6.8631e-15 -1.5708" />
<geometry>
<mesh filename="package://wolfgang_description/urdf/foot_printed_left.stl"/>
</geometry>
<material name="foot_printed_left_material">
<color rgba="0.717647 0.717647 0.717647 1.0"/>
</material>
</visual>
<collision>
<origin xyz="-0.015 0.085 -0.0395" rpy="5.77818e-15 6.8631e-15 -1.5708" />
<geometry>
<mesh filename="package://wolfgang_description/urdf/foot_printed_left.stl"/>
</geometry>
<material name="foot_printed_left_material">
<color rgba="0.717647 0.717647 0.717647 1.0"/>
</material>
</collision>
<visual>
<origin xyz="0.022 0.16 -0.0324" rpy="3.14159 -5.03639e-15 -5.39852e-17" />
<geometry>
<mesh filename="package://wolfgang_description/urdf/forcefoot_pcb.stl"/>
</geometry>
<material name="forcefoot_pcb_material">
<color rgba="0.141176 0.52549 0.141176 1.0"/>
</material>
</visual>
<collision>
<origin xyz="0.022 0.16 -0.0324" rpy="3.14159 -5.03639e-15 -5.39852e-17" />
<geometry>
<mesh filename="package://wolfgang_description/urdf/forcefoot_pcb.stl"/>
</geometry>
<material name="forcefoot_pcb_material">
<color rgba="0.141176 0.52549 0.141176 1.0"/>
</material>
</collision>
<visual>
<origin xyz="-0.00654316 0.0618337 -0.0463905" rpy="1.29452e-15 -3.55046e-15 -1.5708" />
<geometry>
<mesh filename="package://wolfgang_description/urdf/foot_cover.stl"/>
</geometry>
<material name="foot_cover_material">
<color rgba="0.647059 0.647059 0.647059 1.0"/>
</material>
</visual>
<collision>
<origin xyz="-0.00654316 0.0618337 -0.0463905" rpy="1.29452e-15 -3.55046e-15 -1.5708" />
<geometry>
<mesh filename="package://wolfgang_description/urdf/foot_cover.stl"/>
</geometry>
<material name="foot_cover_material">
<color rgba="0.647059 0.647059 0.647059 1.0"/>
</material>
</collision>
<visual>
<origin xyz="0.03 0.177 -0.04375" rpy="6.80641e-15 -4.22482e-15 -1.5708" />
<geometry>
<mesh filename="package://wolfgang_description/urdf/flex_stollen.stl"/>
</geometry>
<material name="flex_stollen_material">
<color rgba="0.615686 0.811765 0.929412 1.0"/>
</material>
</visual>
<collision>
<origin xyz="0.03 0.177 -0.04375" rpy="6.80641e-15 -4.22482e-15 -1.5708" />
<geometry>
<mesh filename="package://wolfgang_description/urdf/flex_stollen.stl"/>
</geometry>
<material name="flex_stollen_material">
<color rgba="0.615686 0.811765 0.929412 1.0"/>
</material>
</collision>
<visual>
<origin xyz="-0.06 -0.007 -0.04375" rpy="2.06603e-14 2.57162e-14 -1.5708" />
<geometry>
<mesh filename="package://wolfgang_description/urdf/flex_stollen.stl"/>
</geometry>
<material name="flex_stollen_material">
<color rgba="0.615686 0.811765 0.929412 1.0"/>
</material>
</visual>
<collision>
<origin xyz="-0.06 -0.007 -0.04375" rpy="2.06603e-14 2.57162e-14 -1.5708" />
<geometry>
<mesh filename="package://wolfgang_description/urdf/flex_stollen.stl"/>
</geometry>
<material name="flex_stollen_material">
<color rgba="0.615686 0.811765 0.929412 1.0"/>
</material>
</collision>
<visual>
<origin xyz="0 0.046 -0.036" rpy="-5.89229e-18 -6.62422e-31 4.13862e-31" />
<geometry>
<mesh filename="package://wolfgang_description/urdf/ankle.stl"/>
</geometry>
<material name="ankle_material">
<color rgba="0.717647 0.717647 0.717647 1.0"/>
</material>
</visual>
<collision>
<origin xyz="0 0.046 -0.036" rpy="-5.89229e-18 -6.62422e-31 4.13862e-31" />
<geometry>
<mesh filename="package://wolfgang_description/urdf/ankle.stl"/>
</geometry>
<material name="ankle_material">
<color rgba="0.717647 0.717647 0.717647 1.0"/>
</material>
</collision>
<visual>
<origin xyz="0.03 0.1635 -0.03375" rpy="-4.35665e-15 -5.77818e-15 -2.20171e-17" />
<geometry>
<mesh filename="package://wolfgang_description/urdf/load_cell.stl"/>
</geometry>
<material name="load_cell_material">
<color rgba="0.717647 0.717647 0.717647 1.0"/>
</material>
</visual>
<collision>
<origin xyz="0.03 0.1635 -0.03375" rpy="-4.35665e-15 -5.77818e-15 -2.20171e-17" />
<geometry>
<mesh filename="package://wolfgang_description/urdf/load_cell.stl"/>
</geometry>
<material name="load_cell_material">
<color rgba="0.717647 0.717647 0.717647 1.0"/>
</material>
</collision>
<visual>
<origin xyz="-0.06 0.0065 -0.03375" rpy="-4.35665e-15 -5.77818e-15 -2.20171e-17" />
<geometry>
<mesh filename="package://wolfgang_description/urdf/load_cell.stl"/>
</geometry>
<material name="load_cell_material">
<color rgba="0.717647 0.717647 0.717647 1.0"/>
</material>
</visual>
<collision>
<origin xyz="-0.06 0.0065 -0.03375" rpy="-4.35665e-15 -5.77818e-15 -2.20171e-17" />
<geometry>
<mesh filename="package://wolfgang_description/urdf/load_cell.stl"/>
</geometry>
<material name="load_cell_material">
<color rgba="0.717647 0.717647 0.717647 1.0"/>
</material>
</collision>
<inertial>
<origin xyz="-0.0121848 0.0915098 -0.029925" rpy="0 0 0"/>
<mass value="0.281772" />
<inertia ixx="0.000951773" ixy="3.22561e-05"  ixz="-5.21736e-06" iyy="0.000343589" iyz="-1.92863e-05" izz="0.00124389" />
</inertial>
</link>

<link name="l_sole">
<inertial>
<origin xyz="0 0 0" rpy="0 0 0" />
<mass value="1e-9" />
<inertia ixx="0" ixy="0" ixz="0" iyy="0" iyz="0" izz="0" />
</inertial>
</link>
<joint name="l_sole_frame" type="fixed">
<origin xyz="-0.0152261 0.0907683 -0.0529" rpy="-5.77818e-15 -7.01261e-15 1.5708" />
<parent link="foot_left_1" />
<child link="l_sole" />
<axis xyz="0 0 0"/>
</joint>

<link name="l_cleat_l_front">
<inertial>
<origin xyz="0 0 0" rpy="0 0 0" />
<mass value="1e-9" />
<inertia ixx="0" ixy="0" ixz="0" iyy="0" iyz="0" izz="0" />
</inertial>
</link>
<joint name="l_cleat_l_front_frame" type="fixed">
<origin xyz="-0.0605 0.177 -0.04975" rpy="-6.55214e-15 4.2513e-15 1.5708" />
<parent link="foot_left_1" />
<child link="l_cleat_l_front" />
<axis xyz="0 0 0"/>
</joint>

<link name="l_cleat_r_front">
<inertial>
<origin xyz="0 0 0" rpy="0 0 0" />
<mass value="1e-9" />
<inertia ixx="0" ixy="0" ixz="0" iyy="0" iyz="0" izz="0" />
</inertial>
</link>
<joint name="l_cleat_r_front_frame" type="fixed">
<origin xyz="0.0295 0.177 -0.04975" rpy="-6.55214e-15 4.2513e-15 1.5708" />
<parent link="foot_left_1" />
<child link="l_cleat_r_front" />
<axis xyz="0 0 0"/>
</joint>

<link name="l_cleat_r_back">
<inertial>
<origin xyz="0 0 0" rpy="0 0 0" />
<mass value="1e-9" />
<inertia ixx="0" ixy="0" ixz="0" iyy="0" iyz="0" izz="0" />
</inertial>
</link>
<joint name="l_cleat_r_back_frame" type="fixed">
<origin xyz="0.0295 -0.007 -0.04975" rpy="-3.99384e-16 1.98982e-15 1.5708" />
<parent link="foot_left_1" />
<child link="l_cleat_r_back" />
<axis xyz="0 0 0"/>
</joint>

<link name="l_cleat_l_back">
<inertial>
<origin xyz="0 0 0" rpy="0 0 0" />
<mass value="1e-9" />
<inertia ixx="0" ixy="0" ixz="0" iyy="0" iyz="0" izz="0" />
</inertial>
</link>
<joint name="l_cleat_l_back_frame" type="fixed">
<origin xyz="-0.0605 -0.007 -0.04975" rpy="-2.04856e-14 -2.56773e-14 1.5708" />
<parent link="foot_left_1" />
<child link="l_cleat_l_back" />
<axis xyz="0 0 0"/>
</joint>

<joint name="LAnkleRoll" type="revolute">
<origin xyz="0.0691 2.22045e-16 -0.026" rpy="1.5708 -1.5708 0" />
<parent link="right_hip_left_ankle_2" />
<child link="foot_left_1" />
<axis xyz="-0 -1 -0"/>
<limit effort="9" velocity="9" lower="-1.0472" upper="1.0472"/>
<joint_properties friction="0.0"/>
</joint>

<joint name="LAnklePitch" type="revolute">
<origin xyz="3.5319e-15 -0.0505 -0.17" rpy="-1.5708 -8.72457e-16 3.14159" />
<parent link="lower_leg_left_1" />
<child link="right_hip_left_ankle_2" />
<axis xyz="-0 -0 -1"/>
<limit effort="9" velocity="9" lower="-1.22173" upper="1.5708"/>
<joint_properties friction="0.0"/>
</joint>

<joint name="LKnee" type="revolute">
<origin xyz="0.00435596 -0.168793 0.049" rpy="1.5708 -1.75248e-15 2.87979" />
<parent link="upper_leg_left_1" />
<child link="lower_leg_left_1" />
<axis xyz="0 -1 0"/>
<limit effort="10" velocity="10" lower="-2.96706" upper="0"/>
<joint_properties friction="0.0"/>
</joint>

<joint name="LHipPitch" type="revolute">
<origin xyz="0.026 6.93889e-18 -0.0691" rpy="2.67116e-16 -1.5708 0" />
<parent link="left_hip_right_ankle_2" />
<child link="upper_leg_left_1" />
<axis xyz="7.95491e-17 -3.00167e-16 -1"/>
<limit effort="9" velocity="9" lower="-1.5708" upper="1.5708"/>
<joint_properties friction="0.0"/>
</joint>

<joint name="LHipRoll" type="revolute">
<origin xyz="-0.046 0.0414 -7.97973e-16" rpy="3.14159 1.5708 0" />
<parent link="hip_u_connector_2" />
<child link="left_hip_right_ankle_2" />
<axis xyz="-0 -0 -1"/>
<limit effort="9" velocity="9" lower="-1.5708" upper="1.5708"/>
<joint_properties friction="0.0"/>
</joint>

<joint name="LHipYaw" type="revolute">
<origin xyz="-2.28983e-16 0.055 2.71051e-18" rpy="-1.5708 -0 0" />
<parent link="body_1" />
<child link="hip_u_connector_2" />
<axis xyz="0 -1 0"/>
<limit effort="9" velocity="9" lower="-1.5708" upper="1.5708"/>
<joint_properties friction="0.0"/>
</joint>

<link name="neck_1">
<visual>
<origin xyz="0.0035 0 -0.0093" rpy="-7.1415e-32 2.28711e-32 -3.97109e-33" />
<geometry>
<mesh filename="package://wolfgang_description/urdf/connector_shoulder.stl"/>
</geometry>
<material name="connector_shoulder_material">
<color rgba="0.717647 0.717647 0.717647 1.0"/>
</material>
</visual>
<collision>
<origin xyz="0.0035 0 -0.0093" rpy="-7.1415e-32 2.28711e-32 -3.97109e-33" />
<geometry>
<mesh filename="package://wolfgang_description/urdf/connector_shoulder.stl"/>
</geometry>
<material name="connector_shoulder_material">
<color rgba="0.717647 0.717647 0.717647 1.0"/>
</material>
</collision>
<visual>
<origin xyz="0.036 3.10152e-17 -0.024" rpy="3.14159 -1.5708 0" />
<geometry>
<mesh filename="package://wolfgang_description/urdf/mx-64-body.stl"/>
</geometry>
<material name="mx-64-body_material">
<color rgba="0.247059 0.247059 0.247059 1.0"/>
</material>
</visual>
<collision>
<origin xyz="0.036 3.10152e-17 -0.024" rpy="3.14159 -1.5708 0" />
<geometry>
<mesh filename="package://wolfgang_description/urdf/mx-64-body.stl"/>
</geometry>
<material name="mx-64-body_material">
<color rgba="0.247059 0.247059 0.247059 1.0"/>
</material>
</collision>
<inertial>
<origin xyz="0.0186912 -7.75177e-05 -0.0220143" rpy="0 0 0"/>
<mass value="0.148233" />
<inertia ixx="3.89355e-05" ixy="-5.28709e-07"  ixz="4.95698e-06" iyy="5.76318e-05" iyz="-2.28158e-08" izz="6.25414e-05" />
</inertial>
</link>

<link name="head_1">
<visual>
<origin xyz="0.0432 0.0795 -0.0235" rpy="-1.5708 -1.5708 0" />
<geometry>
<mesh filename="package://wolfgang_description/urdf/lense.stl"/>
</geometry>
<material name="lense_material">
<color rgba="0.647059 0.647059 0.647059 1.0"/>
</material>
</visual>
<collision>
<origin xyz="0.0432 0.0795 -0.0235" rpy="-1.5708 -1.5708 0" />
<geometry>
<mesh filename="package://wolfgang_description/urdf/lense.stl"/>
</geometry>
<material name="lense_material">
<color rgba="0.647059 0.647059 0.647059 1.0"/>
</material>
</collision>
<visual>
<origin xyz="0 0 3.46945e-18" rpy="3.88389e-31 -1.5433e-31 1.35585e-31" />
<geometry>
<mesh filename="package://wolfgang_description/urdf/sea_ninjaflex.stl"/>
</geometry>
<material name="sea_ninjaflex_material">
<color rgba="0.717647 0.717647 0.717647 1.0"/>
</material>
</visual>
<collision>
<origin xyz="0 0 3.46945e-18" rpy="3.88389e-31 -1.5433e-31 1.35585e-31" />
<geometry>
<mesh filename="package://wolfgang_description/urdf/sea_ninjaflex.stl"/>
</geometry>
<material name="sea_ninjaflex_material">
<color rgba="0.717647 0.717647 0.717647 1.0"/>
</material>
</collision>
<visual>
<origin xyz="-2.08167e-17 -5.55112e-17 0.009" rpy="-8.16317e-16 -2.22045e-16 3.14159" />
<geometry>
<mesh filename="package://wolfgang_description/urdf/sea_connector.stl"/>
</geometry>
<material name="sea_connector_material">
<color rgba="0.262745 0.282353 0.301961 1.0"/>
</material>
</visual>
<collision>
<origin xyz="-2.08167e-17 -5.55112e-17 0.009" rpy="-8.16317e-16 -2.22045e-16 3.14159" />
<geometry>
<mesh filename="package://wolfgang_description/urdf/sea_connector.stl"/>
</geometry>
<material name="sea_connector_material">
<color rgba="0.262745 0.282353 0.301961 1.0"/>
</material>
</collision>
<visual>
<origin xyz="0.01 0.065 0.024" rpy="-1.74915e-15 -1.11022e-15 -1.38778e-15" />
<geometry>
<mesh filename="package://wolfgang_description/urdf/camera_side_basler_wolfgang_v2.2_right.stl"/>
</geometry>
<material name="camera_side_basler_wolfgang_v2.2_right_material">
<color rgba="0.647059 0.647059 0.647059 1.0"/>
</material>
</visual>
<collision>
<origin xyz="0.01 0.065 0.024" rpy="-1.74915e-15 -1.11022e-15 -1.38778e-15" />
<geometry>
<mesh filename="package://wolfgang_description/urdf/camera_side_basler_wolfgang_v2.2_right.stl"/>
</geometry>
<material name="camera_side_basler_wolfgang_v2.2_right_material">
<color rgba="0.647059 0.647059 0.647059 1.0"/>
</material>
</collision>
<visual>
<origin xyz="0.01 0.065 -0.051" rpy="-1.14124e-18 -9.99201e-16 -7.21645e-16" />
<geometry>
<mesh filename="package://wolfgang_description/urdf/camera_side_basler_wolfgang_v2.2_left.stl"/>
</geometry>
<material name="camera_side_basler_wolfgang_v2.2_left_material">
<color rgba="0.647059 0.647059 0.647059 1.0"/>
</material>
</visual>
<collision>
<origin xyz="0.01 0.065 -0.051" rpy="-1.14124e-18 -9.99201e-16 -7.21645e-16" />
<geometry>
<mesh filename="package://wolfgang_description/urdf/camera_side_basler_wolfgang_v2.2_left.stl"/>
</geometry>
<material name="camera_side_basler_wolfgang_v2.2_left_material">
<color rgba="0.647059 0.647059 0.647059 1.0"/>
</material>
</collision>
<visual>
<origin xyz="0.015 0.0795 -0.0235" rpy="-1.5708 -1.5708 0" />
<geometry>
<mesh filename="package://wolfgang_description/urdf/basler_ace_gige_c-mount_v01.stl"/>
</geometry>
<material name="basler_ace_gige_c-mount_v01_material">
<color rgba="0.917647 0.917647 0.917647 1.0"/>
</material>
</visual>
<collision>
<origin xyz="0.015 0.0795 -0.0235" rpy="-1.5708 -1.5708 0" />
<geometry>
<mesh filename="package://wolfgang_description/urdf/basler_ace_gige_c-mount_v01.stl"/>
</geometry>
<material name="basler_ace_gige_c-mount_v01_material">
<color rgba="0.917647 0.917647 0.917647 1.0"/>
</material>
</collision>
<visual>
<origin xyz="0.003 0.065 -0.037945" rpy="3.33067e-16 -1.5708 0" />
<geometry>
<mesh filename="package://wolfgang_description/urdf/camera_lower_basler_wolfgang_imu_v2.2.stl"/>
</geometry>
<material name="camera_lower_basler_wolfgang_imu_v2.2_material">
<color rgba="0.647059 0.647059 0.647059 1.0"/>
</material>
</visual>
<collision>
<origin xyz="0.003 0.065 -0.037945" rpy="3.33067e-16 -1.5708 0" />
<geometry>
<mesh filename="package://wolfgang_description/urdf/camera_lower_basler_wolfgang_imu_v2.2.stl"/>
</geometry>
<material name="camera_lower_basler_wolfgang_imu_v2.2_material">
<color rgba="0.647059 0.647059 0.647059 1.0"/>
</material>
</collision>
<inertial>
<origin xyz="-0.0034709 0.0682828 -0.020251" rpy="0 0 0"/>
<mass value="0.318645" />
<inertia ixx="0.000360976" ixy="-3.54024e-06"  ixz="-2.96129e-06" iyy="0.00044172" iyz="5.19892e-05" izz="0.000524061" />
</inertial>
</link>

<link name="camera">
<inertial>
<origin xyz="0 0 0" rpy="0 0 0" />
<mass value="1e-9" />
<inertia ixx="0" ixy="0" ixz="0" iyy="0" iyz="0" izz="0" />
</inertial>
</link>
<joint name="camera_frame" type="fixed">
<origin xyz="0.0437 0.0795 -0.0235" rpy="-1.5708 -1.45465e-14 -3.33067e-16" />
<parent link="head_1" />
<child link="camera" />
<axis xyz="0 0 0"/>
</joint>

<link name="camera_optical_frame">
<inertial>
<origin xyz="0 0 0" rpy="0 0 0" />
<mass value="1e-9" />
<inertia ixx="0" ixy="0" ixz="0" iyy="0" iyz="0" izz="0" />
</inertial>
</link>
<joint name="camera_optical_frame_frame" type="fixed">
<origin xyz="0.0432 0.08 -0.0235" rpy="3.14159 -1.5708 0" />
<parent link="head_1" />
<child link="camera_optical_frame" />
<axis xyz="0 0 0"/>
</joint>

<joint name="HeadTilt" type="revolute">
<origin xyz="0.036 0.0235 -0.024" rpy="-1.5708 3.17216e-15 -5.33479e-15" />
<parent link="neck_1" />
<child link="head_1" />
<axis xyz="0 0 -1"/>
<limit effort="6" velocity="6" lower="0" upper="1.5708"/>
<joint_properties friction="0.0"/>
</joint>

<joint name="HeadPan" type="revolute">
<origin xyz="-0.0095 2.82644e-16 0.2345" rpy="-3.14159 3.41087e-16 -4.44089e-16" />
<parent link="body_1" />
<child link="neck_1" />
<axis xyz="0 0 1"/>
<limit effort="6" velocity="6" lower="-2.0944" upper="2.0944"/>
<joint_properties friction="0.0"/>
</joint>

<xacro:arg name="use_fake_walk" default="False"/>
<xacro:property name="fake_walk" value="$(arg use_fake_walk)" />

<transmission name="HeadPanTransmission">
<type>transmission_interface/SimpleTransmission</type>
<joint name="HeadPan">
    <hardwareInterface>hardware_interface/EffortJointInterface</hardwareInterface>
</joint>
<actuator name="HeadPanMotor">
    <hardwareInterface>hardware_interface/EffortJointInterface</hardwareInterface>
    <mechanicalReduction>1</mechanicalReduction>
</actuator>
</transmission>
<transmission name="HeadTiltTransmission">
<type>transmission_interface/SimpleTransmission</type>
<joint name="HeadTilt">
    <hardwareInterface>hardware_interface/EffortJointInterface</hardwareInterface>
</joint>
<actuator name="HeadTiltMotor">
    <hardwareInterface>hardware_interface/EffortJointInterface</hardwareInterface>
    <mechanicalReduction>1</mechanicalReduction>
</actuator>
</transmission>
<transmission name="LShoulderPitchTransmission">
<type>transmission_interface/SimpleTransmission</type>
<joint name="LShoulderPitch">
    <hardwareInterface>hardware_interface/EffortJointInterface</hardwareInterface>
</joint>
<actuator name="LShoulderPitchMotor">
    <hardwareInterface>hardware_interface/EffortJointInterface</hardwareInterface>
    <mechanicalReduction>1</mechanicalReduction>
</actuator>
</transmission>
<transmission name="LShoulderRollTransmission">
<type>transmission_interface/SimpleTransmission</type>
<joint name="LShoulderRoll">
    <hardwareInterface>hardware_interface/EffortJointInterface</hardwareInterface>
</joint>
<actuator name="LShoulderRollTransmission">
    <hardwareInterface>hardware_interface/EffortJointInterface</hardwareInterface>
    <mechanicalReduction>1</mechanicalReduction>
</actuator>
</transmission>
<transmission name="LElbowTransmission">
<type>transmission_interface/SimpleTransmission</type>
<joint name="LElbow">
    <hardwareInterface>hardware_interface/EffortJointInterface</hardwareInterface>
</joint>
<actuator name="LElbowMotor">
    <hardwareInterface>hardware_interface/EffortJointInterface</hardwareInterface>
    <mechanicalReduction>1</mechanicalReduction>
</actuator>
</transmission>
<transmission name="RShoulderPitchTransmission">
<type>transmission_interface/SimpleTransmission</type>
<joint name="RShoulderPitch">
    <hardwareInterface>hardware_interface/EffortJointInterface</hardwareInterface>
</joint>
<actuator name="RShoulderPitchMotor">
    <hardwareInterface>hardware_interface/EffortJointInterface</hardwareInterface>
    <mechanicalReduction>1</mechanicalReduction>
</actuator>
</transmission>
<transmission name="RShoulderRollTransmission">
<type>transmission_interface/SimpleTransmission</type>
<joint name="RShoulderRoll">
    <hardwareInterface>hardware_interface/EffortJointInterface</hardwareInterface>
</joint>
<actuator name="RShoulderRollMotor">
    <hardwareInterface>hardware_interface/EffortJointInterface</hardwareInterface>
    <mechanicalReduction>1</mechanicalReduction>
</actuator>
</transmission>
<transmission name="RElbowTransmission">
<type>transmission_interface/SimpleTransmission</type>
<joint name="RElbow">
    <hardwareInterface>hardware_interface/EffortJointInterface</hardwareInterface>
</joint>
<actuator name="RElbowMotor">
    <hardwareInterface>hardware_interface/EffortJointInterface</hardwareInterface>
    <mechanicalReduction>1</mechanicalReduction>
</actuator>
</transmission>
<transmission name="LHipYawTransmission">
<type>transmission_interface/SimpleTransmission</type>
<joint name="LHipYaw">
    <hardwareInterface>hardware_interface/EffortJointInterface</hardwareInterface>
</joint>
<actuator name="LHipYawMotor">
    <hardwareInterface>hardware_interface/EffortJointInterface</hardwareInterface>
    <mechanicalReduction>1</mechanicalReduction>
</actuator>
</transmission>
<transmission name="LHipRollTransmission">
<type>transmission_interface/SimpleTransmission</type>
<joint name="LHipRoll">
    <hardwareInterface>hardware_interface/EffortJointInterface</hardwareInterface>
</joint>
<actuator name="LHipRollMotor">
    <hardwareInterface>hardware_interface/EffortJointInterface</hardwareInterface>
    <mechanicalReduction>1</mechanicalReduction>
</actuator>
</transmission>
<transmission name="LHipPitchTransmission">
<type>transmission_interface/SimpleTransmission</type>
<joint name="LHipPitch">
    <hardwareInterface>hardware_interface/EffortJointInterface</hardwareInterface>
</joint>
<actuator name="LHipPitchMotor">
    <hardwareInterface>hardware_interface/EffortJointInterface</hardwareInterface>
    <mechanicalReduction>1</mechanicalReduction>
</actuator>
</transmission>
<transmission name="LKneeTransmission">
<type>transmission_interface/SimpleTransmission</type>
<joint name="LKnee">
    <hardwareInterface>hardware_interface/EffortJointInterface</hardwareInterface>
</joint>
<actuator name="LKneeMotor">
    <hardwareInterface>hardware_interface/EffortJointInterface</hardwareInterface>
    <mechanicalReduction>1</mechanicalReduction>
</actuator>
</transmission>
<transmission name="LAnklePitchTransmission">
<type>transmission_interface/SimpleTransmission</type>
<joint name="LAnklePitch">
    <hardwareInterface>hardware_interface/EffortJointInterface</hardwareInterface>
</joint>
<actuator name="LAnklePitchMotor">
    <hardwareInterface>hardware_interface/EffortJointInterface</hardwareInterface>
    <mechanicalReduction>1</mechanicalReduction>
</actuator>
</transmission>
<transmission name="LAnkleRollTransmission">
<type>transmission_interface/SimpleTransmission</type>
<joint name="LAnkleRoll">
    <hardwareInterface>hardware_interface/EffortJointInterface</hardwareInterface>
</joint>
<actuator name="LAnkleRollMotor">
    <hardwareInterface>hardware_interface/EffortJointInterface</hardwareInterface>
    <mechanicalReduction>1</mechanicalReduction>
</actuator>
</transmission>
<transmission name="RHipYawTransmission">
<type>transmission_interface/SimpleTransmission</type>
<joint name="RHipYaw">
    <hardwareInterface>hardware_interface/EffortJointInterface</hardwareInterface>
</joint>
<actuator name="RHipYawMotor">
    <hardwareInterface>hardware_interface/EffortJointInterface</hardwareInterface>
    <mechanicalReduction>1</mechanicalReduction>
</actuator>
</transmission>
<transmission name="RHipRollTransmission">
<type>transmission_interface/SimpleTransmission</type>
<joint name="RHipRoll">
    <hardwareInterface>hardware_interface/EffortJointInterface</hardwareInterface>
</joint>
<actuator name="RHipRollMotor">
    <hardwareInterface>hardware_interface/EffortJointInterface</hardwareInterface>
    <mechanicalReduction>1</mechanicalReduction>
</actuator>
</transmission>
<transmission name="RHipPitchTransmission">
<type>transmission_interface/SimpleTransmission</type>
<joint name="RHipPitch">
    <hardwareInterface>hardware_interface/EffortJointInterface</hardwareInterface>
</joint>
<actuator name="RHipPitchMotor">
    <hardwareInterface>hardware_interface/EffortJointInterface</hardwareInterface>
    <mechanicalReduction>1</mechanicalReduction>
</actuator>
</transmission>
<transmission name="RKneeTransmission">
<type>transmission_interface/SimpleTransmission</type>
<joint name="RKnee">
    <hardwareInterface>hardware_interface/EffortJointInterface</hardwareInterface>
</joint>
<actuator name="RKneeMotor">
    <hardwareInterface>hardware_interface/EffortJointInterface</hardwareInterface>
    <mechanicalReduction>1</mechanicalReduction>
</actuator>
</transmission>
<transmission name="RAnklePitchTransmission">
<type>transmission_interface/SimpleTransmission</type>
<joint name="RAnklePitch">
    <hardwareInterface>hardware_interface/EffortJointInterface</hardwareInterface>
</joint>
<actuator name="RAnklePitchMotor">
    <hardwareInterface>hardware_interface/EffortJointInterface</hardwareInterface>
    <mechanicalReduction>1</mechanicalReduction>
</actuator>
</transmission>
<transmission name="RAnkleRollTransmission">
<type>transmission_interface/SimpleTransmission</type>
<joint name="RAnkleRoll">
    <hardwareInterface>hardware_interface/EffortJointInterface</hardwareInterface>
</joint>
<actuator name="RAnkleRollMotor">
    <hardwareInterface>hardware_interface/EffortJointInterface</hardwareInterface>
    <mechanicalReduction>1</mechanicalReduction>
</actuator>
</transmission>
<gazebo reference="r_foot">
<material>Gazebo/FlatBlack</material>
<kp>1000000.0</kp>
<kd>100.0</kd>
<mu1>1.0</mu1>
<mu2>1.0</mu2>
<fdir1>1 0 0</fdir1>
<maxVel>1.0</maxVel>
<minDepth>0.00</minDepth>
</gazebo>
<gazebo reference="l_foot">
<material>Gazebo/FlatBlack</material>
<kp>1000000.0</kp>
<kd>100.0</kd>
<mu1>1.0</mu1>
<mu2>1.0</mu2>
<fdir1>1 0 0</fdir1>
<maxVel>1.0</maxVel>
<minDepth>0.00</minDepth>
</gazebo>

<!-- joint controller -->
<gazebo>
<plugin filename="libgazebo_ros_control.so" name="gazebo_ros_control">
    <robotNamespace>$(arg sim_ns)</robotNamespace>
</plugin>
</gazebo>

<!-- camera sensor -->
<gazebo reference="camera">
<sensor name='camera' type='camera'>
  <pose>-0.050000 -0.010000 0.000000 -1.5708 0.000000 -3.141592</pose>
  <camera name='__default__'>
    <horizontal_fov>0.57</horizontal_fov>
    <image>
      <width>620</width>
      <height>480</height>
    </image>
    <clip>
      <near>0.001000</near>
      <far>100.000000</far>
    </clip>
  </camera>
  <always_on>1</always_on>
  <update_rate>30.000000</update_rate>
  <visualize>1</visualize>
  <plugin name="camera_controller" filename="libgazebo_ros_camera.so">
    <alwaysOn>true</alwaysOn>
    <updateRate>30</updateRate>
    <cameraName>camera</cameraName>
    <imageTopicName>image_raw</imageTopicName>
    <cameraInfoTopicName>camera_info</cameraInfoTopicName>
    <frameName>camera_optical_frame</frameName>
    <hackBaseline>0.07</hackBaseline>
    <distortionK1>0.0</distortionK1>
    <distortionK2>0.0</distortionK2>
    <distortionK3>0.0</distortionK3>
    <distortionT1>0.0</distortionT1>
    <distortionT2>0.0</distortionT2>
  </plugin>
</sensor>
</gazebo>


<!-- IMU sensor -->
<gazebo reference="imu_frame">
<gravity>true</gravity>
<sensor name="imu_sensor" type="imu">
<always_on>true</always_on>
<update_rate>100</update_rate>
<visualize>true</visualize>
<topic>__default_topic__</topic>
<plugin filename="libgazebo_ros_imu_sensor.so" name="imu_plugin">
<topicName>imu</topicName>
<bodyName>imu_frame</bodyName>
<updateRateHZ>100.0</updateRateHZ>
<gaussianNoise>0.0</gaussianNoise>
<xyzOffset>0 0 0</xyzOffset>
<rpyOffset>0 0 0</rpyOffset>
<frameName>imu_frame</frameName>
</plugin>
<pose>0 0 0 0 0 0</pose>
</sensor>
</gazebo>

<!-- fake controller that allows us to move the robot and to get its oposition -->
<!-- rostopic pub /cmd_vel geometry_msgs/Twist "{ linear: [ 0.1, 0, 0], angular: [0.2, 0, 0.1] }" -->
<xacro:if value="${fake_walk == True}">
<!-- only active when fake_walk param is set to True -->
<gazebo>
<plugin name="object_controller" filename="libgazebo_ros_planar_move.so">
<robotNamespace>/</robotNamespace>

<commandTopic>cmd_vel</commandTopic>
<odometryTopic>odom</odometryTopic>
<odometryFrame>odom</odometryFrame>
<odometryRate>100.0</odometryRate>
<robotBaseFrame>base_link</robotBaseFrame>
</plugin>
</gazebo>
</xacro:if>

</robot>
