<sdf version='1.6'>
  <model name='wolfgang'>
    <link name='base_link'>
      <pose frame=''>0 0 0 0 -0 0</pose>
      <inertial>
        <pose frame=''>-0.001776 -9.7e-05 0.107062 0 -0 0</pose>
        <mass>1.79116</mass>
        <inertia>
          <ixx>0.0165883</ixx>
          <ixy>5.67507e-06</ixy>
          <ixz>-0.000843992</ixz>
          <iyy>0.0143606</iyy>
          <iyz>0.000156333</iyz>
          <izz>0.00676935</izz>
        </inertia>
      </inertial>
      <collision name='base_link_fixed_joint_lump__torso_collision'>
        <pose frame=''>-0.0015 0.053 0.2035 3.14159 1.57079 -3e-06</pose>
        <geometry>
          <mesh>
            <scale>1 1 1</scale>
            <uri>model://wolfgang_description/urdf/mx-64-body.stl</uri>
          </mesh>
        </geometry>
      </collision>
      <collision name='base_link_fixed_joint_lump__torso_collision_1'>
        <pose frame=''>0.058 0.07 0.1455 -3.14159 1.57079 1.57079</pose>
        <geometry>
          <mesh>
            <scale>1 1 1</scale>
            <uri>model://wolfgang_description/urdf/nuc_holdingrail_left.stl</uri>
          </mesh>
        </geometry>
      </collision>
      <collision name='base_link_fixed_joint_lump__torso_collision_2'>
        <pose frame=''>-0.02625 0.0025 0.0275 1.5708 0 -1.5708</pose>
        <geometry>
          <mesh>
            <scale>1 1 1</scale>
            <uri>model://wolfgang_description/urdf/battery_dummy.stl</uri>
          </mesh>
        </geometry>
      </collision>
      <collision name='base_link_fixed_joint_lump__torso_collision_3'>
        <pose frame=''>-0.0015 -0.053 0.2035 3.14159 -1.57079 3.14159</pose>
        <geometry>
          <mesh>
            <scale>1 1 1</scale>
            <uri>model://wolfgang_description/urdf/mx-64-body.stl</uri>
          </mesh>
        </geometry>
      </collision>
      <collision name='base_link_fixed_joint_lump__torso_collision_4'>
        <pose frame=''>-0 0.055 0.043 -1.5708 0 1.5708</pose>
        <geometry>
          <mesh>
            <scale>1 1 1</scale>
            <uri>model://wolfgang_description/urdf/router_left.stl</uri>
          </mesh>
        </geometry>
      </collision>
      <collision name='base_link_fixed_joint_lump__torso_collision_5'>
        <pose frame=''>-0.057 0.077 0.213915 -1.5708 0 1.5708</pose>
        <geometry>
          <mesh>
            <scale>1 1 1</scale>
            <uri>model://wolfgang_description/urdf/torso_bumper_right.stl</uri>
          </mesh>
        </geometry>
      </collision>
      <collision name='base_link_fixed_joint_lump__torso_collision_6'>
        <pose frame=''>-0.01 0.001 0.118 -0 0 -1.5708</pose>
        <geometry>
          <mesh>
            <scale>1 1 1</scale>
            <uri>model://wolfgang_description/urdf/core.stl</uri>
          </mesh>
        </geometry>
      </collision>
      <collision name='base_link_fixed_joint_lump__torso_collision_7'>
        <pose frame=''>0 -0.055 0.026 1.5708 0 -1.5708</pose>
        <geometry>
          <mesh>
            <scale>1 1 1</scale>
            <uri>model://wolfgang_description/urdf/mx-106_body.stl</uri>
          </mesh>
        </geometry>
      </collision>
      <collision name='base_link_fixed_joint_lump__torso_collision_8'>
        <pose frame=''>0.053 0.077 0.213915 -1.5708 -0 -1.5708</pose>
        <geometry>
          <mesh>
            <scale>1 1 1</scale>
            <uri>model://wolfgang_description/urdf/torso_bumper_left.stl</uri>
          </mesh>
        </geometry>
      </collision>
      <collision name='base_link_fixed_joint_lump__torso_collision_9'>
        <pose frame=''>-0 0.055 0.026 1.5708 0 -1.5708</pose>
        <geometry>
          <mesh>
            <scale>1 1 1</scale>
            <uri>model://wolfgang_description/urdf/mx-106_body.stl</uri>
          </mesh>
        </geometry>
      </collision>
      <collision name='base_link_fixed_joint_lump__torso_collision_10'>
        <pose frame=''>0.00265 -0.0001 0.1455 0 0 1.5708</pose>
        <geometry>
          <mesh>
            <scale>1 1 1</scale>
            <uri>model://wolfgang_description/urdf/nuc_bottom.stl</uri>
          </mesh>
        </geometry>
      </collision>
      <collision name='base_link_fixed_joint_lump__torso_collision_11'>
        <pose frame=''>-0.0015 -0.036 0.2035 3.14159 1.57079 -3e-06</pose>
        <geometry>
          <mesh>
            <scale>1 1 1</scale>
            <uri>model://wolfgang_description/urdf/imu_holder.stl</uri>
          </mesh>
        </geometry>
      </collision>
      <collision name='base_link_fixed_joint_lump__torso_collision_12'>
        <pose frame=''>0.00265 -0.0001 0.1455 0 -0 1.5708</pose>
        <geometry>
          <mesh>
            <scale>1 1 1</scale>
            <uri>model://wolfgang_description/urdf/nuc_front.stl</uri>
          </mesh>
        </geometry>
      </collision>
      <collision name='base_link_fixed_joint_lump__torso_collision_13'>
        <pose frame=''>-0.062 0.075 0.003 0 -0 0</pose>
        <geometry>
          <mesh>
            <scale>1 1 1</scale>
            <uri>model://wolfgang_description/urdf/torso_bottom.stl</uri>
          </mesh>
        </geometry>
      </collision>
      <collision name='base_link_fixed_joint_lump__torso_collision_14'>
        <pose frame=''>-0.037 -0.0478 0.2141 3.14159 0 -1.5708</pose>
        <geometry>
          <mesh>
            <scale>1 1 1</scale>
            <uri>model://wolfgang_description/urdf/imu_bottom_cover.stl</uri>
          </mesh>
        </geometry>
      </collision>
      <collision name='base_link_fixed_joint_lump__torso_collision_15'>
        <pose frame=''>-0.0095 0 0.211 -1.5708 0 1.5708</pose>
        <geometry>
          <mesh>
            <scale>1 1 1</scale>
            <uri>model://wolfgang_description/urdf/mx-64-body.stl</uri>
          </mesh>
        </geometry>
      </collision>
      <collision name='base_link_fixed_joint_lump__torso_collision_16'>
        <pose frame=''>0 -0.055 0.043 -1.5708 0 1.5708</pose>
        <geometry>
          <mesh>
            <scale>1 1 1</scale>
            <uri>model://wolfgang_description/urdf/router_right.stl</uri>
          </mesh>
        </geometry>
      </collision>
      <collision name='base_link_fixed_joint_lump__torso_collision_17'>
        <pose frame=''>-0.057 -0.077 0.213915 -1.5708 0 1.5708</pose>
        <geometry>
          <mesh>
            <scale>1 1 1</scale>
            <uri>model://wolfgang_description/urdf/torso_bumper_left.stl</uri>
          </mesh>
        </geometry>
      </collision>
      <collision name='base_link_fixed_joint_lump__torso_collision_18'>
        <pose frame=''>-0.002 -0 0.088 -0 -0 -1.5708</pose>
        <geometry>
          <mesh>
            <scale>1 1 1</scale>
            <uri>model://wolfgang_description/urdf/baseplate_odroid_xu4_core.stl</uri>
          </mesh>
        </geometry>
      </collision>
      <collision name='base_link_fixed_joint_lump__torso_collision_19'>
        <pose frame=''>0.051 0.0367 0.057 -1.5708 -0 -1.5708</pose>
        <geometry>
          <mesh>
            <scale>1 1 1</scale>
            <uri>model://wolfgang_description/urdf/router.stl</uri>
          </mesh>
        </geometry>
      </collision>
      <collision name='base_link_fixed_joint_lump__torso_collision_20'>
        <pose frame=''>0.00265 -0.0001 0.1455 0 0 1.5708</pose>
        <geometry>
          <mesh>
            <scale>1 1 1</scale>
            <uri>model://wolfgang_description/urdf/nuc_main.stl</uri>
          </mesh>
        </geometry>
      </collision>
      <collision name='base_link_fixed_joint_lump__torso_collision_21'>
        <pose frame=''>0.053 -0.077 0.213915 -1.5708 -0 -1.5708</pose>
        <geometry>
          <mesh>
            <scale>1 1 1</scale>
            <uri>model://wolfgang_description/urdf/torso_bumper_right.stl</uri>
          </mesh>
        </geometry>
      </collision>
      <collision name='base_link_fixed_joint_lump__torso_collision_22'>
        <pose frame=''>0.058 -0.07 0.1455 -3.14159 1.57079 1.57079</pose>
        <geometry>
          <mesh>
            <scale>1 1 1</scale>
            <uri>model://wolfgang_description/urdf/nuc_holdingrail_right.stl</uri>
          </mesh>
        </geometry>
      </collision>
      <collision name='base_link_fixed_joint_lump__torso_collision_23'>
        <pose frame=''>-0.077 -0.075 0.083 0 -0 1.5708</pose>
        <geometry>
          <mesh>
            <scale>1 1 1</scale>
            <uri>model://wolfgang_description/urdf/torso_top.stl</uri>
          </mesh>
        </geometry>
      </collision>
      <visual name='base_link_fixed_joint_lump__torso_visual'>
        <pose frame=''>-0.0015 0.053 0.2035 3.14159 1.57079 -3e-06</pose>
        <geometry>
          <mesh>
            <scale>1 1 1</scale>
            <uri>model://wolfgang_description/urdf/mx-64-body.stl</uri>
          </mesh>
        </geometry>
      </visual>
      <visual name='base_link_fixed_joint_lump__torso_visual_1'>
        <pose frame=''>0.058 0.07 0.1455 -3.14159 1.57079 1.57079</pose>
        <geometry>
          <mesh>
            <scale>1 1 1</scale>
            <uri>model://wolfgang_description/urdf/nuc_holdingrail_left.stl</uri>
          </mesh>
        </geometry>
      </visual>
      <visual name='base_link_fixed_joint_lump__torso_visual_2'>
        <pose frame=''>-0.02625 0.0025 0.0275 1.5708 0 -1.5708</pose>
        <geometry>
          <mesh>
            <scale>1 1 1</scale>
            <uri>model://wolfgang_description/urdf/battery_dummy.stl</uri>
          </mesh>
        </geometry>
      </visual>
      <visual name='base_link_fixed_joint_lump__torso_visual_3'>
        <pose frame=''>-0.0015 -0.053 0.2035 3.14159 -1.57079 3.14159</pose>
        <geometry>
          <mesh>
            <scale>1 1 1</scale>
            <uri>model://wolfgang_description/urdf/mx-64-body.stl</uri>
          </mesh>
        </geometry>
      </visual>
      <visual name='base_link_fixed_joint_lump__torso_visual_4'>
        <pose frame=''>-0 0.055 0.043 -1.5708 0 1.5708</pose>
        <geometry>
          <mesh>
            <scale>1 1 1</scale>
            <uri>model://wolfgang_description/urdf/router_left.stl</uri>
          </mesh>
        </geometry>
      </visual>
      <visual name='base_link_fixed_joint_lump__torso_visual_5'>
        <pose frame=''>-0.057 0.077 0.213915 -1.5708 0 1.5708</pose>
        <geometry>
          <mesh>
            <scale>1 1 1</scale>
            <uri>model://wolfgang_description/urdf/torso_bumper_right.stl</uri>
          </mesh>
        </geometry>
      </visual>
      <visual name='base_link_fixed_joint_lump__torso_visual_6'>
        <pose frame=''>-0.01 0.001 0.118 -0 0 -1.5708</pose>
        <geometry>
          <mesh>
            <scale>1 1 1</scale>
            <uri>model://wolfgang_description/urdf/core.stl</uri>
          </mesh>
        </geometry>
      </visual>
      <visual name='base_link_fixed_joint_lump__torso_visual_7'>
        <pose frame=''>0 -0.055 0.026 1.5708 0 -1.5708</pose>
        <geometry>
          <mesh>
            <scale>1 1 1</scale>
            <uri>model://wolfgang_description/urdf/mx-106_body.stl</uri>
          </mesh>
        </geometry>
      </visual>
      <visual name='base_link_fixed_joint_lump__torso_visual_8'>
        <pose frame=''>0.053 0.077 0.213915 -1.5708 -0 -1.5708</pose>
        <geometry>
          <mesh>
            <scale>1 1 1</scale>
            <uri>model://wolfgang_description/urdf/torso_bumper_left.stl</uri>
          </mesh>
        </geometry>
      </visual>
      <visual name='base_link_fixed_joint_lump__torso_visual_9'>
        <pose frame=''>-0 0.055 0.026 1.5708 0 -1.5708</pose>
        <geometry>
          <mesh>
            <scale>1 1 1</scale>
            <uri>model://wolfgang_description/urdf/mx-106_body.stl</uri>
          </mesh>
        </geometry>
      </visual>
      <visual name='base_link_fixed_joint_lump__torso_visual_10'>
        <pose frame=''>0.00265 -0.0001 0.1455 0 0 1.5708</pose>
        <geometry>
          <mesh>
            <scale>1 1 1</scale>
            <uri>model://wolfgang_description/urdf/nuc_bottom.stl</uri>
          </mesh>
        </geometry>
      </visual>
      <visual name='base_link_fixed_joint_lump__torso_visual_11'>
        <pose frame=''>-0.0015 -0.036 0.2035 3.14159 1.57079 -3e-06</pose>
        <geometry>
          <mesh>
            <scale>1 1 1</scale>
            <uri>model://wolfgang_description/urdf/imu_holder.stl</uri>
          </mesh>
        </geometry>
      </visual>
      <visual name='base_link_fixed_joint_lump__torso_visual_12'>
        <pose frame=''>0.00265 -0.0001 0.1455 0 -0 1.5708</pose>
        <geometry>
          <mesh>
            <scale>1 1 1</scale>
            <uri>model://wolfgang_description/urdf/nuc_front.stl</uri>
          </mesh>
        </geometry>
      </visual>
      <visual name='base_link_fixed_joint_lump__torso_visual_13'>
        <pose frame=''>-0.062 0.075 0.003 0 -0 0</pose>
        <geometry>
          <mesh>
            <scale>1 1 1</scale>
            <uri>model://wolfgang_description/urdf/torso_bottom.stl</uri>
          </mesh>
        </geometry>
      </visual>
      <visual name='base_link_fixed_joint_lump__torso_visual_14'>
        <pose frame=''>-0.037 -0.0478 0.2141 3.14159 0 -1.5708</pose>
        <geometry>
          <mesh>
            <scale>1 1 1</scale>
            <uri>model://wolfgang_description/urdf/imu_bottom_cover.stl</uri>
          </mesh>
        </geometry>
      </visual>
      <visual name='base_link_fixed_joint_lump__torso_visual_15'>
        <pose frame=''>-0.0095 0 0.211 -1.5708 0 1.5708</pose>
        <geometry>
          <mesh>
            <scale>1 1 1</scale>
            <uri>model://wolfgang_description/urdf/mx-64-body.stl</uri>
          </mesh>
        </geometry>
      </visual>
      <visual name='base_link_fixed_joint_lump__torso_visual_16'>
        <pose frame=''>0 -0.055 0.043 -1.5708 0 1.5708</pose>
        <geometry>
          <mesh>
            <scale>1 1 1</scale>
            <uri>model://wolfgang_description/urdf/router_right.stl</uri>
          </mesh>
        </geometry>
      </visual>
      <visual name='base_link_fixed_joint_lump__torso_visual_17'>
        <pose frame=''>-0.057 -0.077 0.213915 -1.5708 0 1.5708</pose>
        <geometry>
          <mesh>
            <scale>1 1 1</scale>
            <uri>model://wolfgang_description/urdf/torso_bumper_left.stl</uri>
          </mesh>
        </geometry>
      </visual>
      <visual name='base_link_fixed_joint_lump__torso_visual_18'>
        <pose frame=''>-0.002 -0 0.088 -0 -0 -1.5708</pose>
        <geometry>
          <mesh>
            <scale>1 1 1</scale>
            <uri>model://wolfgang_description/urdf/baseplate_odroid_xu4_core.stl</uri>
          </mesh>
        </geometry>
      </visual>
      <visual name='base_link_fixed_joint_lump__torso_visual_19'>
        <pose frame=''>0.051 0.0367 0.057 -1.5708 -0 -1.5708</pose>
        <geometry>
          <mesh>
            <scale>1 1 1</scale>
            <uri>model://wolfgang_description/urdf/router.stl</uri>
          </mesh>
        </geometry>
      </visual>
      <visual name='base_link_fixed_joint_lump__torso_visual_20'>
        <pose frame=''>0.00265 -0.0001 0.1455 0 0 1.5708</pose>
        <geometry>
          <mesh>
            <scale>1 1 1</scale>
            <uri>model://wolfgang_description/urdf/nuc_main.stl</uri>
          </mesh>
        </geometry>
      </visual>
      <visual name='base_link_fixed_joint_lump__torso_visual_21'>
        <pose frame=''>0.053 -0.077 0.213915 -1.5708 -0 -1.5708</pose>
        <geometry>
          <mesh>
            <scale>1 1 1</scale>
            <uri>model://wolfgang_description/urdf/torso_bumper_right.stl</uri>
          </mesh>
        </geometry>
      </visual>
      <visual name='base_link_fixed_joint_lump__torso_visual_22'>
        <pose frame=''>0.058 -0.07 0.1455 -3.14159 1.57079 1.57079</pose>
        <geometry>
          <mesh>
            <scale>1 1 1</scale>
            <uri>model://wolfgang_description/urdf/nuc_holdingrail_right.stl</uri>
          </mesh>
        </geometry>
      </visual>
      <visual name='base_link_fixed_joint_lump__torso_visual_23'>
        <pose frame=''>-0.077 -0.075 0.083 0 -0 1.5708</pose>
        <geometry>
          <mesh>
            <scale>1 1 1</scale>
            <uri>model://wolfgang_description/urdf/torso_top.stl</uri>
          </mesh>
        </geometry>
      </visual>
      <gravity>1</gravity>
      <velocity_decay/>
      <gravity>1</gravity>
      <sensor name='imu_sensor' type='imu'>
        <always_on>1</always_on>
        <update_rate>100</update_rate>
        <visualize>1</visualize>
        <topic>__default_topic__</topic>
        <plugin name='imu_plugin' filename='libgazebo_ros_imu_sensor.so'>
          <topicName>imu</topicName>
          <bodyName>imu_frame</bodyName>
          <updateRateHZ>100.0</updateRateHZ>
          <gaussianNoise>0.0</gaussianNoise>
          <xyzOffset>0 0 0</xyzOffset>
          <rpyOffset>0 0 0</rpyOffset>
          <frameName>imu_frame</frameName>
        </plugin>
        <pose frame=''>-0.03675 -0.047802 0.224 0 -0 0</pose>
      </sensor>
    </link>
    <link name='neck_1'>
      <pose frame=''>-0.0095 0 0.2345 -3.14159 0 -0</pose>
      <inertial>
        <pose frame=''>0.018691 -7.8e-05 -0.022014 0 -0 0</pose>
        <mass>0.148233</mass>
        <inertia>
          <ixx>3.89355e-05</ixx>
          <ixy>-5.28709e-07</ixy>
          <ixz>4.95698e-06</ixz>
          <iyy>5.76318e-05</iyy>
          <iyz>-2.28158e-08</iyz>
          <izz>6.25414e-05</izz>
        </inertia>
      </inertial>
      <collision name='neck_1_collision'>
        <pose frame=''>0.0035 0 -0.0093 -0 0 -0</pose>
        <geometry>
          <mesh>
            <scale>1 1 1</scale>
            <uri>model://wolfgang_description/urdf/connector_shoulder.stl</uri>
          </mesh>
        </geometry>
      </collision>
      <collision name='neck_1_collision_1'>
        <pose frame=''>0.036 0 -0.024 3.14159 -1.57079 -3e-06</pose>
        <geometry>
          <mesh>
            <scale>1 1 1</scale>
            <uri>model://wolfgang_description/urdf/mx-64-body.stl</uri>
          </mesh>
        </geometry>
      </collision>
      <visual name='neck_1_visual'>
        <pose frame=''>0.0035 0 -0.0093 -0 0 -0</pose>
        <geometry>
          <mesh>
            <scale>1 1 1</scale>
            <uri>model://wolfgang_description/urdf/connector_shoulder.stl</uri>
          </mesh>
        </geometry>
      </visual>
      <visual name='neck_1_visual_1'>
        <pose frame=''>0.036 0 -0.024 3.14159 -1.57079 -3e-06</pose>
        <geometry>
          <mesh>
            <scale>1 1 1</scale>
            <uri>model://wolfgang_description/urdf/mx-64-body.stl</uri>
          </mesh>
        </geometry>
      </visual>
    </link>
    <joint name='HeadPan' type='revolute'>
      <child>neck_1</child>
      <parent>base_link</parent>
      <axis>
        <xyz>-0 3e-06 -1</xyz>
        <limit>
          <lower>-2.0944</lower>
          <upper>2.0944</upper>
          <effort>5.43</effort>
          <velocity>10.33</velocity>
        </limit>
        <dynamics>
          <spring_reference>0</spring_reference>
          <spring_stiffness>0</spring_stiffness>
        </dynamics>
        <use_parent_model_frame>1</use_parent_model_frame>
      </axis>
    </joint>
    <link name='head'>
      <pose frame=''>0.0265 -0.0235 0.2585 1.5708 -0 0</pose>
      <inertial>
        <pose frame=''>-0.003471 0.068283 -0.020251 0 -0 0</pose>
        <mass>0.318645</mass>
        <inertia>
          <ixx>0.000360976</ixx>
          <ixy>-3.54024e-06</ixy>
          <ixz>-2.96129e-06</ixz>
          <iyy>0.00044172</iyy>
          <iyz>5.19892e-05</iyz>
          <izz>0.000524061</izz>
        </inertia>
      </inertial>
      <collision name='head_collision'>
        <pose frame=''>0.0432 0.0795 -0.0235 3.14159 -1.57079 1.57079</pose>
        <geometry>
          <mesh>
            <scale>1 1 1</scale>
            <uri>model://wolfgang_description/urdf/lense.stl</uri>
          </mesh>
        </geometry>
      </collision>
      <collision name='head_collision_1'>
        <pose frame=''>0 0 0 0 -0 0</pose>
        <geometry>
          <mesh>
            <scale>1 1 1</scale>
            <uri>model://wolfgang_description/urdf/sea_ninjaflex.stl</uri>
          </mesh>
        </geometry>
      </collision>
      <collision name='head_collision_2'>
        <pose frame=''>-0 -0 0.009 -0 -0 3.14159</pose>
        <geometry>
          <mesh>
            <scale>1 1 1</scale>
            <uri>model://wolfgang_description/urdf/sea_connector.stl</uri>
          </mesh>
        </geometry>
      </collision>
      <collision name='head_collision_3'>
        <pose frame=''>0.01 0.065 0.024 -0 -0 -0</pose>
        <geometry>
          <mesh>
            <scale>1 1 1</scale>
            <uri>model://wolfgang_description/urdf/camera_side_basler_wolfgang_v2.2_right.stl</uri>
          </mesh>
        </geometry>
      </collision>
      <collision name='head_collision_4'>
        <pose frame=''>0.01 0.065 -0.051 -0 -0 -0</pose>
        <geometry>
          <mesh>
            <scale>1 1 1</scale>
            <uri>model://wolfgang_description/urdf/camera_side_basler_wolfgang_v2.2_left.stl</uri>
          </mesh>
        </geometry>
      </collision>
      <collision name='head_collision_5'>
        <pose frame=''>0.015 0.0795 -0.0235 3.14159 -1.57079 1.57079</pose>
        <geometry>
          <mesh>
            <scale>1 1 1</scale>
            <uri>model://wolfgang_description/urdf/basler_ace_gige_c-mount_v01.stl</uri>
          </mesh>
        </geometry>
      </collision>
      <collision name='head_collision_6'>
        <pose frame=''>0.003 0.065 -0.037945 -3.14159 -1.57079 -3.14159</pose>
        <geometry>
          <mesh>
            <scale>1 1 1</scale>
            <uri>model://wolfgang_description/urdf/camera_lower_basler_wolfgang_imu_v2.2.stl</uri>
          </mesh>
        </geometry>
      </collision>
      <visual name='head_visual'>
        <pose frame=''>0.0432 0.0795 -0.0235 3.14159 -1.57079 1.57079</pose>
        <geometry>
          <mesh>
            <scale>1 1 1</scale>
            <uri>model://wolfgang_description/urdf/lense.stl</uri>
          </mesh>
        </geometry>
      </visual>
      <visual name='head_visual_1'>
        <pose frame=''>0 0 0 0 -0 0</pose>
        <geometry>
          <mesh>
            <scale>1 1 1</scale>
            <uri>model://wolfgang_description/urdf/sea_ninjaflex.stl</uri>
          </mesh>
        </geometry>
      </visual>
      <visual name='head_visual_2'>
        <pose frame=''>-0 -0 0.009 -0 -0 3.14159</pose>
        <geometry>
          <mesh>
            <scale>1 1 1</scale>
            <uri>model://wolfgang_description/urdf/sea_connector.stl</uri>
          </mesh>
        </geometry>
      </visual>
      <visual name='head_visual_3'>
        <pose frame=''>0.01 0.065 0.024 -0 -0 -0</pose>
        <geometry>
          <mesh>
            <scale>1 1 1</scale>
            <uri>model://wolfgang_description/urdf/camera_side_basler_wolfgang_v2.2_right.stl</uri>
          </mesh>
        </geometry>
      </visual>
      <visual name='head_visual_4'>
        <pose frame=''>0.01 0.065 -0.051 -0 -0 -0</pose>
        <geometry>
          <mesh>
            <scale>1 1 1</scale>
            <uri>model://wolfgang_description/urdf/camera_side_basler_wolfgang_v2.2_left.stl</uri>
          </mesh>
        </geometry>
      </visual>
      <visual name='head_visual_5'>
        <pose frame=''>0.015 0.0795 -0.0235 3.14159 -1.57079 1.57079</pose>
        <geometry>
          <mesh>
            <scale>1 1 1</scale>
            <uri>model://wolfgang_description/urdf/basler_ace_gige_c-mount_v01.stl</uri>
          </mesh>
        </geometry>
      </visual>
      <visual name='head_visual_6'>
        <pose frame=''>0.003 0.065 -0.037945 -3.14159 -1.57079 -3.14159</pose>
        <geometry>
          <mesh>
            <scale>1 1 1</scale>
            <uri>model://wolfgang_description/urdf/camera_lower_basler_wolfgang_imu_v2.2.stl</uri>
          </mesh>
        </geometry>
      </visual>
      <gravity>1</gravity>
      <velocity_decay/>
      <sensor name='camera' type='camera'>
        <camera name='__default__'>
          <horizontal_fov>0.57</horizontal_fov>
          <image>
            <width>620</width>
            <height>480</height>
          </image>
          <clip>
            <near>0.001</near>
            <far>100</far>
          </clip>
        </camera>
        <always_on>1</always_on>
        <update_rate>30</update_rate>
        <visualize>1</visualize>
        <plugin name='camera_controller' filename='libgazebo_ros_camera.so'>
          <alwaysOn>1</alwaysOn>
          <updateRate>30</updateRate>
          <cameraName>camera</cameraName>
          <imageTopicName>image_raw</imageTopicName>
          <cameraInfoTopicName>camera_info</cameraInfoTopicName>
          <frameName>camera_optical_frame</frameName>
          <hackBaseline>0.07</hackBaseline>
          <distortionK1>0.0</distortionK1>
          <distortionK2>0.0</distortionK2>
          <distortionK3>0.0</distortionK3>
          <distortionT1>0.0</distortionT1>
          <distortionT2>0.0</distortionT2>
        </plugin>
        <pose frame=''>0.0437 0.0795 -0.0235 -1.5708 -0 -0</pose>
      </sensor>
    </link>
    <joint name='HeadTilt' type='revolute'>
      <child>head</child>
      <parent>neck_1</parent>
      <axis>
        <xyz>-0 1 -1e-06</xyz>
        <limit>
          <lower>0</lower>
          <upper>1.5708</upper>
          <effort>5.43</effort>
          <velocity>10.33</velocity>
        </limit>
        <dynamics>
          <spring_reference>0</spring_reference>
          <spring_stiffness>0</spring_stiffness>
        </dynamics>
        <use_parent_model_frame>1</use_parent_model_frame>
      </axis>
    </joint>
    <link name='hip_u_connector_2'>
      <pose frame=''>-0 0.055 0 -1.5708 0 0</pose>
      <inertial>
        <pose frame=''>0 0.010315 -0 0 -0 0</pose>
        <mass>0.0689735</mass>
        <inertia>
          <ixx>2.18955e-05</ixx>
          <ixy>-2.44475e-14</ixy>
          <ixz>3.06793e-15</ixz>
          <iyy>0.00010714</iyy>
          <iyz>-6.56688e-11</iyz>
          <izz>0.000110523</izz>
        </inertia>
      </inertial>
      <collision name='hip_u_connector_2_collision'>
        <pose frame=''>0 -0.0006 -0.018 0 -0 0</pose>
        <geometry>
          <mesh>
            <scale>1 1 1</scale>
            <uri>model://wolfgang_description/urdf/hip_u_connector.stl</uri>
          </mesh>
        </geometry>
      </collision>
      <visual name='hip_u_connector_2_visual'>
        <pose frame=''>0 -0.0006 -0.018 0 -0 0</pose>
        <geometry>
          <mesh>
            <scale>1 1 1</scale>
            <uri>model://wolfgang_description/urdf/hip_u_connector.stl</uri>
          </mesh>
        </geometry>
      </visual>
    </link>
    <joint name='LHipYaw' type='revolute'>
      <child>hip_u_connector_2</child>
      <parent>base_link</parent>
      <axis>
        <xyz>0 4e-06 1</xyz>
        <limit>
          <lower>-1.5708</lower>
          <upper>1.5708</upper>
          <effort>7.57</effort>
          <velocity>8.22</velocity>
        </limit>
        <dynamics>
          <spring_reference>0</spring_reference>
          <spring_stiffness>0</spring_stiffness>
        </dynamics>
        <use_parent_model_frame>1</use_parent_model_frame>
      </axis>
    </joint>
    <link name='left_hip_right_ankle_2'>
      <pose frame=''>-0.046 0.055 -0.0414 1.57079 -4e-06 -1.5708</pose>
      <inertial>
        <pose frame=''>-4e-06 -0.015528 -0.048644 0 -0 0</pose>
        <mass>0.319807</mass>
        <inertia>
          <ixx>0.000268673</ixx>
          <ixy>-7.40992e-08</ixy>
          <ixz>-6.18751e-07</ixz>
          <iyy>0.000268098</iyy>
          <iyz>3.88325e-06</iyz>
          <izz>0.000121333</izz>
        </inertia>
      </inertial>
      <collision name='left_hip_right_ankle_2_collision'>
        <pose frame=''>0.0145 0.007 -0.043 -3.14159 0 -1.5708</pose>
        <geometry>
          <mesh>
            <scale>1 1 1</scale>
            <uri>model://wolfgang_description/urdf/motor_connector.stl</uri>
          </mesh>
        </geometry>
      </collision>
      <collision name='left_hip_right_ankle_2_collision_1'>
        <pose frame=''>0 0 -0.026 -1.5708 -0 0</pose>
        <geometry>
          <mesh>
            <scale>1 1 1</scale>
            <uri>model://wolfgang_description/urdf/mx-106_body.stl</uri>
          </mesh>
        </geometry>
      </collision>
      <collision name='left_hip_right_ankle_2_collision_2'>
        <pose frame=''>0 -0 -0.0691 3.14159 1.57079 -1.57079</pose>
        <geometry>
          <mesh>
            <scale>1 1 1</scale>
            <uri>model://wolfgang_description/urdf/mx-106_body.stl</uri>
          </mesh>
        </geometry>
      </collision>
      <collision name='left_hip_right_ankle_2_collision_3'>
        <pose frame=''>-0.0145 -0.021 -0.043 3.14159 -0 1.5708</pose>
        <geometry>
          <mesh>
            <scale>1 1 1</scale>
            <uri>model://wolfgang_description/urdf/motor_connector.stl</uri>
          </mesh>
        </geometry>
      </collision>
      <collision name='left_hip_right_ankle_2_collision_4'>
        <pose frame=''>0.0151 0.0105 -0.0892 -0 0 -3.14159</pose>
        <geometry>
          <mesh>
            <scale>1 1 1</scale>
            <uri>model://wolfgang_description/urdf/thrustbearingholder.stl</uri>
          </mesh>
        </geometry>
      </collision>
      <visual name='left_hip_right_ankle_2_visual'>
        <pose frame=''>0.0145 0.007 -0.043 -3.14159 0 -1.5708</pose>
        <geometry>
          <mesh>
            <scale>1 1 1</scale>
            <uri>model://wolfgang_description/urdf/motor_connector.stl</uri>
          </mesh>
        </geometry>
      </visual>
      <visual name='left_hip_right_ankle_2_visual_1'>
        <pose frame=''>0 0 -0.026 -1.5708 -0 0</pose>
        <geometry>
          <mesh>
            <scale>1 1 1</scale>
            <uri>model://wolfgang_description/urdf/mx-106_body.stl</uri>
          </mesh>
        </geometry>
      </visual>
      <visual name='left_hip_right_ankle_2_visual_2'>
        <pose frame=''>0 -0 -0.0691 3.14159 1.57079 -1.57079</pose>
        <geometry>
          <mesh>
            <scale>1 1 1</scale>
            <uri>model://wolfgang_description/urdf/mx-106_body.stl</uri>
          </mesh>
        </geometry>
      </visual>
      <visual name='left_hip_right_ankle_2_visual_3'>
        <pose frame=''>-0.0145 -0.021 -0.043 3.14159 -0 1.5708</pose>
        <geometry>
          <mesh>
            <scale>1 1 1</scale>
            <uri>model://wolfgang_description/urdf/motor_connector.stl</uri>
          </mesh>
        </geometry>
      </visual>
      <visual name='left_hip_right_ankle_2_visual_4'>
        <pose frame=''>0.0151 0.0105 -0.0892 -0 0 -3.14159</pose>
        <geometry>
          <mesh>
            <scale>1 1 1</scale>
            <uri>model://wolfgang_description/urdf/thrustbearingholder.stl</uri>
          </mesh>
        </geometry>
      </visual>
    </link>
    <joint name='LHipRoll' type='revolute'>
      <child>left_hip_right_ankle_2</child>
      <parent>hip_u_connector_2</parent>
      <axis>
        <xyz>1 -4e-06 -3e-06</xyz>
        <limit>
          <lower>-1.5708</lower>
          <upper>1.5708</upper>
          <effort>7.57</effort>
          <velocity>8.22</velocity>
        </limit>
        <dynamics>
          <spring_reference>0</spring_reference>
          <spring_stiffness>0</spring_stiffness>
        </dynamics>
        <use_parent_model_frame>1</use_parent_model_frame>
      </axis>
    </joint>
    <link name='l_knee'>
      <pose frame=''>0.0231 0.029 -0.0414 1.5708 -3e-06 3.14159</pose>
      <inertial>
        <pose frame=''>-0.004328 -0.137334 0.0265 0 -0 0</pose>
        <mass>0.220799</mass>
        <inertia>
          <ixx>0.000439144</ixx>
          <ixy>-3.21416e-05</ixy>
          <ixz>2.66786e-06</ixz>
          <iyy>0.000110922</iyy>
          <iyz>2.40516e-06</iyz>
          <izz>0.000401348</izz>
        </inertia>
      </inertial>
      <collision name='l_knee_collision'>
        <pose frame=''>-0.018236 -0.130164 0.028347 3.14159 0 0.523599</pose>
        <geometry>
          <mesh>
            <scale>1 1 1</scale>
            <uri>model://wolfgang_description/urdf/knee_connector.stl</uri>
          </mesh>
        </geometry>
      </collision>
      <collision name='l_knee_collision_1'>
        <pose frame=''>-0.081124 -0.148357 0.049 -3.14159 -0 -0</pose>
        <geometry>
          <mesh>
            <scale>1 1 1</scale>
            <uri>model://wolfgang_description/urdf/part_1.stl</uri>
          </mesh>
        </geometry>
      </collision>
      <collision name='l_knee_collision_2'>
        <pose frame=''>-0.017803 -0.129914 0.020653 0 0 -2.61799</pose>
        <geometry>
          <mesh>
            <scale>1 1 1</scale>
            <uri>model://wolfgang_description/urdf/knee_connector.stl</uri>
          </mesh>
        </geometry>
      </collision>
      <collision name='l_knee_collision_3'>
        <pose frame=''>0.004356 -0.168793 0.0245 0 -0 -2.61799</pose>
        <geometry>
          <mesh>
            <scale>1 1 1</scale>
            <uri>model://wolfgang_description/urdf/xh-540.stl</uri>
          </mesh>
        </geometry>
      </collision>
      <collision name='l_knee_collision_4'>
        <pose frame=''>-0.014 -0.138 0.053 -0 0 2.61799</pose>
        <geometry>
          <mesh>
            <scale>1 1 1</scale>
            <uri>model://wolfgang_description/urdf/spring_holder_upper.stl</uri>
          </mesh>
        </geometry>
      </collision>
      <collision name='l_knee_collision_5'>
        <pose frame=''>-0.081124 0.148357 -0 0 -0 0</pose>
        <geometry>
          <mesh>
            <scale>1 1 1</scale>
            <uri>model://wolfgang_description/urdf/part_1.stl</uri>
          </mesh>
        </geometry>
      </collision>
      <collision name='l_knee_collision_6'>
        <pose frame=''>0 0 -0.002 1.5708 -0 -3.14159</pose>
        <geometry>
          <mesh>
            <scale>1 1 1</scale>
            <uri>model://wolfgang_description/urdf/upper_leg.stl</uri>
          </mesh>
        </geometry>
      </collision>
      <collision name='l_knee_collision_7'>
        <pose frame=''>0 0 0.053 1.5708 0 3.14159</pose>
        <geometry>
          <mesh>
            <scale>1 1 1</scale>
            <uri>model://wolfgang_description/urdf/upper_leg.stl</uri>
          </mesh>
        </geometry>
      </collision>
      <visual name='l_knee_visual'>
        <pose frame=''>-0.018236 -0.130164 0.028347 3.14159 0 0.523599</pose>
        <geometry>
          <mesh>
            <scale>1 1 1</scale>
            <uri>model://wolfgang_description/urdf/knee_connector.stl</uri>
          </mesh>
        </geometry>
      </visual>
      <visual name='l_knee_visual_1'>
        <pose frame=''>-0.081124 -0.148357 0.049 -3.14159 -0 -0</pose>
        <geometry>
          <mesh>
            <scale>1 1 1</scale>
            <uri>model://wolfgang_description/urdf/part_1.stl</uri>
          </mesh>
        </geometry>
      </visual>
      <visual name='l_knee_visual_2'>
        <pose frame=''>-0.017803 -0.129914 0.020653 0 0 -2.61799</pose>
        <geometry>
          <mesh>
            <scale>1 1 1</scale>
            <uri>model://wolfgang_description/urdf/knee_connector.stl</uri>
          </mesh>
        </geometry>
      </visual>
      <visual name='l_knee_visual_3'>
        <pose frame=''>0.004356 -0.168793 0.0245 0 -0 -2.61799</pose>
        <geometry>
          <mesh>
            <scale>1 1 1</scale>
            <uri>model://wolfgang_description/urdf/xh-540.stl</uri>
          </mesh>
        </geometry>
      </visual>
      <visual name='l_knee_visual_4'>
        <pose frame=''>-0.014 -0.138 0.053 -0 0 2.61799</pose>
        <geometry>
          <mesh>
            <scale>1 1 1</scale>
            <uri>model://wolfgang_description/urdf/spring_holder_upper.stl</uri>
          </mesh>
        </geometry>
      </visual>
      <visual name='l_knee_visual_5'>
        <pose frame=''>-0.081124 0.148357 -0 0 -0 0</pose>
        <geometry>
          <mesh>
            <scale>1 1 1</scale>
            <uri>model://wolfgang_description/urdf/part_1.stl</uri>
          </mesh>
        </geometry>
      </visual>
      <visual name='l_knee_visual_6'>
        <pose frame=''>0 0 -0.002 1.5708 -0 -3.14159</pose>
        <geometry>
          <mesh>
            <scale>1 1 1</scale>
            <uri>model://wolfgang_description/urdf/upper_leg.stl</uri>
          </mesh>
        </geometry>
      </visual>
      <visual name='l_knee_visual_7'>
        <pose frame=''>0 0 0.053 1.5708 0 3.14159</pose>
        <geometry>
          <mesh>
            <scale>1 1 1</scale>
            <uri>model://wolfgang_description/urdf/upper_leg.stl</uri>
          </mesh>
        </geometry>
      </visual>
    </link>
    <joint name='LHipPitch' type='revolute'>
      <child>l_knee</child>
      <parent>left_hip_right_ankle_2</parent>
      <axis>
        <xyz>-7e-06 -1 4e-06</xyz>
        <limit>
          <lower>-1.5708</lower>
          <upper>1.5708</upper>
          <effort>7.57</effort>
          <velocity>8.22</velocity>
        </limit>
        <dynamics>
          <spring_reference>0</spring_reference>
          <spring_stiffness>0</spring_stiffness>
        </dynamics>
        <use_parent_model_frame>1</use_parent_model_frame>
      </axis>
    </joint>
    <link name='lower_leg_left_1'>
      <pose frame=''>0.018744 0.077999 -0.210193 -0 -0.2618 -6e-06</pose>
      <inertial>
        <pose frame=''>0.001315 -0.007651 -0.045763 0 -0 0</pose>
        <mass>0.0842512</mass>
        <inertia>
          <ixx>0.000356356</ixx>
          <ixy>-1.78213e-06</ixy>
          <ixz>-1.07459e-05</ixz>
          <iyy>0.000301696</iyy>
          <iyz>-5.93333e-05</iyz>
          <izz>7.37841e-05</izz>
        </inertia>
      </inertial>
      <collision name='lower_leg_left_1_collision'>
        <pose frame=''>0 0.0035 0.17 3.14159 -0 -0</pose>
        <geometry>
          <mesh>
            <scale>1 1 1</scale>
            <uri>model://wolfgang_description/urdf/springholder_new.stl</uri>
          </mesh>
        </geometry>
      </collision>
      <collision name='lower_leg_left_1_collision_1'>
        <pose frame=''>0.002179 -0.0033 -0.145095 0 0 -3.14159</pose>
        <geometry>
          <mesh>
            <scale>1 1 1</scale>
            <uri>model://wolfgang_description/urdf/spring_holder_lower.stl</uri>
          </mesh>
        </geometry>
      </collision>
      <collision name='lower_leg_left_1_collision_2'>
        <pose frame=''>0 0.0035 -0 3.14159 -0 -0</pose>
        <geometry>
          <mesh>
            <scale>1 1 1</scale>
            <uri>model://wolfgang_description/urdf/springholder_bottom.stl</uri>
          </mesh>
        </geometry>
      </collision>
      <collision name='lower_leg_left_1_collision_3'>
        <pose frame=''>0 0.0062 -0 -1.5708 0.087267 -0</pose>
        <geometry>
          <mesh>
            <scale>1 1 1</scale>
            <uri>model://wolfgang_description/urdf/torson_spring_sodemann_t105-180-813l.stl</uri>
          </mesh>
        </geometry>
      </collision>
      <collision name='lower_leg_left_1_collision_4'>
        <pose frame=''>0.02797 0.019019 -0.15413 -0 -0 0</pose>
        <geometry>
          <mesh>
            <scale>1 1 1</scale>
            <uri>model://wolfgang_description/urdf/knee_spacer.stl</uri>
          </mesh>
        </geometry>
      </collision>
      <collision name='lower_leg_left_1_collision_5'>
        <pose frame=''>0.02797 -0.031481 -0.15413 -0 -0 0</pose>
        <geometry>
          <mesh>
            <scale>1 1 1</scale>
            <uri>model://wolfgang_description/urdf/knee_spacer.stl</uri>
          </mesh>
        </geometry>
      </collision>
      <collision name='lower_leg_left_1_collision_6'>
        <pose frame=''>0 -0.0505 -0.17 -0 -0 -0</pose>
        <geometry>
          <mesh>
            <scale>1 1 1</scale>
            <uri>model://wolfgang_description/urdf/lower_leg.stl</uri>
          </mesh>
        </geometry>
      </collision>
      <collision name='lower_leg_left_1_collision_7'>
        <pose frame=''>0 0.0035 -0.17 -0 -0 -0</pose>
        <geometry>
          <mesh>
            <scale>1 1 1</scale>
            <uri>model://wolfgang_description/urdf/lower_leg.stl</uri>
          </mesh>
        </geometry>
      </collision>
      <visual name='lower_leg_left_1_visual'>
        <pose frame=''>0 0.0035 0.17 3.14159 -0 -0</pose>
        <geometry>
          <mesh>
            <scale>1 1 1</scale>
            <uri>model://wolfgang_description/urdf/springholder_new.stl</uri>
          </mesh>
        </geometry>
      </visual>
      <visual name='lower_leg_left_1_visual_1'>
        <pose frame=''>0.002179 -0.0033 -0.145095 0 0 -3.14159</pose>
        <geometry>
          <mesh>
            <scale>1 1 1</scale>
            <uri>model://wolfgang_description/urdf/spring_holder_lower.stl</uri>
          </mesh>
        </geometry>
      </visual>
      <visual name='lower_leg_left_1_visual_2'>
        <pose frame=''>0 0.0035 -0 3.14159 -0 -0</pose>
        <geometry>
          <mesh>
            <scale>1 1 1</scale>
            <uri>model://wolfgang_description/urdf/springholder_bottom.stl</uri>
          </mesh>
        </geometry>
      </visual>
      <visual name='lower_leg_left_1_visual_3'>
        <pose frame=''>0 0.0062 -0 -1.5708 0.087267 -0</pose>
        <geometry>
          <mesh>
            <scale>1 1 1</scale>
            <uri>model://wolfgang_description/urdf/torson_spring_sodemann_t105-180-813l.stl</uri>
          </mesh>
        </geometry>
      </visual>
      <visual name='lower_leg_left_1_visual_4'>
        <pose frame=''>0.02797 0.019019 -0.15413 -0 -0 0</pose>
        <geometry>
          <mesh>
            <scale>1 1 1</scale>
            <uri>model://wolfgang_description/urdf/knee_spacer.stl</uri>
          </mesh>
        </geometry>
      </visual>
      <visual name='lower_leg_left_1_visual_5'>
        <pose frame=''>0.02797 -0.031481 -0.15413 -0 -0 0</pose>
        <geometry>
          <mesh>
            <scale>1 1 1</scale>
            <uri>model://wolfgang_description/urdf/knee_spacer.stl</uri>
          </mesh>
        </geometry>
      </visual>
      <visual name='lower_leg_left_1_visual_6'>
        <pose frame=''>0 -0.0505 -0.17 -0 -0 -0</pose>
        <geometry>
          <mesh>
            <scale>1 1 1</scale>
            <uri>model://wolfgang_description/urdf/lower_leg.stl</uri>
          </mesh>
        </geometry>
      </visual>
      <visual name='lower_leg_left_1_visual_7'>
        <pose frame=''>0 0.0035 -0.17 -0 -0 -0</pose>
        <geometry>
          <mesh>
            <scale>1 1 1</scale>
            <uri>model://wolfgang_description/urdf/lower_leg.stl</uri>
          </mesh>
        </geometry>
      </visual>
    </link>
    <joint name='LKnee' type='revolute'>
      <child>lower_leg_left_1</child>
      <parent>l_knee</parent>
      <axis>
        <xyz>-6e-06 -1 0</xyz>
        <limit>
          <lower>-2.96706</lower>
          <upper>0</upper>
          <effort>10</effort>
          <velocity>10</velocity>
        </limit>
        <dynamics>
          <spring_reference>0</spring_reference>
          <spring_stiffness>0</spring_stiffness>
        </dynamics>
        <use_parent_model_frame>1</use_parent_model_frame>
      </axis>
    </joint>
    <link name='right_hip_left_ankle_2'>
      <pose frame=''>0.062743 0.027499 -0.374401 -1.5708 0.2618 3.14158</pose>
      <inertial>
        <pose frame=''>0.020459 -0.015528 -0.026014 0 -0 0</pose>
        <mass>0.319807</mass>
        <inertia>
          <ixx>0.000116773</ixx>
          <ixy>4.53857e-06</ixy>
          <ixz>-6.75013e-07</ixz>
          <iyy>0.000268424</iyy>
          <iyz>-7.24073e-07</iyz>
          <izz>0.00027281</izz>
        </inertia>
      </inertial>
      <collision name='right_hip_left_ankle_2_collision'>
        <pose frame=''>0.0261 0.007 -0.0405 1.5708 0 -1.5708</pose>
        <geometry>
          <mesh>
            <scale>1 1 1</scale>
            <uri>model://wolfgang_description/urdf/motor_connector.stl</uri>
          </mesh>
        </geometry>
      </collision>
      <collision name='right_hip_left_ankle_2_collision_1'>
        <pose frame=''>-0.0201 0.0105 -0.04 3.14159 -1.57079 3e-06</pose>
        <geometry>
          <mesh>
            <scale>1 1 1</scale>
            <uri>model://wolfgang_description/urdf/thrustbearingholder.stl</uri>
          </mesh>
        </geometry>
      </collision>
      <collision name='right_hip_left_ankle_2_collision_2'>
        <pose frame=''>0.0261 -0.021 -0.0115 -1.5708 0 1.5708</pose>
        <geometry>
          <mesh>
            <scale>1 1 1</scale>
            <uri>model://wolfgang_description/urdf/motor_connector.stl</uri>
          </mesh>
        </geometry>
      </collision>
      <collision name='right_hip_left_ankle_2_collision_3'>
        <pose frame=''>0 0 -0.026 -1.5708 -0 -0</pose>
        <geometry>
          <mesh>
            <scale>1 1 1</scale>
            <uri>model://wolfgang_description/urdf/mx-106_body.stl</uri>
          </mesh>
        </geometry>
      </collision>
      <collision name='right_hip_left_ankle_2_collision_4'>
        <pose frame=''>0.0431 0 -0.026 3.14159 1.57079 -1.57079</pose>
        <geometry>
          <mesh>
            <scale>1 1 1</scale>
            <uri>model://wolfgang_description/urdf/mx-106_body.stl</uri>
          </mesh>
        </geometry>
      </collision>
      <visual name='right_hip_left_ankle_2_visual'>
        <pose frame=''>0.0261 0.007 -0.0405 1.5708 0 -1.5708</pose>
        <geometry>
          <mesh>
            <scale>1 1 1</scale>
            <uri>model://wolfgang_description/urdf/motor_connector.stl</uri>
          </mesh>
        </geometry>
      </visual>
      <visual name='right_hip_left_ankle_2_visual_1'>
        <pose frame=''>-0.0201 0.0105 -0.04 3.14159 -1.57079 3e-06</pose>
        <geometry>
          <mesh>
            <scale>1 1 1</scale>
            <uri>model://wolfgang_description/urdf/thrustbearingholder.stl</uri>
          </mesh>
        </geometry>
      </visual>
      <visual name='right_hip_left_ankle_2_visual_2'>
        <pose frame=''>0.0261 -0.021 -0.0115 -1.5708 0 1.5708</pose>
        <geometry>
          <mesh>
            <scale>1 1 1</scale>
            <uri>model://wolfgang_description/urdf/motor_connector.stl</uri>
          </mesh>
        </geometry>
      </visual>
      <visual name='right_hip_left_ankle_2_visual_3'>
        <pose frame=''>0 0 -0.026 -1.5708 -0 -0</pose>
        <geometry>
          <mesh>
            <scale>1 1 1</scale>
            <uri>model://wolfgang_description/urdf/mx-106_body.stl</uri>
          </mesh>
        </geometry>
      </visual>
      <visual name='right_hip_left_ankle_2_visual_4'>
        <pose frame=''>0.0431 0 -0.026 3.14159 1.57079 -1.57079</pose>
        <geometry>
          <mesh>
            <scale>1 1 1</scale>
            <uri>model://wolfgang_description/urdf/mx-106_body.stl</uri>
          </mesh>
        </geometry>
      </visual>
    </link>
    <joint name='LAnklePitch' type='revolute'>
      <child>right_hip_left_ankle_2</child>
      <parent>lower_leg_left_1</parent>
      <axis>
        <xyz>8e-06 1 4e-06</xyz>
        <limit>
          <lower>-1.22173</lower>
          <upper>1.5708</upper>
          <effort>7.57</effort>
          <velocity>8.22</velocity>
        </limit>
        <dynamics>
          <spring_reference>0</spring_reference>
          <spring_stiffness>0</spring_stiffness>
        </dynamics>
        <use_parent_model_frame>1</use_parent_model_frame>
      </axis>
    </joint>
    <link name='l_foot'>
      <pose frame=''>-0.004002 0.053499 -0.392285 0.261804 3e-06 -1.5708</pose>
      <inertial>
        <pose frame=''>-0.012185 0.09151 -0.029925 0 -0 0</pose>
        <mass>0.281772</mass>
        <inertia>
          <ixx>0.000951773</ixx>
          <ixy>3.2256e-05</ixy>
          <ixz>-5.21956e-06</ixz>
          <iyy>0.000343589</iyy>
          <iyz>-1.92863e-05</iyz>
          <izz>0.00124388</izz>
        </inertia>
      </inertial>
      <collision name='l_foot_collision'>
        <pose frame=''>0.03 -0.007 -0.04375 0 -0 -1.5708</pose>
        <geometry>
          <mesh>
            <scale>1 1 1</scale>
            <uri>model://wolfgang_description/urdf/flex_stollen.stl</uri>
          </mesh>
        </geometry>
        <surface>
          <contact>
            <ode>
              <kp>1e+06</kp>
              <kd>100</kd>
              <max_vel>1</max_vel>
              <min_depth>0</min_depth>
            </ode>
          </contact>
          <friction>
            <ode>
              <mu>1</mu>
              <mu2>1</mu2>
              <fdir1>1 0 0</fdir1>
            </ode>
          </friction>
        </surface>
      </collision>
      <collision name='l_foot_collision_1'>
        <pose frame=''>-0.06 0.177 -0.04375 0 -0 -1.5708</pose>
        <geometry>
          <mesh>
            <scale>1 1 1</scale>
            <uri>model://wolfgang_description/urdf/flex_stollen.stl</uri>
          </mesh>
        </geometry>
        <surface>
          <contact>
            <ode>
              <kp>1e+06</kp>
              <kd>100</kd>
              <max_vel>1</max_vel>
              <min_depth>0</min_depth>
            </ode>
          </contact>
          <friction>
            <ode>
              <mu>1</mu>
              <mu2>1</mu2>
              <fdir1>1 0 0</fdir1>
            </ode>
          </friction>
        </surface>
      </collision>
      <collision name='l_foot_collision_2'>
        <pose frame=''>-0.06 0.1635 -0.03375 -0 -0 -0</pose>
        <geometry>
          <mesh>
            <scale>1 1 1</scale>
            <uri>model://wolfgang_description/urdf/load_cell.stl</uri>
          </mesh>
        </geometry>
        <surface>
          <contact>
            <ode>
              <kp>1e+06</kp>
              <kd>100</kd>
              <max_vel>1</max_vel>
              <min_depth>0</min_depth>
            </ode>
          </contact>
          <friction>
            <ode>
              <mu>1</mu>
              <mu2>1</mu2>
              <fdir1>1 0 0</fdir1>
            </ode>
          </friction>
        </surface>
      </collision>
      <collision name='l_foot_collision_3'>
        <pose frame=''>0.03 0.0065 -0.03375 0 0 3.14159</pose>
        <geometry>
          <mesh>
            <scale>1 1 1</scale>
            <uri>model://wolfgang_description/urdf/load_cell.stl</uri>
          </mesh>
        </geometry>
        <surface>
          <contact>
            <ode>
              <kp>1e+06</kp>
              <kd>100</kd>
              <max_vel>1</max_vel>
              <min_depth>0</min_depth>
            </ode>
          </contact>
          <friction>
            <ode>
              <mu>1</mu>
              <mu2>1</mu2>
              <fdir1>1 0 0</fdir1>
            </ode>
          </friction>
        </surface>
      </collision>
      <collision name='l_foot_collision_4'>
        <pose frame=''>-0.015 0.085 -0.0395 0 0 -1.5708</pose>
        <geometry>
          <mesh>
            <scale>1 1 1</scale>
            <uri>model://wolfgang_description/urdf/foot_printed_left.stl</uri>
          </mesh>
        </geometry>
        <surface>
          <contact>
            <ode>
              <kp>1e+06</kp>
              <kd>100</kd>
              <max_vel>1</max_vel>
              <min_depth>0</min_depth>
            </ode>
          </contact>
          <friction>
            <ode>
              <mu>1</mu>
              <mu2>1</mu2>
              <fdir1>1 0 0</fdir1>
            </ode>
          </friction>
        </surface>
      </collision>
      <collision name='l_foot_collision_5'>
        <pose frame=''>0.022 0.16 -0.0324 3.14159 -0 -0</pose>
        <geometry>
          <mesh>
            <scale>1 1 1</scale>
            <uri>model://wolfgang_description/urdf/forcefoot_pcb.stl</uri>
          </mesh>
        </geometry>
        <surface>
          <contact>
            <ode>
              <kp>1e+06</kp>
              <kd>100</kd>
              <max_vel>1</max_vel>
              <min_depth>0</min_depth>
            </ode>
          </contact>
          <friction>
            <ode>
              <mu>1</mu>
              <mu2>1</mu2>
              <fdir1>1 0 0</fdir1>
            </ode>
          </friction>
        </surface>
      </collision>
      <collision name='l_foot_collision_6'>
        <pose frame=''>-0.006543 0.061834 -0.046391 0 -0 -1.5708</pose>
        <geometry>
          <mesh>
            <scale>1 1 1</scale>
            <uri>model://wolfgang_description/urdf/foot_cover.stl</uri>
          </mesh>
        </geometry>
        <surface>
          <contact>
            <ode>
              <kp>1e+06</kp>
              <kd>100</kd>
              <max_vel>1</max_vel>
              <min_depth>0</min_depth>
            </ode>
          </contact>
          <friction>
            <ode>
              <mu>1</mu>
              <mu2>1</mu2>
              <fdir1>1 0 0</fdir1>
            </ode>
          </friction>
        </surface>
      </collision>
      <collision name='l_foot_collision_7'>
        <pose frame=''>0.03 0.177 -0.04375 0 -0 -1.5708</pose>
        <geometry>
          <mesh>
            <scale>1 1 1</scale>
            <uri>model://wolfgang_description/urdf/flex_stollen.stl</uri>
          </mesh>
        </geometry>
        <surface>
          <contact>
            <ode>
              <kp>1e+06</kp>
              <kd>100</kd>
              <max_vel>1</max_vel>
              <min_depth>0</min_depth>
            </ode>
          </contact>
          <friction>
            <ode>
              <mu>1</mu>
              <mu2>1</mu2>
              <fdir1>1 0 0</fdir1>
            </ode>
          </friction>
        </surface>
      </collision>
      <collision name='l_foot_collision_8'>
        <pose frame=''>0 0.046 -0.036 -0 -0 0</pose>
        <geometry>
          <mesh>
            <scale>1 1 1</scale>
            <uri>model://wolfgang_description/urdf/ankle.stl</uri>
          </mesh>
        </geometry>
        <surface>
          <contact>
            <ode>
              <kp>1e+06</kp>
              <kd>100</kd>
              <max_vel>1</max_vel>
              <min_depth>0</min_depth>
            </ode>
          </contact>
          <friction>
            <ode>
              <mu>1</mu>
              <mu2>1</mu2>
              <fdir1>1 0 0</fdir1>
            </ode>
          </friction>
        </surface>
      </collision>
      <collision name='l_foot_collision_9'>
        <pose frame=''>0.03 0.1635 -0.03375 -0 -0 -0</pose>
        <geometry>
          <mesh>
            <scale>1 1 1</scale>
            <uri>model://wolfgang_description/urdf/load_cell.stl</uri>
          </mesh>
        </geometry>
        <surface>
          <contact>
            <ode>
              <kp>1e+06</kp>
              <kd>100</kd>
              <max_vel>1</max_vel>
              <min_depth>0</min_depth>
            </ode>
          </contact>
          <friction>
            <ode>
              <mu>1</mu>
              <mu2>1</mu2>
              <fdir1>1 0 0</fdir1>
            </ode>
          </friction>
        </surface>
      </collision>
      <collision name='l_foot_collision_10'>
        <pose frame=''>-0.06 0.0065 -0.03375 -0 -0 -0</pose>
        <geometry>
          <mesh>
            <scale>1 1 1</scale>
            <uri>model://wolfgang_description/urdf/load_cell.stl</uri>
          </mesh>
        </geometry>
        <surface>
          <contact>
            <ode>
              <kp>1e+06</kp>
              <kd>100</kd>
              <max_vel>1</max_vel>
              <min_depth>0</min_depth>
            </ode>
          </contact>
          <friction>
            <ode>
              <mu>1</mu>
              <mu2>1</mu2>
              <fdir1>1 0 0</fdir1>
            </ode>
          </friction>
        </surface>
      </collision>
      <collision name='l_foot_fixed_joint_lump__llb_collision_11'>
        <pose frame=''>-0.06 -0.007 -0.04375 0 -0 -1.5708</pose>
        <geometry>
          <mesh>
            <scale>1 1 1</scale>
            <uri>model://wolfgang_description/urdf/flex_stollen.stl</uri>
          </mesh>
        </geometry>
      </collision>
      <visual name='l_foot_visual'>
        <pose frame=''>0.03 -0.007 -0.04375 0 -0 -1.5708</pose>
        <geometry>
          <mesh>
            <scale>1 1 1</scale>
            <uri>model://wolfgang_description/urdf/flex_stollen.stl</uri>
          </mesh>
        </geometry>
        <material>
          <script>
            <name>Gazebo/FlatBlack</name>
            <uri>file://media/materials/scripts/gazebo.material</uri>
          </script>
        </material>
      </visual>
      <visual name='l_foot_visual_1'>
        <pose frame=''>-0.06 0.177 -0.04375 0 -0 -1.5708</pose>
        <geometry>
          <mesh>
            <scale>1 1 1</scale>
            <uri>model://wolfgang_description/urdf/flex_stollen.stl</uri>
          </mesh>
        </geometry>
        <material>
          <script>
            <name>Gazebo/FlatBlack</name>
            <uri>file://media/materials/scripts/gazebo.material</uri>
          </script>
        </material>
      </visual>
      <visual name='l_foot_visual_2'>
        <pose frame=''>-0.06 0.1635 -0.03375 -0 -0 -0</pose>
        <geometry>
          <mesh>
            <scale>1 1 1</scale>
            <uri>model://wolfgang_description/urdf/load_cell.stl</uri>
          </mesh>
        </geometry>
        <material>
          <script>
            <name>Gazebo/FlatBlack</name>
            <uri>file://media/materials/scripts/gazebo.material</uri>
          </script>
        </material>
      </visual>
      <visual name='l_foot_visual_3'>
        <pose frame=''>0.03 0.0065 -0.03375 0 0 3.14159</pose>
        <geometry>
          <mesh>
            <scale>1 1 1</scale>
            <uri>model://wolfgang_description/urdf/load_cell.stl</uri>
          </mesh>
        </geometry>
        <material>
          <script>
            <name>Gazebo/FlatBlack</name>
            <uri>file://media/materials/scripts/gazebo.material</uri>
          </script>
        </material>
      </visual>
      <visual name='l_foot_visual_4'>
        <pose frame=''>-0.015 0.085 -0.0395 0 0 -1.5708</pose>
        <geometry>
          <mesh>
            <scale>1 1 1</scale>
            <uri>model://wolfgang_description/urdf/foot_printed_left.stl</uri>
          </mesh>
        </geometry>
        <material>
          <script>
            <name>Gazebo/FlatBlack</name>
            <uri>file://media/materials/scripts/gazebo.material</uri>
          </script>
        </material>
      </visual>
      <visual name='l_foot_visual_5'>
        <pose frame=''>0.022 0.16 -0.0324 3.14159 -0 -0</pose>
        <geometry>
          <mesh>
            <scale>1 1 1</scale>
            <uri>model://wolfgang_description/urdf/forcefoot_pcb.stl</uri>
          </mesh>
        </geometry>
        <material>
          <script>
            <name>Gazebo/FlatBlack</name>
            <uri>file://media/materials/scripts/gazebo.material</uri>
          </script>
        </material>
      </visual>
      <visual name='l_foot_visual_6'>
        <pose frame=''>-0.006543 0.061834 -0.046391 0 -0 -1.5708</pose>
        <geometry>
          <mesh>
            <scale>1 1 1</scale>
            <uri>model://wolfgang_description/urdf/foot_cover.stl</uri>
          </mesh>
        </geometry>
        <material>
          <script>
            <name>Gazebo/FlatBlack</name>
            <uri>file://media/materials/scripts/gazebo.material</uri>
          </script>
        </material>
      </visual>
      <visual name='l_foot_visual_7'>
        <pose frame=''>0.03 0.177 -0.04375 0 -0 -1.5708</pose>
        <geometry>
          <mesh>
            <scale>1 1 1</scale>
            <uri>model://wolfgang_description/urdf/flex_stollen.stl</uri>
          </mesh>
        </geometry>
        <material>
          <script>
            <name>Gazebo/FlatBlack</name>
            <uri>file://media/materials/scripts/gazebo.material</uri>
          </script>
        </material>
      </visual>
      <visual name='l_foot_visual_8'>
        <pose frame=''>0 0.046 -0.036 -0 -0 0</pose>
        <geometry>
          <mesh>
            <scale>1 1 1</scale>
            <uri>model://wolfgang_description/urdf/ankle.stl</uri>
          </mesh>
        </geometry>
        <material>
          <script>
            <name>Gazebo/FlatBlack</name>
            <uri>file://media/materials/scripts/gazebo.material</uri>
          </script>
        </material>
      </visual>
      <visual name='l_foot_visual_9'>
        <pose frame=''>0.03 0.1635 -0.03375 -0 -0 -0</pose>
        <geometry>
          <mesh>
            <scale>1 1 1</scale>
            <uri>model://wolfgang_description/urdf/load_cell.stl</uri>
          </mesh>
        </geometry>
        <material>
          <script>
            <name>Gazebo/FlatBlack</name>
            <uri>file://media/materials/scripts/gazebo.material</uri>
          </script>
        </material>
      </visual>
      <visual name='l_foot_visual_10'>
        <pose frame=''>-0.06 0.0065 -0.03375 -0 -0 -0</pose>
        <geometry>
          <mesh>
            <scale>1 1 1</scale>
            <uri>model://wolfgang_description/urdf/load_cell.stl</uri>
          </mesh>
        </geometry>
        <material>
          <script>
            <name>Gazebo/FlatBlack</name>
            <uri>file://media/materials/scripts/gazebo.material</uri>
          </script>
        </material>
      </visual>
      <visual name='l_foot_fixed_joint_lump__llb_visual_11'>
        <pose frame=''>-0.06 -0.007 -0.04375 0 -0 -1.5708</pose>
        <geometry>
          <mesh>
            <scale>1 1 1</scale>
            <uri>model://wolfgang_description/urdf/flex_stollen.stl</uri>
          </mesh>
        </geometry>
      </visual>
      <gravity>1</gravity>
      <velocity_decay/>
    </link>
    <joint name='LAnkleRoll' type='revolute'>
      <child>l_foot</child>
      <parent>right_hip_left_ankle_2</parent>
      <axis>
        <xyz>-0.965925 5e-06 -0.258823</xyz>
        <limit>
          <lower>-1.0472</lower>
          <upper>1.0472</upper>
          <effort>7.57</effort>
          <velocity>8.22</velocity>
        </limit>
        <dynamics>
          <spring_reference>0</spring_reference>
          <spring_stiffness>0</spring_stiffness>
        </dynamics>
        <use_parent_model_frame>1</use_parent_model_frame>
      </axis>
    </joint>
    <link name='shoulder_left_1'>
      <pose frame=''>-0.0015 0.0765 0.2035 3.14159 0 3.14159</pose>
      <inertial>
        <pose frame=''>-0.01354 0.028402 2e-06 0 -0 0</pose>
        <mass>0.041445</mass>
        <inertia>
          <ixx>1.85473e-05</ixx>
          <ixy>7.63058e-06</ixy>
          <ixz>9.41386e-10</ixz>
          <iyy>2.76649e-05</iyy>
          <iyz>-8.71825e-10</iyz>
          <izz>3.49573e-05</izz>
        </inertia>
      </inertial>
      <collision name='shoulder_left_1_collision'>
        <pose frame=''>-0.02595 0.042 0 1.5708 0 -1.5708</pose>
        <geometry>
          <mesh>
            <scale>1 1 1</scale>
            <uri>model://wolfgang_description/urdf/sea_connector.stl</uri>
          </mesh>
        </geometry>
      </collision>
      <collision name='shoulder_left_1_collision_1'>
        <pose frame=''>0 0 0 -0 -0 0</pose>
        <geometry>
          <mesh>
            <scale>1 1 1</scale>
            <uri>model://wolfgang_description/urdf/shoulder_connector.stl</uri>
          </mesh>
        </geometry>
      </collision>
      <collision name='shoulder_left_1_collision_2'>
        <pose frame=''>-0.01695 0.042 0 1.5708 0 -1.5708</pose>
        <geometry>
          <mesh>
            <scale>1 1 1</scale>
            <uri>model://wolfgang_description/urdf/sea_ninjaflex.stl</uri>
          </mesh>
        </geometry>
      </collision>
      <visual name='shoulder_left_1_visual'>
        <pose frame=''>-0.02595 0.042 0 1.5708 0 -1.5708</pose>
        <geometry>
          <mesh>
            <scale>1 1 1</scale>
            <uri>model://wolfgang_description/urdf/sea_connector.stl</uri>
          </mesh>
        </geometry>
      </visual>
      <visual name='shoulder_left_1_visual_1'>
        <pose frame=''>0 0 0 -0 -0 0</pose>
        <geometry>
          <mesh>
            <scale>1 1 1</scale>
            <uri>model://wolfgang_description/urdf/shoulder_connector.stl</uri>
          </mesh>
        </geometry>
      </visual>
      <visual name='shoulder_left_1_visual_2'>
        <pose frame=''>-0.01695 0.042 0 1.5708 0 -1.5708</pose>
        <geometry>
          <mesh>
            <scale>1 1 1</scale>
            <uri>model://wolfgang_description/urdf/sea_ninjaflex.stl</uri>
          </mesh>
        </geometry>
      </visual>
    </link>
    <joint name='LShoulderPitch' type='revolute'>
      <child>shoulder_left_1</child>
      <parent>base_link</parent>
      <axis>
        <xyz>-3e-06 -1 -3e-06</xyz>
        <limit>
          <lower>-3.14159</lower>
          <upper>3.14159</upper>
          <effort>5.43</effort>
          <velocity>10.33</velocity>
        </limit>
        <dynamics>
          <spring_reference>0</spring_reference>
          <spring_stiffness>0</spring_stiffness>
        </dynamics>
        <use_parent_model_frame>1</use_parent_model_frame>
      </axis>
    </joint>
    <link name='upper_arm_2'>
      <pose frame=''>0.01545 0.1185 0.2035 1.57079 -3e-06 1.57079</pose>
      <inertial>
        <pose frame=''>0 -0.028656 -0.023556 0 -0 0</pose>
        <mass>0.206164</mass>
        <inertia>
          <ixx>0.000204986</ixx>
          <ixy>1.94871e-12</ixy>
          <ixz>3.40342e-12</ixz>
          <iyy>0.000171949</iyy>
          <iyz>-3.58687e-07</iyz>
          <izz>0.000333232</izz>
        </inertia>
      </inertial>
      <collision name='upper_arm_2_collision'>
        <pose frame=''>0 0 -0.0235 -1.5708 0 0</pose>
        <geometry>
          <mesh>
            <scale>1 1 1</scale>
            <uri>model://wolfgang_description/urdf/mx-64-body.stl</uri>
          </mesh>
        </geometry>
      </collision>
      <collision name='upper_arm_2_collision_1'>
        <pose frame=''>-0.0147 -0.0105 -0.0235 -1.5708 0 1.5708</pose>
        <geometry>
          <mesh>
            <scale>1 1 1</scale>
            <uri>model://wolfgang_description/urdf/connector_shoulder.stl</uri>
          </mesh>
        </geometry>
      </collision>
      <collision name='upper_arm_2_collision_2'>
        <pose frame=''>0.0147 -0.0105 -0.0235 1.5708 0 1.5708</pose>
        <geometry>
          <mesh>
            <scale>1 1 1</scale>
            <uri>model://wolfgang_description/urdf/connector_shoulder.stl</uri>
          </mesh>
        </geometry>
      </collision>
      <collision name='upper_arm_2_collision_3'>
        <pose frame=''>-0.0265 -0.144 -0.0235 3.14159 1.57079 -1.57079</pose>
        <geometry>
          <mesh>
            <scale>1 1 1</scale>
            <uri>model://wolfgang_description/urdf/upper_arm.stl</uri>
          </mesh>
        </geometry>
      </collision>
      <collision name='upper_arm_2_collision_4'>
        <pose frame=''>0.0265 -0.144 -0.0235 3.14159 -1.57079 1.57079</pose>
        <geometry>
          <mesh>
            <scale>1 1 1</scale>
            <uri>model://wolfgang_description/urdf/upper_arm.stl</uri>
          </mesh>
        </geometry>
      </collision>
      <visual name='upper_arm_2_visual'>
        <pose frame=''>0 0 -0.0235 -1.5708 0 0</pose>
        <geometry>
          <mesh>
            <scale>1 1 1</scale>
            <uri>model://wolfgang_description/urdf/mx-64-body.stl</uri>
          </mesh>
        </geometry>
      </visual>
      <visual name='upper_arm_2_visual_1'>
        <pose frame=''>-0.0147 -0.0105 -0.0235 -1.5708 0 1.5708</pose>
        <geometry>
          <mesh>
            <scale>1 1 1</scale>
            <uri>model://wolfgang_description/urdf/connector_shoulder.stl</uri>
          </mesh>
        </geometry>
      </visual>
      <visual name='upper_arm_2_visual_2'>
        <pose frame=''>0.0147 -0.0105 -0.0235 1.5708 0 1.5708</pose>
        <geometry>
          <mesh>
            <scale>1 1 1</scale>
            <uri>model://wolfgang_description/urdf/connector_shoulder.stl</uri>
          </mesh>
        </geometry>
      </visual>
      <visual name='upper_arm_2_visual_3'>
        <pose frame=''>-0.0265 -0.144 -0.0235 3.14159 1.57079 -1.57079</pose>
        <geometry>
          <mesh>
            <scale>1 1 1</scale>
            <uri>model://wolfgang_description/urdf/upper_arm.stl</uri>
          </mesh>
        </geometry>
      </visual>
      <visual name='upper_arm_2_visual_4'>
        <pose frame=''>0.0265 -0.144 -0.0235 3.14159 -1.57079 1.57079</pose>
        <geometry>
          <mesh>
            <scale>1 1 1</scale>
            <uri>model://wolfgang_description/urdf/upper_arm.stl</uri>
          </mesh>
        </geometry>
      </visual>
    </link>
    <joint name='LShoulderRoll' type='revolute'>
      <child>upper_arm_2</child>
      <parent>shoulder_left_1</parent>
      <axis>
        <xyz>1 -6e-06 4e-06</xyz>
        <limit>
          <lower>0</lower>
          <upper>3.14159</upper>
          <effort>5.43</effort>
          <velocity>10.33</velocity>
        </limit>
        <dynamics>
          <spring_reference>0</spring_reference>
          <spring_stiffness>0</spring_stiffness>
        </dynamics>
        <use_parent_model_frame>1</use_parent_model_frame>
      </axis>
    </joint>
    <link name='lower_arm_left_1'>
      <pose frame=''>-0.00805 0.094501 0.0595 -2.61558 -1.57079 -2.09682</pose>
      <inertial>
        <pose frame=''>-0.000436 -0.060513 -0.023555 0 -0 0</pose>
        <mass>0.207774</mass>
        <inertia>
          <ixx>0.001088</ixx>
          <ixy>-1.14836e-05</ixy>
          <ixz>5.01178e-09</ixz>
          <iyy>8.90324e-05</iyy>
          <iyz>-3.22666e-08</iyz>
          <izz>0.00110076</izz>
        </inertia>
      </inertial>
      <collision name='lower_arm_left_1_collision'>
        <pose frame=''>0 -0 -0.0235 -1.5708 -0 -0</pose>
        <geometry>
          <mesh>
            <scale>1 1 1</scale>
            <uri>model://wolfgang_description/urdf/mx-64-body.stl</uri>
          </mesh>
        </geometry>
      </collision>
      <collision name='lower_arm_left_1_collision_1'>
        <pose frame=''>0 -0.163682 -0.0405 1.5708 -0 -0</pose>
        <geometry>
          <mesh>
            <scale>1 1 1</scale>
            <uri>model://wolfgang_description/urdf/lower_arm.stl</uri>
          </mesh>
        </geometry>
      </collision>
      <collision name='lower_arm_left_1_collision_2'>
        <pose frame=''>-0 -0.163682 -0.0405 -1.5708 0 3.14159</pose>
        <geometry>
          <mesh>
            <scale>1 1 1</scale>
            <uri>model://wolfgang_description/urdf/hand.stl</uri>
          </mesh>
        </geometry>
      </collision>
      <collision name='lower_arm_left_1_collision_3'>
        <pose frame=''>0 -0.163682 -0.0045 1.5708 -0 -0</pose>
        <geometry>
          <mesh>
            <scale>1 1 1</scale>
            <uri>model://wolfgang_description/urdf/lower_arm.stl</uri>
          </mesh>
        </geometry>
      </collision>
      <visual name='lower_arm_left_1_visual'>
        <pose frame=''>0 -0 -0.0235 -1.5708 -0 -0</pose>
        <geometry>
          <mesh>
            <scale>1 1 1</scale>
            <uri>model://wolfgang_description/urdf/mx-64-body.stl</uri>
          </mesh>
        </geometry>
      </visual>
      <visual name='lower_arm_left_1_visual_1'>
        <pose frame=''>0 -0.163682 -0.0405 1.5708 -0 -0</pose>
        <geometry>
          <mesh>
            <scale>1 1 1</scale>
            <uri>model://wolfgang_description/urdf/lower_arm.stl</uri>
          </mesh>
        </geometry>
      </visual>
      <visual name='lower_arm_left_1_visual_2'>
        <pose frame=''>-0 -0.163682 -0.0405 -1.5708 0 3.14159</pose>
        <geometry>
          <mesh>
            <scale>1 1 1</scale>
            <uri>model://wolfgang_description/urdf/hand.stl</uri>
          </mesh>
        </geometry>
      </visual>
      <visual name='lower_arm_left_1_visual_3'>
        <pose frame=''>0 -0.163682 -0.0045 1.5708 -0 -0</pose>
        <geometry>
          <mesh>
            <scale>1 1 1</scale>
            <uri>model://wolfgang_description/urdf/lower_arm.stl</uri>
          </mesh>
        </geometry>
      </visual>
    </link>
    <joint name='LElbow' type='revolute'>
      <child>lower_arm_left_1</child>
      <parent>upper_arm_2</parent>
      <axis>
        <xyz>-1e-05 -1 -6e-06</xyz>
        <limit>
          <lower>-1.5708</lower>
          <upper>1.0472</upper>
          <effort>5.43</effort>
          <velocity>10.33</velocity>
        </limit>
        <dynamics>
          <spring_reference>0</spring_reference>
          <spring_stiffness>0</spring_stiffness>
        </dynamics>
        <use_parent_model_frame>1</use_parent_model_frame>
      </axis>
    </joint>
    <link name='hip_u_connector_1'>
      <pose frame=''>-0 -0.055 -0 -1.5708 0 0</pose>
      <inertial>
        <pose frame=''>0 0.010315 -0 0 -0 0</pose>
        <mass>0.0689735</mass>
        <inertia>
          <ixx>2.18955e-05</ixx>
          <ixy>-2.44475e-14</ixy>
          <ixz>3.06793e-15</ixz>
          <iyy>0.00010714</iyy>
          <iyz>-6.56688e-11</iyz>
          <izz>0.000110523</izz>
        </inertia>
      </inertial>
      <collision name='hip_u_connector_1_collision'>
        <pose frame=''>0 -0.0006 -0.018 -0 -0 0</pose>
        <geometry>
          <mesh>
            <scale>1 1 1</scale>
            <uri>model://wolfgang_description/urdf/hip_u_connector.stl</uri>
          </mesh>
        </geometry>
      </collision>
      <visual name='hip_u_connector_1_visual'>
        <pose frame=''>0 -0.0006 -0.018 -0 -0 0</pose>
        <geometry>
          <mesh>
            <scale>1 1 1</scale>
            <uri>model://wolfgang_description/urdf/hip_u_connector.stl</uri>
          </mesh>
        </geometry>
      </visual>
    </link>
    <joint name='RHipYaw' type='revolute'>
      <child>hip_u_connector_1</child>
      <parent>base_link</parent>
      <axis>
        <xyz>0 4e-06 1</xyz>
        <limit>
          <lower>-1.5708</lower>
          <upper>1.5708</upper>
          <effort>7.57</effort>
          <velocity>8.22</velocity>
        </limit>
        <dynamics>
          <spring_reference>0</spring_reference>
          <spring_stiffness>0</spring_stiffness>
        </dynamics>
        <use_parent_model_frame>1</use_parent_model_frame>
      </axis>
    </joint>
    <link name='right_hip_left_ankle_1'>
      <pose frame=''>-0.046 -0.055 -0.0414 1.5708 -4e-06 -1.5708</pose>
      <inertial>
        <pose frame=''>1.4e-05 -0.015528 -0.048641 0 -0 0</pose>
        <mass>0.319807</mass>
        <inertia>
          <ixx>0.000268627</ixx>
          <ixy>6.08561e-08</ixy>
          <ixz>6.67248e-07</ixz>
          <iyy>0.000268049</iyy>
          <iyz>3.87608e-06</iyz>
          <izz>0.000121331</izz>
        </inertia>
      </inertial>
      <collision name='right_hip_left_ankle_1_collision'>
        <pose frame=''>0 0 -0.026 -1.5708 0 -0</pose>
        <geometry>
          <mesh>
            <scale>1 1 1</scale>
            <uri>model://wolfgang_description/urdf/mx-106_body.stl</uri>
          </mesh>
        </geometry>
      </collision>
      <collision name='right_hip_left_ankle_1_collision_1'>
        <pose frame=''>-0.0145 -0.021 -0.043 -3.14159 -0 1.5708</pose>
        <geometry>
          <mesh>
            <scale>1 1 1</scale>
            <uri>model://wolfgang_description/urdf/motor_connector.stl</uri>
          </mesh>
        </geometry>
      </collision>
      <collision name='right_hip_left_ankle_1_collision_2'>
        <pose frame=''>0.014 0.0105 -0.0892 0 0 -3.14159</pose>
        <geometry>
          <mesh>
            <scale>1 1 1</scale>
            <uri>model://wolfgang_description/urdf/thrustbearingholder.stl</uri>
          </mesh>
        </geometry>
      </collision>
      <collision name='right_hip_left_ankle_1_collision_3'>
        <pose frame=''>0.0145 0.007 -0.043 -3.14159 -0 -1.5708</pose>
        <geometry>
          <mesh>
            <scale>1 1 1</scale>
            <uri>model://wolfgang_description/urdf/motor_connector.stl</uri>
          </mesh>
        </geometry>
      </collision>
      <collision name='right_hip_left_ankle_1_collision_4'>
        <pose frame=''>-0 -0 -0.0691 3.14159 -1.57079 1.57079</pose>
        <geometry>
          <mesh>
            <scale>1 1 1</scale>
            <uri>model://wolfgang_description/urdf/mx-106_body.stl</uri>
          </mesh>
        </geometry>
      </collision>
      <visual name='right_hip_left_ankle_1_visual'>
        <pose frame=''>0 0 -0.026 -1.5708 0 -0</pose>
        <geometry>
          <mesh>
            <scale>1 1 1</scale>
            <uri>model://wolfgang_description/urdf/mx-106_body.stl</uri>
          </mesh>
        </geometry>
      </visual>
      <visual name='right_hip_left_ankle_1_visual_1'>
        <pose frame=''>-0.0145 -0.021 -0.043 -3.14159 -0 1.5708</pose>
        <geometry>
          <mesh>
            <scale>1 1 1</scale>
            <uri>model://wolfgang_description/urdf/motor_connector.stl</uri>
          </mesh>
        </geometry>
      </visual>
      <visual name='right_hip_left_ankle_1_visual_2'>
        <pose frame=''>0.014 0.0105 -0.0892 0 0 -3.14159</pose>
        <geometry>
          <mesh>
            <scale>1 1 1</scale>
            <uri>model://wolfgang_description/urdf/thrustbearingholder.stl</uri>
          </mesh>
        </geometry>
      </visual>
      <visual name='right_hip_left_ankle_1_visual_3'>
        <pose frame=''>0.0145 0.007 -0.043 -3.14159 -0 -1.5708</pose>
        <geometry>
          <mesh>
            <scale>1 1 1</scale>
            <uri>model://wolfgang_description/urdf/motor_connector.stl</uri>
          </mesh>
        </geometry>
      </visual>
      <visual name='right_hip_left_ankle_1_visual_4'>
        <pose frame=''>-0 -0 -0.0691 3.14159 -1.57079 1.57079</pose>
        <geometry>
          <mesh>
            <scale>1 1 1</scale>
            <uri>model://wolfgang_description/urdf/mx-106_body.stl</uri>
          </mesh>
        </geometry>
      </visual>
    </link>
    <joint name='RHipRoll' type='revolute'>
      <child>right_hip_left_ankle_1</child>
      <parent>hip_u_connector_1</parent>
      <axis>
        <xyz>1 -4e-06 3e-06</xyz>
        <limit>
          <lower>-1.5708</lower>
          <upper>1.5708</upper>
          <effort>7.57</effort>
          <velocity>8.22</velocity>
        </limit>
        <dynamics>
          <spring_reference>0</spring_reference>
          <spring_stiffness>0</spring_stiffness>
        </dynamics>
        <use_parent_model_frame>1</use_parent_model_frame>
      </axis>
    </joint>
    <link name='r_knee'>
      <pose frame=''>0.0231 -0.0285 -0.0414 -7e-06 -3e-06 0</pose>
      <inertial>
        <pose frame=''>0.004666 -0.0285 -0.137529 0 -0 0</pose>
        <mass>0.220799</mass>
        <inertia>
          <ixx>0.000445136</ixx>
          <ixy>7.62336e-06</ixy>
          <ixz>2.06864e-05</ixz>
          <iyy>0.000405122</iyy>
          <iyz>-2.50431e-06</iyz>
          <izz>0.000104011</izz>
        </inertia>
      </inertial>
      <collision name='r_knee_collision'>
        <pose frame=''>0.018236 -0.022653 -0.130164 -1.5708 -0.523599 3.14159</pose>
        <geometry>
          <mesh>
            <scale>1 1 1</scale>
            <uri>model://wolfgang_description/urdf/knee_connector.stl</uri>
          </mesh>
        </geometry>
      </collision>
      <collision name='r_knee_collision_1'>
        <pose frame=''>-0 0.002 0 0 0 -0</pose>
        <geometry>
          <mesh>
            <scale>1 1 1</scale>
            <uri>model://wolfgang_description/urdf/upper_leg.stl</uri>
          </mesh>
        </geometry>
      </collision>
      <collision name='r_knee_collision_2'>
        <pose frame=''>-0.003923 -0.053 -0.169043 -1.5708 -0.523599 3.14159</pose>
        <geometry>
          <mesh>
            <scale>1 1 1</scale>
            <uri>model://wolfgang_description/urdf/part_1.stl</uri>
          </mesh>
        </geometry>
      </collision>
      <collision name='r_knee_collision_3'>
        <pose frame=''>-0.003923 -0.0265 -0.169043 -1.5708 -0.523599 3.14159</pose>
        <geometry>
          <mesh>
            <scale>1 1 1</scale>
            <uri>model://wolfgang_description/urdf/xh-540.stl</uri>
          </mesh>
        </geometry>
      </collision>
      <collision name='r_knee_collision_4'>
        <pose frame=''>0.014 -0.055 -0.138 1.5708 -0 -0</pose>
        <geometry>
          <mesh>
            <scale>1 1 1</scale>
            <uri>model://wolfgang_description/urdf/spring_holder_upper.stl</uri>
          </mesh>
        </geometry>
      </collision>
      <collision name='r_knee_collision_5'>
        <pose frame=''>-0.003923 -0.002 -0.169043 -1.5708 -0.523599 3.14159</pose>
        <geometry>
          <mesh>
            <scale>1 1 1</scale>
            <uri>model://wolfgang_description/urdf/part_1.stl</uri>
          </mesh>
        </geometry>
      </collision>
      <collision name='r_knee_collision_6'>
        <pose frame=''>0 -0.053 0 0 -0 -0</pose>
        <geometry>
          <mesh>
            <scale>1 1 1</scale>
            <uri>model://wolfgang_description/urdf/upper_leg.stl</uri>
          </mesh>
        </geometry>
      </collision>
      <collision name='r_knee_collision_7'>
        <pose frame=''>0.018669 -0.030347 -0.130414 -1.5708 0.523599 -0</pose>
        <geometry>
          <mesh>
            <scale>1 1 1</scale>
            <uri>model://wolfgang_description/urdf/knee_connector.stl</uri>
          </mesh>
        </geometry>
      </collision>
      <visual name='r_knee_visual'>
        <pose frame=''>0.018236 -0.022653 -0.130164 -1.5708 -0.523599 3.14159</pose>
        <geometry>
          <mesh>
            <scale>1 1 1</scale>
            <uri>model://wolfgang_description/urdf/knee_connector.stl</uri>
          </mesh>
        </geometry>
      </visual>
      <visual name='r_knee_visual_1'>
        <pose frame=''>-0 0.002 0 0 0 -0</pose>
        <geometry>
          <mesh>
            <scale>1 1 1</scale>
            <uri>model://wolfgang_description/urdf/upper_leg.stl</uri>
          </mesh>
        </geometry>
      </visual>
      <visual name='r_knee_visual_2'>
        <pose frame=''>-0.003923 -0.053 -0.169043 -1.5708 -0.523599 3.14159</pose>
        <geometry>
          <mesh>
            <scale>1 1 1</scale>
            <uri>model://wolfgang_description/urdf/part_1.stl</uri>
          </mesh>
        </geometry>
      </visual>
      <visual name='r_knee_visual_3'>
        <pose frame=''>-0.003923 -0.0265 -0.169043 -1.5708 -0.523599 3.14159</pose>
        <geometry>
          <mesh>
            <scale>1 1 1</scale>
            <uri>model://wolfgang_description/urdf/xh-540.stl</uri>
          </mesh>
        </geometry>
      </visual>
      <visual name='r_knee_visual_4'>
        <pose frame=''>0.014 -0.055 -0.138 1.5708 -0 -0</pose>
        <geometry>
          <mesh>
            <scale>1 1 1</scale>
            <uri>model://wolfgang_description/urdf/spring_holder_upper.stl</uri>
          </mesh>
        </geometry>
      </visual>
      <visual name='r_knee_visual_5'>
        <pose frame=''>-0.003923 -0.002 -0.169043 -1.5708 -0.523599 3.14159</pose>
        <geometry>
          <mesh>
            <scale>1 1 1</scale>
            <uri>model://wolfgang_description/urdf/part_1.stl</uri>
          </mesh>
        </geometry>
      </visual>
      <visual name='r_knee_visual_6'>
        <pose frame=''>0 -0.053 0 0 -0 -0</pose>
        <geometry>
          <mesh>
            <scale>1 1 1</scale>
            <uri>model://wolfgang_description/urdf/upper_leg.stl</uri>
          </mesh>
        </geometry>
      </visual>
      <visual name='r_knee_visual_7'>
        <pose frame=''>0.018669 -0.030347 -0.130414 -1.5708 0.523599 -0</pose>
        <geometry>
          <mesh>
            <scale>1 1 1</scale>
            <uri>model://wolfgang_description/urdf/knee_connector.stl</uri>
          </mesh>
        </geometry>
      </visual>
    </link>
    <joint name='RHipPitch' type='revolute'>
      <child>r_knee</child>
      <parent>right_hip_left_ankle_1</parent>
      <axis>
        <xyz>0 1 -7e-06</xyz>
        <limit>
          <lower>-1.5708</lower>
          <upper>1.5708</upper>
          <effort>7.57</effort>
          <velocity>8.22</velocity>
        </limit>
        <dynamics>
          <spring_reference>0</spring_reference>
          <spring_stiffness>0</spring_stiffness>
        </dynamics>
        <use_parent_model_frame>1</use_parent_model_frame>
      </axis>
    </joint>
    <link name='lower_leg_right_1'>
      <pose frame=''>0.019178 -0.079502 -0.210443 -8e-06 -0.261802 2e-06</pose>
      <inertial>
        <pose frame=''>0.001315 0.007653 -0.045778 0 -0 0</pose>
        <mass>0.0842452</mass>
        <inertia>
          <ixx>0.000356238</ixx>
          <ixy>1.78249e-06</ixy>
          <ixz>-1.06939e-05</ixz>
          <iyy>0.00030159</iyy>
          <iyz>5.93058e-05</iyz>
          <izz>7.37898e-05</izz>
        </inertia>
      </inertial>
      <collision name='lower_leg_right_1_collision'>
        <pose frame=''>-0 -0.0062 -3.6e-05 1.5708 0.087267 0</pose>
        <geometry>
          <mesh>
            <scale>1 1 1</scale>
            <uri>model://wolfgang_description/urdf/torsion_spring_sodemann_t105-180-813r.stl</uri>
          </mesh>
        </geometry>
      </collision>
      <collision name='lower_leg_right_1_collision_1'>
        <pose frame=''>0.02797 0.017519 -0.15413 -0 0 0</pose>
        <geometry>
          <mesh>
            <scale>1 1 1</scale>
            <uri>model://wolfgang_description/urdf/knee_spacer.stl</uri>
          </mesh>
        </geometry>
      </collision>
      <collision name='lower_leg_right_1_collision_2'>
        <pose frame=''>0.02797 0.068019 -0.15413 -0 -0 0</pose>
        <geometry>
          <mesh>
            <scale>1 1 1</scale>
            <uri>model://wolfgang_description/urdf/knee_spacer.stl</uri>
          </mesh>
        </geometry>
      </collision>
      <collision name='lower_leg_right_1_collision_3'>
        <pose frame=''>0 0.0525 -0.17 -0 -0 -0</pose>
        <geometry>
          <mesh>
            <scale>1 1 1</scale>
            <uri>model://wolfgang_description/urdf/lower_leg.stl</uri>
          </mesh>
        </geometry>
      </collision>
      <collision name='lower_leg_right_1_collision_4'>
        <pose frame=''>0 -0.0015 -0.17 -0 0 0</pose>
        <geometry>
          <mesh>
            <scale>1 1 1</scale>
            <uri>model://wolfgang_description/urdf/lower_leg.stl</uri>
          </mesh>
        </geometry>
      </collision>
      <collision name='lower_leg_right_1_collision_5'>
        <pose frame=''>0 -0.0035 -0.17 -0 0 0</pose>
        <geometry>
          <mesh>
            <scale>1 1 1</scale>
            <uri>model://wolfgang_description/urdf/springholder_new.stl</uri>
          </mesh>
        </geometry>
      </collision>
      <collision name='lower_leg_right_1_collision_6'>
        <pose frame=''>0.020241 0.0033 0.061353 -3.14159 -0.174533 3.14159</pose>
        <geometry>
          <mesh>
            <scale>1 1 1</scale>
            <uri>model://wolfgang_description/urdf/spring_holder_lower.stl</uri>
          </mesh>
        </geometry>
      </collision>
      <collision name='lower_leg_right_1_collision_7'>
        <pose frame=''>0 -0.0035 -0 -0 0 0</pose>
        <geometry>
          <mesh>
            <scale>1 1 1</scale>
            <uri>model://wolfgang_description/urdf/springholder_bottom.stl</uri>
          </mesh>
        </geometry>
      </collision>
      <visual name='lower_leg_right_1_visual'>
        <pose frame=''>-0 -0.0062 -3.6e-05 1.5708 0.087267 0</pose>
        <geometry>
          <mesh>
            <scale>1 1 1</scale>
            <uri>model://wolfgang_description/urdf/torsion_spring_sodemann_t105-180-813r.stl</uri>
          </mesh>
        </geometry>
      </visual>
      <visual name='lower_leg_right_1_visual_1'>
        <pose frame=''>0.02797 0.017519 -0.15413 -0 0 0</pose>
        <geometry>
          <mesh>
            <scale>1 1 1</scale>
            <uri>model://wolfgang_description/urdf/knee_spacer.stl</uri>
          </mesh>
        </geometry>
      </visual>
      <visual name='lower_leg_right_1_visual_2'>
        <pose frame=''>0.02797 0.068019 -0.15413 -0 -0 0</pose>
        <geometry>
          <mesh>
            <scale>1 1 1</scale>
            <uri>model://wolfgang_description/urdf/knee_spacer.stl</uri>
          </mesh>
        </geometry>
      </visual>
      <visual name='lower_leg_right_1_visual_3'>
        <pose frame=''>0 0.0525 -0.17 -0 -0 -0</pose>
        <geometry>
          <mesh>
            <scale>1 1 1</scale>
            <uri>model://wolfgang_description/urdf/lower_leg.stl</uri>
          </mesh>
        </geometry>
      </visual>
      <visual name='lower_leg_right_1_visual_4'>
        <pose frame=''>0 -0.0015 -0.17 -0 0 0</pose>
        <geometry>
          <mesh>
            <scale>1 1 1</scale>
            <uri>model://wolfgang_description/urdf/lower_leg.stl</uri>
          </mesh>
        </geometry>
      </visual>
      <visual name='lower_leg_right_1_visual_5'>
        <pose frame=''>0 -0.0035 -0.17 -0 0 0</pose>
        <geometry>
          <mesh>
            <scale>1 1 1</scale>
            <uri>model://wolfgang_description/urdf/springholder_new.stl</uri>
          </mesh>
        </geometry>
      </visual>
      <visual name='lower_leg_right_1_visual_6'>
        <pose frame=''>0.020241 0.0033 0.061353 -3.14159 -0.174533 3.14159</pose>
        <geometry>
          <mesh>
            <scale>1 1 1</scale>
            <uri>model://wolfgang_description/urdf/spring_holder_lower.stl</uri>
          </mesh>
        </geometry>
      </visual>
      <visual name='lower_leg_right_1_visual_7'>
        <pose frame=''>0 -0.0035 -0 -0 0 0</pose>
        <geometry>
          <mesh>
            <scale>1 1 1</scale>
            <uri>model://wolfgang_description/urdf/springholder_bottom.stl</uri>
          </mesh>
        </geometry>
      </visual>
    </link>
    <joint name='RKnee' type='revolute'>
      <child>lower_leg_right_1</child>
      <parent>r_knee</parent>
      <axis>
        <xyz>0 1 -7e-06</xyz>
        <limit>
          <lower>0</lower>
          <upper>2.96706</upper>
          <effort>10</effort>
          <velocity>10</velocity>
        </limit>
        <dynamics>
          <spring_reference>0</spring_reference>
          <spring_stiffness>0</spring_stiffness>
        </dynamics>
        <use_parent_model_frame>1</use_parent_model_frame>
      </axis>
    </joint>
    <link name='left_hip_right_ankle_1'>
      <pose frame=''>0.063177 -0.029003 -0.37465 -1.57081 -0.261802 2e-06</pose>
      <inertial>
        <pose frame=''>-0.020456 -0.015528 -0.026004 0 -0 0</pose>
        <mass>0.319807</mass>
        <inertia>
          <ixx>0.000116775</ixx>
          <ixy>-4.53798e-06</ixy>
          <ixz>6.10986e-07</ixz>
          <iyy>0.000268473</iyy>
          <iyz>-7.45081e-07</iyz>
          <izz>0.000272856</izz>
        </inertia>
      </inertial>
      <collision name='left_hip_right_ankle_1_collision'>
        <pose frame=''>-0.0261 -0.021 -0.0405 1.5708 0 1.5708</pose>
        <geometry>
          <mesh>
            <scale>1 1 1</scale>
            <uri>model://wolfgang_description/urdf/motor_connector.stl</uri>
          </mesh>
        </geometry>
      </collision>
      <collision name='left_hip_right_ankle_1_collision_1'>
        <pose frame=''>-0.0431 0 -0.026 3.14159 -1.57079 1.57079</pose>
        <geometry>
          <mesh>
            <scale>1 1 1</scale>
            <uri>model://wolfgang_description/urdf/mx-106_body.stl</uri>
          </mesh>
        </geometry>
      </collision>
      <collision name='left_hip_right_ankle_1_collision_2'>
        <pose frame=''>-0.0261 0.007 -0.0115 -1.5708 -0 -1.5708</pose>
        <geometry>
          <mesh>
            <scale>1 1 1</scale>
            <uri>model://wolfgang_description/urdf/motor_connector.stl</uri>
          </mesh>
        </geometry>
      </collision>
      <collision name='left_hip_right_ankle_1_collision_3'>
        <pose frame=''>0.0201 0.0105 -0.0109 3.14159 1.57079 -3e-06</pose>
        <geometry>
          <mesh>
            <scale>1 1 1</scale>
            <uri>model://wolfgang_description/urdf/thrustbearingholder.stl</uri>
          </mesh>
        </geometry>
      </collision>
      <collision name='left_hip_right_ankle_1_collision_4'>
        <pose frame=''>-0 0 -0.026 -1.5708 0 -0</pose>
        <geometry>
          <mesh>
            <scale>1 1 1</scale>
            <uri>model://wolfgang_description/urdf/mx-106_body.stl</uri>
          </mesh>
        </geometry>
      </collision>
      <visual name='left_hip_right_ankle_1_visual'>
        <pose frame=''>-0.0261 -0.021 -0.0405 1.5708 0 1.5708</pose>
        <geometry>
          <mesh>
            <scale>1 1 1</scale>
            <uri>model://wolfgang_description/urdf/motor_connector.stl</uri>
          </mesh>
        </geometry>
      </visual>
      <visual name='left_hip_right_ankle_1_visual_1'>
        <pose frame=''>-0.0431 0 -0.026 3.14159 -1.57079 1.57079</pose>
        <geometry>
          <mesh>
            <scale>1 1 1</scale>
            <uri>model://wolfgang_description/urdf/mx-106_body.stl</uri>
          </mesh>
        </geometry>
      </visual>
      <visual name='left_hip_right_ankle_1_visual_2'>
        <pose frame=''>-0.0261 0.007 -0.0115 -1.5708 -0 -1.5708</pose>
        <geometry>
          <mesh>
            <scale>1 1 1</scale>
            <uri>model://wolfgang_description/urdf/motor_connector.stl</uri>
          </mesh>
        </geometry>
      </visual>
      <visual name='left_hip_right_ankle_1_visual_3'>
        <pose frame=''>0.0201 0.0105 -0.0109 3.14159 1.57079 -3e-06</pose>
        <geometry>
          <mesh>
            <scale>1 1 1</scale>
            <uri>model://wolfgang_description/urdf/thrustbearingholder.stl</uri>
          </mesh>
        </geometry>
      </visual>
      <visual name='left_hip_right_ankle_1_visual_4'>
        <pose frame=''>-0 0 -0.026 -1.5708 0 -0</pose>
        <geometry>
          <mesh>
            <scale>1 1 1</scale>
            <uri>model://wolfgang_description/urdf/mx-106_body.stl</uri>
          </mesh>
        </geometry>
      </visual>
    </link>
    <joint name='RAnklePitch' type='revolute'>
      <child>left_hip_right_ankle_1</child>
      <parent>lower_leg_right_1</parent>
      <axis>
        <xyz>-1e-06 -1 1.1e-05</xyz>
        <limit>
          <lower>-1.22173</lower>
          <upper>1.5708</upper>
          <effort>7.57</effort>
          <velocity>8.22</velocity>
        </limit>
        <dynamics>
          <spring_reference>0</spring_reference>
          <spring_stiffness>0</spring_stiffness>
        </dynamics>
        <use_parent_model_frame>1</use_parent_model_frame>
      </axis>
    </joint>
    <link name='r_foot'>
      <pose frame=''>-0.003568 -0.055003 -0.392534 0.261805 -1e-05 -1.5708</pose>
      <inertial>
        <pose frame=''>0.0121 0.091494 -0.029994 0 -0 0</pose>
        <mass>0.281772</mass>
        <inertia>
          <ixx>0.000952692</ixx>
          <ixy>-3.29806e-05</ixy>
          <ixz>5.20707e-06</ixz>
          <iyy>0.000344273</iyy>
          <iyz>-1.94309e-05</iyz>
          <izz>0.00124519</izz>
        </inertia>
      </inertial>
      <collision name='r_foot_collision'>
        <pose frame=''>-0.029996 0.006049 -0.03425 -0 0 0</pose>
        <geometry>
          <mesh>
            <scale>1 1 1</scale>
            <uri>model://wolfgang_description/urdf/load_cell.stl</uri>
          </mesh>
        </geometry>
        <surface>
          <contact>
            <ode>
              <kp>1e+06</kp>
              <kd>100</kd>
              <max_vel>1</max_vel>
              <min_depth>0</min_depth>
            </ode>
          </contact>
          <friction>
            <ode>
              <mu>1</mu>
              <mu2>1</mu2>
              <fdir1>1 0 0</fdir1>
            </ode>
          </friction>
        </surface>
      </collision>
      <collision name='r_foot_collision_1'>
        <pose frame=''>0 0.046 -0.036 -0 0 0</pose>
        <geometry>
          <mesh>
            <scale>1 1 1</scale>
            <uri>model://wolfgang_description/urdf/ankle.stl</uri>
          </mesh>
        </geometry>
        <surface>
          <contact>
            <ode>
              <kp>1e+06</kp>
              <kd>100</kd>
              <max_vel>1</max_vel>
              <min_depth>0</min_depth>
            </ode>
          </contact>
          <friction>
            <ode>
              <mu>1</mu>
              <mu2>1</mu2>
              <fdir1>1 0 0</fdir1>
            </ode>
          </friction>
        </surface>
      </collision>
      <collision name='r_foot_collision_2'>
        <pose frame=''>0.06 0.1635 -0.03425 0 -0 0</pose>
        <geometry>
          <mesh>
            <scale>1 1 1</scale>
            <uri>model://wolfgang_description/urdf/load_cell.stl</uri>
          </mesh>
        </geometry>
        <surface>
          <contact>
            <ode>
              <kp>1e+06</kp>
              <kd>100</kd>
              <max_vel>1</max_vel>
              <min_depth>0</min_depth>
            </ode>
          </contact>
          <friction>
            <ode>
              <mu>1</mu>
              <mu2>1</mu2>
              <fdir1>1 0 0</fdir1>
            </ode>
          </friction>
        </surface>
      </collision>
      <collision name='r_foot_collision_3'>
        <pose frame=''>0.037 0.16 -0.0324 -3.14159 0 -0</pose>
        <geometry>
          <mesh>
            <scale>1 1 1</scale>
            <uri>model://wolfgang_description/urdf/forcefoot_pcb.stl</uri>
          </mesh>
        </geometry>
        <surface>
          <contact>
            <ode>
              <kp>1e+06</kp>
              <kd>100</kd>
              <max_vel>1</max_vel>
              <min_depth>0</min_depth>
            </ode>
          </contact>
          <friction>
            <ode>
              <mu>1</mu>
              <mu2>1</mu2>
              <fdir1>1 0 0</fdir1>
            </ode>
          </friction>
        </surface>
      </collision>
      <collision name='r_foot_collision_4'>
        <pose frame=''>-0.03 0.1635 -0.03425 0 0 -0</pose>
        <geometry>
          <mesh>
            <scale>1 1 1</scale>
            <uri>model://wolfgang_description/urdf/load_cell.stl</uri>
          </mesh>
        </geometry>
        <surface>
          <contact>
            <ode>
              <kp>1e+06</kp>
              <kd>100</kd>
              <max_vel>1</max_vel>
              <min_depth>0</min_depth>
            </ode>
          </contact>
          <friction>
            <ode>
              <mu>1</mu>
              <mu2>1</mu2>
              <fdir1>1 0 0</fdir1>
            </ode>
          </friction>
        </surface>
      </collision>
      <collision name='r_foot_collision_5'>
        <pose frame=''>0.06 -0.007 -0.04425 0 0 -1.5708</pose>
        <geometry>
          <mesh>
            <scale>1 1 1</scale>
            <uri>model://wolfgang_description/urdf/flex_stollen.stl</uri>
          </mesh>
        </geometry>
        <surface>
          <contact>
            <ode>
              <kp>1e+06</kp>
              <kd>100</kd>
              <max_vel>1</max_vel>
              <min_depth>0</min_depth>
            </ode>
          </contact>
          <friction>
            <ode>
              <mu>1</mu>
              <mu2>1</mu2>
              <fdir1>1 0 0</fdir1>
            </ode>
          </friction>
        </surface>
      </collision>
      <collision name='r_foot_collision_6'>
        <pose frame=''>-0.145 0.085 -0.0395 -0 -0 -1.5708</pose>
        <geometry>
          <mesh>
            <scale>1 1 1</scale>
            <uri>model://wolfgang_description/urdf/foot_printed_right.stl</uri>
          </mesh>
        </geometry>
        <surface>
          <contact>
            <ode>
              <kp>1e+06</kp>
              <kd>100</kd>
              <max_vel>1</max_vel>
              <min_depth>0</min_depth>
            </ode>
          </contact>
          <friction>
            <ode>
              <mu>1</mu>
              <mu2>1</mu2>
              <fdir1>1 0 0</fdir1>
            </ode>
          </friction>
        </surface>
      </collision>
      <collision name='r_foot_collision_7'>
        <pose frame=''>0.06 0.0065 -0.03425 -0 -0 3.14159</pose>
        <geometry>
          <mesh>
            <scale>1 1 1</scale>
            <uri>model://wolfgang_description/urdf/load_cell.stl</uri>
          </mesh>
        </geometry>
        <surface>
          <contact>
            <ode>
              <kp>1e+06</kp>
              <kd>100</kd>
              <max_vel>1</max_vel>
              <min_depth>0</min_depth>
            </ode>
          </contact>
          <friction>
            <ode>
              <mu>1</mu>
              <mu2>1</mu2>
              <fdir1>1 0 0</fdir1>
            </ode>
          </friction>
        </surface>
      </collision>
      <collision name='r_foot_collision_8'>
        <pose frame=''>-0.03 0.177 -0.04425 0 -0 -1.5708</pose>
        <geometry>
          <mesh>
            <scale>1 1 1</scale>
            <uri>model://wolfgang_description/urdf/flex_stollen.stl</uri>
          </mesh>
        </geometry>
        <surface>
          <contact>
            <ode>
              <kp>1e+06</kp>
              <kd>100</kd>
              <max_vel>1</max_vel>
              <min_depth>0</min_depth>
            </ode>
          </contact>
          <friction>
            <ode>
              <mu>1</mu>
              <mu2>1</mu2>
              <fdir1>1 0 0</fdir1>
            </ode>
          </friction>
        </surface>
      </collision>
      <collision name='r_foot_collision_9'>
        <pose frame=''>-0.029996 -0.007451 -0.04425 -0 -0 -1.5708</pose>
        <geometry>
          <mesh>
            <scale>1 1 1</scale>
            <uri>model://wolfgang_description/urdf/flex_stollen.stl</uri>
          </mesh>
        </geometry>
        <surface>
          <contact>
            <ode>
              <kp>1e+06</kp>
              <kd>100</kd>
              <max_vel>1</max_vel>
              <min_depth>0</min_depth>
            </ode>
          </contact>
          <friction>
            <ode>
              <mu>1</mu>
              <mu2>1</mu2>
              <fdir1>1 0 0</fdir1>
            </ode>
          </friction>
        </surface>
      </collision>
      <collision name='r_foot_collision_10'>
        <pose frame=''>0.06 0.177 -0.04425 0 0 -1.5708</pose>
        <geometry>
          <mesh>
            <scale>1 1 1</scale>
            <uri>model://wolfgang_description/urdf/flex_stollen.stl</uri>
          </mesh>
        </geometry>
        <surface>
          <contact>
            <ode>
              <kp>1e+06</kp>
              <kd>100</kd>
              <max_vel>1</max_vel>
              <min_depth>0</min_depth>
            </ode>
          </contact>
          <friction>
            <ode>
              <mu>1</mu>
              <mu2>1</mu2>
              <fdir1>1 0 0</fdir1>
            </ode>
          </friction>
        </surface>
      </collision>
      <collision name='r_foot_collision_11'>
        <pose frame=''>0.023457 0.061834 -0.046391 -0 0 -1.5708</pose>
        <geometry>
          <mesh>
            <scale>1 1 1</scale>
            <uri>model://wolfgang_description/urdf/foot_cover.stl</uri>
          </mesh>
        </geometry>
        <surface>
          <contact>
            <ode>
              <kp>1e+06</kp>
              <kd>100</kd>
              <max_vel>1</max_vel>
              <min_depth>0</min_depth>
            </ode>
          </contact>
          <friction>
            <ode>
              <mu>1</mu>
              <mu2>1</mu2>
              <fdir1>1 0 0</fdir1>
            </ode>
          </friction>
        </surface>
      </collision>
      <visual name='r_foot_visual'>
        <pose frame=''>-0.029996 0.006049 -0.03425 -0 0 0</pose>
        <geometry>
          <mesh>
            <scale>1 1 1</scale>
            <uri>model://wolfgang_description/urdf/load_cell.stl</uri>
          </mesh>
        </geometry>
        <material>
          <script>
            <name>Gazebo/FlatBlack</name>
            <uri>file://media/materials/scripts/gazebo.material</uri>
          </script>
        </material>
      </visual>
      <visual name='r_foot_visual_1'>
        <pose frame=''>0 0.046 -0.036 -0 0 0</pose>
        <geometry>
          <mesh>
            <scale>1 1 1</scale>
            <uri>model://wolfgang_description/urdf/ankle.stl</uri>
          </mesh>
        </geometry>
        <material>
          <script>
            <name>Gazebo/FlatBlack</name>
            <uri>file://media/materials/scripts/gazebo.material</uri>
          </script>
        </material>
      </visual>
      <visual name='r_foot_visual_2'>
        <pose frame=''>0.06 0.1635 -0.03425 0 -0 0</pose>
        <geometry>
          <mesh>
            <scale>1 1 1</scale>
            <uri>model://wolfgang_description/urdf/load_cell.stl</uri>
          </mesh>
        </geometry>
        <material>
          <script>
            <name>Gazebo/FlatBlack</name>
            <uri>file://media/materials/scripts/gazebo.material</uri>
          </script>
        </material>
      </visual>
      <visual name='r_foot_visual_3'>
        <pose frame=''>0.037 0.16 -0.0324 -3.14159 0 -0</pose>
        <geometry>
          <mesh>
            <scale>1 1 1</scale>
            <uri>model://wolfgang_description/urdf/forcefoot_pcb.stl</uri>
          </mesh>
        </geometry>
        <material>
          <script>
            <name>Gazebo/FlatBlack</name>
            <uri>file://media/materials/scripts/gazebo.material</uri>
          </script>
        </material>
      </visual>
      <visual name='r_foot_visual_4'>
        <pose frame=''>-0.03 0.1635 -0.03425 0 0 -0</pose>
        <geometry>
          <mesh>
            <scale>1 1 1</scale>
            <uri>model://wolfgang_description/urdf/load_cell.stl</uri>
          </mesh>
        </geometry>
        <material>
          <script>
            <name>Gazebo/FlatBlack</name>
            <uri>file://media/materials/scripts/gazebo.material</uri>
          </script>
        </material>
      </visual>
      <visual name='r_foot_visual_5'>
        <pose frame=''>0.06 -0.007 -0.04425 0 0 -1.5708</pose>
        <geometry>
          <mesh>
            <scale>1 1 1</scale>
            <uri>model://wolfgang_description/urdf/flex_stollen.stl</uri>
          </mesh>
        </geometry>
        <material>
          <script>
            <name>Gazebo/FlatBlack</name>
            <uri>file://media/materials/scripts/gazebo.material</uri>
          </script>
        </material>
      </visual>
      <visual name='r_foot_visual_6'>
        <pose frame=''>-0.145 0.085 -0.0395 -0 -0 -1.5708</pose>
        <geometry>
          <mesh>
            <scale>1 1 1</scale>
            <uri>model://wolfgang_description/urdf/foot_printed_right.stl</uri>
          </mesh>
        </geometry>
        <material>
          <script>
            <name>Gazebo/FlatBlack</name>
            <uri>file://media/materials/scripts/gazebo.material</uri>
          </script>
        </material>
      </visual>
      <visual name='r_foot_visual_7'>
        <pose frame=''>0.06 0.0065 -0.03425 -0 -0 3.14159</pose>
        <geometry>
          <mesh>
            <scale>1 1 1</scale>
            <uri>model://wolfgang_description/urdf/load_cell.stl</uri>
          </mesh>
        </geometry>
        <material>
          <script>
            <name>Gazebo/FlatBlack</name>
            <uri>file://media/materials/scripts/gazebo.material</uri>
          </script>
        </material>
      </visual>
      <visual name='r_foot_visual_8'>
        <pose frame=''>-0.03 0.177 -0.04425 0 -0 -1.5708</pose>
        <geometry>
          <mesh>
            <scale>1 1 1</scale>
            <uri>model://wolfgang_description/urdf/flex_stollen.stl</uri>
          </mesh>
        </geometry>
        <material>
          <script>
            <name>Gazebo/FlatBlack</name>
            <uri>file://media/materials/scripts/gazebo.material</uri>
          </script>
        </material>
      </visual>
      <visual name='r_foot_visual_9'>
        <pose frame=''>-0.029996 -0.007451 -0.04425 -0 -0 -1.5708</pose>
        <geometry>
          <mesh>
            <scale>1 1 1</scale>
            <uri>model://wolfgang_description/urdf/flex_stollen.stl</uri>
          </mesh>
        </geometry>
        <material>
          <script>
            <name>Gazebo/FlatBlack</name>
            <uri>file://media/materials/scripts/gazebo.material</uri>
          </script>
        </material>
      </visual>
      <visual name='r_foot_visual_10'>
        <pose frame=''>0.06 0.177 -0.04425 0 0 -1.5708</pose>
        <geometry>
          <mesh>
            <scale>1 1 1</scale>
            <uri>model://wolfgang_description/urdf/flex_stollen.stl</uri>
          </mesh>
        </geometry>
        <material>
          <script>
            <name>Gazebo/FlatBlack</name>
            <uri>file://media/materials/scripts/gazebo.material</uri>
          </script>
        </material>
      </visual>
      <visual name='r_foot_visual_11'>
        <pose frame=''>0.023457 0.061834 -0.046391 -0 0 -1.5708</pose>
        <geometry>
          <mesh>
            <scale>1 1 1</scale>
            <uri>model://wolfgang_description/urdf/foot_cover.stl</uri>
          </mesh>
        </geometry>
        <material>
          <script>
            <name>Gazebo/FlatBlack</name>
            <uri>file://media/materials/scripts/gazebo.material</uri>
          </script>
        </material>
      </visual>
      <gravity>1</gravity>
      <velocity_decay/>
    </link>
    <joint name='RAnkleRoll' type='revolute'>
      <child>r_foot</child>
      <parent>left_hip_right_ankle_1</parent>
      <axis>
        <xyz>-0.965924 2e-06 -0.258825</xyz>
        <limit>
          <lower>-1.0472</lower>
          <upper>1.0472</upper>
          <effort>7.57</effort>
          <velocity>8.22</velocity>
        </limit>
        <dynamics>
          <spring_reference>0</spring_reference>
          <spring_stiffness>0</spring_stiffness>
        </dynamics>
        <use_parent_model_frame>1</use_parent_model_frame>
      </axis>
    </joint>
    <link name='shoulder_right_1'>
      <pose frame=''>-0.0015 -0.0765 0.2035 -0 0 -3.14159</pose>
      <inertial>
        <pose frame=''>-0.01354 0.028402 -2e-06 0 -0 0</pose>
        <mass>0.041445</mass>
        <inertia>
          <ixx>1.85473e-05</ixx>
          <ixy>7.63058e-06</ixy>
          <ixz>-9.41386e-10</ixz>
          <iyy>2.76649e-05</iyy>
          <iyz>8.71825e-10</iyz>
          <izz>3.49573e-05</izz>
        </inertia>
      </inertial>
      <collision name='shoulder_right_1_collision'>
        <pose frame=''>-0.02595 0.042 0 -1.5708 0 1.5708</pose>
        <geometry>
          <mesh>
            <scale>1 1 1</scale>
            <uri>model://wolfgang_description/urdf/sea_connector.stl</uri>
          </mesh>
        </geometry>
      </collision>
      <collision name='shoulder_right_1_collision_1'>
        <pose frame=''>-0.01695 0.042 0 -1.5708 0 1.5708</pose>
        <geometry>
          <mesh>
            <scale>1 1 1</scale>
            <uri>model://wolfgang_description/urdf/sea_ninjaflex.stl</uri>
          </mesh>
        </geometry>
      </collision>
      <collision name='shoulder_right_1_collision_2'>
        <pose frame=''>0 0 0 0 -0 -0</pose>
        <geometry>
          <mesh>
            <scale>1 1 1</scale>
            <uri>model://wolfgang_description/urdf/shoulder_connector.stl</uri>
          </mesh>
        </geometry>
      </collision>
      <visual name='shoulder_right_1_visual'>
        <pose frame=''>-0.02595 0.042 0 -1.5708 0 1.5708</pose>
        <geometry>
          <mesh>
            <scale>1 1 1</scale>
            <uri>model://wolfgang_description/urdf/sea_connector.stl</uri>
          </mesh>
        </geometry>
      </visual>
      <visual name='shoulder_right_1_visual_1'>
        <pose frame=''>-0.01695 0.042 0 -1.5708 0 1.5708</pose>
        <geometry>
          <mesh>
            <scale>1 1 1</scale>
            <uri>model://wolfgang_description/urdf/sea_ninjaflex.stl</uri>
          </mesh>
        </geometry>
      </visual>
      <visual name='shoulder_right_1_visual_2'>
        <pose frame=''>0 0 0 0 -0 -0</pose>
        <geometry>
          <mesh>
            <scale>1 1 1</scale>
            <uri>model://wolfgang_description/urdf/shoulder_connector.stl</uri>
          </mesh>
        </geometry>
      </visual>
    </link>
    <joint name='RShoulderPitch' type='revolute'>
      <child>shoulder_right_1</child>
      <parent>base_link</parent>
      <axis>
        <xyz>-3e-06 1 0</xyz>
        <limit>
          <lower>-3.14159</lower>
          <upper>3.14159</upper>
          <effort>5.43</effort>
          <velocity>10.33</velocity>
        </limit>
        <dynamics>
          <spring_reference>0</spring_reference>
          <spring_stiffness>0</spring_stiffness>
        </dynamics>
        <use_parent_model_frame>1</use_parent_model_frame>
      </axis>
    </joint>
    <link name='upper_arm_1'>
      <pose frame=''>0.01545 -0.1185 0.2035 1.5708 0 1.5708</pose>
      <inertial>
        <pose frame=''>0 -0.028656 -0.023556 0 -0 0</pose>
        <mass>0.206164</mass>
        <inertia>
          <ixx>0.000204986</ixx>
          <ixy>1.94871e-12</ixy>
          <ixz>3.40342e-12</ixz>
          <iyy>0.000171949</iyy>
          <iyz>-3.58687e-07</iyz>
          <izz>0.000333232</izz>
        </inertia>
      </inertial>
      <collision name='upper_arm_1_collision'>
        <pose frame=''>0 0 -0.0235 -1.5708 0 -0</pose>
        <geometry>
          <mesh>
            <scale>1 1 1</scale>
            <uri>model://wolfgang_description/urdf/mx-64-body.stl</uri>
          </mesh>
        </geometry>
      </collision>
      <collision name='upper_arm_1_collision_1'>
        <pose frame=''>0.0265 -0.144 -0.0235 3.14159 -1.57079 1.57079</pose>
        <geometry>
          <mesh>
            <scale>1 1 1</scale>
            <uri>model://wolfgang_description/urdf/upper_arm.stl</uri>
          </mesh>
        </geometry>
      </collision>
      <collision name='upper_arm_1_collision_2'>
        <pose frame=''>-0.0147 -0.0105 -0.0235 -1.5708 -0 1.5708</pose>
        <geometry>
          <mesh>
            <scale>1 1 1</scale>
            <uri>model://wolfgang_description/urdf/connector_shoulder.stl</uri>
          </mesh>
        </geometry>
      </collision>
      <collision name='upper_arm_1_collision_3'>
        <pose frame=''>-0.0265 -0.144 -0.0235 3.14159 1.57079 -1.57079</pose>
        <geometry>
          <mesh>
            <scale>1 1 1</scale>
            <uri>model://wolfgang_description/urdf/upper_arm.stl</uri>
          </mesh>
        </geometry>
      </collision>
      <collision name='upper_arm_1_collision_4'>
        <pose frame=''>0.0147 -0.0105 -0.0235 1.5708 -0 1.5708</pose>
        <geometry>
          <mesh>
            <scale>1 1 1</scale>
            <uri>model://wolfgang_description/urdf/connector_shoulder.stl</uri>
          </mesh>
        </geometry>
      </collision>
      <visual name='upper_arm_1_visual'>
        <pose frame=''>0 0 -0.0235 -1.5708 0 -0</pose>
        <geometry>
          <mesh>
            <scale>1 1 1</scale>
            <uri>model://wolfgang_description/urdf/mx-64-body.stl</uri>
          </mesh>
        </geometry>
      </visual>
      <visual name='upper_arm_1_visual_1'>
        <pose frame=''>0.0265 -0.144 -0.0235 3.14159 -1.57079 1.57079</pose>
        <geometry>
          <mesh>
            <scale>1 1 1</scale>
            <uri>model://wolfgang_description/urdf/upper_arm.stl</uri>
          </mesh>
        </geometry>
      </visual>
      <visual name='upper_arm_1_visual_2'>
        <pose frame=''>-0.0147 -0.0105 -0.0235 -1.5708 -0 1.5708</pose>
        <geometry>
          <mesh>
            <scale>1 1 1</scale>
            <uri>model://wolfgang_description/urdf/connector_shoulder.stl</uri>
          </mesh>
        </geometry>
      </visual>
      <visual name='upper_arm_1_visual_3'>
        <pose frame=''>-0.0265 -0.144 -0.0235 3.14159 1.57079 -1.57079</pose>
        <geometry>
          <mesh>
            <scale>1 1 1</scale>
            <uri>model://wolfgang_description/urdf/upper_arm.stl</uri>
          </mesh>
        </geometry>
      </visual>
      <visual name='upper_arm_1_visual_4'>
        <pose frame=''>0.0147 -0.0105 -0.0235 1.5708 -0 1.5708</pose>
        <geometry>
          <mesh>
            <scale>1 1 1</scale>
            <uri>model://wolfgang_description/urdf/connector_shoulder.stl</uri>
          </mesh>
        </geometry>
      </visual>
    </link>
    <joint name='RShoulderRoll' type='revolute'>
      <child>upper_arm_1</child>
      <parent>shoulder_right_1</parent>
      <axis>
        <xyz>1 -1e-06 -4e-06</xyz>
        <limit>
          <lower>-3.14159</lower>
          <upper>0</upper>
          <effort>5.43</effort>
          <velocity>10.33</velocity>
        </limit>
        <dynamics>
          <spring_reference>0</spring_reference>
          <spring_stiffness>0</spring_stiffness>
        </dynamics>
        <use_parent_model_frame>1</use_parent_model_frame>
      </axis>
    </joint>
    <link name='lower_arm_right_1'>
      <pose frame=''>-0.00805 -0.0945 0.0595 2.35619 1.57079 -2.3562</pose>
      <inertial>
        <pose frame=''>0.000436 -0.060513 -0.023555 0 -0 0</pose>
        <mass>0.207774</mass>
        <inertia>
          <ixx>0.001088</ixx>
          <ixy>-1.16188e-06</ixy>
          <ixz>-5.01515e-09</ixz>
          <iyy>8.90324e-05</iyy>
          <iyz>-3.22666e-08</iyz>
          <izz>0.00110076</izz>
        </inertia>
      </inertial>
      <collision name='lower_arm_right_1_collision'>
        <pose frame=''>0 -0.163682 -0.0065 -1.5708 -0 -3.14159</pose>
        <geometry>
          <mesh>
            <scale>1 1 1</scale>
            <uri>model://wolfgang_description/urdf/lower_arm.stl</uri>
          </mesh>
        </geometry>
      </collision>
      <collision name='lower_arm_right_1_collision_1'>
        <pose frame=''>0 -0 -0.0235 -1.5708 0 -0</pose>
        <geometry>
          <mesh>
            <scale>1 1 1</scale>
            <uri>model://wolfgang_description/urdf/mx-64-body.stl</uri>
          </mesh>
        </geometry>
      </collision>
      <collision name='lower_arm_right_1_collision_2'>
        <pose frame=''>0 -0.163682 -0.0065 1.5708 0 0</pose>
        <geometry>
          <mesh>
            <scale>1 1 1</scale>
            <uri>model://wolfgang_description/urdf/hand.stl</uri>
          </mesh>
        </geometry>
      </collision>
      <collision name='lower_arm_right_1_collision_3'>
        <pose frame=''>0 -0.163682 -0.0425 -1.5708 -0 -3.14159</pose>
        <geometry>
          <mesh>
            <scale>1 1 1</scale>
            <uri>model://wolfgang_description/urdf/lower_arm.stl</uri>
          </mesh>
        </geometry>
      </collision>
      <visual name='lower_arm_right_1_visual'>
        <pose frame=''>0 -0.163682 -0.0065 -1.5708 -0 -3.14159</pose>
        <geometry>
          <mesh>
            <scale>1 1 1</scale>
            <uri>model://wolfgang_description/urdf/lower_arm.stl</uri>
          </mesh>
        </geometry>
      </visual>
      <visual name='lower_arm_right_1_visual_1'>
        <pose frame=''>0 -0 -0.0235 -1.5708 0 -0</pose>
        <geometry>
          <mesh>
            <scale>1 1 1</scale>
            <uri>model://wolfgang_description/urdf/mx-64-body.stl</uri>
          </mesh>
        </geometry>
      </visual>
      <visual name='lower_arm_right_1_visual_2'>
        <pose frame=''>0 -0.163682 -0.0065 1.5708 0 0</pose>
        <geometry>
          <mesh>
            <scale>1 1 1</scale>
            <uri>model://wolfgang_description/urdf/hand.stl</uri>
          </mesh>
        </geometry>
      </visual>
      <visual name='lower_arm_right_1_visual_3'>
        <pose frame=''>0 -0.163682 -0.0425 -1.5708 -0 -3.14159</pose>
        <geometry>
          <mesh>
            <scale>1 1 1</scale>
            <uri>model://wolfgang_description/urdf/lower_arm.stl</uri>
          </mesh>
        </geometry>
      </visual>
    </link>
    <joint name='RElbow' type='revolute'>
      <child>lower_arm_right_1</child>
      <parent>upper_arm_1</parent>
      <axis>
        <xyz>-3e-06 1 -4e-06</xyz>
        <limit>
          <lower>-1.0472</lower>
          <upper>1.5708</upper>
          <effort>5.43</effort>
          <velocity>10.33</velocity>
        </limit>
        <dynamics>
          <spring_reference>0</spring_reference>
          <spring_stiffness>0</spring_stiffness>
        </dynamics>
        <use_parent_model_frame>1</use_parent_model_frame>
      </axis>
    </joint>
    <plugin name='gazebo_ros_control' filename='libgazebo_ros_control.so'>
      <robotNamespace>$(arg sim_ns)</robotNamespace>
    </plugin>
    <static>0</static>
    <plugin name='gazebo_ros_f3d' filename='libgazebo_ros_f3d.so'>
      <alwaysOn>1</alwaysOn>
      <updateRate>100.0</updateRate>
      <bodyName>r_foot</bodyName>
      <topicName>tst_test_test</topicName>
      <robotNamespace>demo</robotNamespace>
    </plugin>
  </model>
</sdf>
