<?xml version="1.0" encoding="UTF-8"?>
<robot xmlns:xacro="http://www.ros.org/wiki/xacro" name="wolfgang">

    <xacro:arg name="sim_ns" default="/" />

    <xacro:property name="tofa" value="1" /> <!--Torque factor-->
    <xacro:property name="infa" value="1" /> <!--inertia factor-->
    <xacro:property name="insu" value="0" /> <!--inertia summand-->
    <xacro:property name="d" value="1" /> <!-- damping -->
    <xacro:property name="f" value="1" /> <!-- friction -->
    <material name="black">
        <color rgba="0.1 0.1 0.1 1" />
    </material>

    <link name="base_link" />

    <link name="torso">
        <inertial>
            <origin xyz="-0.016856 -0.00019822 0.019225" rpy="0 0 0" />
            <mass value="1.8051" />
            <inertia ixx="0.016444" ixy="1.4574E-05" ixz="0.00048254" iyy="0.013972" iyz="5.0355E-06" izz="0.0064508" />
        </inertial>
        <visual>
            <origin xyz="0 0 0" rpy="0 0 0" />
            <geometry>
                <mesh filename="package://wolfgang_description/mesh/trunk_link.STL" />
            </geometry>
            <material name="black" />
        </visual>
        <collision>
            <origin xyz="0 0 0" rpy="0 0 0" />
            <geometry>
                <mesh filename="package://wolfgang_description/mesh/trunk_link.dae" />
            </geometry>
        </collision>
    </link>

    <link name="r_hip_1">
        <inertial>
            <origin xyz="4.7878E-16 2.8449E-16 -0.013803" rpy="0 0 0" />
            <mass value="0.073374" />
            <inertia ixx="2.6774E-05" ixy="1.5536E-19" ixz="-9.0622E-19" iyy="0.00011478" iyz="-2.2736E-19" izz="0.00010743" />
        </inertial>
        <visual>
            <origin xyz="0 0 0" rpy="0 0 0" />
            <geometry>
                <mesh filename="package://wolfgang_description/mesh/right_hip_yaw_link.STL" />
            </geometry>
            <material name="black" />
        </visual>
        <collision>
            <origin xyz="0 0 0" rpy="0 0 0" />
            <geometry>
                <mesh filename="package://wolfgang_description/mesh/right_hip_yaw_link.dae" />
            </geometry>
        </collision>
    </link>

    <link name="r_hip_2">
        <inertial>
            <origin xyz="0.010896 0.00023756 -0.014538" rpy="0 0 0" />
            <mass value="0.35903" />
            <inertia ixx="0.00015503" ixy="1.738E-06" ixz="8.5148E-06" iyy="0.0003299" iyz="2.4403E-07" izz="0.0002782" />
        </inertial>
        <visual>
            <origin xyz="0 0 0" rpy="0 0 0" />
            <geometry>
                <mesh filename="package://wolfgang_description/mesh/right_hip_roll_link.STL" />
            </geometry>
            <material name="black" />
        </visual>
        <collision>
            <origin xyz="0 0 0" rpy="0 0 0" />
            <geometry>
                <mesh filename="package://wolfgang_description/mesh/right_hip_roll_link.dae" />
            </geometry>
        </collision>
    </link>

    <link name="r_upper_leg">
        <inertial>
            <origin xyz="0.0038549 0.00023828 -0.1495" rpy="0 0 0" />
            <mass value="0.38276" />
            <inertia ixx="0.0020951" ixy="1.8755E-07" ixz="-0.00017816" iyy="0.0020043" iyz="-5.4867E-06" izz="0.00027919" />
        </inertial>
        <visual>
            <origin xyz="0 0 0" rpy="0 0 0" />
            <geometry>
                <mesh filename="package://wolfgang_description/mesh/left_thigh_link.STL" />
            </geometry>
            <material name="black" />
        </visual>
        <!--<collision>
            <origin xyz="0 0 0" rpy="0 0 0" />
            <geometry>
                <mesh filename="package://wolfgang_description/mesh/left_thigh_link.dae" />
            </geometry>
        </collision>-->
    </link>

    <link name="r_lower_leg">
        <inertial>
            <origin xyz="-0.0033779 6.578E-10 -0.10469" rpy="0 0 3.14159265359" />
            <mass value="0.20549" />
            <inertia ixx="0.0011378" ixy="-2.8771E-12" ixz="9.7123E-05" iyy="0.0010393" iyz="-1.4479E-11" izz="0.00019656" />
        </inertial>
        <visual>
            <origin xyz="0 0 0" rpy="0 0 0" />
            <geometry>
                <mesh filename="package://wolfgang_description/mesh/right_shank_link.STL" />
            </geometry>
            <material name="black" />
        </visual>
        <!--<collision>
            <origin xyz="0 0 0" rpy="0 0 0" />
            <geometry>
                <mesh filename="package://wolfgang_description/mesh/right_shank_link.dae" />
            </geometry>
        </collision>-->
    </link>

    <link name="r_ankle">
        <inertial>
            <origin xyz="-0.019434 0.00024988 0.014536" rpy="0 0 0" />
            <mass value="0.35844" />
            <inertia ixx="0.00015501" ixy="1.7299E-06" ixz="-8.5156E-06" iyy="0.00032958" iyz="-2.4435E-07" izz="0.00027786" />
        </inertial>
        <!--<visual>
            <origin xyz="0 0 0" rpy="0 0 0" />
            <geometry>
                <mesh filename="package://wolfgang_description/mesh/right_ankle_link.STL" />
            </geometry>
            <material name="black" />
        </visual>
        <collision>
            <origin xyz="0 0 0" rpy="0 0 0" />
            <geometry>
                <mesh filename="package://wolfgang_description/mesh/right_ankle_link.dae" />
            </geometry>
        </collision>-->
    </link>

    <link name="r_foot">
        <inertial>
            <origin xyz="0.003669 -0.0081165 -0.030903" rpy="0 0 0" />
            <mass value="0.1488" />
            <inertia ixx="0.00018527" ixy="-1.1504E-05" ixz="-7.2667E-06" iyy="0.00060485" iyz="5.8883E-06" izz="0.00075217" />
        </inertial>
        <visual>
            <origin xyz="0 0 -0.012" rpy="0 0 0" />
            <geometry>
                <mesh filename="package://wolfgang_description/mesh/right_foot_link.STL" />
            </geometry>
            <material name="black" />
        </visual>
        <collision>
            <origin xyz="0 0 -0.012" rpy="0 0 0" />
            <geometry>
                <mesh filename="package://wolfgang_description/mesh/right_foot_link.dae" />
            </geometry>
        </collision>
    </link>
    
    <link name="r_sole">
        <inertial>
          <origin xyz="0 0 0" rpy="0 0 0" />
          <mass value="0.01" />
          <inertia ixx="0" ixy="0" ixz="0" iyy="0" iyz="0" izz="0" />
        </inertial>
    </link>

    <link name="r_toe">
        <inertial>
          <origin xyz="0 0 0" rpy="0 0 0" />
          <mass value="0.01" />
          <inertia ixx="0" ixy="0" ixz="0" iyy="0" iyz="0" izz="0" />
        </inertial>
    </link>

    <link name="l_hip_1">
        <inertial>
            <origin xyz="4.996E-16 2.5674E-16 -0.013803" rpy="0 0 0" />
            <mass value="0.073374" />
            <inertia ixx="2.6774E-05" ixy="1.9727E-19" ixz="-8.7961E-19" iyy="0.00011478" iyz="-2.3128E-19" izz="0.00010743" />
        </inertial>
        <visual>
            <origin xyz="0 0 0" rpy="0 0 0" />
            <geometry>
                <mesh filename="package://wolfgang_description/mesh/left_hip_yaw_link.STL" />
            </geometry>
            <material name="black" />
        </visual>
        <collision>
            <origin xyz="0 0 0" rpy="0 0 0" />
            <geometry>
                <mesh filename="package://wolfgang_description/mesh/left_hip_yaw_link.dae" />
            </geometry>
        </collision>
    </link>

    <link name="l_hip_2">
        <inertial>
            <origin xyz="-0.019434 -0.0014499 -0.014536" rpy="0 0 0" />
            <mass value="0.35844" />
            <inertia ixx="0.00015501" ixy="-1.7299E-06" ixz="8.5156E-06" iyy="0.00032958" iyz="-2.4435E-07" izz="0.00027786" />
        </inertial>
        <visual>
            <origin xyz="0.033 0 0" rpy="0 0 0" />
            <geometry>
                <mesh filename="package://wolfgang_description/mesh/left_hip_roll_link.STL" />
            </geometry>
            <material name="black" />
        </visual>
        <collision>
            <origin xyz="0.033 0 0" rpy="0 0 0" />
            <geometry>
                <mesh filename="package://wolfgang_description/mesh/left_hip_roll_link.dae" />
            </geometry>
        </collision>
    </link>

    <link name="l_upper_leg">
        <inertial>
            <origin xyz="0.0038576 -0.0014383 -0.1495" rpy="0 0 0" />
            <mass value="0.38276" />
            <inertia ixx="0.0020952" ixy="-1.9541E-07" ixz="-0.00017822" iyy="0.0020044" iyz="5.4912E-06" izz="0.00027919" />
        </inertial>
        <visual>
            <origin xyz="0 0 0" rpy="0 0 0" />
            <geometry>
                <mesh filename="package://wolfgang_description/mesh/left_thigh_link.STL" />
            </geometry>
            <material name="black" />
        </visual>
        <!--<collision>
            <origin xyz="0 0 0" rpy="0 0 0" />
            <geometry>
                <mesh filename="package://wolfgang_description/mesh/left_thigh_link.dae" />
            </geometry>
        </collision>-->
    </link>

    <link name="l_lower_leg">
        <inertial>
            <origin xyz="-0.0033779 -0.0012 -0.10469" rpy="0 0 0" />
            <mass value="0.20549" />
            <inertia ixx="0.0011378" ixy="-2.8771E-12" ixz="9.7123E-05" iyy="0.0010393" iyz="-1.4479E-11" izz="0.00019656" />
        </inertial>
        <visual>
            <origin xyz="0 0 0" rpy="0 0 0" />
            <geometry>
                <mesh filename="package://wolfgang_description/mesh/left_shank_link.STL" />
            </geometry>
            <material name="black" />
        </visual>
        <!--<collision>
            <origin xyz="0 0 0" rpy="0 0 0" />
            <geometry>
                <mesh filename="package://wolfgang_description/mesh/left_shank_link.dae" />
            </geometry>
        </collision>-->
    </link>

    <link name="l_ankle">
        <inertial>
            <origin xyz="-0.019418 -0.0014376 0.014538" rpy="0 0 0" />
            <mass value="0.35903" />
            <inertia ixx="0.00015503" ixy="-1.738E-06" ixz="-8.5148E-06" iyy="0.0003299" iyz="2.4403E-07" izz="0.0002782" />
        </inertial>
        <!--<visual>
            <origin xyz="0 0 0" rpy="0 0 0" />
            <geometry>
                <mesh filename="package://wolfgang_description/mesh/left_ankle_link.STL" />
            </geometry>
            <material name="black" />
        </visual>
        <collision>
            <origin xyz="0 0 0" rpy="0 0 0" />
            <geometry>
                <mesh filename="package://wolfgang_description/mesh/left_ankle_link.dae" />
            </geometry>
        </collision>-->
    </link>

    <link name="l_foot">
        <inertial>
            <origin xyz="0.0036084 0.0081189 -0.03091" rpy="0 0 0" />
            <mass value="0.1488" />
            <inertia ixx="0.0001853" ixy="1.1466E-05" ixz="-8.3793E-06" iyy="0.00060485" iyz="-5.9046E-06" izz="0.00075213" />
        </inertial>
        <visual>
            <origin xyz="0 0 -0.012" rpy="0 0 0" />
            <geometry>
                <mesh filename="package://wolfgang_description/mesh/left_foot_link.STL" />
            </geometry>
            <material name="black" />
        </visual>
        <collision>
            <origin xyz="0 0 -0.012" rpy="0 0 0" />
            <geometry>
                <mesh filename="package://wolfgang_description/mesh/left_foot_link.dae" />
            </geometry>
        </collision>
    </link>

    <link name="l_sole">
        <inertial>
          <origin xyz="0 0 0" rpy="0 0 0" />
          <mass value="0.01" />
          <inertia ixx="0" ixy="0" ixz="0" iyy="0" iyz="0" izz="0" />
        </inertial>
    </link>

    <link name="l_toe">
        <inertial>
          <origin xyz="0 0 0" rpy="0 0 0" />
          <mass value="0.01" />
          <inertia ixx="0" ixy="0" ixz="0" iyy="0" iyz="0" izz="0" />
        </inertial>
    </link>

    <link name="r_shoulder">
        <inertial>
            <origin xyz="0 -0.014621 0" rpy="0 0 0" />
            <mass value="0.025434" />
            <inertia ixx="6.7511E-06" ixy="1.5595E-20" ixz="-5.4198E-21" iyy="1.2425E-05" iyz="-2.4006E-20" izz="1.4317E-05" />
        </inertial>
        <visual>
            <origin xyz="0 0 0" rpy="0 0 0" />
            <geometry>
                <mesh filename="package://wolfgang_description/mesh/right_shoulder_pitch_link.STL" />
            </geometry>
            <material name="black" />
        </visual>
        <collision>
            <origin xyz="0 0 0" rpy="0 0 0" />
            <geometry>
                <mesh filename="package://wolfgang_description/mesh/right_shoulder_pitch_link.dae" />
            </geometry>
        </collision>
    </link>

    <link name="r_upper_arm">
        <inertial>
            <origin xyz="0.0013671 0.00022653 -0.049517" rpy="0 0 0" />
            <mass value="0.2575" />
            <inertia ixx="0.00081539" ixy="1.1134E-07" ixz="-5.114E-05" iyy="0.0007994" iyz="-2.4756E-06" izz="0.00012883" />
        </inertial>
        <visual>
            <origin xyz="0 0 0" rpy="0 0 0" />
            <geometry>
                <mesh filename="package://wolfgang_description/mesh/right_shoulder_arm_link.STL" />
            </geometry>
            <material name="black" />
        </visual>
        <collision>
            <origin xyz="0 0 0" rpy="0 0 0" />
            <geometry>
                <mesh filename="package://wolfgang_description/mesh/right_shoulder_arm_link.dae" />
            </geometry>
        </collision>
    </link>

    <link name="r_lower_arm">
        <inertial>
            <origin xyz="0.0018497 -0.00091671 -0.059095" rpy="0 0 0" />
            <mass value="0.23502" />
            <inertia ixx="0.0011613" ixy="-5.8221E-07" ixz="-7.4224E-05" iyy="0.0011747" iyz="2.0082E-05" izz="0.00010273" />
        </inertial>
        <visual>
            <origin xyz="0 0 0" rpy="0 -1.57 0" />
            <geometry>
                <mesh filename="package://wolfgang_description/mesh/right_lower_arm_link.STL" />
            </geometry>
            <material name="black" />
        </visual>
        <collision>
            <origin xyz="0 0 0" rpy="0 -1.57 0" />
            <geometry>
                <mesh filename="package://wolfgang_description/mesh/right_lower_arm_link.dae" />
            </geometry>
        </collision>
    </link>

    <link name="r_wrist"> </link>    

    <link name="l_shoulder">
        <inertial>
            <origin xyz="0 0.014621 0" rpy="0 0 0" />
            <mass value="0.025434" />
            <inertia ixx="6.7511E-06" ixy="6.4644E-21" ixz="-3.365E-21" iyy="1.2425E-05" iyz="-4.6109E-22" izz="1.4317E-05" />
        </inertial>
        <visual>
            <origin xyz="0 0 0" rpy="0 0 0" />
            <geometry>
                <mesh filename="package://wolfgang_description/mesh/left_shoulder_pitch_link.STL" />
            </geometry>
            <material name="black" />
        </visual>
        <collision>
            <origin xyz="0 0 0" rpy="0 0 0" />
            <geometry>
                <mesh filename="package://wolfgang_description/mesh/left_shoulder_pitch_link.dae" />
            </geometry>
        </collision>
    </link>

    <link name="l_upper_arm">
        <inertial>
            <origin xyz="0.0013671 0.00022653 -0.049517" rpy="0 0 0" />
            <mass value="0.2575" />
            <inertia ixx="0.00081539" ixy="1.1134E-07" ixz="-5.114E-05" iyy="0.0007994" iyz="-2.4756E-06" izz="0.00012883" />
        </inertial>
        <visual>
            <origin xyz="0 0 0" rpy="0 0 0" />
            <geometry>
                <mesh filename="package://wolfgang_description/mesh/left_upper_arm_link.STL" />
            </geometry>
            <material name="black" />
        </visual>
        <collision>
            <origin xyz="0 0 0" rpy="0 0 0" />
            <geometry>
                <mesh filename="package://wolfgang_description/mesh/left_upper_arm_link.dae" />
            </geometry>
        </collision>
    </link>

    <link name="l_lower_arm">
        <inertial>
            <origin xyz="0.001742 -6.4508E-05 -0.059095" rpy="0 0 0" />
            <mass value="0.23502" />
            <inertia ixx="0.0011616" ixy="-2.6303E-07" ixz="-7.2367E-05" iyy="0.0011751" iyz="9.5624E-06" izz="0.00010214" />
        </inertial>
        <visual>
            <origin xyz="0 0 0" rpy="0 -1.57 0" />
            <geometry>
                <mesh filename="package://wolfgang_description/mesh/left_lower_arm_link.STL" />
            </geometry>
            <material name="black" />
        </visual>
        <collision>
            <origin xyz="0 0 0" rpy="0 -1.57 0" />
            <geometry>
                <mesh filename="package://wolfgang_description/mesh/left_lower_arm_link.dae" />
            </geometry>
        </collision>
    </link>

    <link name="l_wrist"> </link>

    <link name="neck">
        <inertial>
            <origin xyz="2.1595E-05 0.00064781 0.033208" rpy="0 0 0" />
            <mass value="0.15587" />
            <inertia ixx="7.5209E-05" ixy="-1.8422E-06" ixz="-4.9817E-07" iyy="6.2999E-05" iyz="-9.9088E-08" izz="3.826E-05" />
        </inertial>
        <visual>
            <origin xyz="0 0 0" rpy="0 0 0" />
            <geometry>
                <mesh filename="package://wolfgang_description/mesh/neck_link.STL" />
            </geometry>
            <material name="black" />
        </visual>
        <collision>
            <origin xyz="0 0 0" rpy="0 0 0" />
            <geometry>
                <mesh filename="package://wolfgang_description/mesh/neck_link.dae" />
            </geometry>
        </collision>
    </link>
    <link name="camera" />
    <link name="imu" />

    <link name="head">
        <inertial>
            <origin xyz="0.014358 0.0005519 0.069919" rpy="0 0 0" />
            <mass value="0.40746" />
            <inertia ixx="0.0014813" ixy="3.1631E-07" ixz="-4.1003E-05" iyy="0.0016361" iyz="6.7483E-07" izz="0.0017353" />
        </inertial>
        <!--<visual>
            <origin xyz="0 0 0" rpy="0 0 0" />
            <geometry>
                <mesh filename="package://wolfgang_description/mesh/head_link.STL" />
            </geometry>
            <material name="">
                <color rgba="0.8 0.8 0.8 1" />
            </material>
        </visual>
        <collision>
            <origin xyz="0 0 0" rpy="0 0 0" />
            <geometry>
                <mesh filename="package://wolfgang_description/mesh/head_link.dae" />
            </geometry>
        </collision>-->
    </link>





    <joint name="RHipYaw" type="revolute">
        <origin xyz="0 -0.055 0" rpy="0 0 0" />
        <parent link="base_link" />
        <child link="r_hip_1" />
        <axis xyz="0 0 -1" />
        <limit effort="${tofa*2.5}" velocity="5.6548668" lower="-0.9250245035547" upper="0.9250245035547" />
        <dynamics damping="${d}" friction="${f}" />
    </joint>

    <joint name="RHipRoll" type="revolute">
        <origin xyz="-0.0072 0 -0.0438" rpy="0 0 0" />
        <parent link="r_hip_1" />
        <child link="r_hip_2" />
        <axis xyz="1 0 0" />
        <limit effort="${tofa*6.0}" velocity="6.597344565" lower="-1.57" upper="0.7853981633955001" />
        <dynamics damping="${d}" friction="${f}" />
    </joint>

    <joint name="RHipPitch" type="revolute">
        <origin xyz="0.0303 0 0" rpy="0 0 0" />
        <parent link="r_hip_2" />
        <child link="r_upper_leg" />
        <axis xyz="0 1 0" />
        <limit effort="${tofa*8.4}" velocity="4.712388975" lower="-1.919862177189" upper="0.48869219055720003" />
        <dynamics damping="${d}" friction="${f}" />
    </joint>

    <joint name="RKnee" type="revolute">
        <origin xyz="-0.03 0 -0.17" rpy="0 0 0" />
        <parent link="r_upper_leg" />
        <child link="r_lower_leg" />
        <axis xyz="0 1 0" />
        <limit effort="${tofa*8.4}" velocity="4.712388975" lower="0" upper="2.268928027587" />
        <dynamics damping="${d}" friction="${f}" />
    </joint>

    <joint name="RAnklePitch" type="revolute">
        <origin xyz="0.02 0 -0.17" rpy="0 0 0" />
        <parent link="r_lower_leg" />
        <child link="r_ankle" />
        <axis xyz="0 -1 0" />
        <limit effort="${tofa*8.4}" velocity="4.712388975" lower="-1.2391837689129" upper="1.6406094968706" />
        <dynamics damping="${d}" friction="${f}" />
    </joint>

    <joint name="RAnkleRoll" type="revolute">
        <origin xyz="0 0 0" rpy="0 0 0" />
        <parent link="r_ankle" />
        <child link="r_foot" />
        <axis xyz="-1 0 0" />
        <limit effort="${tofa*6.0}" velocity="6.597344565" lower="-1.4660765716716" upper="1.4660765716716" />
        <dynamics damping="${d}" friction="${f}" />
    </joint>

    <joint name="r_foot_to_sole" type="fixed">
        <origin xyz="0 0 -0.06" rpy="0 0 0" /> <!-- -0.04 - stollen-->
        <parent link="r_foot" />
        <child link="r_sole" />
        <axis xyz="0 0 0" />
    </joint>

    <joint name="r_foot_to_toe" type="fixed">
        <origin xyz="0.105 0 0" rpy="0 0 0" />
        <parent link="r_sole" />
        <child link="r_toe" />
        <axis xyz="0 0 0" />
    </joint>

    <joint name="LHipYaw" type="revolute">
        <origin xyz="0 0.055 0" rpy="0 0 0" />
        <parent link="base_link" />
        <child link="l_hip_1" />
        <axis xyz="0 0 -1" />
        <limit effort="${tofa*2.5}" velocity="5.6548668" lower="-0.9250245035547" upper="0.9250245035547" />
        <dynamics damping="${d}" friction="${f}" />
    </joint>

    <joint name="LHipRoll" type="revolute">
        <origin xyz="-0.0072 0 -0.0438" rpy="0 0 0" />
        <parent link="l_hip_1" />
        <child link="l_hip_2" />
        <axis xyz="1 0 0" />
        <limit effort="${tofa*6.0}" velocity="6.597344565" lower="-0.7853981633955001" upper="1.57" />
        <dynamics damping="${d}" friction="${f}" />
    </joint>

    <joint name="LHipPitch" type="revolute">
        <origin xyz="0.0303 0 0" rpy="0 0 0" />
        <parent link="l_hip_2" />
        <child link="l_upper_leg" />
        <axis xyz="0 -1 0" />
        <limit effort="${tofa*8.4}" velocity="4.712388975" lower="-0.48869219055720003" upper="1.919862177189" />
        <dynamics damping="${d}" friction="${f}" />
    </joint>

    <joint name="LKnee" type="revolute">
        <origin xyz="-0.030 0 -0.17" rpy="0 0 0" />
        <parent link="l_upper_leg" />
        <child link="l_lower_leg" />
        <axis xyz="0 -1 0" />
        <limit effort="${tofa*8.4}" velocity="4.712388975" lower="-2.268928027587" upper="0" />
        <dynamics damping="${d}" friction="${f}" />
    </joint>

    <joint name="LAnklePitch" type="revolute">
        <origin xyz="0.020 0 -0.17" rpy="0 0 0" />
        <parent link="l_lower_leg" />
        <child link="l_ankle" />
        <axis xyz="0 1 0" />
        <limit effort="${tofa*8.4}" velocity="4.712388975" lower="-1.6406094968706" upper="1.2391837689129" />
        <dynamics damping="${d}" friction="${f}" />
    </joint>

    <joint name="LAnkleRoll" type="revolute">
        <origin xyz="0 0 0" rpy="0 0 0" />
        <parent link="l_ankle" />
        <child link="l_foot" />
        <axis xyz="-1 0 0" />
        <limit effort="${tofa*6.0}" velocity="6.597344565" lower="-1.4660765716716" upper="1.4660765716716" />
        <dynamics damping="${d}" friction="${f}" />
    </joint>

    <joint name="left_foot_to_sole" type="fixed">
        <origin xyz="0 0 -0.06" rpy="0 0 0" />
        <parent link="l_foot" />
        <child link="l_sole" />
        <axis xyz="0 0 0" />
    </joint>

    <joint name="left_foot_to_toe" type="fixed">
        <origin xyz="0.105 0 0" rpy="0 0 0" />
        <parent link="l_sole" />
        <child link="l_toe" />
        <axis xyz="0 0 0" />
    </joint>

    <joint name="base_link_to_torso" type="fixed">
        <parent link="base_link" />
        <child link="torso" />
        <origin rpy="0.0 0 0" xyz="0 0 0.09" />
    </joint>

    <joint name="torso_to_imu" type="fixed">
        <parent link="torso" />
        <child link="imu" />
        <origin rpy="0.0 0 0" xyz="-0.045 0.025 0.023" />
    </joint>
    

    <joint name="RShoulderPitch" type="revolute">
        <origin xyz="0.0 -0.075 0.11" rpy="0 0 0" />
        <parent link="torso" />
        <child link="r_shoulder" />
        <axis xyz="0 -1 0" />
        <limit effort="${tofa*6.0}" velocity="6.597344565" lower="-3.1415926535820002" upper="3.1415926535820002" />
        <dynamics damping="${d}" friction="${f}" />
    </joint>

    <joint name="RShoulderRoll" type="revolute">
        <origin xyz="0 -0.04 0" rpy="0 0 0" />
        <parent link="r_shoulder" />
        <child link="r_upper_arm" />
        <axis xyz="-1 0 0" />
        <limit effort="${tofa*2.5}" velocity="5.648668" lower="-0.7853981633955001" upper="2.3561944901865" />
        <dynamics damping="${d}" friction="${f}" />
    </joint>

    <joint name="RElbow" type="revolute">
        <origin xyz="-0.0075 0 -0.145" rpy="0 0 0" />
        <parent link="r_upper_arm" />
        <child link="r_lower_arm" />
        <axis xyz="0 1 0" />
        <limit effort="${tofa*2.5}" velocity="5.6548668" lower="-1.635" upper="1.5707963267910001" />
        <dynamics damping="${d}" friction="${f}" />
    </joint>

    <joint name="r_elbow_to_wrist" type="fixed">
        <parent link="r_lower_arm" />
        <child link="r_wrist" />
        <origin xyz="0.225 0 0" rpy="0 0 0"/> 
    </joint>

    <joint name="LShoulderPitch" type="revolute">
        <origin xyz="0.0 0.075 0.11" rpy="0 0 0" />
        <parent link="torso" />
        <child link="l_shoulder" />
        <axis xyz="0 1 0" />
        <limit effort="${tofa*6.0}" velocity="6.597344565" lower="-3.1415926535820002" upper="3.1415926535820002" />
        <dynamics damping="${d}" friction="${f}" />
    </joint>

    <joint name="LShoulderRoll" type="revolute">
        <origin xyz="0 0.04 0" rpy="0 0 0" />
        <parent link="l_shoulder" />
        <child link="l_upper_arm" />
        <axis xyz="-1 0 0" />
        <limit effort="${tofa*2.5}" velocity="5.648668" lower="-2.3561944901865" upper="0.7853981633955001" />
        <dynamics damping="${d}" friction="${f}" />
    </joint>

    <joint name="LElbow" type="revolute">
        <origin xyz="-0.0075 0 -0.145" rpy="0 0 0" />
        <parent link="l_upper_arm" />
        <child link="l_lower_arm" />
        <axis xyz="0 -1 0" />
        <limit effort="${tofa*2.5}" velocity="5.6548668" lower="-1.1344640137935" upper="1.5707963267910001" />
        <dynamics damping="${d}" friction="${f}" />
    </joint>

    <joint name="l_elbow_to_wrist" type="fixed">
        <parent link="l_lower_arm" />
        <child link="l_wrist" />
        <origin xyz="0.225 0 0" rpy="0 0 0"/>
    </joint>

    <joint name="HeadPan" type="revolute">
        <origin xyz="-0.0285 0 0.1365" rpy="0 0 0" />
        <parent link="torso" />
        <child link="neck" />
        <axis xyz="0 0 1" />
        <limit effort="${tofa*2.5}" velocity="5.6548668" lower="-2.1816615649875" upper="2.1816615649875" />
        <dynamics damping="${d}" friction="${f}" />
    </joint>

    <joint name="HeadTilt" type="revolute">
        <origin xyz="0 0 0.0505" rpy="0 0 0" />
        <parent link="neck" />
        <child link="head" />
        <axis xyz="0 1 0" />
        <limit effort="${tofa*2.5}" velocity="5.6548668" lower="-1.5707963267910001" upper="0" />
        <dynamics damping="${d}" friction="${f}" />
    </joint>


    <joint name="head_to_camera" type="fixed">
        <origin xyz="0.03 0 0.05" rpy="0 0 0" />
        <parent link="head" />
        <child link="camera" />
        <axis xyz="0 0 0" />
        <dynamics damping="${d}" friction="${f}" />
    </joint>

    <transmission name="HeadPanTransmission">
        <type>transmission_interface/SimpleTransmission</type>
        <joint name="HeadPan">
            <hardwareInterface>hardware_interface/EffortJointInterface</hardwareInterface>
        </joint>
        <actuator name="HeadPanMotor">
            <hardwareInterface>hardware_interface/EffortJointInterface</hardwareInterface>
            <mechanicalReduction>1</mechanicalReduction>
        </actuator>
    </transmission>
    <transmission name="HeadTiltTransmission">
        <type>transmission_interface/SimpleTransmission</type>
        <joint name="HeadTilt">
            <hardwareInterface>hardware_interface/EffortJointInterface</hardwareInterface>
        </joint>
        <actuator name="HeadTiltMotor">
            <hardwareInterface>hardware_interface/EffortJointInterface</hardwareInterface>
            <mechanicalReduction>1</mechanicalReduction>
        </actuator>
    </transmission>
    <transmission name="LShoulderPitchTransmission">
        <type>transmission_interface/SimpleTransmission</type>
        <joint name="LShoulderPitch">
            <hardwareInterface>hardware_interface/EffortJointInterface</hardwareInterface>
        </joint>
        <actuator name="LShoulderPitchMotor">
            <hardwareInterface>hardware_interface/EffortJointInterface</hardwareInterface>
            <mechanicalReduction>1</mechanicalReduction>
        </actuator>
    </transmission>
    <transmission name="LShoulderRollTransmission">
        <type>transmission_interface/SimpleTransmission</type>
        <joint name="LShoulderRoll">
            <hardwareInterface>hardware_interface/EffortJointInterface</hardwareInterface>
        </joint>
        <actuator name="LShoulderRollTransmission">
            <hardwareInterface>hardware_interface/EffortJointInterface</hardwareInterface>
            <mechanicalReduction>1</mechanicalReduction>
        </actuator>
    </transmission>
    <transmission name="LElbowTransmission">
        <type>transmission_interface/SimpleTransmission</type>
        <joint name="LElbow">
            <hardwareInterface>hardware_interface/EffortJointInterface</hardwareInterface>
        </joint>
        <actuator name="LElbowMotor">
            <hardwareInterface>hardware_interface/EffortJointInterface</hardwareInterface>
            <mechanicalReduction>1</mechanicalReduction>
        </actuator>
    </transmission>
    <transmission name="RShoulderPitchTransmission">
        <type>transmission_interface/SimpleTransmission</type>
        <joint name="RShoulderPitch">
            <hardwareInterface>hardware_interface/EffortJointInterface</hardwareInterface>
        </joint>
        <actuator name="RShoulderPitchMotor">
            <hardwareInterface>hardware_interface/EffortJointInterface</hardwareInterface>
            <mechanicalReduction>1</mechanicalReduction>
        </actuator>
    </transmission>
    <transmission name="RShoulderRollTransmission">
        <type>transmission_interface/SimpleTransmission</type>
        <joint name="RShoulderRoll">
            <hardwareInterface>hardware_interface/EffortJointInterface</hardwareInterface>
        </joint>
        <actuator name="RShoulderRollMotor">
            <hardwareInterface>hardware_interface/EffortJointInterface</hardwareInterface>
            <mechanicalReduction>1</mechanicalReduction>
        </actuator>
    </transmission>
    <transmission name="RElbowTransmission">
        <type>transmission_interface/SimpleTransmission</type>
        <joint name="RElbow">
            <hardwareInterface>hardware_interface/EffortJointInterface</hardwareInterface>
        </joint>
        <actuator name="RElbowMotor">
            <hardwareInterface>hardware_interface/EffortJointInterface</hardwareInterface>
            <mechanicalReduction>1</mechanicalReduction>
        </actuator>
    </transmission>
    <transmission name="LHipYawTransmission">
        <type>transmission_interface/SimpleTransmission</type>
        <joint name="LHipYaw">
            <hardwareInterface>hardware_interface/EffortJointInterface</hardwareInterface>
        </joint>
        <actuator name="LHipYawMotor">
            <hardwareInterface>hardware_interface/EffortJointInterface</hardwareInterface>
            <mechanicalReduction>1</mechanicalReduction>
        </actuator>
    </transmission>
    <transmission name="LHipRollTransmission">
        <type>transmission_interface/SimpleTransmission</type>
        <joint name="LHipRoll">
            <hardwareInterface>hardware_interface/EffortJointInterface</hardwareInterface>
        </joint>
        <actuator name="LHipRollMotor">
            <hardwareInterface>hardware_interface/EffortJointInterface</hardwareInterface>
            <mechanicalReduction>1</mechanicalReduction>
        </actuator>
    </transmission>
    <transmission name="LHipPitchTransmission">
        <type>transmission_interface/SimpleTransmission</type>
        <joint name="LHipPitch">
            <hardwareInterface>hardware_interface/EffortJointInterface</hardwareInterface>
        </joint>
        <actuator name="LHipPitchMotor">
            <hardwareInterface>hardware_interface/EffortJointInterface</hardwareInterface>
            <mechanicalReduction>1</mechanicalReduction>
        </actuator>
    </transmission>
    <transmission name="LKneeTransmission">
        <type>transmission_interface/SimpleTransmission</type>
        <joint name="LKnee">
            <hardwareInterface>hardware_interface/EffortJointInterface</hardwareInterface>
        </joint>
        <actuator name="LKneeMotor">
            <hardwareInterface>hardware_interface/EffortJointInterface</hardwareInterface>
            <mechanicalReduction>1</mechanicalReduction>
        </actuator>
    </transmission>
    <transmission name="LAnklePitchTransmission">
        <type>transmission_interface/SimpleTransmission</type>
        <joint name="LAnklePitch">
            <hardwareInterface>hardware_interface/EffortJointInterface</hardwareInterface>
        </joint>
        <actuator name="LAnklePitchMotor">
            <hardwareInterface>hardware_interface/EffortJointInterface</hardwareInterface>
            <mechanicalReduction>1</mechanicalReduction>
        </actuator>
    </transmission>
    <transmission name="LAnkleRollTransmission">
        <type>transmission_interface/SimpleTransmission</type>
        <joint name="LAnkleRoll">
            <hardwareInterface>hardware_interface/EffortJointInterface</hardwareInterface>
        </joint>
        <actuator name="LAnkleRollMotor">
            <hardwareInterface>hardware_interface/EffortJointInterface</hardwareInterface>
            <mechanicalReduction>1</mechanicalReduction>
        </actuator>
    </transmission>
    <transmission name="RHipYawTransmission">
        <type>transmission_interface/SimpleTransmission</type>
        <joint name="RHipYaw">
            <hardwareInterface>hardware_interface/EffortJointInterface</hardwareInterface>
        </joint>
        <actuator name="RHipYawMotor">
            <hardwareInterface>hardware_interface/EffortJointInterface</hardwareInterface>
            <mechanicalReduction>1</mechanicalReduction>
        </actuator>
    </transmission>
    <transmission name="RHipRollTransmission">
        <type>transmission_interface/SimpleTransmission</type>
        <joint name="RHipRoll">
            <hardwareInterface>hardware_interface/EffortJointInterface</hardwareInterface>
        </joint>
        <actuator name="RHipRollMotor">
            <hardwareInterface>hardware_interface/EffortJointInterface</hardwareInterface>
            <mechanicalReduction>1</mechanicalReduction>
        </actuator>
    </transmission>
    <transmission name="RHipPitchTransmission">
        <type>transmission_interface/SimpleTransmission</type>
        <joint name="RHipPitch">
            <hardwareInterface>hardware_interface/EffortJointInterface</hardwareInterface>
        </joint>
        <actuator name="RHipPitchMotor">
            <hardwareInterface>hardware_interface/EffortJointInterface</hardwareInterface>
            <mechanicalReduction>1</mechanicalReduction>
        </actuator>
    </transmission>
    <transmission name="RKneeTransmission">
        <type>transmission_interface/SimpleTransmission</type>
        <joint name="RKnee">
            <hardwareInterface>hardware_interface/EffortJointInterface</hardwareInterface>
        </joint>
        <actuator name="RKneeMotor">
            <hardwareInterface>hardware_interface/EffortJointInterface</hardwareInterface>
            <mechanicalReduction>1</mechanicalReduction>
        </actuator>
    </transmission>
    <transmission name="RAnklePitchTransmission">
        <type>transmission_interface/SimpleTransmission</type>
        <joint name="RAnklePitch">
            <hardwareInterface>hardware_interface/EffortJointInterface</hardwareInterface>
        </joint>
        <actuator name="RAnklePitchMotor">
            <hardwareInterface>hardware_interface/EffortJointInterface</hardwareInterface>
            <mechanicalReduction>1</mechanicalReduction>
        </actuator>
    </transmission>
    <transmission name="RAnkleRollTransmission">
        <type>transmission_interface/SimpleTransmission</type>
        <joint name="RAnkleRoll">
            <hardwareInterface>hardware_interface/EffortJointInterface</hardwareInterface>
        </joint>
        <actuator name="RAnkleRollMotor">
            <hardwareInterface>hardware_interface/EffortJointInterface</hardwareInterface>
            <mechanicalReduction>1</mechanicalReduction>
        </actuator>
    </transmission>

    <gazebo reference="r_foot">
        <material>gazebo/Grey</material>
        <kp>1000000.0</kp>
        <kd>100.0</kd>
        <mu1>1.0</mu1>
        <mu2>1.0</mu2>
        <fdir1>1 0 0</fdir1>
        <maxVel>1.0</maxVel>
        <minDepth>0.00</minDepth>
    </gazebo>
    <gazebo reference="l_foot">
        <material>gazebo/Grey</material>
        <kp>1000000.0</kp>
        <kd>100.0</kd>
        <mu1>1.0</mu1>
        <mu2>1.0</mu2>
        <fdir1>1 0 0</fdir1>
        <maxVel>1.0</maxVel>
        <minDepth>0.00</minDepth>
    </gazebo>

  <!-- joint controller -->
    <gazebo>
        <plugin filename="libgazebo_ros_control.so" name="gazebo_ros_control">
            <robotNamespace>$(arg sim_ns)</robotNamespace>
        </plugin>
    </gazebo>

  <!-- camera sensor -->
  <gazebo reference="camera">
        <sensor name='camera' type='camera'>
          <pose>-0.050000 -0.010000 0.000000 -1.5708 0.000000 -3.141592</pose>
          <camera name='__default__'>
            <horizontal_fov>1.012300</horizontal_fov>
            <image>
              <width>800</width>
              <height>600</height>
            </image>
            <clip>
              <near>0.001000</near>
              <far>100.000000</far>
            </clip>
          </camera>
          <always_on>1</always_on>
          <update_rate>30.000000</update_rate>
          <visualize>1</visualize>
          <plugin name="camera_controller" filename="libgazebo_ros_camera.so">
            <alwaysOn>true</alwaysOn>
            <updateRate>30</updateRate>
            <cameraName>camera</cameraName>
            <imageTopicName>image_raw</imageTopicName>
            <cameraInfoTopicName>camera_info</cameraInfoTopicName>
            <frameName>camera</frameName>
            <hackBaseline>0.07</hackBaseline>
            <distortionK1>0.0</distortionK1>
            <distortionK2>0.0</distortionK2>
            <distortionK3>0.0</distortionK3>
            <distortionT1>0.0</distortionT1>
            <distortionT2>0.0</distortionT2>
          </plugin>
      </sensor>
  </gazebo>


   <!-- IMU sensor -->
   <gazebo reference="L_IMU">
    <gravity>true</gravity>
    <sensor name="imu_sensor" type="imu">
      <always_on>true</always_on>
      <update_rate>100</update_rate>
      <visualize>true</visualize>
      <topic>__default_topic__</topic>
      <plugin filename="libgazebo_ros_imu_sensor.so" name="imu_plugin">
        <topicName>imu</topicName>
        <bodyName>torso</bodyName>
        <updateRateHZ>100.0</updateRateHZ>
        <gaussianNoise>0.0</gaussianNoise>
        <xyzOffset>0 0 0</xyzOffset>
        <rpyOffset>0 0 0</rpyOffset>
        <frameName>imu</frameName>
      </plugin>
      <pose>0 0 0 0 0 0</pose>
    </sensor>
  </gazebo>

   <!-- fake controller that allows us to move the robot and to get its oposition -->
   <!-- rostopic pub /minibot/cmd_vel geometry_msgs/Twist "{ linear: [ 0.1, 0, 0], angular: [0.2, 0, 0.1] }" -->
   <!--<gazebo>
    <plugin name="object_controller" filename="libgazebo_ros_planar_move.so">
      <robotNamespace>wolves</robotNamespace>

      <commandTopic>cmd_vel</commandTopic>
      <odometryTopic>odom</odometryTopic>
      <odometryFrame>odom</odometryFrame>
      <odometryRate>100.0</odometryRate>
      <robotBaseFrame>base_link</robotBaseFrame>
    </plugin>
  </gazebo> -->

</robot>

