<?xml version="1.0" encoding="UTF-8"?>
<robot xmlns:xacro="http://www.ros.org/wiki/xacro" name="wolfgang">

    <xacro:arg name="sim_ns" default="/" />
    <xacro:arg name="cleats" default="-0.013" />
    <xacro:arg name="use_fake_walk" default="False"/>
    <xacro:property name="fake_walk" value="$(arg use_fake_walk)" />

    <xacro:property name="tofa" value="1" />  <!--Torque factor-->
    <!--<xacro:property name="infa" value="1" /> --> <!--inertia factor--> 
    <xacro:property name="d" value="1" /> <!-- damping -->
    <xacro:property name="f" value="1" /> <!-- friction -->
    <material name="black">
        <color rgba="0.1 0.1 0.1 1" />
    </material>
    <material name="metal">
        <color rgba="0.85 0.85 0.85 1" />
    </material>
    <material name="carbon">
        <color rgba="0.3 0.3 0.3 1" />
    </material>

    <link name="base_link" />

    <link name="torso">
        <inertial>
            <!--<origin xyz="0.007 -0.002 0.021" rpy="${-pi/64} ${-pi/32} 0" />-->
            <origin xyz="0.014563 0.001600 0.016559" rpy="${-pi/64} ${-pi/32} 0" />
            <mass value="2.889" />
            <inertia ixx="0.021175651" ixy="0.000145103" ixz="-0.001622146" iyy="0.018733911" iyz="0.000373507" izz="0.009304" />
        </inertial>
        <visual>
            <origin xyz="0 0 0" rpy="0 0 0" />
            <geometry>
                <mesh filename="package://wolfgang_description/mesh/torso_link.stl"  />
            </geometry>
            <material name="metal" />
        </visual>
        <visual>
            <origin xyz="0 0 0" rpy="0 0 0" />
            <geometry>
                <mesh filename="package://wolfgang_description/mesh/torso_link_motors.stl"/>
            </geometry>
            <material name="black" />
        </visual>
        <collision>
            <origin xyz="0 0 0" rpy="0 0 0" />
            <geometry>
                <mesh filename="package://wolfgang_description/mesh/collision/torso_link.stl" />
            </geometry>
        </collision>
    </link>

    <link name="r_hip_1">
        <inertial>
            <!--<origin xyz="0 0 -0.011" rpy="0 0 0" />-->
            <origin xyz="-0.000001 0 -0.014563" rpy="0 0 0" />
            <mass value="0.098" />
            <inertia ixx="0.000013709" ixy="-0.000002388" ixz="-0.000000001" iyy="0.000054561" iyz="0" izz="0.000049167" />
        </inertial>
        <visual>
            <origin xyz="0 0 0" rpy="0 0 0" />
            <geometry>
                <mesh filename="package://wolfgang_description/mesh/hip_connector.stl"/>
            </geometry>
            <material name="metal" />    
        </visual>
        <collision>
            <origin xyz="0 0 0" rpy="0 0 0" />
            <geometry>
                <mesh filename="package://wolfgang_description/mesh/collision/hip_connector.stl" />
            </geometry>
        </collision>
    </link>

    <link name="r_hip_2">
        <inertial>
            <!--<origin xyz="0.046 -0.002 -0.026" rpy="0 ${pi/64} 0" />-->
            <origin xyz="0.051391 0.000232 -0.014250" rpy="0 ${pi/64} 0" />
            <mass value="0.349" />
            <inertia ixx="0.000156848" ixy="-0.000002134" ixz="-0.000005733" iyy="0.000355019" iyz="-0.000001749" izz="0.000308883" />
        </inertial>
        <visual>
            <origin xyz="0 0 0" rpy="0 0 0" />
            <geometry>
                <mesh filename="package://wolfgang_description/mesh/hip_link_2.stl" />
            </geometry>
            <material name="black" />
        </visual>
        <collision>
            <origin xyz="0 0 0" rpy="0 0 0" />
            <geometry>
                <mesh filename="package://wolfgang_description/mesh/collision/hip_link_2.stl" />
            </geometry>
        </collision>
    </link>

    <link name="r_upper_leg">
        <inertial>
            <!--<origin xyz="0.0056 0.004 0.126" rpy="0 0 0" />-->
            <origin xyz="0.004721 0.000424 -0.132759" rpy="0 0 0" />
            <mass value="0.248" />
            <inertia ixx="0.000660963" ixy="0.000000544" ixz="-0.000016736" iyy="0.000606384" iyz="-0.000004189" izz="0.000150136" />
        </inertial>
        <visual>
            <origin xyz="0 0 0" rpy="0 ${pi} 0" />
            <geometry>
                <mesh filename="package://wolfgang_description/mesh/upper_leg_carbon.stl" />
            </geometry>
            <material name="carbon" />
        </visual>
        <visual>
            <origin xyz="0 0 0" rpy="0 ${pi} 0" />
            <geometry>
                <mesh filename="package://wolfgang_description/mesh/upper_leg_metal.stl" />
            </geometry>
            <material name="metal"/>
        </visual>
        <visual>
            <origin xyz="0 0 0" rpy="0 ${pi} 0" />
            <geometry>
                <mesh filename="package://wolfgang_description/mesh/upper_leg_motor.stl" />
            </geometry>
            <material name="black" />
        </visual>
        <collision>
            <origin xyz="0 0 0" rpy="0 ${pi} 0" />
            <geometry>
                <mesh filename="package://wolfgang_description/mesh/collision/upper_leg_carbon.stl" />
            </geometry>
        </collision>
        <collision>
            <origin xyz="0 0 0" rpy="0 ${pi} 0" />
            <geometry>
                <mesh filename="package://wolfgang_description/mesh/collision/upper_leg_metal.stl" />
            </geometry>
        </collision>
        <collision>
            <origin xyz="0 0 0" rpy="0 ${pi} 0" />
            <geometry>
                <mesh filename="package://wolfgang_description/mesh/collision/upper_leg_motor.stl" />
            </geometry>
        </collision>
    </link>

    <link name="r_lower_leg">
        <inertial>
            <!--<origin xyz="0.012 0 -0.076" rpy="0 0 3.14159265359" />-->
             <origin xyz="0.070129 -0.000102 -0.061824" rpy="0 ${-pi/4} 0" />
            <mass value="0.085" />
            <inertia ixx="0.000278504" ixy="0.000000060" ixz="-0.000004917" iyy="0.000241283" iyz="-0.000000066" izz="0.000070447" />
        </inertial>
        <visual>
            <origin xyz="0 0 0" rpy="0 ${-pi/4} 0" />
            <geometry>
                <mesh filename="package://wolfgang_description/mesh/lower_leg.stl" />
            </geometry>
            <material name="carbon" />
        </visual>
        <collision>
            <origin xyz="0 0 0" rpy="0 ${-pi/4} 0" />
            <geometry>
                <mesh filename="package://wolfgang_description/mesh/collision/lower_leg.stl" />
            </geometry>
        </collision>
    </link>

    <link name="r_ankle">
        <inertial>
            <!--<origin xyz="-0.02 -0.005 0.026" rpy="${-pi/64} ${-pi/32} ${-pi/64}" />-->
            <origin xyz="-0.017874 0.000190 0.013809" rpy="${-pi/64} ${-pi/32} ${-pi/64}" />
            <mass value="0.349" />
            <inertia ixx="0.000159124" ixy="-0.000001620" ixz="0.000011391" iyy="0.000355570" iyz="0.000001710" izz="0.000307157" />
        </inertial>
        <visual>
            <origin xyz="0 0 0" rpy="0 0 0" />
            <geometry>
                <mesh filename="package://wolfgang_description/mesh/ankle.stl" />
            </geometry>
            <material name="black" />
        </visual>
        <collision>
            <origin xyz="0 0 0" rpy="0 0 0" />
            <geometry>
                <mesh filename="package://wolfgang_description/mesh/collision/ankle.stl" />
            </geometry>
        </collision>
    </link>

    <link name="r_foot">
        <inertial>
            <!--<origin xyz="0.081 0.016 -0.033" rpy="${pi/64} ${-pi/64} 0" />-->
            <origin xyz="0.075576 -0.013868 -0.035997" rpy="0 ${-pi/64} 0" />
            <mass value="0.312" />
            <inertia ixx="0.000320638" ixy="0.000010416" ixz="0.000013477" iyy="0.000978515" iyz="-0.000006347" izz="0.001270766" />
        </inertial>
        <visual>
            <origin xyz="0 0 0" rpy="0 0 0" />
            <geometry>
                <mesh filename="package://wolfgang_description/mesh/right_foot.stl" />
            </geometry>
            <material name="metal" />
        </visual>
        <xacro:if value="${fake_walk== False}">
            <!-- only active when fake_walk is off, to prevent collisions with ground -->
            <collision>
                <origin xyz="0 0 -0.012" rpy="0 0 0" />
                <geometry>
                    <mesh filename="package://wolfgang_description/mesh/collision/right_foot.stl" />
                </geometry>
            </collision>
        </xacro:if>
    </link>
    
    <link name="r_sole">
        <inertial>
          <origin xyz="0 0 0" rpy="0 0 0" />
          <mass value="0.01" />
          <inertia ixx="0" ixy="0" ixz="0" iyy="0" iyz="0" izz="0" />
        </inertial>
    </link>

    <link name="r_toe">
        <inertial>
          <origin xyz="0 0 0" rpy="0 0 0" />
          <mass value="0.01" />
          <inertia ixx="0" ixy="0" ixz="0" iyy="0" iyz="0" izz="0" />
        </inertial>
    </link>

    <link name="l_hip_1">
        <inertial>
            <!--<origin xyz="0 0 -0.011" rpy="0 0 0" />-->
            <origin xyz="-0.000001 0 -0.014563" rpy="0 0 0" />
            <mass value="0.098" />
            <inertia ixx="0.000013709" ixy="-0.000002388" ixz="-0.000000001" iyy="0.000054561" iyz="0" izz="0.000049167" />
        </inertial>
        <visual>
            <origin xyz="0 0 0" rpy="0 0 0" />
            <geometry>
                <mesh filename="package://wolfgang_description/mesh/hip_connector.stl"/>
            </geometry>
            <material name="metal" />    
        </visual>
        <collision>
            <origin xyz="0 0 0" rpy="0 0 0" />
            <geometry>
                <mesh filename="package://wolfgang_description/mesh/collision/hip_connector.stl" />
            </geometry>
        </collision>
    </link>

    <link name="l_hip_2">
         <inertial>
            <!--<origin xyz="0.046 -0.002 -0.026" rpy="0 ${pi/64} 0" />-->
            <origin xyz="0.051391 0.000232 -0.014250" rpy="0 ${pi/64} 0" />
            <mass value="0.349" />
            <inertia ixx="0.000156848" ixy="-0.000002134" ixz="-0.000005733" iyy="0.000355019" iyz="-0.000001749" izz="0.000308883" />
        </inertial>
        <visual>
            <origin xyz="0 0 0" rpy="0 0 0" />
            <geometry>
                <mesh filename="package://wolfgang_description/mesh/hip_link_2.stl" />
            </geometry>
            <material name="black" />
        </visual>
        <collision>
            <origin xyz="0 0 0" rpy="0 0 0" />
            <geometry>
                <mesh filename="package://wolfgang_description/mesh/collision/hip_link_2.stl" />
            </geometry>
        </collision>
    </link>

    <link name="l_upper_leg">
         <inertial>
            <!--<origin xyz="-0.0056 0.004 -0.126" rpy="0 0 0" />-->
            <origin xyz="0.004721 0.000424 -0.132759" rpy="0 0 0" />
            <mass value="0.248" />
            <inertia ixx="0.000660963" ixy="0.000000544" ixz="-0.000016736" iyy="0.000606384" iyz="-0.000004189" izz="0.000150136" />
        </inertial>
        <visual>
            <origin xyz="0 0 0" rpy="0 ${pi} 0" />
            <geometry>
                <mesh filename="package://wolfgang_description/mesh/upper_leg_carbon.stl" />
            </geometry>
            <material name="carbon" />
        </visual>
        <visual>
            <origin xyz="0 0 0" rpy="0 ${pi} 0" />
            <geometry>
                <mesh filename="package://wolfgang_description/mesh/upper_leg_motor.stl" />
            </geometry>
            <material name="black" />
        </visual>
        <visual>
            <origin xyz="0 0 0" rpy="0 ${pi} 0" />
            <geometry>
                <mesh filename="package://wolfgang_description/mesh/upper_leg_metal.stl" />
            </geometry>
            <material name="metal" />
        </visual>
        <collision>
            <origin xyz="0 0 0" rpy="0 ${pi} 0" />
            <geometry>
                <mesh filename="package://wolfgang_description/mesh/collision/upper_leg_carbon.stl" />
            </geometry>
        </collision>
        <collision>
            <origin xyz="0 0 0" rpy="0 ${pi} 0" />
            <geometry>
                <mesh filename="package://wolfgang_description/mesh/collision/upper_leg_metal.stl" />
            </geometry>
        </collision>
        <collision>
            <origin xyz="0 0 0" rpy="0 ${pi} 0" />
            <geometry>
                <mesh filename="package://wolfgang_description/mesh/collision/upper_leg_motor.stl" />
            </geometry>
        </collision>
    </link>

    <link name="l_lower_leg">
        <inertial>
            <!--<origin xyz="0.062 0 -0.045" rpy="0 ${-pi/4} 0" />-->
            <!-- gedreht um -45 grad-->
            <origin xyz="0.070129 -0.000102 -0.061824" rpy="0 ${-pi/4} 0" />
            <mass value="0.085" />
            <inertia ixx="0.000278504" ixy="0.000000060" ixz="-0.000004917" iyy="0.000241283" iyz="-0.000000066" izz="0.000070447" />
        </inertial>
        <visual>
            <origin xyz="0 0 0" rpy="0 ${-pi/4} 0" />
            <geometry>
                <mesh filename="package://wolfgang_description/mesh/lower_leg.stl" />
            </geometry>
            <material name="carbon" />
        </visual>
        <collision>
            <origin xyz="0 0 0" rpy="0 ${-pi/4} 0" />
            <geometry>
                <mesh filename="package://wolfgang_description/mesh/collision/lower_leg.stl" />
            </geometry>
        </collision>
    </link>

    <link name="l_ankle">
        <inertial>
            <!--<origin xyz="-0.02 -0.005 0.026" rpy="${-pi/64} ${-pi/32} ${-pi/64}" />-->
            <origin xyz="-0.017874 0.000190 0.013809" rpy="${-pi/64} ${-pi/32} ${-pi/64}" />
            <mass value="0.349" />
            <inertia ixx="0.000159124" ixy="-0.000001620" ixz="0.000011391" iyy="0.000355570" iyz="0.000001710" izz="0.000307157" />
        </inertial>
        <visual>
            <origin xyz="0 0 0" rpy="0 0 0" />
            <geometry>
                <mesh filename="package://wolfgang_description/mesh/ankle.stl" />
            </geometry>
            <material name="black" />
        </visual>
        <collision>
            <origin xyz="0 0 0" rpy="0 0 0" />
            <geometry>
                <mesh filename="package://wolfgang_description/mesh/collision/ankle.stl" />
            </geometry>
            <material name="metal" />
        </collision>
    </link>

    <link name="l_foot">
        <inertial>
            <!--<origin xyz="0.081 -0.016 -0.033" rpy="${-pi/64} ${-pi/64} 0" />-->
            <origin xyz="0.075576 0.013868 -0.035997" rpy="0 ${-pi/64} 0" />
            <mass value="0.312" />
            <inertia ixx="0.000320638" ixy="0.000010416" ixz="0.000013477" iyy="0.000978515" iyz="-0.000006347" izz="0.001270766" />
        </inertial>
        <visual>
            <origin xyz="0 0 0" rpy="0 0 0" />
            <geometry>
                <mesh filename="package://wolfgang_description/mesh/left_foot.stl" />
            </geometry>
            <material name="metal" />
        </visual>
        <xacro:if value="${fake_walk== False}">
        <!-- only active when fake_walk is off, to prevent collisions with ground -->
            <collision>
                <origin xyz="0 0 -0.012" rpy="0 0 0" />
                <geometry>
                    <mesh filename="package://wolfgang_description/mesh/collision/left_foot.stl" />
                </geometry>
            </collision>
        </xacro:if>
    </link>

    <link name="l_sole">
        <inertial>
          <origin xyz="0 0 0" rpy="0 0 0" />
          <mass value="0.01" />
          <inertia ixx="0" ixy="0" ixz="0" iyy="0" iyz="0" izz="0" />
        </inertial>
    </link>

    <link name="l_toe">
        <inertial>
          <origin xyz="0 0 0" rpy="0 0 0" />
          <mass value="0.01" />
          <inertia ixx="0" ixy="0" ixz="0" iyy="0" iyz="0" izz="0" />
        </inertial>
    </link>

    <link name="r_shoulder">
        <inertial>
            <!--<origin xyz="0.012 -0.02 0" rpy="0 ${-pi/8} 0" />-->
            <origin xyz="0.010164 -0.022268 -0.000376" rpy="0 ${-pi/8} 0" />
            <mass value="0.097" />
            <inertia ixx="0.000044153" ixy="-0.000000525" ixz="0.000015185" iyy="0.000086852" iyz="0.000000524" izz="0.000065734" />
            <!--<inertia ixx="0.000044153" ixy="0.000015185" ixz="-0.000000525" iyy="0.000065734" iyz="0.000000524" izz="0.000086852" />-->
        </inertial>
        <visual>
            <origin xyz="0 0 0" rpy="0 0 ${pi}" />
            <geometry>
                <mesh filename="package://wolfgang_description/mesh/shoulder.stl" />
            </geometry>
            <material name="metal" />
        </visual>
        <collision>
            <origin xyz="0 0 0" rpy="0 0 ${pi}" />
            <geometry>
                <mesh filename="package://wolfgang_description/mesh/collision/shoulder.stl" />
            </geometry>
        </collision>
    </link>

    <link name="r_upper_arm">
        <inertial>
            <!--<origin xyz="0 0 -0.031" rpy="0 0 0" />-->
            <origin xyz="0.000158 -0.000012 -0.035495" rpy="0 0 0" />
            <mass value="0.229" />
            <inertia ixx="0.000490959" ixy="-0.000000004" ixz="-0.000004117" iyy="0.000461542" iyz="-0.000000191" izz="0.000102122" />
        </inertial>
        <visual>
            <origin xyz="0 0 0" rpy="0 ${pi} 0" />
            <geometry>
                <mesh filename="package://wolfgang_description/mesh/upper_arm.stl" />
            </geometry>
            <material name="black" />
        </visual>
        <collision>
            <origin xyz="0 0 0" rpy="0 ${pi} 0" />
            <geometry>
                <mesh filename="package://wolfgang_description/mesh/collision/upper_arm.stl" />
            </geometry>
        </collision>
    </link>

    <link name="r_lower_arm">
        <inertial>
            <!--<origin xyz="0.055 0 0.001" rpy="${pi/8} 0 0" />-->
            <origin xyz="0.050639 -0.000164 0.000492" rpy="${pi/8} 0 0" />
            <mass value="0.208" />
            <inertia ixx="0.000085671" ixy="-0.000002277" ixz="0.000000392" iyy="0.000903139" iyz="0.000001021" izz="0.000904792" />
        </inertial>
        <visual>
            <origin xyz="0 0 0" rpy="0 0 0" />
            <geometry>
                <mesh filename="package://wolfgang_description/mesh/lower_arm.stl" />
            </geometry>
            <material name="black" />
        </visual>
        <collision>
            <origin xyz="0 0 0" rpy="0 0 0" />
            <geometry>
                <mesh filename="package://wolfgang_description/mesh/collision/lower_arm.stl" />
            </geometry>
        </collision>
    </link>

    <link name="r_wrist"> </link>    

    <link name="l_shoulder">
        <inertial>
            <!--<origin xyz="0.012 0.02 0" rpy="0 ${-pi/8} 0" />-->
            <origin xyz="0.010164 0.022268 -0.000376" rpy="0 ${-pi/8} 0" />
            <mass value="0.097" />
            <!--<inertia ixx="0.000044153" ixy="0.000015185" ixz="-0.000000525" iyy="0.000065734" iyz="0.000000524" izz="0.000086852" />-->
            <inertia ixx="0.000044153" ixy="-0.000000525" ixz="0.000015185" iyy="0.000086852" iyz="0.000000524" izz="0.000065734" />
        </inertial>
        <visual>
            <origin xyz="0 0 0" rpy="0 0 0" />
            <geometry>
                <mesh filename="package://wolfgang_description/mesh/shoulder.stl" />
            </geometry>
            <material name="metal" />
        </visual>
        <collision>
            <origin xyz="0 0 0" rpy="0 0 0" />
            <geometry>
                <mesh filename="package://wolfgang_description/mesh/collision/shoulder.stl" />
            </geometry>
        </collision>
    </link>

    <link name="l_upper_arm">
        <inertial>
            <!--<origin xyz="0 0 -0.031" rpy="0 0 0" />-->
            <origin xyz="0.000158 -0.000012 -0.035495" rpy="0 0 0" />
            <mass value="0.229" />
            <inertia ixx="0.000490959" ixy="-0.000000004" ixz="-0.000004117" iyy="0.000461542" iyz="-0.000000191" izz="0.000102122" />
        </inertial>
        <visual>
            <origin xyz="0 0 0" rpy="0 ${pi} 0" />
            <geometry>
                <mesh filename="package://wolfgang_description/mesh/upper_arm.stl" />
            </geometry>
            <material name="black" />
        </visual>
        <collision>
            <origin xyz="0 0 0" rpy="0 ${pi} 0" />
            <geometry>
                <mesh filename="package://wolfgang_description/mesh/collision/upper_arm.stl" />
            </geometry>
        </collision>
    </link>

    <link name="l_lower_arm">
       <inertial>
            <!--<origin xyz="0.055 0 0.001" rpy="${pi/8} 0 0" />-->
            <origin xyz="0.050639 -0.000164 0.000492" rpy="${pi/8} 0 0" />
            <mass value="0.208" />
            <inertia ixx="0.000085671" ixy="-0.000002277" ixz="0.000000392" iyy="0.000903139" iyz="0.000001021" izz="0.000904792" />
        </inertial>
        <visual>
            <origin xyz="0 0 0" rpy="0 0 0" />
            <geometry>
                <mesh filename="package://wolfgang_description/mesh/lower_arm.stl" />
            </geometry>
            <material name="black" />
        </visual>
        <collision>
            <origin xyz="0 0 0" rpy="0 0 0" />
            <geometry>
                <mesh filename="package://wolfgang_description/mesh/collision/lower_arm.stl" />
            </geometry>
        </collision>
    </link>

    <link name="l_wrist"> </link>

    <link name="neck">
        <inertial>
            <!--<origin xyz="0.0045 0 0.016" rpy="0 0 0" />-->
            <origin xyz="0.027758 0.000252 0.032356" rpy="0 0 0" />
            <xacro:if value="${fake_walk== True}">
                <mass value="0.00015587" />
            </xacro:if>            
            <xacro:if value="${fake_walk== False}">
                <mass value="0.153" />
            </xacro:if>            
            <inertia ixx="0.000072487" ixy="-0.000000033" ixz="0.000003661" iyy="0.000064592" iyz="0.000001234" izz="0.000044157" />
        </inertial>
        <visual>
            <origin xyz="0 0 0" rpy="0 0 ${pi}" />
            <geometry>
                <mesh filename="package://wolfgang_description/mesh/neck.stl" />
            </geometry>
            <material name="black" />
        </visual>
        <collision>
            <origin xyz="0 0 0" rpy="0 0 ${pi}" />
            <geometry>
                <mesh filename="package://wolfgang_description/mesh/collision/neck.stl" />
            </geometry>
        </collision>
    </link>
    <link name="camera" />
    <link name="camera_optical_frame"/>

    <link name="imu_frame" />

    <link name="l_cleat_l_front"/>
    <link name="l_cleat_r_front"/>
    <link name="l_cleat_l_back"/>
    <link name="l_cleat_r_back"/>
    <link name="r_cleat_l_front"/>
    <link name="r_cleat_r_front"/>
    <link name="r_cleat_l_back"/>
    <link name="r_cleat_r_back"/>

    <link name="head">
        <inertial>
            <!--<origin xyz="0.004 0 0.096" rpy="0 0 0" />-->
            <origin xyz="0.012794 -0.000380 0.100180" rpy="0 0 0" />
            <xacro:if value="${fake_walk== True}">
                <mass value="0.00040746" />
            </xacro:if>            
            <xacro:if value="${fake_walk== False}">   
                <mass value="0.110" />
            </xacro:if>             
            <inertia ixx="0.000216591" ixy="0.000001444" ixz="-0.000024793" iyy="0.000169162" iyz="0.000000772" izz="0.000081113" />
        </inertial>
        <visual>
            <origin xyz="0 0 0" rpy="0 0 0" />
            <geometry>
                <mesh filename="package://wolfgang_description/mesh/head.stl" />
            </geometry>
            <material name="black" />
        </visual>
        <collision>
            <origin xyz="0 0 0" rpy="0 0 0" />
            <geometry>
                <mesh filename="package://wolfgang_description/mesh/collision/head.stl" />
            </geometry>
        </collision>
    </link>



    <!-- JOINTS JOINTS JOINTS JOINTS JOINTS JOINTS JOINTS JOINTS JOINTS JOINTS --> 

    <joint name="RHipYaw" type="revolute">
        <origin xyz="0 -0.055 0" rpy="0 0 0" />
        <parent link="base_link" />
        <child link="r_hip_1" />
        <axis xyz="0 0 -1" />
        <limit effort="10.0" velocity="5,759586525" lower="-0.9250245035547" upper="0.9250245035547" />
        <dynamics damping="${d}" friction="${f}" />
    </joint>

    <joint name="RHipRoll" type="revolute">
        <origin xyz="-0.046 0 -0.042" rpy="0 0 0" />
        <parent link="r_hip_1" />
        <child link="r_hip_2" />
        <axis xyz="1 0 0" />
        <limit effort="10.0" velocity="5,759586525" lower="-1.57" upper="0.7853981633955001" />
        <dynamics damping="${d}" friction="${f}" />
    </joint>

    <joint name="RHipPitch" type="revolute">
        <origin xyz="0.0692 0 0" rpy="0 0 0" />
        <parent link="r_hip_2" />
        <child link="r_upper_leg" />
        <axis xyz="0 1 0" />
        <limit effort="10.0" velocity="5,759586525" lower="-1.919862177189" upper="0.48869219055720003" />
        <dynamics damping="${d}" friction="${f}" />
    </joint>

    <joint name="RKnee" type="revolute">
        <origin xyz="-0.004 0 -0.1692" rpy="0 ${pi/6} 0" />
        <parent link="r_upper_leg" />
        <child link="r_lower_leg" />
        <axis xyz="0 1 0" />
        <limit effort="10.0" velocity="4.712388975" lower="0" upper="2.268928027587" />
        <dynamics damping="${d}" friction="${f}" />
    </joint>

    <joint name="RAnklePitch" type="revolute">
        <origin xyz="0.120208 0 -0.120208" rpy="0 ${-pi/4} 0" />
        <parent link="r_lower_leg" />
        <child link="r_ankle" />
        <axis xyz="0 -1 0" />
        <limit effort="10.0" velocity="5,759586525" lower="-1.2391837689129" upper="1.6406094968706" />
        <dynamics damping="${d}" friction="${f}" />
    </joint>

    <joint name="RAnkleRoll" type="revolute">
        <origin xyz="-0.0692 0 0" rpy="0 0 0" />
        <parent link="r_ankle" />
        <child link="r_foot" />
        <axis xyz="-1 0 0" />
        <limit effort="10.0" velocity="5,759586525" lower="-1.4660765716716" upper="1.4660765716716" />
        <dynamics damping="${d}" friction="${f}" />
    </joint>

    <joint name="r_foot_to_sole" type="fixed">
        <origin xyz="0.083 -0.015 -0.039" rpy="0 0 0" /> 
        <parent link="r_foot" />
        <child link="r_sole" />
        <axis xyz="0 0 0" />
    </joint>

    <joint name="r_foot_to_toe" type="fixed">
        <origin xyz="0.1 0 0" rpy="0 0 0" />
        <parent link="r_sole" />
        <child link="r_toe" />
        <axis xyz="0 0 0" />
    </joint>

    <joint name="LHipYaw" type="revolute">
        <origin xyz="0 0.055 0" rpy="0 0 0" />
        <parent link="base_link" />
        <child link="l_hip_1" />
        <axis xyz="0 0 -1" />
        <limit effort="10.0" velocity="5,759586525" lower="-0.9250245035547" upper="0.9250245035547" />
        <dynamics damping="${d}" friction="${f}" />
    </joint>

    <joint name="LHipRoll" type="revolute">
        <origin xyz="-0.046 0 -0.042" rpy="0 0 0" />
        <parent link="l_hip_1" />
        <child link="l_hip_2" />
        <axis xyz="1 0 0" />
        <limit effort="10.0" velocity="5,759586525" lower="-0.7853981633955001" upper="1.57" />
        <dynamics damping="${d}" friction="${f}" />
    </joint>

    <joint name="LHipPitch" type="revolute">
        <origin xyz="0.0692 0 0" rpy="0 0 0" />
        <parent link="l_hip_2" />
        <child link="l_upper_leg" />
        <axis xyz="0 -1 0" />
        <limit effort="10.0" velocity="5,759586525" lower="-0.48869219055720003" upper="1.919862177189" />
        <dynamics damping="${d}" friction="${f}" />
    </joint>

    <joint name="LKnee" type="revolute">
        <origin xyz="-0.004 0 -0.1692" rpy="0 ${pi/6} 0" />
        <parent link="l_upper_leg" />
        <child link="l_lower_leg" />
        <axis xyz="0 -1 0" />
        <limit effort="10.0" velocity="5,759586525" lower="-2.268928027587" upper="0" />
        <dynamics damping="${d}" friction="${f}" />
    </joint>

    <joint name="LAnklePitch" type="revolute">
        <origin xyz="0.120208 0 -0.120208" rpy="0 ${-pi/4} 0" />
        <parent link="l_lower_leg" />
        <child link="l_ankle" />
        <axis xyz="0 1 0" />
        <limit effort="10.0" velocity="5,759586525" lower="-1.6406094968706" upper="1.2391837689129" />
        <dynamics damping="${d}" friction="${f}" />
    </joint>

    <joint name="LAnkleRoll" type="revolute">
        <origin xyz="-0.0692 0 0" rpy="0 0 0" />
        <parent link="l_ankle" />
        <child link="l_foot" />
        <axis xyz="-1 0 0" />
        <limit effort="10.0" velocity="5,759586525" lower="-1.4660765716716" upper="1.4660765716716" />
        <dynamics damping="${d}" friction="${f}" />
    </joint>

    <joint name="left_foot_to_sole" type="fixed">
        <origin xyz="0.083 0.015 -0.039" rpy="0 0 0" />
        <parent link="l_foot" />
        <child link="l_sole" />
        <axis xyz="0 0 0" />
    </joint>

    <joint name="left_foot_to_toe" type="fixed">
        <origin xyz="0.1 0 0" rpy="0 0 0" />
        <parent link="l_sole" />
        <child link="l_toe" />
        <axis xyz="0 0 0" />
    </joint>

    <joint name="base_link_to_torso" type="fixed">
        <parent link="base_link" />
        <child link="torso" />
        <origin rpy="0.0 0 0" xyz="0 0 0.0881" />
    </joint>

    <joint name="torso_to_imu" type="fixed">
        <parent link="torso" />
        <child link="imu_frame" />
        <origin rpy="0.0 0 0" xyz="-0.045 0.025 0.023" />
    </joint>

    <joint name="RShoulderPitch" type="revolute">
        <origin xyz="-0.0015 -0.076501 0.1155" rpy="0 0 0" />
        <parent link="torso" />
        <child link="r_shoulder" />
        <axis xyz="0 -1 0" />
        <limit effort="7.3" velocity="8.16814089" lower="-3.1415926535820002" upper="3.1415926535820002" />
        <dynamics damping="${d}" friction="${f}" />
    </joint>

    <joint name="RShoulderRoll" type="revolute">
        <origin xyz="0 -0.042 0" rpy="0 0 0" />
        <parent link="r_shoulder" />
        <child link="r_upper_arm" />
        <axis xyz="-1 0 0" />
        <limit effort="7.3" velocity="8.16814089" lower="-0.7853981633955001" upper="2.3561944901865" />
        <dynamics damping="${d}" friction="${f}" />
    </joint>

    <joint name="RElbow" type="revolute">
        <origin xyz="0 0 -0.144" rpy="0 0 0" />
        <parent link="r_upper_arm" />
        <child link="r_lower_arm" />
        <axis xyz="0 1 0" />
        <limit effort="7.3" velocity="8.16814089" lower="-1.635" upper="1.5707963267910001" />
        <dynamics damping="${d}" friction="${f}" />
    </joint>

    <joint name="r_elbow_to_wrist" type="fixed">
        <parent link="r_lower_arm" />
        <child link="r_wrist" />
        <origin xyz="0.225 0 0" rpy="0 0 0"/> 
    </joint>

    <joint name="LShoulderPitch" type="revolute">
        <origin xyz="-0.0015 0.076501 0.1155" rpy="0 0 0" />
        <parent link="torso" />
        <child link="l_shoulder" />
        <axis xyz="0 1 0" />
        <limit effort="7.3" velocity="8.16814089" lower="-3.1415926535820002" upper="3.1415926535820002" />
        <dynamics damping="${d}" friction="${f}" />
    </joint>

    <joint name="LShoulderRoll" type="revolute">
        <origin xyz="0 0.042 0" rpy="0 0 0" />
        <parent link="l_shoulder" />
        <child link="l_upper_arm" />
        <axis xyz="-1 0 0" />
        <limit effort="7.3" velocity="8.16814089" lower="-2.3561944901865" upper="0.7853981633955001" />
        <dynamics damping="${d}" friction="${f}" />
    </joint>

    <joint name="LElbow" type="revolute">
        <origin xyz="0 0 -0.144" rpy="0 0 0" />
        <parent link="l_upper_arm" />
        <child link="l_lower_arm" />
        <axis xyz="0 -1 0" />
        <limit effort="7.3" velocity="8.16814089" lower="-1.1344640137935" upper="1.5707963267910001" />
        <dynamics damping="${d}" friction="${f}" />
    </joint>

    <joint name="l_elbow_to_wrist" type="fixed">
        <parent link="l_lower_arm" />
        <child link="l_wrist" />
        <origin xyz="0.225 0 0" rpy="0 0 0"/>
    </joint>

    <joint name="HeadPan" type="revolute">
        <origin xyz="-0.0095 0 0.146501" rpy="0 0 0" />
        <parent link="torso" />
        <child link="neck" />
        <axis xyz="0 0 1" />
        <limit effort="7.3" velocity="8.16814089" lower="-1.2" upper="1.2" />
        <dynamics damping="${d}" friction="${f}" />
    </joint>

    <joint name="HeadTilt" type="revolute">
        <origin xyz="0.0286 0 0.0205" rpy="0 0 0" />
        <parent link="neck" />
        <child link="head" />
        <axis xyz="0 -1 0" />
        <limit effort="7.3" velocity="8.16814089" lower="-1.2" upper="0.2" />
        <dynamics damping="${d}" friction="${f}" />
    </joint>
    
    <joint name="head_to_camera" type="fixed">
        <origin xyz="0.02 0 0.1115" rpy="0 0 0" />
        <parent link="head" />
        <child link="camera" />
        <axis xyz="0 0 0" />
        <dynamics damping="${d}" friction="${f}" />
    </joint>
    
    <joint name="camera__optical_joint" type="fixed">
      <origin xyz="0 0 0" rpy="${-pi/2} 0 ${-pi/2}" />
      <parent link="camera" />
      <child link="camera_optical_frame" />
    </joint>

    <!-- left foot cleats -->
    <joint name="l_sole_to_l_cleat_l_front" type="fixed">
      <origin xyz="0.085 0.045 $(arg cleats)" rpy="0 0 0" />
      <parent link="l_sole" />
      <child link="l_cleat_l_front" />
    </joint>

    <joint name="l_sole_to_l_cleat_r_front" type="fixed">
      <origin xyz="0.085 -0.045 $(arg cleats)" rpy="0 0 0" />
      <parent link="l_sole" />
      <child link="l_cleat_r_front" />
    </joint>

    <joint name="l_sole_to_l_cleat_l_back" type="fixed">
      <origin xyz="-0.085 0.045 $(arg cleats)" rpy="0 0 0" />
      <parent link="l_sole" />
      <child link="l_cleat_l_back" />
    </joint>

    <joint name="l_sole_to_l_cleat_r_back" type="fixed">
      <origin xyz="-0.085 -0.045 $(arg cleats)" rpy="0 0 0" />
      <parent link="l_sole" />
      <child link="l_cleat_r_back" />
    </joint>

    <!-- right foot cleats -->
    <joint name="r_sole_to_r_cleat_l_front" type="fixed">
      <origin xyz="0.085 0.045 $(arg cleats)" rpy="0 0 0" />
      <parent link="r_sole" />
      <child link="r_cleat_l_front" />
    </joint>

    <joint name="r_sole_to_r_cleat_r_front" type="fixed">
      <origin xyz="0.085 -0.045 $(arg cleats)" rpy="0 0 0" />
      <parent link="r_sole" />
      <child link="r_cleat_r_front" />
    </joint>

    <joint name="r_sole_to_r_cleat_l_back" type="fixed">
      <origin xyz="-0.085 0.045 $(arg cleats)" rpy="0 0 0" />
      <parent link="r_sole" />
      <child link="r_cleat_l_back" />
    </joint>

    <joint name="r_sole_to_r_cleat_r_back" type="fixed">
      <origin xyz="-0.085 -0.045 $(arg cleats)" rpy="0 0 0" />
      <parent link="r_sole" />
      <child link="r_cleat_r_back" />
    </joint>

    <!-- TRANSMISSIONS TRANSMISSIONS TRANSMISSIONS TRANSMISSIONS TRANSMISSIONS TRANSMISSIONS TRANSMISSIONS -->

    <transmission name="HeadPanTransmission">
        <type>transmission_interface/SimpleTransmission</type>
        <joint name="HeadPan">
            <hardwareInterface>hardware_interface/EffortJointInterface</hardwareInterface>
        </joint>
        <actuator name="HeadPanMotor">
            <hardwareInterface>hardware_interface/EffortJointInterface</hardwareInterface>
            <mechanicalReduction>1</mechanicalReduction>
        </actuator>
    </transmission>
    <transmission name="HeadTiltTransmission">
        <type>transmission_interface/SimpleTransmission</type>
        <joint name="HeadTilt">
            <hardwareInterface>hardware_interface/EffortJointInterface</hardwareInterface>
        </joint>
        <actuator name="HeadTiltMotor">
            <hardwareInterface>hardware_interface/EffortJointInterface</hardwareInterface>
            <mechanicalReduction>1</mechanicalReduction>
        </actuator>
    </transmission>
    <transmission name="LShoulderPitchTransmission">
        <type>transmission_interface/SimpleTransmission</type>
        <joint name="LShoulderPitch">
            <hardwareInterface>hardware_interface/EffortJointInterface</hardwareInterface>
        </joint>
        <actuator name="LShoulderPitchMotor">
            <hardwareInterface>hardware_interface/EffortJointInterface</hardwareInterface>
            <mechanicalReduction>1</mechanicalReduction>
        </actuator>
    </transmission>
    <transmission name="LShoulderRollTransmission">
        <type>transmission_interface/SimpleTransmission</type>
        <joint name="LShoulderRoll">
            <hardwareInterface>hardware_interface/EffortJointInterface</hardwareInterface>
        </joint>
        <actuator name="LShoulderRollTransmission">
            <hardwareInterface>hardware_interface/EffortJointInterface</hardwareInterface>
            <mechanicalReduction>1</mechanicalReduction>
        </actuator>
    </transmission>
    <transmission name="LElbowTransmission">
        <type>transmission_interface/SimpleTransmission</type>
        <joint name="LElbow">
            <hardwareInterface>hardware_interface/EffortJointInterface</hardwareInterface>
        </joint>
        <actuator name="LElbowMotor">
            <hardwareInterface>hardware_interface/EffortJointInterface</hardwareInterface>
            <mechanicalReduction>1</mechanicalReduction>
        </actuator>
    </transmission>
    <transmission name="RShoulderPitchTransmission">
        <type>transmission_interface/SimpleTransmission</type>
        <joint name="RShoulderPitch">
            <hardwareInterface>hardware_interface/EffortJointInterface</hardwareInterface>
        </joint>
        <actuator name="RShoulderPitchMotor">
            <hardwareInterface>hardware_interface/EffortJointInterface</hardwareInterface>
            <mechanicalReduction>1</mechanicalReduction>
        </actuator>
    </transmission>
    <transmission name="RShoulderRollTransmission">
        <type>transmission_interface/SimpleTransmission</type>
        <joint name="RShoulderRoll">
            <hardwareInterface>hardware_interface/EffortJointInterface</hardwareInterface>
        </joint>
        <actuator name="RShoulderRollMotor">
            <hardwareInterface>hardware_interface/EffortJointInterface</hardwareInterface>
            <mechanicalReduction>1</mechanicalReduction>
        </actuator>
    </transmission>
    <transmission name="RElbowTransmission">
        <type>transmission_interface/SimpleTransmission</type>
        <joint name="RElbow">
            <hardwareInterface>hardware_interface/EffortJointInterface</hardwareInterface>
        </joint>
        <actuator name="RElbowMotor">
            <hardwareInterface>hardware_interface/EffortJointInterface</hardwareInterface>
            <mechanicalReduction>1</mechanicalReduction>
        </actuator>
    </transmission>
    <transmission name="LHipYawTransmission">
        <type>transmission_interface/SimpleTransmission</type>
        <joint name="LHipYaw">
            <hardwareInterface>hardware_interface/EffortJointInterface</hardwareInterface>
        </joint>
        <actuator name="LHipYawMotor">
            <hardwareInterface>hardware_interface/EffortJointInterface</hardwareInterface>
            <mechanicalReduction>1</mechanicalReduction>
        </actuator>
    </transmission>
    <transmission name="LHipRollTransmission">
        <type>transmission_interface/SimpleTransmission</type>
        <joint name="LHipRoll">
            <hardwareInterface>hardware_interface/EffortJointInterface</hardwareInterface>
        </joint>
        <actuator name="LHipRollMotor">
            <hardwareInterface>hardware_interface/EffortJointInterface</hardwareInterface>
            <mechanicalReduction>1</mechanicalReduction>
        </actuator>
    </transmission>
    <transmission name="LHipPitchTransmission">
        <type>transmission_interface/SimpleTransmission</type>
        <joint name="LHipPitch">
            <hardwareInterface>hardware_interface/EffortJointInterface</hardwareInterface>
        </joint>
        <actuator name="LHipPitchMotor">
            <hardwareInterface>hardware_interface/EffortJointInterface</hardwareInterface>
            <mechanicalReduction>1</mechanicalReduction>
        </actuator>
    </transmission>
    <transmission name="LKneeTransmission">
        <type>transmission_interface/SimpleTransmission</type>
        <joint name="LKnee">
            <hardwareInterface>hardware_interface/EffortJointInterface</hardwareInterface>
        </joint>
        <actuator name="LKneeMotor">
            <hardwareInterface>hardware_interface/EffortJointInterface</hardwareInterface>
            <mechanicalReduction>1</mechanicalReduction>
        </actuator>
    </transmission>
    <transmission name="LAnklePitchTransmission">
        <type>transmission_interface/SimpleTransmission</type>
        <joint name="LAnklePitch">
            <hardwareInterface>hardware_interface/EffortJointInterface</hardwareInterface>
        </joint>
        <actuator name="LAnklePitchMotor">
            <hardwareInterface>hardware_interface/EffortJointInterface</hardwareInterface>
            <mechanicalReduction>1</mechanicalReduction>
        </actuator>
    </transmission>
    <transmission name="LAnkleRollTransmission">
        <type>transmission_interface/SimpleTransmission</type>
        <joint name="LAnkleRoll">
            <hardwareInterface>hardware_interface/EffortJointInterface</hardwareInterface>
        </joint>
        <actuator name="LAnkleRollMotor">
            <hardwareInterface>hardware_interface/EffortJointInterface</hardwareInterface>
            <mechanicalReduction>1</mechanicalReduction>
        </actuator>
    </transmission>
    <transmission name="RHipYawTransmission">
        <type>transmission_interface/SimpleTransmission</type>
        <joint name="RHipYaw">
            <hardwareInterface>hardware_interface/EffortJointInterface</hardwareInterface>
        </joint>
        <actuator name="RHipYawMotor">
            <hardwareInterface>hardware_interface/EffortJointInterface</hardwareInterface>
            <mechanicalReduction>1</mechanicalReduction>
        </actuator>
    </transmission>
    <transmission name="RHipRollTransmission">
        <type>transmission_interface/SimpleTransmission</type>
        <joint name="RHipRoll">
            <hardwareInterface>hardware_interface/EffortJointInterface</hardwareInterface>
        </joint>
        <actuator name="RHipRollMotor">
            <hardwareInterface>hardware_interface/EffortJointInterface</hardwareInterface>
            <mechanicalReduction>1</mechanicalReduction>
        </actuator>
    </transmission>
    <transmission name="RHipPitchTransmission">
        <type>transmission_interface/SimpleTransmission</type>
        <joint name="RHipPitch">
            <hardwareInterface>hardware_interface/EffortJointInterface</hardwareInterface>
        </joint>
        <actuator name="RHipPitchMotor">
            <hardwareInterface>hardware_interface/EffortJointInterface</hardwareInterface>
            <mechanicalReduction>1</mechanicalReduction>
        </actuator>
    </transmission>
    <transmission name="RKneeTransmission">
        <type>transmission_interface/SimpleTransmission</type>
        <joint name="RKnee">
            <hardwareInterface>hardware_interface/EffortJointInterface</hardwareInterface>
        </joint>
        <actuator name="RKneeMotor">
            <hardwareInterface>hardware_interface/EffortJointInterface</hardwareInterface>
            <mechanicalReduction>1</mechanicalReduction>
        </actuator>
    </transmission>
    <transmission name="RAnklePitchTransmission">
        <type>transmission_interface/SimpleTransmission</type>
        <joint name="RAnklePitch">
            <hardwareInterface>hardware_interface/EffortJointInterface</hardwareInterface>
        </joint>
        <actuator name="RAnklePitchMotor">
            <hardwareInterface>hardware_interface/EffortJointInterface</hardwareInterface>
            <mechanicalReduction>1</mechanicalReduction>
        </actuator>
    </transmission>
    <transmission name="RAnkleRollTransmission">
        <type>transmission_interface/SimpleTransmission</type>
        <joint name="RAnkleRoll">
            <hardwareInterface>hardware_interface/EffortJointInterface</hardwareInterface>
        </joint>
        <actuator name="RAnkleRollMotor">
            <hardwareInterface>hardware_interface/EffortJointInterface</hardwareInterface>
            <mechanicalReduction>1</mechanicalReduction>
        </actuator>
    </transmission>

    <gazebo reference="r_foot">
        <material>gazebo/Grey</material>
        <kp>1000000.0</kp>
        <kd>100.0</kd>
        <mu1>1.0</mu1>
        <mu2>1.0</mu2>
        <fdir1>1 0 0</fdir1>
        <maxVel>1.0</maxVel>
        <minDepth>0.00</minDepth>
    </gazebo>
    <gazebo reference="l_foot">
        <material>gazebo/Grey</material>
        <kp>1000000.0</kp>
        <kd>100.0</kd>
        <mu1>1.0</mu1>
        <mu2>1.0</mu2>
        <fdir1>1 0 0</fdir1>
        <maxVel>1.0</maxVel>
        <minDepth>0.00</minDepth>
    </gazebo>

  <!-- joint controller -->
    <gazebo>
        <plugin filename="libgazebo_ros_control.so" name="gazebo_ros_control">
            <robotNamespace>$(arg sim_ns)</robotNamespace>
        </plugin>
    </gazebo>

  <!-- camera sensor -->
  <gazebo reference="camera">
        <sensor name='camera' type='camera'>
          <pose>-0.050000 -0.010000 0.000000 -1.5708 0.000000 -3.141592</pose>
          <camera name='__default__'>
            <horizontal_fov>1.012300</horizontal_fov>
            <image>
              <width>800</width>
              <height>600</height>
            </image>
            <clip>
              <near>0.001000</near>
              <far>100.000000</far>
            </clip>
          </camera>
          <always_on>1</always_on>
          <update_rate>30.000000</update_rate>
          <visualize>1</visualize>
          <plugin name="camera_controller" filename="libgazebo_ros_camera.so">
            <alwaysOn>true</alwaysOn>
            <updateRate>30</updateRate>
            <cameraName>camera</cameraName>
            <imageTopicName>image_raw</imageTopicName>
            <cameraInfoTopicName>camera_info</cameraInfoTopicName>
            <frameName>camera_optical_frame</frameName>
            <hackBaseline>0.07</hackBaseline>
            <distortionK1>0.0</distortionK1>
            <distortionK2>0.0</distortionK2>
            <distortionK3>0.0</distortionK3>
            <distortionT1>0.0</distortionT1>
            <distortionT2>0.0</distortionT2>
          </plugin>
      </sensor>
  </gazebo>


   <!-- IMU sensor -->
   <gazebo reference="L_IMU">
    <gravity>true</gravity>
    <sensor name="imu_sensor" type="imu">
      <always_on>true</always_on>
      <update_rate>100</update_rate>
      <visualize>true</visualize>
      <topic>__default_topic__</topic>
      <plugin filename="libgazebo_ros_imu_sensor.so" name="imu_plugin">
        <topicName>imu</topicName>
        <bodyName>torso</bodyName>
        <updateRateHZ>100.0</updateRateHZ>
        <gaussianNoise>0.0</gaussianNoise>
        <xyzOffset>0 0 0</xyzOffset>
        <rpyOffset>0 0 0</rpyOffset>
        <frameName>imu</frameName>
      </plugin>
      <pose>0 0 0 0 0 0</pose>
    </sensor>
  </gazebo>

   <!-- fake controller that allows us to move the robot and to get its oposition -->
   <!-- rostopic pub /cmd_vel geometry_msgs/Twist "{ linear: [ 0.1, 0, 0], angular: [0.2, 0, 0.1] }" -->
   <xacro:if value="${fake_walk == True}">
   <!-- only active when fake_walk param is set to True -->
    <gazebo>
        <plugin name="object_controller" filename="libgazebo_ros_planar_move.so">
        <robotNamespace>/</robotNamespace>

        <commandTopic>cmd_vel</commandTopic>
        <odometryTopic>odom</odometryTopic>
        <odometryFrame>odom</odometryFrame>
        <odometryRate>100.0</odometryRate>
        <robotBaseFrame>base_link</robotBaseFrame>
        </plugin>
    </gazebo>
    </xacro:if>
</robot>

