<?xml version="1.0" encoding="utf-8"?>

<robot name="x2">
  <mujoco>
    <compiler meshdir="./meshes" discardvisual="false" />
  </mujoco>


  <!-- [CAUTION] uncomment when convert to mujoco -->
  <!--<link name="world"></link>
  <joint name="pelvis_link" type="floating">
    <parent link="world" />
    <child link="pelvis_link" />
  </joint>  -->

  <link name="pelvis_link">
    <inertial>
      <origin xyz="-0.0000717 0.0001443 -0.0195866" rpy="0 0 0" />
      <mass value="0.5786" />
      <inertia ixx="0.0004533504" ixy="-0.0000000581" ixz="-0.0000006777" iyy="0.0004080524" iyz="0.0000027471" izz="0.0005122071" />
    </inertial>
    <visual>
      <origin xyz="0 0 0" rpy="0 0 0" />
      <geometry>
        <mesh filename="package://x02_description/urdf/meshes/pelvis_link.STL" />
      </geometry>
      <material name="">
        <color rgba="1 1 1 1" />
      </material>
    </visual>
    <collision>
    <origin xyz="0 0 0" rpy="0 0 0" />
    <geometry>
      <mesh filename="package://x02_description/urdf/meshes/pelvis_link.STL" />
    </geometry>
    </collision>
  </link>
  <link name="L_hip_yaw_link">
    <inertial>
      <origin xyz="0.001115 0.049187 -0.051444" rpy="0 0 0" />
      <mass value="1.758" />
      <inertia ixx="0.004988888" ixy="0.000039059" ixz="-0.000005421" iyy="0.002479734" iyz="-0.0001035324" izz="0.003849267" />
    </inertial>
    <visual>
      <origin xyz="0 0 0" rpy="0 0 0" />
      <geometry>
        <mesh filename="package://x02_description/urdf/meshes/L_hip_yaw_link.STL" />
      </geometry>
      <material name="">
        <color rgba="0.898039215686275 0.917647058823529 0.929411764705882 1" />
      </material>
    </visual>
    <collision>
    <origin xyz="0 0 0" rpy="0 0 0" />
    <geometry>
      <mesh filename="package://x02_description/urdf/meshes/L_hip_yaw_link.STL" />
    </geometry>
    </collision>
  </link>
  <joint name="LHipYaw" type="revolute">
    <origin xyz="0 0 -0.06" rpy="0 0 0" />
    <parent link="pelvis_link" />
    <child link="L_hip_yaw_link" />
    <axis xyz="0 0 1" />
    <limit lower="-0.55" upper="0.55" effort="50" velocity="10.472"/>
  </joint>
  <link name="L_hip_roll_link">
    <inertial>
      <origin xyz="-0.03247252 0.00017925 -0.07264839" rpy="0 0 0" />
      <mass value="2.667" />
      <inertia ixx="0.007970422" ixy="-0.00001767" ixz="0.00171027" iyy="0.01086223" iyz="-0.00001804" izz="0.00754180" />
    </inertial>
    <visual>
      <origin xyz="0 0 0" rpy="0 0 0" />
      <geometry>
        <mesh filename="package://x02_description/urdf/meshes/L_hip_roll_link.STL" />
      </geometry>
      <material name="">
        <color rgba="1 1 1 1" />
      </material>
    </visual>
    <collision>
      <origin xyz="0 0 0" rpy="0 0 0" />
      <geometry>
        <mesh filename="package://x02_description/urdf/meshes/L_hip_roll_link.STL" />
      </geometry>
    </collision>
  </link>
  <joint name="LHipRoll" type="revolute">
    <origin xyz="-0.0095 0.1 -0.0474" rpy="0 0 0" />
    <parent link="L_hip_yaw_link" />
    <child link="L_hip_roll_link" />
    <axis xyz="1 0 0" />
    <limit lower="-0.35" upper="0.524" effort="50" velocity="10.471975511965978"/>
  </joint>
  <link name="L_hip_pitch_link">
    <inertial>
      <origin xyz="0.00382921 0 -0.18548450" rpy="0 0 0" />
      <mass value="1.664" />
      <inertia ixx="0.01443710" ixy="0.00000000" ixz="-0.00089513" iyy="0.01484426" iyz="-0.00000003" izz="0.00315739" />
    </inertial>
    <visual>
      <origin xyz="0 0 0" rpy="0 0 0" />
      <geometry>
        <mesh filename="package://x02_description/urdf/meshes/L_hip_pitch_link.STL" />
      </geometry>
      <material name="">
        <color rgba="1 1 1 1" />
      </material>
    </visual>
    <collision>
      <origin xyz="0 0 0" rpy="0 0 0" />
      <geometry>
        <mesh filename="package://x02_description/urdf/meshes/L_hip_pitch_link.STL" />
      </geometry>
    </collision>
  </link>
  <joint name="LHipPitch" type="revolute">
    <origin xyz="0.0085 0 -0.11" rpy="0 0 0" />
    <parent link="L_hip_roll_link" />
    <child link="L_hip_pitch_link" />
    <axis xyz="0 -1 0" />
    <limit lower="-0.45" upper="2.076" effort="72" velocity="9.163"/>
  </joint>
  <link name="L_knee_pitch_link">
    <inertial>
      <origin xyz="0.00140265 0 -0.15875986" rpy="0 0 0" />
      <mass value="1.125" />
      <inertia ixx="0.00985892" ixy="0.00000000" ixz="0.00035856" iyy="0.00999859" iyz="-0.00000003" izz="0.00102379" />
    </inertial>
    <visual>
      <origin xyz="0 0 0" rpy="0 0 0" />
      <geometry>
        <mesh filename="package://x02_description/urdf/meshes/L_knee_pitch_link.STL" />
      </geometry>
      <material name="">
        <color rgba="1 1 1 1" />
      </material>
    </visual>
    <collision>
      <origin xyz="0 0 0" rpy="0 0 0" />
      <geometry>
        <mesh filename="package://x02_description/urdf/meshes/L_knee_pitch_link.STL" />
      </geometry>
    </collision>
  </link>
  <joint name="LKnee" type="revolute">
    <origin xyz="0 0 -0.35" rpy="0 0 0" />
    <parent link="L_hip_pitch_link" />
    <child link="L_knee_pitch_link" />
    <axis xyz="0 -1 0" />
    <limit lower="-2.216" upper="0.016" effort="60" velocity="7.3304"/>
  </joint>
  <link name="L_ankle_pitch_link">
    <inertial>
      <origin xyz="0.0393987623680991 -0.000237277713772188 -0.0784143417886232" rpy="0 0 0" />
      <mass value="0.556154115746433" />
      <inertia ixx="0.00032584056406277" ixy="-3.52704729229917E-06" ixz="-3.15470198590693E-05" iyy="0.00243296196329658" iyz="3.92516794179968E-07" izz="0.00260484732439791" />
      <!--      <inertia ixx="0.01" ixy="0" ixz="-2.9E-06" iyy="0.01" iyz="0" izz="0.01"/>-->
    </inertial>
    <visual>
      <origin xyz="0 0 0" rpy="0 0 0" />
      <geometry>
        <mesh filename="package://x02_description/urdf/meshes/L_ankle_pitch_link.STL" />
      </geometry>
      <material name="">
        <color rgba="1 1 1 1" />
      </material>
    </visual>
        <collision>
      <origin xyz="-0.095 0.0 -0.087" rpy="0 0 0"/>
      <geometry>
        <sphere radius="0.005"/>
      </geometry>
    </collision>
    <collision>
      <origin xyz="-0.052 0.026 -0.087" rpy="0 0 0"/>
      <geometry>
        <sphere radius="0.005"/>
      </geometry>
    </collision>
    <collision>
      <origin xyz="-0.052 -0.028 -0.087" rpy="0 0 0"/>
      <geometry>
        <sphere radius="0.005"/>
      </geometry>
    </collision>
    <collision>
      <origin xyz="0.075 0.038 -0.087" rpy="0 0 0"/>
      <geometry>
        <sphere radius="0.005"/>
      </geometry>
    </collision>
    <collision>
      <origin xyz="0.075 -0.038 -0.087" rpy="0 0 0"/>
      <geometry>
        <sphere radius="0.005"/>
      </geometry>
    </collision>
    <collision>
      <origin xyz="0.136 -0.00 -0.087" rpy="0 0 0"/>
      <geometry>
        <sphere radius="0.005"/>
      </geometry>
    </collision>
  </link>
  <joint name="LAnklePitch" type="revolute">
    <origin xyz="0 0 -0.35" rpy="0 0 0" />
    <parent link="L_knee_pitch_link" />
    <child link="L_ankle_pitch_link" />
    <axis xyz="0 -1 0" />
    <limit lower="-1.14" upper="1.128" effort="30" velocity="10" />
  </joint>
  <link name="R_hip_yaw_link">
    <inertial>
      <origin xyz="0.001115 -0.049187 0.001444" rpy="0 0 0" />
      <mass value="0.907" />
      <inertia ixx="0.002067018" ixy="-0.000035043" ixz="-0.000000909" iyy="0.000567723" iyz="0.000020295" izz="0.002016525" />
    </inertial>
    <visual>
      <origin xyz="0 0 0" rpy="0 0 0" />
      <geometry>
        <mesh filename="package://x02_description/urdf/meshes/R_hip_yaw_link.STL" />
      </geometry>
      <material name="">
        <color rgba="0.898039215686275 0.917647058823529 0.929411764705882 1" />
      </material>
    </visual>
    <collision>
    <origin xyz="0 0 0" rpy="0 0 0" />
    <geometry>
      <mesh filename="package://x02_description/urdf/meshes/R_hip_yaw_link.STL" />
    </geometry>
    </collision>
  </link>
  <joint name="RHipYaw" type="revolute">
    <origin xyz="0 0 -0.1074" rpy="0 0 0" />
    <parent link="pelvis_link" />
    <child link="R_hip_yaw_link" />
    <axis xyz="0 0 -1" />
    <limit lower="-0.55" upper="0.55" effort="50" velocity="10.472"/>
  </joint>
  <link name="R_hip_roll_link">
    <inertial>
      <origin xyz="-0.03247252 0.00017925 -0.07264839" rpy="0 0 0" />
      <mass value="2.667" />
      <inertia ixx="0.007970422" ixy="-0.00001767" ixz="0.00171027" iyy="0.01086223" iyz="-0.00001804" izz="0.00754180" />
    </inertial>
    <visual>
      <origin xyz="0 0 0" rpy="0 0 0" />
      <geometry>
        <mesh filename="package://x02_description/urdf/meshes/R_hip_roll_link.STL" />
      </geometry>
      <material name="">
        <color rgba="1 1 1 1" />
      </material>
    </visual>
    <collision>
      <origin xyz="0 0 0" rpy="0 0 0" />
      <geometry>
        <mesh filename="package://x02_description/urdf/meshes/R_hip_roll_link.STL" />
      </geometry>
    </collision>
  </link>
  <joint name="RHipRoll" type="revolute">
    <origin xyz="-0.0095 -0.1 0" rpy="0 0 0" />
    <parent link="R_hip_yaw_link" />
    <child link="R_hip_roll_link" />
    <axis xyz="-1 0 0" />
    <limit lower="-0.35" upper="0.524" effort="50" velocity="10.472"/>
  </joint>
  <link name="R_hip_pitch_link">
    <inertial>
      <origin xyz="0.00382921 0 -0.1854850" rpy="0 0 0" />
      <mass value="1.664" />
      <inertia ixx="0.01443710" ixy="-0.00000000" ixz="-0.00089513" iyy="0.01484426" iyz="0.00000003" izz="0.00315739" />
    </inertial>
    <visual>
      <origin xyz="0 0 0" rpy="0 0 0" />
      <geometry>
        <mesh filename="package://x02_description/urdf/meshes/R_hip_pitch_link.STL" />
      </geometry>
      <material name="">
        <color rgba="1 1 1 1" />
      </material>
    </visual>
    <collision>
      <origin xyz="0 0 0" rpy="0 0 0" />
      <geometry>
        <mesh filename="package://x02_description/urdf/meshes/R_hip_pitch_link.STL" />
      </geometry>
    </collision>
  </link>
  <joint name="RHipPitch" type="revolute">
    <origin xyz="0.0085 0 -0.11" rpy="0 0 0" />
    <parent link="R_hip_roll_link" />
    <child link="R_hip_pitch_link" />
    <axis xyz="0 -1 0" />
    <limit lower="-0.45" upper="2.076" effort="72" velocity="9.163"/>
  </joint>
  <link name="R_knee_pitch_link">
    <inertial>
      <origin xyz="0.00140265 0 -0.15875986" rpy="0 0 0" />
      <mass value="1.125" />
      <inertia ixx="0.00985892" ixy="-0.00000000" ixz="0.00035856" iyy="0.00999859" iyz="0.00000003" izz="0.00102379" />
    </inertial>
    <visual>
      <origin xyz="0 0 0" rpy="0 0 0" />
      <geometry>
        <mesh filename="package://x02_description/urdf/meshes/R_knee_pitch_link.STL" />
      </geometry>
      <material name="">
        <color rgba="1 1 1 1" />
      </material>
    </visual>
    <collision>
      <origin xyz="0 0 0" rpy="0 0 0" />
      <geometry>
        <mesh filename="package://x02_description/urdf/meshes/R_knee_pitch_link.STL" />
      </geometry>
    </collision>
  </link>
  <joint name="RKnee" type="revolute">
    <origin xyz="0 0 -0.35" rpy="0 0 0" />
    <parent link="R_hip_pitch_link" />
    <child link="R_knee_pitch_link" />
    <axis xyz="0 -1 0" />
   <limit lower="-2.216" upper="0.016" effort="60" velocity="7.3304"/>
  </joint>
  <link name="R_ankle_pitch_link">
    <inertial>
      <origin xyz="0.0393998134614837 0.000237080400869755 -0.078414481781949" rpy="0 0 0" />
      <mass value="0.556160945494453" />
      <inertia ixx="0.00032584056406277" ixy="3.52704729229917E-06" ixz="-3.15470198590693E-05" iyy="0.00243296196329658" iyz="-3.92516794179968E-07" izz="0.00260484732439791" />
      <!--      <inertia ixx="0.01" ixy="0" ixz="-2.9E-06" iyy="0.01" iyz="0" izz="0.01"/>-->
    </inertial>
    <visual>
      <origin xyz="0 0 0" rpy="0 0 0" />
      <geometry>
        <mesh filename="package://x02_description/urdf/meshes/R_ankle_pitch_link.STL" />
      </geometry>
      <material name="">
        <color rgba="1 1 1 1" />
      </material>
    </visual>
    <collision>
      <origin xyz="-0.095 0.0 -0.087" rpy="0 0 0"/>
      <geometry>
        <sphere radius="0.005"/>
      </geometry>
    </collision>
    <collision>
      <origin xyz="-0.052 0.028 -0.087" rpy="0 0 0"/>
      <geometry>
        <sphere radius="0.005"/>
      </geometry>
    </collision>
    <collision>
      <origin xyz="-0.052 -0.026 -0.087" rpy="0 0 0"/>
      <geometry>
        <sphere radius="0.005"/>
      </geometry>
    </collision>
    <collision>
      <origin xyz="0.075 0.038 -0.087" rpy="0 0 0"/>
      <geometry>
        <sphere radius="0.005"/>
      </geometry>
    </collision>
    <collision>
      <origin xyz="0.075 -0.038 -0.087" rpy="0 0 0"/>
      <geometry>
        <sphere radius="0.005"/>
      </geometry>
    </collision>
    <collision>
      <origin xyz="0.136 -0.00 -0.087" rpy="0 0 0"/>
      <geometry>
        <sphere radius="0.005"/>
      </geometry>
    </collision>
  </link>
  <joint name="RAnklePitch" type="revolute">
    <origin xyz="0 0 -0.35" rpy="0 0 0" />
    <parent link="R_knee_pitch_link" />
    <child link="R_ankle_pitch_link" />
    <axis xyz="0 -1 0" />
    <limit lower="-1.14" upper="1.128" effort="30" velocity="10" />
  </joint>
  <link name="base_link">
    <inertial>
      <origin xyz="0.0031437 0.0003242 0.1851956" rpy="0 0 0" />
      <mass value="9.2618" />
      <inertia ixx="0.1425570539" ixy="-0.0002470731" ixz="-0.0010896186" iyy="0.1131721333" iyz="0.0002687928" izz="0.0741723374" />
    </inertial>
    <visual>
      <origin xyz="0 0 0" rpy="0 0 0" />
      <geometry>
        <mesh filename="package://x02_description/urdf/meshes/torso_link.STL" />
      </geometry>
      <material name="">
        <color rgba="0.823529411764706 0.823529411764706 0.823529411764706 1" />
      </material>
    </visual>
    <collision>
      <origin xyz="0 0 0" rpy="0 0 0" />
      <geometry>
        <mesh filename="package://x02_description/urdf/meshes/torso_link.STL" />
      </geometry>
    </collision>
  </link>
  <joint name="torso" type="fixed">
    <origin xyz="0 0 0" rpy="0 0 0" />
    <parent link="pelvis_link" />
    <child link="base_link" />
    <axis xyz="0 0 1" />
    <limit lower="-1" upper="1" effort="50" velocity="10.471975511965978"/>
  </joint>
  <link name="logo_link">
    <inertial>
      <origin xyz="0.0780100780349841 0.000141230703059829 0.212276372633898" rpy="0 0 0" />
      <mass value="0.00512067007990884" />
      <inertia ixx="1.26286978002528E-06" ixy="-5.85012656774689E-11" ixz="4.38730918441945E-07" iyy="1.09931895773858E-06" iyz="5.41542411728218E-10" izz="9.49430143120174E-07" />
    </inertial>
    <visual>
      <origin xyz="0 0 0" rpy="0 0 0" />
      <geometry>
        <mesh filename="package://x02_description/urdf/meshes/logo_link.STL" />
      </geometry>
      <material name="">
        <color rgba="1 0 0 1" />
      </material>
    </visual>
    <collision>
      <origin xyz="0 0 0" rpy="0 0 0" />
      <geometry>
        <mesh filename="package://x02_description/urdf/meshes/logo_link.STL" />
      </geometry>
    </collision>
  </link>
  <joint name="logo" type="fixed">
    <origin xyz="0 0 0" rpy="0 0 0" />
    <parent link="base_link" />
    <child link="logo_link" />
    <axis xyz="0 0 0" />
  </joint>
  <link name="head_link">
    <inertial>
      <origin xyz="0.01547561 0 0.16472894" rpy="0 0 0" />
      <mass value="1.67" />
      <inertia ixx="0.00882503" ixy="0.00000000" ixz="0.00010108" iyy="0.01008134" iyz="0.00000000" izz="0.00524807" />
    </inertial>
    <visual>
      <origin xyz="0 0 0" rpy="0 0 0" />
      <geometry>
        <mesh filename="package://x02_description/urdf/meshes/head_link.STL" />
      </geometry>
      <material name="">
        <color rgba="1 1 1 1" />
      </material>
    </visual>
    <collision>
      <origin xyz="0 0 0" rpy="0 0 0" />
      <geometry>
        <mesh filename="package://x02_description/urdf/meshes/head_link.STL" />
      </geometry>
    </collision>
  </link>
  <joint name="head_joint" type="fixed">
    <origin xyz="0 0 0.3645" rpy="0 0 0" />
    <parent link="base_link" />
    <child link="head_link" />
    <axis xyz="0 0 1" />
    <limit lower="-1.571" upper="1.571" effort="50" velocity="5" />
  </joint>
  <link name="L_shoulder_pitch_link">
    <inertial>
      <origin xyz="0.000994 0.000135 0.015061" rpy="0 0 0" />
      <mass value="0.3" />
      <inertia ixx="0.000621497" ixy="-0.000000128" ixz="0.000008777" iyy="0.000564556" iyz="0.000001116" izz="0.000170804" />
    </inertial>
    <visual>
      <origin xyz="0 0 0" rpy="0 0 0" />
      <geometry>
        <mesh filename="package://x02_description/urdf/meshes/L_shoulder_pitch_link.STL" />
      </geometry>
      <material name="">
        <color rgba="1 1 1 1" />
      </material>
    </visual>
    <collision>
      <origin xyz="0 0 0" rpy="0 0 0" />
      <geometry>
        <mesh filename="package://x02_description/urdf/meshes/L_shoulder_pitch_link.STL" />
      </geometry>
    </collision>
  </link>
  <joint name="LShoulderPitch" type="revolute">
    <origin xyz="-0.01 0.14477 0.31534" rpy="0.17453 0.12 0" />
    <parent link="base_link" />
    <child link="L_shoulder_pitch_link" />
    <axis xyz="0 -1 0" />
    <limit lower="-2.66" upper="2.88" effort="24" velocity="37" />
  </joint>
  <link name="L_shoulder_roll_link">
    <inertial>
      <origin xyz="0.000056 -0.000273 -0.043319" rpy="0 0 0" />
      <mass value="0.704" />
      <inertia ixx="0.001450385" ixy="-0.000000085" ixz="-0.000005229" iyy="0.001502613" iyz="0.000008088" izz="0.000295478" />
    </inertial>
    <visual>
      <origin xyz="0 0 0" rpy="0 0 0" />
      <geometry>
        <mesh filename="package://x02_description/urdf/meshes/L_shoulder_roll_link.STL" />
      </geometry>
      <material name="">
        <color rgba="1 1 1 1" />
      </material>
    </visual>
    <collision>
      <origin xyz="0 0 0" rpy="0 0 0" />
      <geometry>
        <mesh filename="package://x02_description/urdf/meshes/L_shoulder_roll_link.STL" />
      </geometry>
    </collision>
  </link>
  <joint name="LShoulderRoll" type="revolute">
    <origin xyz="0 0.061 0" rpy="-0.17453 0 0" />
    <parent link="L_shoulder_pitch_link" />
    <child link="L_shoulder_roll_link" />
    <axis xyz="1 0 0" />
    <limit lower="-0.15" upper="3.54" effort="24" velocity="37" />
  </joint>
  <link name="L_shoulder_yaw_link">
    <inertial>
      <origin xyz="0.000230 -0.004330 -0.102049" rpy="0 0 0" />
      <mass value="0.523" />
      <inertia ixx="0.002033687" ixy="0.000000601" ixz="0.000003592" iyy="0.002073388" iyz="-0.000000601" izz="0.000293100" />
    </inertial>
    <visual>
      <origin xyz="0 0 0" rpy="0 0 0" />
      <geometry>
        <mesh filename="package://x02_description/urdf/meshes/L_shoulder_yaw_link.STL" />
      </geometry>
      <material name="">
        <color rgba="1 1 1 1" />
      </material>
    </visual>
    <collision>
      <origin xyz="0 0 0" rpy="0 0 0" />
      <geometry>
        <mesh filename="package://x02_description/urdf/meshes/L_shoulder_yaw_link.STL" />
      </geometry>
    </collision>
  </link>
  <joint name="LShoulderYaw" type="revolute">
    <origin xyz="0 0 -0.112" rpy="0 0 0" />
    <parent link="L_shoulder_roll_link" />
    <child link="L_shoulder_yaw_link" />
    <axis xyz="0 0 1" />
    <limit lower="-2.1" upper="2.25" effort="24" velocity="37" />
  </joint>
  <link name="L_elbow_pitch_link">
    <inertial>
      <origin xyz="-0.0123066 0 -0.13266023" rpy="0 0 0" />
      <mass value="0.24" />
      <inertia ixx="0.00247994" ixy="0.00000000" ixz="0.00000793" iyy="0.00246631" iyz="0.00000001" izz="0.00012575" />
    </inertial>
    <visual>
      <origin xyz="0 0 0" rpy="0 0 0" />
      <geometry>
        <mesh filename="package://x02_description/urdf/meshes/L_elbow_pitch_link.STL" />
      </geometry>
      <material name="">
        <color rgba="1 1 1 1" />
      </material>
    </visual>
    <collision>
      <origin xyz="0 0 0" rpy="0 0 0" />
      <geometry>
        <mesh filename="package://x02_description/urdf/meshes/L_elbow_pitch_link.STL" />
      </geometry>
    </collision>
  </link>
  <joint name="LElbow" type="revolute">
    <origin xyz="0.01 0 -0.173" rpy="0 -0.25 0" />
    <parent link="L_shoulder_yaw_link" />
    <child link="L_elbow_pitch_link" />
    <axis xyz="0 -1 0" />
    <limit lower="-0.25" upper="2.35" effort="24" velocity="37" />
  </joint>
  <link name="R_shoulder_pitch_link">
    <inertial>
      <origin xyz="0.000994 -0.000135 0.015061" rpy="0 0 0" />
      <mass value="0.3" />
      <inertia ixx="0.000621496" ixy="0.000000130" ixz="0.000008777" iyy="0.000564553" iyz="-0.000001116" izz="0.000170801" />
    </inertial>
    <visual>
      <origin xyz="0 0 0" rpy="0 0 0" />
      <geometry>
        <mesh filename="package://x02_description/urdf/meshes/R_shoulder_pitch_link.STL" />
      </geometry>
      <material name="">
        <color rgba="1 1 1 1" />
      </material>
    </visual>
    <collision>
      <origin xyz="0 0 0" rpy="0 0 0" />
      <geometry>
        <mesh filename="package://x02_description/urdf/meshes/R_shoulder_pitch_link.STL" />
      </geometry>
    </collision>
  </link>
  <joint name="RShoulderPitch" type="revolute">
    <origin xyz="-0.01 -0.14477 0.31534" rpy="-0.17453 0.12 0" />
    <parent link="base_link" />
    <child link="R_shoulder_pitch_link" />
    <axis xyz="0 -1 0" />
    <limit lower="-2.66" upper="2.88" effort="24" velocity="37" />
  </joint>
  <link name="R_shoulder_roll_link">
    <inertial>
      <origin xyz="0.000056 -0.000273 -0.043319" rpy="0 0 0" />
      <mass value="0.704" />
      <inertia ixx="0.001450385" ixy="-0.000000085" ixz="-0.000005229" iyy="0.001502613" iyz="0.000008088" izz="0.000295478" />
    </inertial>
    <visual>
      <origin xyz="0 0 0" rpy="0 0 0" />
      <geometry>
        <mesh filename="package://x02_description/urdf/meshes/R_shoulder_roll_link.STL" />
      </geometry>
      <material name="">
        <color rgba="1 1 1 1" />
      </material>
    </visual>
    <collision>
      <origin xyz="0 0 0" rpy="0 0 0" />
      <geometry>
        <mesh filename="package://x02_description/urdf/meshes/R_shoulder_roll_link.STL" />
      </geometry>
    </collision>
  </link>
  <joint name="RShoulderRoll" type="revolute">
    <origin xyz="0 -0.061 0" rpy="0.17453 0 0" />
    <parent link="R_shoulder_pitch_link" />
    <child link="R_shoulder_roll_link" />
    <axis xyz="-1 0 0" />
    <limit lower="-0.15" upper="3.54" effort="24" velocity="37"/>
  </joint>
  <link name="R_shoulder_yaw_link">
    <inertial>
      <origin xyz="0.000230 -0.004330 -0.102049" rpy="0 0 0" />
      <mass value="0.523" />
      <inertia ixx="0.002033687" ixy="0.000000601" ixz="0.000003592" iyy="0.002073388" iyz="-0.000000601" izz="0.000293100" />
    </inertial>
    <visual>
      <origin xyz="0 0 0" rpy="0 0 0" />
      <geometry>
        <mesh filename="package://x02_description/urdf/meshes/R_shoulder_yaw_link.STL" />
      </geometry>
      <material name="">
        <color rgba="1 1 1 1" />
      </material>
    </visual>
    <collision>
      <origin xyz="0 0 0" rpy="0 0 0" />
      <geometry>
        <mesh filename="package://x02_description/urdf/meshes/R_shoulder_yaw_link.STL" />
      </geometry>
    </collision>
  </link>
  <joint name="RShoulderYaw" type="revolute">
    <origin xyz="-3.8964E-05 0 -0.112" rpy="0 0 0" />
    <parent link="R_shoulder_roll_link" />
    <child link="R_shoulder_yaw_link" />
    <axis xyz="0 0 -1" />
    <limit lower="-2.1" upper="2.25" effort="24" velocity="37" />
  </joint>
  <link name="R_elbow_pitch_link">
    <inertial>
      <origin xyz="-0.0123066 0 -0.13266023" rpy="0 0 0" />
      <mass value="0.24" /> <!--0.1-->
      <inertia ixx="0.00247994" ixy="0.00000000" ixz="0.00000793" iyy="0.00246631" iyz="0.00000001" izz="0.00012575" />
    </inertial>
    <visual>
      <origin xyz="0 0 0" rpy="0 0 0" />
      <geometry>
        <mesh filename="package://x02_description/urdf/meshes/R_elbow_pitch_link.STL" />
      </geometry>
      <material name="">
        <color rgba="1 1 1 1" />
      </material>
    </visual>
    <collision>
      <origin xyz="0 0 0" rpy="0 0 0" />
      <geometry>
        <mesh filename="package://x02_description/urdf/meshes/R_elbow_pitch_link.STL" />
      </geometry>
    </collision>
  </link>
  <joint name="RElbow" type="revolute">
    <origin xyz="0.010039 0 -0.173" rpy="0 -0.25 0" />
    <parent link="R_shoulder_yaw_link" />
    <child link="R_elbow_pitch_link" />
    <axis xyz="0 -1 0" />
    <limit lower="-0.25" upper="2.35" effort="24" velocity="37" />
  </joint>
  <link name="imu_frame_uncalibrated"/>
  <joint name="imu_frame_uncalibrated_joint" type="fixed">
    <origin xyz="0.0 0 0.0" rpy="0 0 0" />
    <parent link="base_link" />
    <child link="imu_frame_uncalibrated" />
  </joint>
  <link name="camera_frame_uncalibrated"/>
  <joint name="camera_frame_uncalibrated_joint" type="fixed">
    <origin xyz="0.085 0.0 0.43" rpy="0 1.035398163 0" />
    <parent link="base_link" />
    <child link="camera_frame_uncalibrated" />
  </joint>
  <link name="camera_optical_frame_uncalibrated"/>
  <joint name="camera_optical_frame_uncalibrated_joint" type="fixed">
    <origin xyz="0.0 0.0 0.0" rpy="-1.570796327 0 -1.570796327" />
    <parent link="camera_frame_uncalibrated" />
    <child link="camera_optical_frame_uncalibrated" />
  </joint>
</robot>
